Workbook
Name json_path: Config!$B$2

Sheet Config
A1: Setting | B1: Value
A2: json_path | B2: C:\Projects\03-Finance\ai-fund\data\exports\generated\ticker\OPCH\20260606-231710-xlsx-50e54f4b\OPCH_latest.json
A4: Instructions:
A5: 1. Change B2 to point at a different ticker (e.g. ORCL_latest.json)
A6: 2. Data → Refresh All (Ctrl+Alt+F5)
A7: 3. All Assumptions Col B values update from the new JSON.
A8: 4. The path must match what batch_runner --json last wrote.

Sheet Cover
B4: EQUITY VALUATION MODEL
B5: IBM — International Business Machines Corporation
B7: Sector | C7: Technology
B8: As of | C8: 2026-03-09
B9: Price | C9: $253.33
B10: EV ($mm) | C10: $293,093
B11: Shares | C11: 948.7mm
B12: Model | C12: DCF Bear / Base / Bull + Comps + EP cross-check
B14: Sheet Guide
B15: Assumptions — All inputs with JSON baseline + PM override column (yellow)
B16: DCF_Base — 10-year FCFF projection, live formulas, Base scenario
B17: DCF_Bear — Bear scenario (growth ×0.6, margin ×0.75, WACC +200bp)
B18: DCF_Bull — Bull scenario (growth ×1.4, margin ×1.15, WACC -100bp)
B19: Equity_Bridge— Enterprise → Equity value, IV per share, expected IV
B20: Comps — Peer multiples table, live medians, exclude toggle
B21: Sensitivity — IV grid: WACC × terminal growth (±200bp each)
B22: QoE — Quality of Earnings signals (Sloan, cash conv, NWC drift)
B23: Output — Summary dashboard with colour-coded upside flags
B25: Override pattern: Col B = JSON baseline (blue) | Col C = PM override (yellow, type here) | Col D = Active (formula: =IF(C="",B,C))
B26: Press F9 to recalculate all formulas after editing.

Sheet Assumptions
A1: Driver | B1: JSON Baseline | C1: PM Override | D1: Active | E1: Source
A2: MARKET DATA | C2: ← Type override here (yellow cells)
A3: DCF GROWTH DRIVERS | B3: 66799 | D3: =IF(C3="",B3,C3) | E3: CIQ
A4: Revenue Growth — Near (Y1–Y5) | B4: 0.065728103 | D4: =IF(C4="",B4,C4) | E4: CIQ consensus
A5: Revenue Growth — Mid (Y6–Y10) | B5: 0.046009672 | D5: =IF(C5="",B5,C5) | E5: CIQ consensus blend
A6: Terminal Revenue Growth | B6: 0.035 | D6: =IF(C6="",B6,C6) | E6: GDP anchor
A7: MARGIN DRIVERS
A8: EBIT Margin — Start | B8: 0.12543194 | D8: =IF(C8="",B8,C8) | E8: CIQ LTM
A9: EBIT Margin — Target (Y10) | B9: 0.2 | D9: =IF(C9="",B9,C9) | E9: Sector median
A10: D&A / CAPEX
A11: D&A % Revenue | B11: 0.011273167 | D11: =IF(C11="",B11,C11) | E11: CIQ LTM
A12: Capex % Revenue | B12: 0.016061013 | D12: =IF(C12="",B12,C12) | E12: CIQ LTM
A13: TAX
A14: Effective Tax Rate — Start | B14: 0.14741124 | D14: =IF(C14="",B14,C14) | E14: CIQ LTM
A15: Effective Tax Rate — Target | B15: 0.15 | D15: =IF(C15="",B15,C15) | E15: Company guidance
A16: WORKING CAPITAL DRIVERS
A17: DSO Start (days) | B17: 47 | D17: =IF(C17="",B17,C17) | E17: CIQ LTM
A18: DSO Target (days) | B18: 45.6 | D18: =IF(C18="",B18,C18) | E18: Sector median
A19: DIO Start (days) | B19: 6.7 | D19: =IF(C19="",B19,C19) | E19: CIQ LTM
A20: DIO Target (days) | B20: 26.51 | D20: =IF(C20="",B20,C20) | E20: Sector median
A21: DPO Start (days) | B21: 26 | D21: =IF(C21="",B21,C21) | E21: CIQ LTM
A22: DPO Target (days) | B22: 34.4 | D22: =IF(C22="",B22,C22) | E22: Sector median
A23: TERMINAL VALUE
A24: Exit Multiple (EV/EBITDA) | B24: 7.8924 | D24: =IF(C24="",B24,C24) | E24: Forward comps
A25: RONIC Terminal | B25: 0.15 | D25: =IF(C25="",B25,C25) | E25: ROIC estimate
A26: WACC BUILD-UP
A27: Risk-Free Rate | B27: 0.045 | D27: =IF(C27="",B27,C27) | E27: 10Y UST
A28: Equity Risk Premium | B28: 0.05 | D28: =IF(C28="",B28,C28) | E28: Damodaran
A29: Beta (re-levered) | B29: 0.71 | D29: =IF(C29="",B29,C29) | E29: Hamada / peers
A30: Size Premium | B30: 0 | D30: =IF(C30="",B30,C30) | E30: Duff & Phelps
A31: Cost of Equity (Ke) | B31: 0.0803 | D31: =IF(C31="",D27+D29*D28+D30,C31) | E31: CAPM: Rf + β×ERP + size premium
A32: Cost of Debt (pre-tax) | B32: 0.027804687 | D32: =IF(C32="",B32,C32) | E32: Interest expense / total debt (CIQ)
A33: Tax Rate (for Kd) | D33: =D14 | E33: =Assumptions D14
A34: Cost of Debt after-tax (Kd) | B34: 0.023705963 | D34: =IF(C34="",D32*(1-D33),C34) | E34: Kd × (1 - tax)
A35: Equity Weight | B35: 0.8256 | D35: =IF(C35="",B35,C35) | E35: Market cap / TEV
A36: Debt Weight | B36: 0.1744 | D36: =IF(C36="",B36,C36) | E36: Net debt / TEV
A37: WACC | B37: 0.07043 | D37: =IF(C37="",B37,C37) | E37: JSON baseline (batch_runner) — override C37 to adjust
A38: EQUITY BRIDGE ITEMS ($mm)
A39: Net Debt ($mm) | B39: 51020 | D39: =IF(C39="",B39,C39) | E39: CIQ balance sheet
A40: Shares Outstanding (mm) | B40: 948.675 | D40: =IF(C40="",B40,C40) | E40: CIQ
...

Sheet DCF_Base
A1: IBM — BASE SCENARIO | IBM Valuation
A2: 10-YEAR FCFF PROJECTION ($mm) | B2: LTM | C2: Y1 | D2: Y2 | E2: Y3 | F2: Y4 | G2: Y5 | H2: Y6 | I2: Y7 | J2: Y8 | K2: Y9 | L2: Y10 | M2: Terminal
A3: ── REVENUE ─────────────────────────────────
A4: Revenue ($mm) | B4: =Assumptions!$D$3 | C4: =B4*(1+Assumptions!$D$4) | D4: =C4*(1+Assumptions!$D$4) | E4: =D4*(1+Assumptions!$D$4) | F4: =E4*(1+Assumptions!$D$4) | G4: =F4*(1+Assumptions!$D$4) | H4: =G4*(1+Assumptions!$D$5) | I4: =H4*(1+Assumptions!$D$5) | J4: =I4*(1+Assumptions!$D$5) | K4: =J4*(1+Assumptions!$D$5) | L4: =K4*(1+Assumptions!$D$5) | M4: =L4*(1+Assumptions!$D$6)
A5: Revenue Growth % | C5: =C4/B4-1 | D5: =D4/C4-1 | E5: =E4/D4-1 | F5: =F4/E4-1 | G5: =G4/F4-1 | H5: =H4/G4-1 | I5: =I4/H4-1 | J5: =J4/I4-1 | ... M5: =M4/L4-1
A6: ── PROFITABILITY ────────────────────────────
A7: EBIT Margin % | C7: =Assumptions!$D$8+(Assumptions!$D$9-Assumptions!$D$8)*(COLUMN()-2)/10 | D7: =Assumptions!$D$8+(Assumptions!$D$9-Assumptions!$D$8)*(COLUMN()-2)/10 | E7: =Assumptions!$D$8+(Assumptions!$D$9-Assumptions!$D$8)*(COLUMN()-2)/10 | F7: =Assumptions!$D$8+(Assumptions!$D$9-Assumptions!$D$8)*(COLUMN()-2)/10 | G7: =Assumptions!$D$8+(Assumptions!$D$9-Assumptions!$D$8)*(COLUMN()-2)/10 | H7: =Assumptions!$D$8+(Assumptions!$D$9-Assumptions!$D$8)*(COLUMN()-2)/10 | I7: =Assumptions!$D$8+(Assumptions!$D$9-Assumptions!$D$8)*(COLUMN()-2)/10 | J7: =Assumptions!$D$8+(Assumptions!$D$9-Assumptions!$D$8)*(COLUMN()-2)/10 | ... L7: =Assumptions!$D$8+(Assumptions!$D$9-Assumptions!$D$8)*(COLUMN()-2)/10 | M7: =Assumptions!$D$9
A8: EBIT ($mm) | C8: =C4*C7 | D8: =D4*D7 | E8: =E4*E7 | F8: =F4*F7 | G8: =G4*G7 | H8: =H4*H7 | I8: =I4*I7 | J8: =J4*J7 | ... M8: =M4*M7
A9: EBITDA ($mm) | C9: =C8+C14 | D9: =D8+D14 | E9: =E8+E14 | F9: =F8+F14 | G9: =G8+G14 | H9: =H8+H14 | I9: =I8+I14 | J9: =J8+J14 | ... M9: =M8+M14
A10: Tax Rate % | C10: =Assumptions!$D$14+(Assumptions!$D$15-Assumptions!$D$14)*(COLUMN()-2)/10 | D10: =Assumptions!$D$14+(Assumptions!$D$15-Assumptions!$D$14)*(COLUMN()-2)/10 | E10: =Assumptions!$D$14+(Assumptions!$D$15-Assumptions!$D$14)*(COLUMN()-2)/10 | F10: =Assumptions!$D$14+(Assumptions!$D$15-Assumptions!$D$14)*(COLUMN()-2)/10 | G10: =Assumptions!$D$14+(Assumptions!$D$15-Assumptions!$D$14)*(COLUMN()-2)/10 | H10: =Assumptions!$D$14+(Assumptions!$D$15-Assumptions!$D$14)*(COLUMN()-2)/10 | I10: =Assumptions!$D$14+(Assumptions!$D$15-Assumptions!$D$14)*(COLUMN()-2)/10 | J10: =Assumptions!$D$14+(Assumptions!$D$15-Assumptions!$D$14)*(COLUMN()-2)/10 | ... L10: =Assumptions!$D$14+(Assumptions!$D$15-Assumptions!$D$14)*(COLUMN()-2)/10 | M10: =Assumptions!$D$15
A11: NOPAT ($mm) | C11: =C8*(1-C10) | D11: =D8*(1-D10) | E11: =E8*(1-E10) | F11: =F8*(1-F10) | G11: =G8*(1-G10) | H11: =H8*(1-H10) | I11: =I8*(1-I10) | J11: =J8*(1-J10) | ... M11: =M8*(1-M10)
A12: ── D&A / CAPEX ──────────────────────────────
A13: D&A % Revenue | B13: =Assumptions!$D$11 | C13: =Assumptions!$D$11 | D13: =Assumptions!$D$11 | E13: =Assumptions!$D$11 | F13: =Assumptions!$D$11 | G13: =Assumptions!$D$11 | H13: =Assumptions!$D$11 | I13: =Assumptions!$D$11 | ... M13: =Assumptions!$D$11
A14: D&A ($mm) | C14: =C4*C13 | D14: =D4*D13 | E14: =E4*E13 | F14: =F4*F13 | G14: =G4*G13 | H14: =H4*H13 | I14: =I4*I13 | J14: =J4*J13 | ... M14: =M4*M13
A15: Capex % Revenue | B15: =Assumptions!$D$12 | C15: =Assumptions!$D$12 | D15: =Assumptions!$D$12 | E15: =Assumptions!$D$12 | F15: =Assumptions!$D$12 | G15: =Assumptions!$D$12 | H15: =Assumptions!$D$12 | I15: =Assumptions!$D$12 | ... L15: =Assumptions!$D$12
A16: Capex ($mm) | C16: =C4*C15 | D16: =D4*D15 | E16: =E4*E15 | F16: =F4*F15 | G16: =G4*G15 | H16: =H4*H15 | I16: =I4*I15 | J16: =J4*J15 | ... L16: =L4*L15
A17: ── NWC DRIVERS ──────────────────────────────
A18: DSO (days) | B18: =Assumptions!$D$17 | C18: =Assumptions!$D$17+(Assumptions!$D$18-Assumptions!$D$17)*(COLUMN()-2)/10 | D18: =Assumptions!$D$17+(Assumptions!$D$18-Assumptions!$D$17)*(COLUMN()-2)/10 | E18: =Assumptions!$D$17+(Assumptions!$D$18-Assumptions!$D$17)*(COLUMN()-2)/10 | F18: =Assumptions!$D$17+(Assumptions!$D$18-Assumptions!$D$17)*(COLUMN()-2)/10 | G18: =Assumptions!$D$17+(Assumptions!$D$18-Assumptions!$D$17)*(COLUMN()-2)/10 | H18: =Assumptions!$D$17+(Assumptions!$D$18-Assumptions!$D$17)*(COLUMN()-2)/10 | I18: =Assumptions!$D$17+(Assumptions!$D$18-Assumptions!$D$17)*(COLUMN()-2)/10 | J18: =Assumptions!$D$17+(Assumptions!$D$18-Assumptions!$D$17)*(COLUMN()-2)/10 | ... L18: =Assumptions!$D$17+(Assumptions!$D$18-Assumptions!$D$17)*(COLUMN()-2)/10
A19: DIO (days) | B19: =Assumptions!$D$19 | C19: =Assumptions!$D$19+(Assumptions!$D$20-Assumptions!$D$19)*(COLUMN()-2)/10 | D19: =Assumptions!$D$19+(Assumptions!$D$20-Assumptions!$D$19)*(COLUMN()-2)/10 | E19: =Assumptions!$D$19+(Assumptions!$D$20-Assumptions!$D$19)*(COLUMN()-2)/10 | F19: =Assumptions!$D$19+(Assumptions!$D$20-Assumptions!$D$19)*(COLUMN()-2)/10 | G19: =Assumptions!$D$19+(Assumptions!$D$20-Assumptions!$D$19)*(COLUMN()-2)/10 | H19: =Assumptions!$D$19+(Assumptions!$D$20-Assumptions!$D$19)*(COLUMN()-2)/10 | I19: =Assumptions!$D$19+(Assumptions!$D$20-Assumptions!$D$19)*(COLUMN()-2)/10 | J19: =Assumptions!$D$19+(Assumptions!$D$20-Assumptions!$D$19)*(COLUMN()-2)/10 | ... L19: =Assumptions!$D$19+(Assumptions!$D$20-Assumptions!$D$19)*(COLUMN()-2)/10
A20: DPO (days) | B20: =Assumptions!$D$21 | C20: =Assumptions!$D$21+(Assumptions!$D$22-Assumptions!$D$21)*(COLUMN()-2)/10 | D20: =Assumptions!$D$21+(Assumptions!$D$22-Assumptions!$D$21)*(COLUMN()-2)/10 | E20: =Assumptions!$D$21+(Assumptions!$D$22-Assumptions!$D$21)*(COLUMN()-2)/10 | F20: =Assumptions!$D$21+(Assumptions!$D$22-Assumptions!$D$21)*(COLUMN()-2)/10 | G20: =Assumptions!$D$21+(Assumptions!$D$22-Assumptions!$D$21)*(COLUMN()-2)/10 | H20: =Assumptions!$D$21+(Assumptions!$D$22-Assumptions!$D$21)*(COLUMN()-2)/10 | I20: =Assumptions!$D$21+(Assumptions!$D$22-Assumptions!$D$21)*(COLUMN()-2)/10 | J20: =Assumptions!$D$21+(Assumptions!$D$22-Assumptions!$D$21)*(COLUMN()-2)/10 | ... L20: =Assumptions!$D$21+(Assumptions!$D$22-Assumptions!$D$21)*(COLUMN()-2)/10
A21: AR ($mm) | B21: =B4/365*B18 | C21: =C4/365*C18 | D21: =D4/365*D18 | E21: =E4/365*E18 | F21: =F4/365*F18 | G21: =G4/365*G18 | H21: =H4/365*H18 | I21: =I4/365*I18 | ... L21: =L4/365*L18
A22: Inventory ($mm) | B22: =B4/365*B19 | C22: =C4/365*C19 | D22: =D4/365*D19 | E22: =E4/365*E19 | F22: =F4/365*F19 | G22: =G4/365*G19 | H22: =H4/365*H19 | I22: =I4/365*I19 | ... L22: =L4/365*L19
A23: AP ($mm) | B23: =B4/365*B20 | C23: =C4/365*C20 | D23: =D4/365*D20 | E23: =E4/365*E20 | F23: =F4/365*F20 | G23: =G4/365*G20 | H23: =H4/365*H20 | I23: =I4/365*I20 | ... L23: =L4/365*L20
A24: NWC ($mm) | B24: =B21+B22-B23 | C24: =C21+C22-C23 | D24: =D21+D22-D23 | E24: =E21+E22-E23 | F24: =F21+F22-F23 | G24: =G21+G22-G23 | H24: =H21+H22-H23 | I24: =I21+I22-I23 | ... L24: =L21+L22-L23
A25: ΔNWC ($mm) | C25: =C24-B24 | D25: =D24-C24 | E25: =E24-D24 | F25: =F24-E24 | G25: =G24-F24 | H25: =H24-G24 | I25: =I24-H24 | J25: =J24-I24 | ... L25: =L24-K24
A26: ── FREE CASH FLOW ───────────────────────────
A27: FCFF ($mm) | C27: =C11+C14-C16-C25 | D27: =D11+D14-D16-D25 | E27: =E11+E14-E16-E25 | F27: =F11+F14-F16-F25 | G27: =G11+G14-G16-G25 | H27: =H11+H14-H16-H25 | I27: =I11+I14-I16-I25 | J27: =J11+J14-J16-J25 | ... L27: =L11+L14-L16-L25
A28: Discount Factor | C28: =1/(1+Assumptions!$D$37)^1 | D28: =1/(1+Assumptions!$D$37)^2 | E28: =1/(1+Assumptions!$D$37)^3 | F28: =1/(1+Assumptions!$D$37)^4 | G28: =1/(1+Assumptions!$D$37)^5 | H28: =1/(1+Assumptions!$D$37)^6 | I28: =1/(1+Assumptions!$D$37)^7 | J28: =1/(1+Assumptions!$D$37)^8 | K28: =1/(1+Assumptions!$D$37)^9 | L28: =1/(1+Assumptions!$D$37)^10 | M28: =1/(1+Assumptions!$D$37)^10
A29: PV FCFF ($mm) | C29: =C27*C28 | D29: =D27*D28 | E29: =E27*E28 | F29: =F27*F28 | G29: =G27*G28 | H29: =H27*H28 | I29: =I27*I28 | J29: =J27*J28 | ... L29: =L27*L28
A30: Cumulative PV FCFF ($mm) | C30: =C29 | D30: =C30+D29 | E30: =D30+E29 | F30: =E30+F29 | G30: =F30+G29 | H30: =G30+H29 | I30: =H30+I29 | J30: =I30+J29 | K30: =J30+K29 | L30: =K30+L29
A31: ── RETURNS ──────────────────────────────────
A32: Invested Capital ($mm) | B32: =Assumptions!$D$41 | C32: =B32+C16+C25-C14 | D32: =C32+D16+D25-D14 | E32: =D32+E16+E25-E14 | F32: =E32+F16+F25-F14 | G32: =F32+G16+G25-G14 | H32: =G32+H16+H25-H14 | I32: =H32+I16+I25-I14 | J32: =I32+J16+J25-J14 | ... L32: =K32+L16+L25-L14
A33: ROIC % | C33: =C11/B32 | D33: =D11/C32 | E33: =E11/D32 | F33: =F11/E32 | G33: =G11/F32 | H33: =H11/G32 | I33: =I11/H32 | J33: =J11/I32 | ... L33: =L11/K32
A34: Economic Profit ($mm) | C34: =C11-B32*Assumptions!$D$37 | D34: =D11-C32*Assumptions!$D$37 | E34: =E11-D32*Assumptions!$D$37 | F34: =F11-E32*Assumptions!$D$37 | G34: =G11-F32*Assumptions!$D$37 | H34: =H11-G32*Assumptions!$D$37 | I34: =I11-H32*Assumptions!$D$37 | J34: =J11-I32*Assumptions!$D$37 | ... L34: =L11-K32*Assumptions!$D$37
A35: TERMINAL VALUE & EV SUMMARY
A36: Gordon Growth TV ($mm) | M36: =IF(Assumptions!$D$37>Assumptions!$D$6,M11*(1-Assumptions!$D$6/Assumptions!$D$25)/(Assumptions!$D$37-Assumptions!$D$6),0)
A37: Exit Multiple TV ($mm) | M37: =L9*Assumptions!$D$24
A38: Blended TV ($mm) | M38: =(M36+M37)/2
A39: PV of Blended TV ($mm) | M39: =M38*L28
A41: Sum PV FCFF ($mm) | M41: =L30
...

Sheet DCF_Bear
A1: IBM — BEAR SCENARIO | IBM Valuation
A2: SCENARIO PARAMETERS
A3: Growth Multiplier | B3: 0.6
A4: EBIT Margin Multiplier | B4: 0.75
A5: Capex Multiplier | B5: 1.2
A6: WACC Adjustment (add) | B6: 0.02
A7: Exit Multiple Multiplier | B7: 0.7
A9: 10-YEAR FCFF PROJECTION ($mm) | B9: LTM | C9: Y1 | D9: Y2 | E9: Y3 | F9: Y4 | G9: Y5 | H9: Y6 | I9: Y7 | J9: Y8 | K9: Y9 | L9: Y10 | M9: Terminal
A10: ── REVENUE ─────────────────────────────────
A11: Revenue ($mm) | B11: =Assumptions!$D$3 | C11: =B11*(1+Assumptions!$D$4*$B$3) | D11: =C11*(1+Assumptions!$D$4*$B$3) | E11: =D11*(1+Assumptions!$D$4*$B$3) | F11: =E11*(1+Assumptions!$D$4*$B$3) | G11: =F11*(1+Assumptions!$D$4*$B$3) | H11: =G11*(1+Assumptions!$D$5*$B$3) | I11: =H11*(1+Assumptions!$D$5*$B$3) | J11: =I11*(1+Assumptions!$D$5*$B$3) | K11: =J11*(1+Assumptions!$D$5*$B$3) | L11: =K11*(1+Assumptions!$D$5*$B$3) | M11: =L11*(1+Assumptions!$D$6)
A12: Revenue Growth % | C12: =C11/B11-1 | D12: =D11/C11-1 | E12: =E11/D11-1 | F12: =F11/E11-1 | G12: =G11/F11-1 | H12: =H11/G11-1 | I12: =I11/H11-1 | J12: =J11/I11-1 | ... M12: =M11/L11-1
A13: ── PROFITABILITY ────────────────────────────
A14: EBIT Margin % | C14: =Assumptions!$D$8+(Assumptions!$D$9*$B$4-Assumptions!$D$8)*(COLUMN()-2)/10 | D14: =Assumptions!$D$8+(Assumptions!$D$9*$B$4-Assumptions!$D$8)*(COLUMN()-2)/10 | E14: =Assumptions!$D$8+(Assumptions!$D$9*$B$4-Assumptions!$D$8)*(COLUMN()-2)/10 | F14: =Assumptions!$D$8+(Assumptions!$D$9*$B$4-Assumptions!$D$8)*(COLUMN()-2)/10 | G14: =Assumptions!$D$8+(Assumptions!$D$9*$B$4-Assumptions!$D$8)*(COLUMN()-2)/10 | H14: =Assumptions!$D$8+(Assumptions!$D$9*$B$4-Assumptions!$D$8)*(COLUMN()-2)/10 | I14: =Assumptions!$D$8+(Assumptions!$D$9*$B$4-Assumptions!$D$8)*(COLUMN()-2)/10 | J14: =Assumptions!$D$8+(Assumptions!$D$9*$B$4-Assumptions!$D$8)*(COLUMN()-2)/10 | ... L14: =Assumptions!$D$8+(Assumptions!$D$9*$B$4-Assumptions!$D$8)*(COLUMN()-2)/10 | M14: =Assumptions!$D$9
A15: EBIT ($mm) | C15: =C11*C14 | D15: =D11*D14 | E15: =E11*E14 | F15: =F11*F14 | G15: =G11*G14 | H15: =H11*H14 | I15: =I11*I14 | J15: =J11*J14 | ... M15: =M11*M14
A16: EBITDA ($mm) | C16: =C15+C21 | D16: =D15+D21 | E16: =E15+E21 | F16: =F15+F21 | G16: =G15+G21 | H16: =H15+H21 | I16: =I15+I21 | J16: =J15+J21 | ... M16: =M15+M21
A17: Tax Rate % | C17: =Assumptions!$D$14+(Assumptions!$D$15-Assumptions!$D$14)*(COLUMN()-2)/10 | D17: =Assumptions!$D$14+(Assumptions!$D$15-Assumptions!$D$14)*(COLUMN()-2)/10 | E17: =Assumptions!$D$14+(Assumptions!$D$15-Assumptions!$D$14)*(COLUMN()-2)/10 | F17: =Assumptions!$D$14+(Assumptions!$D$15-Assumptions!$D$14)*(COLUMN()-2)/10 | G17: =Assumptions!$D$14+(Assumptions!$D$15-Assumptions!$D$14)*(COLUMN()-2)/10 | H17: =Assumptions!$D$14+(Assumptions!$D$15-Assumptions!$D$14)*(COLUMN()-2)/10 | I17: =Assumptions!$D$14+(Assumptions!$D$15-Assumptions!$D$14)*(COLUMN()-2)/10 | J17: =Assumptions!$D$14+(Assumptions!$D$15-Assumptions!$D$14)*(COLUMN()-2)/10 | ... L17: =Assumptions!$D$14+(Assumptions!$D$15-Assumptions!$D$14)*(COLUMN()-2)/10 | M17: =Assumptions!$D$15
A18: NOPAT ($mm) | C18: =C15*(1-C17) | D18: =D15*(1-D17) | E18: =E15*(1-E17) | F18: =F15*(1-F17) | G18: =G15*(1-G17) | H18: =H15*(1-H17) | I18: =I15*(1-I17) | J18: =J15*(1-J17) | ... M18: =M15*(1-M17)
A19: ── D&A / CAPEX ──────────────────────────────
A20: D&A % Revenue | B20: =Assumptions!$D$11 | C20: =Assumptions!$D$11 | D20: =Assumptions!$D$11 | E20: =Assumptions!$D$11 | F20: =Assumptions!$D$11 | G20: =Assumptions!$D$11 | H20: =Assumptions!$D$11 | I20: =Assumptions!$D$11 | ... M20: =Assumptions!$D$11
A21: D&A ($mm) | C21: =C11*C20 | D21: =D11*D20 | E21: =E11*E20 | F21: =F11*F20 | G21: =G11*G20 | H21: =H11*H20 | I21: =I11*I20 | J21: =J11*J20 | ... M21: =M11*M20
A22: Capex % Revenue | B22: =Assumptions!$D$12 | C22: =Assumptions!$D$12*$B$5 | D22: =Assumptions!$D$12*$B$5 | E22: =Assumptions!$D$12*$B$5 | F22: =Assumptions!$D$12*$B$5 | G22: =Assumptions!$D$12*$B$5 | H22: =Assumptions!$D$12*$B$5 | I22: =Assumptions!$D$12*$B$5 | J22: =Assumptions!$D$12*$B$5 | ... L22: =Assumptions!$D$12*$B$5
A23: Capex ($mm) | C23: =C11*C22 | D23: =D11*D22 | E23: =E11*E22 | F23: =F11*F22 | G23: =G11*G22 | H23: =H11*H22 | I23: =I11*I22 | J23: =J11*J22 | ... L23: =L11*L22
A24: ── NWC DRIVERS ──────────────────────────────
A25: DSO (days) | B25: =Assumptions!$D$17 | C25: =Assumptions!$D$17+(Assumptions!$D$18-Assumptions!$D$17)*(COLUMN()-2)/10 | D25: =Assumptions!$D$17+(Assumptions!$D$18-Assumptions!$D$17)*(COLUMN()-2)/10 | E25: =Assumptions!$D$17+(Assumptions!$D$18-Assumptions!$D$17)*(COLUMN()-2)/10 | F25: =Assumptions!$D$17+(Assumptions!$D$18-Assumptions!$D$17)*(COLUMN()-2)/10 | G25: =Assumptions!$D$17+(Assumptions!$D$18-Assumptions!$D$17)*(COLUMN()-2)/10 | H25: =Assumptions!$D$17+(Assumptions!$D$18-Assumptions!$D$17)*(COLUMN()-2)/10 | I25: =Assumptions!$D$17+(Assumptions!$D$18-Assumptions!$D$17)*(COLUMN()-2)/10 | J25: =Assumptions!$D$17+(Assumptions!$D$18-Assumptions!$D$17)*(COLUMN()-2)/10 | ... L25: =Assumptions!$D$17+(Assumptions!$D$18-Assumptions!$D$17)*(COLUMN()-2)/10
A26: DIO (days) | B26: =Assumptions!$D$19 | C26: =Assumptions!$D$19+(Assumptions!$D$20-Assumptions!$D$19)*(COLUMN()-2)/10 | D26: =Assumptions!$D$19+(Assumptions!$D$20-Assumptions!$D$19)*(COLUMN()-2)/10 | E26: =Assumptions!$D$19+(Assumptions!$D$20-Assumptions!$D$19)*(COLUMN()-2)/10 | F26: =Assumptions!$D$19+(Assumptions!$D$20-Assumptions!$D$19)*(COLUMN()-2)/10 | G26: =Assumptions!$D$19+(Assumptions!$D$20-Assumptions!$D$19)*(COLUMN()-2)/10 | H26: =Assumptions!$D$19+(Assumptions!$D$20-Assumptions!$D$19)*(COLUMN()-2)/10 | I26: =Assumptions!$D$19+(Assumptions!$D$20-Assumptions!$D$19)*(COLUMN()-2)/10 | J26: =Assumptions!$D$19+(Assumptions!$D$20-Assumptions!$D$19)*(COLUMN()-2)/10 | ... L26: =Assumptions!$D$19+(Assumptions!$D$20-Assumptions!$D$19)*(COLUMN()-2)/10
A27: DPO (days) | B27: =Assumptions!$D$21 | C27: =Assumptions!$D$21+(Assumptions!$D$22-Assumptions!$D$21)*(COLUMN()-2)/10 | D27: =Assumptions!$D$21+(Assumptions!$D$22-Assumptions!$D$21)*(COLUMN()-2)/10 | E27: =Assumptions!$D$21+(Assumptions!$D$22-Assumptions!$D$21)*(COLUMN()-2)/10 | F27: =Assumptions!$D$21+(Assumptions!$D$22-Assumptions!$D$21)*(COLUMN()-2)/10 | G27: =Assumptions!$D$21+(Assumptions!$D$22-Assumptions!$D$21)*(COLUMN()-2)/10 | H27: =Assumptions!$D$21+(Assumptions!$D$22-Assumptions!$D$21)*(COLUMN()-2)/10 | I27: =Assumptions!$D$21+(Assumptions!$D$22-Assumptions!$D$21)*(COLUMN()-2)/10 | J27: =Assumptions!$D$21+(Assumptions!$D$22-Assumptions!$D$21)*(COLUMN()-2)/10 | ... L27: =Assumptions!$D$21+(Assumptions!$D$22-Assumptions!$D$21)*(COLUMN()-2)/10
A28: AR ($mm) | B28: =B11/365*B25 | C28: =C11/365*C25 | D28: =D11/365*D25 | E28: =E11/365*E25 | F28: =F11/365*F25 | G28: =G11/365*G25 | H28: =H11/365*H25 | I28: =I11/365*I25 | ... L28: =L11/365*L25
A29: Inventory ($mm) | B29: =B11/365*B26 | C29: =C11/365*C26 | D29: =D11/365*D26 | E29: =E11/365*E26 | F29: =F11/365*F26 | G29: =G11/365*G26 | H29: =H11/365*H26 | I29: =I11/365*I26 | ... L29: =L11/365*L26
A30: AP ($mm) | B30: =B11/365*B27 | C30: =C11/365*C27 | D30: =D11/365*D27 | E30: =E11/365*E27 | F30: =F11/365*F27 | G30: =G11/365*G27 | H30: =H11/365*H27 | I30: =I11/365*I27 | ... L30: =L11/365*L27
A31: NWC ($mm) | B31: =B28+B29-B30 | C31: =C28+C29-C30 | D31: =D28+D29-D30 | E31: =E28+E29-E30 | F31: =F28+F29-F30 | G31: =G28+G29-G30 | H31: =H28+H29-H30 | I31: =I28+I29-I30 | ... L31: =L28+L29-L30
A32: ΔNWC ($mm) | C32: =C31-B31 | D32: =D31-C31 | E32: =E31-D31 | F32: =F31-E31 | G32: =G31-F31 | H32: =H31-G31 | I32: =I31-H31 | J32: =J31-I31 | ... L32: =L31-K31
A33: ── FREE CASH FLOW ───────────────────────────
A34: FCFF ($mm) | C34: =C18+C21-C23-C32 | D34: =D18+D21-D23-D32 | E34: =E18+E21-E23-E32 | F34: =F18+F21-F23-F32 | G34: =G18+G21-G23-G32 | H34: =H18+H21-H23-H32 | I34: =I18+I21-I23-I32 | J34: =J18+J21-J23-J32 | ... L34: =L18+L21-L23-L32
A35: Discount Factor | C35: =1/(1+(Assumptions!$D$37+$B$6))^1 | D35: =1/(1+(Assumptions!$D$37+$B$6))^2 | E35: =1/(1+(Assumptions!$D$37+$B$6))^3 | F35: =1/(1+(Assumptions!$D$37+$B$6))^4 | G35: =1/(1+(Assumptions!$D$37+$B$6))^5 | H35: =1/(1+(Assumptions!$D$37+$B$6))^6 | I35: =1/(1+(Assumptions!$D$37+$B$6))^7 | J35: =1/(1+(Assumptions!$D$37+$B$6))^8 | K35: =1/(1+(Assumptions!$D$37+$B$6))^9 | L35: =1/(1+(Assumptions!$D$37+$B$6))^10 | M35: =1/(1+(Assumptions!$D$37+$B$6))^10
A36: PV FCFF ($mm) | C36: =C34*C35 | D36: =D34*D35 | E36: =E34*E35 | F36: =F34*F35 | G36: =G34*G35 | H36: =H34*H35 | I36: =I34*I35 | J36: =J34*J35 | ... L36: =L34*L35
A37: Cumulative PV FCFF ($mm) | C37: =C36 | D37: =C37+D36 | E37: =D37+E36 | F37: =E37+F36 | G37: =F37+G36 | H37: =G37+H36 | I37: =H37+I36 | J37: =I37+J36 | K37: =J37+K36 | L37: =K37+L36
A38: ── RETURNS ──────────────────────────────────
A39: Invested Capital ($mm) | B39: =Assumptions!$D$41 | C39: =B39+C23+C32-C21 | D39: =C39+D23+D32-D21 | E39: =D39+E23+E32-E21 | F39: =E39+F23+F32-F21 | G39: =F39+G23+G32-G21 | H39: =G39+H23+H32-H21 | I39: =H39+I23+I32-I21 | J39: =I39+J23+J32-J21 | ... L39: =K39+L23+L32-L21
A40: ROIC % | C40: =C18/B39 | D40: =D18/C39 | E40: =E18/D39 | F40: =F18/E39 | G40: =G18/F39 | H40: =H18/G39 | I40: =I18/H39 | J40: =J18/I39 | ... L40: =L18/K39
A41: Economic Profit ($mm) | C41: =C18-B39*(Assumptions!$D$37+$B$6) | D41: =D18-C39*(Assumptions!$D$37+$B$6) | E41: =E18-D39*(Assumptions!$D$37+$B$6) | F41: =F18-E39*(Assumptions!$D$37+$B$6) | G41: =G18-F39*(Assumptions!$D$37+$B$6) | H41: =H18-G39*(Assumptions!$D$37+$B$6) | I41: =I18-H39*(Assumptions!$D$37+$B$6) | J41: =J18-I39*(Assumptions!$D$37+$B$6) | ... L41: =L18-K39*(Assumptions!$D$37+$B$6)
...

Sheet DCF_Bull
A1: IBM — BULL SCENARIO | IBM Valuation
A2: SCENARIO PARAMETERS
A3: Growth Multiplier | B3: 1.4
A4: EBIT Margin Multiplier | B4: 1.15
A5: Capex Multiplier | B5: 0.9
A6: WACC Adjustment (add) | B6: -0.01
A7: Exit Multiple Multiplier | B7: 1.3
A9: 10-YEAR FCFF PROJECTION ($mm) | B9: LTM | C9: Y1 | D9: Y2 | E9: Y3 | F9: Y4 | G9: Y5 | H9: Y6 | I9: Y7 | J9: Y8 | K9: Y9 | L9: Y10 | M9: Terminal
A10: ── REVENUE ─────────────────────────────────
A11: Revenue ($mm) | B11: =Assumptions!$D$3 | C11: =B11*(1+Assumptions!$D$4*$B$3) | D11: =C11*(1+Assumptions!$D$4*$B$3) | E11: =D11*(1+Assumptions!$D$4*$B$3) | F11: =E11*(1+Assumptions!$D$4*$B$3) | G11: =F11*(1+Assumptions!$D$4*$B$3) | H11: =G11*(1+Assumptions!$D$5*$B$3) | I11: =H11*(1+Assumptions!$D$5*$B$3) | J11: =I11*(1+Assumptions!$D$5*$B$3) | K11: =J11*(1+Assumptions!$D$5*$B$3) | L11: =K11*(1+Assumptions!$D$5*$B$3) | M11: =L11*(1+Assumptions!$D$6)
A12: Revenue Growth % | C12: =C11/B11-1 | D12: =D11/C11-1 | E12: =E11/D11-1 | F12: =F11/E11-1 | G12: =G11/F11-1 | H12: =H11/G11-1 | I12: =I11/H11-1 | J12: =J11/I11-1 | ... M12: =M11/L11-1
A13: ── PROFITABILITY ────────────────────────────
A14: EBIT Margin % | C14: =Assumptions!$D$8+(Assumptions!$D$9*$B$4-Assumptions!$D$8)*(COLUMN()-2)/10 | D14: =Assumptions!$D$8+(Assumptions!$D$9*$B$4-Assumptions!$D$8)*(COLUMN()-2)/10 | E14: =Assumptions!$D$8+(Assumptions!$D$9*$B$4-Assumptions!$D$8)*(COLUMN()-2)/10 | F14: =Assumptions!$D$8+(Assumptions!$D$9*$B$4-Assumptions!$D$8)*(COLUMN()-2)/10 | G14: =Assumptions!$D$8+(Assumptions!$D$9*$B$4-Assumptions!$D$8)*(COLUMN()-2)/10 | H14: =Assumptions!$D$8+(Assumptions!$D$9*$B$4-Assumptions!$D$8)*(COLUMN()-2)/10 | I14: =Assumptions!$D$8+(Assumptions!$D$9*$B$4-Assumptions!$D$8)*(COLUMN()-2)/10 | J14: =Assumptions!$D$8+(Assumptions!$D$9*$B$4-Assumptions!$D$8)*(COLUMN()-2)/10 | ... L14: =Assumptions!$D$8+(Assumptions!$D$9*$B$4-Assumptions!$D$8)*(COLUMN()-2)/10 | M14: =Assumptions!$D$9
A15: EBIT ($mm) | C15: =C11*C14 | D15: =D11*D14 | E15: =E11*E14 | F15: =F11*F14 | G15: =G11*G14 | H15: =H11*H14 | I15: =I11*I14 | J15: =J11*J14 | ... M15: =M11*M14
A16: EBITDA ($mm) | C16: =C15+C21 | D16: =D15+D21 | E16: =E15+E21 | F16: =F15+F21 | G16: =G15+G21 | H16: =H15+H21 | I16: =I15+I21 | J16: =J15+J21 | ... M16: =M15+M21
A17: Tax Rate % | C17: =Assumptions!$D$14+(Assumptions!$D$15-Assumptions!$D$14)*(COLUMN()-2)/10 | D17: =Assumptions!$D$14+(Assumptions!$D$15-Assumptions!$D$14)*(COLUMN()-2)/10 | E17: =Assumptions!$D$14+(Assumptions!$D$15-Assumptions!$D$14)*(COLUMN()-2)/10 | F17: =Assumptions!$D$14+(Assumptions!$D$15-Assumptions!$D$14)*(COLUMN()-2)/10 | G17: =Assumptions!$D$14+(Assumptions!$D$15-Assumptions!$D$14)*(COLUMN()-2)/10 | H17: =Assumptions!$D$14+(Assumptions!$D$15-Assumptions!$D$14)*(COLUMN()-2)/10 | I17: =Assumptions!$D$14+(Assumptions!$D$15-Assumptions!$D$14)*(COLUMN()-2)/10 | J17: =Assumptions!$D$14+(Assumptions!$D$15-Assumptions!$D$14)*(COLUMN()-2)/10 | ... L17: =Assumptions!$D$14+(Assumptions!$D$15-Assumptions!$D$14)*(COLUMN()-2)/10 | M17: =Assumptions!$D$15
A18: NOPAT ($mm) | C18: =C15*(1-C17) | D18: =D15*(1-D17) | E18: =E15*(1-E17) | F18: =F15*(1-F17) | G18: =G15*(1-G17) | H18: =H15*(1-H17) | I18: =I15*(1-I17) | J18: =J15*(1-J17) | ... M18: =M15*(1-M17)
A19: ── D&A / CAPEX ──────────────────────────────
A20: D&A % Revenue | B20: =Assumptions!$D$11 | C20: =Assumptions!$D$11 | D20: =Assumptions!$D$11 | E20: =Assumptions!$D$11 | F20: =Assumptions!$D$11 | G20: =Assumptions!$D$11 | H20: =Assumptions!$D$11 | I20: =Assumptions!$D$11 | ... M20: =Assumptions!$D$11
A21: D&A ($mm) | C21: =C11*C20 | D21: =D11*D20 | E21: =E11*E20 | F21: =F11*F20 | G21: =G11*G20 | H21: =H11*H20 | I21: =I11*I20 | J21: =J11*J20 | ... M21: =M11*M20
A22: Capex % Revenue | B22: =Assumptions!$D$12 | C22: =Assumptions!$D$12*$B$5 | D22: =Assumptions!$D$12*$B$5 | E22: =Assumptions!$D$12*$B$5 | F22: =Assumptions!$D$12*$B$5 | G22: =Assumptions!$D$12*$B$5 | H22: =Assumptions!$D$12*$B$5 | I22: =Assumptions!$D$12*$B$5 | J22: =Assumptions!$D$12*$B$5 | ... L22: =Assumptions!$D$12*$B$5
A23: Capex ($mm) | C23: =C11*C22 | D23: =D11*D22 | E23: =E11*E22 | F23: =F11*F22 | G23: =G11*G22 | H23: =H11*H22 | I23: =I11*I22 | J23: =J11*J22 | ... L23: =L11*L22
A24: ── NWC DRIVERS ──────────────────────────────
A25: DSO (days) | B25: =Assumptions!$D$17 | C25: =Assumptions!$D$17+(Assumptions!$D$18-Assumptions!$D$17)*(COLUMN()-2)/10 | D25: =Assumptions!$D$17+(Assumptions!$D$18-Assumptions!$D$17)*(COLUMN()-2)/10 | E25: =Assumptions!$D$17+(Assumptions!$D$18-Assumptions!$D$17)*(COLUMN()-2)/10 | F25: =Assumptions!$D$17+(Assumptions!$D$18-Assumptions!$D$17)*(COLUMN()-2)/10 | G25: =Assumptions!$D$17+(Assumptions!$D$18-Assumptions!$D$17)*(COLUMN()-2)/10 | H25: =Assumptions!$D$17+(Assumptions!$D$18-Assumptions!$D$17)*(COLUMN()-2)/10 | I25: =Assumptions!$D$17+(Assumptions!$D$18-Assumptions!$D$17)*(COLUMN()-2)/10 | J25: =Assumptions!$D$17+(Assumptions!$D$18-Assumptions!$D$17)*(COLUMN()-2)/10 | ... L25: =Assumptions!$D$17+(Assumptions!$D$18-Assumptions!$D$17)*(COLUMN()-2)/10
A26: DIO (days) | B26: =Assumptions!$D$19 | C26: =Assumptions!$D$19+(Assumptions!$D$20-Assumptions!$D$19)*(COLUMN()-2)/10 | D26: =Assumptions!$D$19+(Assumptions!$D$20-Assumptions!$D$19)*(COLUMN()-2)/10 | E26: =Assumptions!$D$19+(Assumptions!$D$20-Assumptions!$D$19)*(COLUMN()-2)/10 | F26: =Assumptions!$D$19+(Assumptions!$D$20-Assumptions!$D$19)*(COLUMN()-2)/10 | G26: =Assumptions!$D$19+(Assumptions!$D$20-Assumptions!$D$19)*(COLUMN()-2)/10 | H26: =Assumptions!$D$19+(Assumptions!$D$20-Assumptions!$D$19)*(COLUMN()-2)/10 | I26: =Assumptions!$D$19+(Assumptions!$D$20-Assumptions!$D$19)*(COLUMN()-2)/10 | J26: =Assumptions!$D$19+(Assumptions!$D$20-Assumptions!$D$19)*(COLUMN()-2)/10 | ... L26: =Assumptions!$D$19+(Assumptions!$D$20-Assumptions!$D$19)*(COLUMN()-2)/10
A27: DPO (days) | B27: =Assumptions!$D$21 | C27: =Assumptions!$D$21+(Assumptions!$D$22-Assumptions!$D$21)*(COLUMN()-2)/10 | D27: =Assumptions!$D$21+(Assumptions!$D$22-Assumptions!$D$21)*(COLUMN()-2)/10 | E27: =Assumptions!$D$21+(Assumptions!$D$22-Assumptions!$D$21)*(COLUMN()-2)/10 | F27: =Assumptions!$D$21+(Assumptions!$D$22-Assumptions!$D$21)*(COLUMN()-2)/10 | G27: =Assumptions!$D$21+(Assumptions!$D$22-Assumptions!$D$21)*(COLUMN()-2)/10 | H27: =Assumptions!$D$21+(Assumptions!$D$22-Assumptions!$D$21)*(COLUMN()-2)/10 | I27: =Assumptions!$D$21+(Assumptions!$D$22-Assumptions!$D$21)*(COLUMN()-2)/10 | J27: =Assumptions!$D$21+(Assumptions!$D$22-Assumptions!$D$21)*(COLUMN()-2)/10 | ... L27: =Assumptions!$D$21+(Assumptions!$D$22-Assumptions!$D$21)*(COLUMN()-2)/10
A28: AR ($mm) | B28: =B11/365*B25 | C28: =C11/365*C25 | D28: =D11/365*D25 | E28: =E11/365*E25 | F28: =F11/365*F25 | G28: =G11/365*G25 | H28: =H11/365*H25 | I28: =I11/365*I25 | ... L28: =L11/365*L25
A29: Inventory ($mm) | B29: =B11/365*B26 | C29: =C11/365*C26 | D29: =D11/365*D26 | E29: =E11/365*E26 | F29: =F11/365*F26 | G29: =G11/365*G26 | H29: =H11/365*H26 | I29: =I11/365*I26 | ... L29: =L11/365*L26
A30: AP ($mm) | B30: =B11/365*B27 | C30: =C11/365*C27 | D30: =D11/365*D27 | E30: =E11/365*E27 | F30: =F11/365*F27 | G30: =G11/365*G27 | H30: =H11/365*H27 | I30: =I11/365*I27 | ... L30: =L11/365*L27
A31: NWC ($mm) | B31: =B28+B29-B30 | C31: =C28+C29-C30 | D31: =D28+D29-D30 | E31: =E28+E29-E30 | F31: =F28+F29-F30 | G31: =G28+G29-G30 | H31: =H28+H29-H30 | I31: =I28+I29-I30 | ... L31: =L28+L29-L30
A32: ΔNWC ($mm) | C32: =C31-B31 | D32: =D31-C31 | E32: =E31-D31 | F32: =F31-E31 | G32: =G31-F31 | H32: =H31-G31 | I32: =I31-H31 | J32: =J31-I31 | ... L32: =L31-K31
A33: ── FREE CASH FLOW ───────────────────────────
A34: FCFF ($mm) | C34: =C18+C21-C23-C32 | D34: =D18+D21-D23-D32 | E34: =E18+E21-E23-E32 | F34: =F18+F21-F23-F32 | G34: =G18+G21-G23-G32 | H34: =H18+H21-H23-H32 | I34: =I18+I21-I23-I32 | J34: =J18+J21-J23-J32 | ... L34: =L18+L21-L23-L32
A35: Discount Factor | C35: =1/(1+(Assumptions!$D$37+$B$6))^1 | D35: =1/(1+(Assumptions!$D$37+$B$6))^2 | E35: =1/(1+(Assumptions!$D$37+$B$6))^3 | F35: =1/(1+(Assumptions!$D$37+$B$6))^4 | G35: =1/(1+(Assumptions!$D$37+$B$6))^5 | H35: =1/(1+(Assumptions!$D$37+$B$6))^6 | I35: =1/(1+(Assumptions!$D$37+$B$6))^7 | J35: =1/(1+(Assumptions!$D$37+$B$6))^8 | K35: =1/(1+(Assumptions!$D$37+$B$6))^9 | L35: =1/(1+(Assumptions!$D$37+$B$6))^10 | M35: =1/(1+(Assumptions!$D$37+$B$6))^10
A36: PV FCFF ($mm) | C36: =C34*C35 | D36: =D34*D35 | E36: =E34*E35 | F36: =F34*F35 | G36: =G34*G35 | H36: =H34*H35 | I36: =I34*I35 | J36: =J34*J35 | ... L36: =L34*L35
A37: Cumulative PV FCFF ($mm) | C37: =C36 | D37: =C37+D36 | E37: =D37+E36 | F37: =E37+F36 | G37: =F37+G36 | H37: =G37+H36 | I37: =H37+I36 | J37: =I37+J36 | K37: =J37+K36 | L37: =K37+L36
A38: ── RETURNS ──────────────────────────────────
A39: Invested Capital ($mm) | B39: =Assumptions!$D$41 | C39: =B39+C23+C32-C21 | D39: =C39+D23+D32-D21 | E39: =D39+E23+E32-E21 | F39: =E39+F23+F32-F21 | G39: =F39+G23+G32-G21 | H39: =G39+H23+H32-H21 | I39: =H39+I23+I32-I21 | J39: =I39+J23+J32-J21 | ... L39: =K39+L23+L32-L21
A40: ROIC % | C40: =C18/B39 | D40: =D18/C39 | E40: =E18/D39 | F40: =F18/E39 | G40: =G18/F39 | H40: =H18/G39 | I40: =I18/H39 | J40: =J18/I39 | ... L40: =L18/K39
A41: Economic Profit ($mm) | C41: =C18-B39*(Assumptions!$D$37+$B$6) | D41: =D18-C39*(Assumptions!$D$37+$B$6) | E41: =E18-D39*(Assumptions!$D$37+$B$6) | F41: =F18-E39*(Assumptions!$D$37+$B$6) | G41: =G18-F39*(Assumptions!$D$37+$B$6) | H41: =H18-G39*(Assumptions!$D$37+$B$6) | I41: =I18-H39*(Assumptions!$D$37+$B$6) | J41: =J18-I39*(Assumptions!$D$37+$B$6) | ... L41: =L18-K39*(Assumptions!$D$37+$B$6)
...

Sheet Equity_Bridge
A1: IBM — EQUITY BRIDGE & INTRINSIC VALUE
A2: Item | B2: Bear | C2: Base | D2: Bull | E2: Notes
A3: Sum PV FCFF (Y1-Y10) $mm | B3: =DCF_Bear!M48 | C3: =DCF_Base!M41 | D3: =DCF_Bull!M48
A4: PV Terminal Value $mm | B4: =DCF_Bear!M46 | C4: =DCF_Base!M39 | D4: =DCF_Bull!M46 | E4: Blended (Gordon+Exit)/2
A5: EV — Operations $mm | B5: =DCF_Bear!M49 | C5: =DCF_Base!M42 | D5: =DCF_Bull!M49
A6: TV % of EV | B6: =DCF_Bear!M50 | C6: =DCF_Base!M43 | D6: =DCF_Bull!M50 | E6: Flag if >75%
A7: (+) Non-Operating Assets $mm | B7: =Assumptions!$D$42 | C7: =Assumptions!$D$42 | D7: =Assumptions!$D$42
A8: EV — Total $mm | B8: =B5+B7 | C8: =C5+C7 | D8: =D5+D7 | E8: EV_ops + Non-op assets
A9: (-) Net Debt $mm | B9: =Assumptions!$D$39 | C9: =Assumptions!$D$39 | D9: =Assumptions!$D$39
A10: (-) Minority Interest $mm | B10: =Assumptions!$D$43 | C10: =Assumptions!$D$43 | D10: =Assumptions!$D$43
A11: (-) Preferred Equity $mm | B11: =Assumptions!$D$44 | C11: =Assumptions!$D$44 | D11: =Assumptions!$D$44
A12: (-) Pension Deficit $mm | B12: =Assumptions!$D$45 | C12: =Assumptions!$D$45 | D12: =Assumptions!$D$45
A13: (-) Lease Liabilities $mm | B13: =Assumptions!$D$46 | C13: =Assumptions!$D$46 | D13: =Assumptions!$D$46
A14: (-) Options Value $mm | B14: =Assumptions!$D$47 | C14: =Assumptions!$D$47 | D14: =Assumptions!$D$47
A15: (-) Convertibles $mm | B15: =Assumptions!$D$48 | C15: =Assumptions!$D$48 | D15: =Assumptions!$D$48
A16: Equity Value $mm | B16: =B8-B9-B10-B11-B12-B13-B14-B15 | C16: =C8-C9-C10-C11-C12-C13-C14-C15 | D16: =D8-D9-D10-D11-D12-D13-D14-D15 | E16: EV_Total − all claims
A17: Shares Outstanding (mm) | B17: =Assumptions!$D$40 | C17: =Assumptions!$D$40 | D17: =Assumptions!$D$40
A18: Intrinsic Value / Share | B18: =B16/B17 | C18: =C16/C17 | D18: =D16/D17 | E18: Equity / Shares
A19: Market Price | B19: 253.33 | C19: 253.33 | D19: 253.33 | E19: As of 2026-03-09
A20: Upside / (Downside) % | B20: =B18/B19-1 | C20: =C18/C19-1 | D20: =D18/D19-1
A21: EXPECTED INTRINSIC VALUE
A22: Expected IV / Share (probability-weighted) | C22: =B18*Assumptions!$D$50+C18*Assumptions!$D$51+D18*Assumptions!$D$52
A23: Expected Upside % | C23: =C22/B19-1

Sheet Comps
A1: OPCH - Comparable Companies Appendix
A2: Company | B2: Option Care Health, Inc. | D2: As Of | E2: 2026-06-07
A3: Source File | B3: public_market_yfinance_fallback | D3: Current Price | E3: 20.51
A4: Headline Valuation
A5: Primary Metric | B5: tev_ebitda_ltm
A6: Blended Base IV | B6: 35.6754
A7: Bear / Base / Bull | B7: 22.6583 / 32.7897 / 37.2331
A8: Peer Counts (raw / clean) | B8: 6 / 5
A9: Similarity Method | B9: embedding_cosine
A10: Weighting Formula | B10: 0.60*description_similarity + 0.40*market_cap_proximity
A12: Valuation By Metric
A13: Metric | B13: Target Multiple | C13: Peer Median | D13: Bear Multiple | E13: Base Multiple | F13: Bull Multiple | G13: Bear IV | H13: Base IV | I13: Bull IV | J13: N Raw | K13: N Clean | L13: Primary
A14: TEV / EBITDA LTM | B14: 10.739 | C14: 16.4145 | D14: 11.58 | E14: 15.545 | F14: 17.284 | G14: 22.6583 | H14: 32.7897 | I14: 37.2331 | J14: 6 | K14: 5 | L14: Yes
A15: P / E LTM | B15: 16.023438 | C15: 32.0756 | D15: 26.941 | E15: 30.1259 | F15: 34.0254 | G15: 34.4844 | H15: 38.5612 | I15: 43.5524 | J15: 6 | K15: 5
A17: Target Vs Peer Benchmarks
A18: Metric | B18: Target | C18: Peer Median | D18: Delta
A19: TEV / EBITDA LTM | B19: 10.739 | C19: 16.4145 | D19: -5.6755
A20: P / E LTM | B20: 16.023438 | C20: 32.0756 | D20: -16.0522
A21: Revenue Growth | B21: 0.013
A22: EBIT Margin | B22: 0.05371
A23: Net Debt / EBITDA | B23: 2.7124
A25: Peer Table
A26: Ticker | B26: Company | C26: Similarity Score | D26: Model Weight | E26: Revenue LTM | F26: EBITDA LTM | G26: EBIT LTM | H26: Revenue Growth | I26: EBIT Margin | J26: Net Debt / EBITDA | K26: TEV / EBITDA LTM | L26: TEV / EBIT LTM | M26: P / E LTM
A27: UNH | B27: UNH | C27: 0.76821487 | D27: 0.1765 | K27: 19.423 | M27: 30.125942
A28: ABBV | B28: ABBV | C28: 0.75048274 | D28: 0.1724 | K28: 15.545 | M28: 110.8439
A29: PFE | B29: PFE | C29: 0.72301752 | D29: 0.1661 | K29: 7.87 | M29: 19.877865
A30: JNJ | B30: JNJ | C30: 0.7071033 | D30: 0.1624 | K30: 17.284 | M30: 26.940971
A31: MRK | B31: MRK | C31: 0.7065917 | D31: 0.1623 | K31: 11.58 | M31: 34.025352
A32: LLY | B32: LLY | C32: 0.69739522 | D32: 0.1602 | K32: 28.911 | M32: 40.164005

Sheet Comps Diagnostics
A1: OPCH - Comps Diagnostics
A4: Audit Flags
A5: No CIQ comps detail available; using public market yfinance fallback comps
A6: Outliers removed from tev_ebitda_ltm: LLY
A7: Peer set cleaned from 6 to 5
A9: Notes | B9: primary=tev_ebitda_ltm; 2 metrics computed; 5/6 peers after IQR cleaning
A11: Metric Status
A12: Ticker | B12: Company | C12: Metric | D12: Label | E12: Raw Multiple | F12: Status
A13: UNH | B13: UNH | C13: tev_ebitda_ltm | D13: TEV / EBITDA LTM | E13: 19.423 | F13: included
A14: ABBV | B14: ABBV | C14: tev_ebitda_ltm | D14: TEV / EBITDA LTM | E14: 15.545 | F14: included
A15: PFE | B15: PFE | C15: tev_ebitda_ltm | D15: TEV / EBITDA LTM | E15: 7.87 | F15: included
A16: JNJ | B16: JNJ | C16: tev_ebitda_ltm | D16: TEV / EBITDA LTM | E16: 17.284 | F16: included
A17: MRK | B17: MRK | C17: tev_ebitda_ltm | D17: TEV / EBITDA LTM | E17: 11.58 | F17: included
A18: LLY | B18: LLY | C18: tev_ebitda_ltm | D18: TEV / EBITDA LTM | E18: 28.911 | F18: outlier_removed
A19: UNH | B19: UNH | C19: pe_ltm | D19: P / E LTM | E19: 30.125942 | F19: included
A20: ABBV | B20: ABBV | C20: pe_ltm | D20: P / E LTM | E20: 110.8439 | F20: outlier_removed
A21: PFE | B21: PFE | C21: pe_ltm | D21: P / E LTM | E21: 19.877865 | F21: included
A22: JNJ | B22: JNJ | C22: pe_ltm | D22: P / E LTM | E22: 26.940971 | F22: included
A23: MRK | B23: MRK | C23: pe_ltm | D23: P / E LTM | E23: 34.025352 | F23: included
A24: LLY | B24: LLY | C24: pe_ltm | D24: P / E LTM | E24: 40.164005 | F24: included
A26: Football Field
A27: Label | B27: Bear | C27: Base | D27: Bull
A28: TEV / EBITDA LTM | B28: 22.6583 | C28: 32.7897 | D28: 37.2331
A29: P / E LTM | B29: 34.4844 | C29: 38.5612 | D29: 43.5524
A31: Historical Multiples Summary
A32: Metric | B32: Current | C32: Median | D32: P25 | E32: P75 | F32: Current Percentile
A33: pe_trailing | B33: 16.0234 | C33: 23.2969 | F33: 0.0151
A34: ev_ebitda | B34: 10.739 | C34: 14.3825 | F34: 0.0151
A35: ev_revenue | B35: 0.76 | C35: 1.0178 | F35: 0.0151
A36: price_to_book | B36: 2.3832 | C36: 3.465 | F36: 0.0151

Sheet Sensitivity
A1: IBM — SENSITIVITY ANALYSIS | IV / Share vs WACC × Terminal Growth
A2: IV/Share ($) — WACC (rows) × Terminal Growth (cols)
A3: WACC \ Term. g | B3: 0.015 | C3: 0.02 | D3: 0.025 | E3: 0.03 | F3: 0.035 | G3: 0.04 | H3: 0.045 | I3: 0.05 | J3: 0.055
A4: 0.05043 | B4: 380.03 | C4: 421.19 | D4: 478.37 | E4: 563.34 | F4: 703.1 | G4: 976.46 | H4: 1752.47 | I4: 20565.41 | J4: 55.18
A5: 0.05543 | B5: 323.99 | C5: 352.3 | D5: 389.78 | E5: 441.83 | F5: 519.18 | G5: 646.38 | H5: 895.17 | I5: 1601.39 | J5: 18722.08
A6: 0.06043 | B6: 280.4 | C6: 300.54 | D6: 326.25 | E6: 360.29 | F6: 407.56 | G6: 477.78 | H6: 593.26 | I6: 819.1 | J6: 1460.15
A7: 0.06543 | B7: 245.55 | C7: 260.25 | D7: 278.5 | E7: 301.78 | F7: 332.61 | G7: 375.41 | H7: 438.98 | I7: 543.52 | J7: 747.93
A8: 0.07043 | B8: 217.08 | C8: 228.02 | D8: 241.3 | E8: 257.78 | F8: 278.8 | G8: 306.63 | H8: 345.25 | I8: 402.62 | J8: 496.93
A9: 0.07543 | B9: 193.39 | C9: 201.67 | D9: 211.52 | E9: 223.48 | F9: 238.3 | G9: 257.22 | H9: 282.24 | I9: 316.97 | J9: 368.54
A10: 0.08043 | B10: 173.39 | C10: 179.73 | D10: 187.16 | E10: 196 | F10: 206.71 | G10: 220 | H10: 236.94 | I10: 259.35 | J10: 290.45
A11: 0.08543 | B11: 156.29 | C11: 161.19 | D11: 166.86 | E11: 173.49 | F11: 181.38 | G11: 190.94 | H11: 202.79 | I11: 217.9 | J11: 237.88
A12: 0.09043 | B12: 141.51 | C12: 145.33 | D12: 149.69 | E12: 154.73 | F12: 160.63 | G12: 167.63 | H12: 176.11 | I12: 186.62 | J12: 200.02
A14: Price = $253.33 | Green = IV > Price+20% | Yellow = within 5% | Red = IV < Price-5%

Sheet QoE
A1: IBM — QUALITY OF EARNINGS SIGNALS
A2: QoE Composite Score: 3/5 | Flag: AMBER | As of 2026-03-09
A3: Signal | B3: Value | C3: Score | D3: Threshold | E3: Interpretation
A4: Sloan Accruals Ratio | B4: 0.045 | C4: AMBER | D4: <5% green / >10% red | E4: Earnings quality (lower = better)
A5: Cash Conversion (CFO/NOPAT) | B5: 0.82 | C5: AMBER | D5: >90% green / <70% red | E5: Cash backing for earnings
A6: DSO Drift (vs 3Y baseline) | B6: 0 | C6: GREEN | D6: <3d green / >7d red | E6: AR quality; negative = improving
A7: Capex/D&A Ratio | B7: 0 | C7: GREEN | D7: <1.5x green / >2.5x red | E7: Maintenance vs growth capex
A8: DIO Drift | B8: 0 | C8: GREEN | D8: <5d green / >10d red | E8: Inventory build-up check
A9: Revenue recognition flag | B9: N/A | C9: GREEN | D9: N/A | E9: No restatements flagged
A10: Auditor flag | B10: None | C10: GREEN | D10: N/A | E10: Clean Big-4 opinion
A13: NWC BASELINE DETAIL
A14: DSO — Current | B14: 47
A15: DSO — 3Y Baseline | B15: 0
A16: DSO — Drift | B16: 0

Sheet Output
A1: IBM — VALUATION SUMMARY | 2026-03-09
A2: MARKET DATA
A3: Price | B3: 253.33
A4: Market Cap ($mm) | B4: 237632
A5: Enterprise Value ($mm) | B5: 293093
A6: P/E (Trailing) | B6: 22.761005
A7: P/E (Forward) | B7: 18.879555
A8: EV/EBITDA | B8: 18.184
A9: Analyst Target | B9: 318.3437
A10: Analyst Rec. | B10: buy
A11: # Analysts | B11: 19
A13: INTRINSIC VALUE SUMMARY
B14: Bear | C14: Base | D14: Bull
A15: Intrinsic Value / Share | B15: =Equity_Bridge!B18 | C15: =Equity_Bridge!C18 | D15: =Equity_Bridge!D18
A16: Upside / (Downside) | B16: =Equity_Bridge!B20 | C16: =Equity_Bridge!C20 | D16: =Equity_Bridge!D20
A17: Scenario Probability | B17: =Assumptions!$D$50 | C17: =Assumptions!$D$51 | D17: =Assumptions!$D$52
A18: Expected IV / Share | B18: =Equity_Bridge!C22
A19: Expected Upside | B19: =Equity_Bridge!C23
A21: WACC SUMMARY
A22: WACC | B22: =Assumptions!$D$37
A23: Cost of Equity | B23: =Assumptions!$D$31
A24: Cost of Debt (at) | B24: =Assumptions!$D$34
A25: Beta (Re-levered) | B25: =Assumptions!$D$29
A26: Equity Weight | B26: =Assumptions!$D$35
A28: QoE FLAGS
A29: QoE Score | B29: 3
A30: QoE Flag | B30: AMBER
A31: Sloan Accruals Ratio | B31: 0.045
A32: Cash Conversion | B32: 0.82
A33: DSO Drift (days) | B33: 0
