Workbook

Sheet Cover
A1: TTWO — Take-Two Interactive Software, Inc.
A2: Advanced DCF review workbook (deterministic backend + agent judgment)
A4: Headline
A5: Sector / Industry | B5: Communication Services / Electronic Gaming & Multimedia
A6: Current price | B6: 216.23
A7: Backend Base IV | B7: 179.38
A8: Base upside | B8: -0.17
A9: Expected IV (prob-weighted) | B9: 186.14
A10: Expected upside | B10: -0.139
A11: Margin of safety | B11: -0.205
A12: Analyst target / rec | B12: 279.11 (strong_buy)
A13: Model applicability | B13: dcf_applicable
A14: Model trust state | B14: watch
A15: Default resolution | B15: review_required_high
A17: Reconciliation to deterministic backend
A18: Workbook Base IV (rebuilt) | B18: 179.38257
A19: Backend Base IV | B19: 179.38
A20: Gap | B20: 0.0025655794
A21: Status | B21: RECONCILED
A23: How to read this workbook
A24: Thesis_Drivers | B24: Agent thesis cards (when a guided workup exists) + the deterministic story/sector layer.
A25: PM_Review_Queue | B25: Agent driver proposals + missing-data flags + deterministic resolution items for your sign-off.
A26: Assumptions | B26: Every input with provenance + register flag. Edit the PM Override column only.
A27: DCF_Base | B27: Transparent Base DCF; reconciles to backend IV. Terminal shown both ways + blend.
A28: Scenarios | B28: Backend bear/base/bull (official) with context-advisory set alongside.
A29: Valuation_Bridge | B29: DCF vs EP vs FCFE vs comps vs market — the full method spread.
A30: Checks | B30: Reconciliation, trust state, and model-hygiene flags to clear before discussion.
A32: Source JSON | B32: C:\Projects\03-Finance\ai-fund\data\valuations\json\TTWO_latest.json
A33: Generated | B33: 2026-06-15T22:38:52
A34: Note | B34: Review artifact only — does not write back to the database or approved assumptions.

Sheet Thesis_Drivers
A1: Story & Driver Layer (deterministic)
A2: Source: story_sector. These are deterministic story/sector priors, NOT a per-name agent read.
A3: NOTE: No guided-workup / analyst-prep run was found for this ticker, so there is no per-name agent judgment to show. story_profile below is a deterministic sector prior. Run the guided ticker workup (output/guided_workups/) to populate agent thesis and driver proposals.
A4: Story Profile (deterministic sector prior)
A5: Attribute | B5: Assessment | C5: Scale | D5: Read
A6: Moat strength | B6: 4 | C6: 0-5 | D6: Durability of competitive advantage
A7: Pricing power | B7: 4 | C7: 0-5 | D7: Ability to pass through cost / take price
A8: Cyclicality | B8: low | C8: low/med/high | D8: Sensitivity of demand to the cycle
A9: Capital intensity | B9: medium | C9: low/med/high | D9: Reinvestment needed to grow
A10: Governance risk | B10: medium | C10: low/med/high | D10: Capital-allocation / disclosure risk
A11: Advantage period | B11: 9 | C11: years | D11: Years of excess returns assumed
A13: Story -> Model Adjustments (what the thesis changed)
A14: Adjustment | B14: Value | C14: Effect on the model
A15: Growth add | B15: 0.008 | C15: Added to near/mid revenue growth
A16: Margin add | B16: 0.012 | C16: Added to EBIT margin path
A17: Cyclicality growth multiplier | B17: 1.05 | C17: Scales growth for cycle exposure
A18: Cyclicality WACC add | B18: -0.003 | C18: Raises discount rate for cyclical names
A19: Governance WACC add | B19: 0 | C19: Raises discount rate for governance risk
A20: Capex target add | B20: 0 | C20: Raises terminal reinvestment intensity
A21: D&A target add | B21: 0 | C21: Adjusts terminal D&A intensity
A22: Exit multiple cyclicality mult. | B22: 1.05 | C22: Haircut/premium on exit multiple
A23: Exit multiple governance mult. | B23: 1 | C23: Haircut/premium on exit multiple
A24: Terminal blend — Gordon weight | B24: 0.64 | C24: Weight on Gordon TV (cyclicality-driven)
A25: Terminal blend — Exit weight | B25: 0.36 | C25: Weight on exit-multiple TV
A27: These adjustments are produced by the deterministic story layer and are already baked into the assumptions and terminal blend on the DCF tabs. They are shown here so the qualitative thesis and the numbers are auditable together. Change them via the PM Decision Queue, not in this workbook.

Sheet PM_Review_Queue
A1: PM Review Queue
A2: Default resolution status: review_required_high (resolved 5, review_required 2)
A4: Default-resolution fields (deterministic)
A5: Field | B5: Value | C5: Source | D5: Source class | E5: Severity | F5: PM review? | G5: Fallback | H5: Why it matters
A6: exit_multiple | B6: 14.7 | C6: default|story_sector | D6: story_prior | E6: high | F6: YES | G6: 14 | H6: Directly affects terminal value and equity value.
A7: pension_deficit | B7: 0 | C7: default | D7: unproven_zero | E7: medium | F7: YES | G7: 0 | H7: Can be a non-equity claim in the equity bridge.
A8: dso_start | B8: 45.6 | C8: yfinance | D8: public_market | E8: medium | F8: no | G8: 50 | H8: Affects working-capital cash drag.
A9: dio_start | B9: 5 | C9: yfinance | D9: public_market | E9: medium | F9: no | G9: 30 | H9: Affects inventory investment and working-capital cash drag.
A10: dpo_start | B10: 25.9 | C10: yfinance | D10: public_market | E10: medium | F10: no | G10: 42 | H10: Affects supplier financing and working-capital cash drag.
A11: minority_interest | B11: 232785000 | C11: edgar_xbrl | D11: filing | E11: low | F11: no | G11: 0 | H11: Can be a non-equity claim in the equity bridge.
A12: preferred_equity | B12: 0 | C12: yfinance | D12: public_market | E12: low | F12: no | G12: 0 | H12: Can be a non-equity claim in the equity bridge.

Sheet Assumptions
A1: Assumptions
A2: Edit only the PM Override column. Source = provenance; Flag = assumption-register hygiene.
A4: Category | B4: Key | C4: Source Value | D4: PM Override | E4: Effective Value | F4: Unit | G4: Source | H4: Flag
A5: Company | B5: current_price | C5: 216.23 | E5: =IF(D5="",C5,D5) | F5: $/sh
A6: Company | B6: shares_outstanding_mm | C6: 183.9 | E6: =IF(D6="",C6,D6) | F6: mm | G6: yfinance_diluted
A7: Company | B7: annual_dilution_pct | C7: 0 | E7: =IF(D7="",C7,D7) | F7: %
A8: Company | B8: net_debt_mm | C8: 1517.5 | E8: =IF(D8="",C8,D8) | F8: $mm | G8: yfinance+leases
A9: Company | B9: non_operating_assets_mm | C9: 1856.172 | E9: =IF(D9="",C9,D9) | F9: $mm | G9: yfinance_cash_excess
A10: Company | B10: minority_interest_mm | C10: 232.785 | E10: =IF(D10="",C10,D10) | F10: $mm | G10: edgar_xbrl
A11: Company | B11: preferred_equity_mm | C11: 0 | E11: =IF(D11="",C11,D11) | F11: $mm | G11: yfinance
A12: Company | B12: pension_deficit_mm | C12: 0 | E12: =IF(D12="",C12,D12) | F12: $mm | G12: default
A13: Company | B13: lease_liabilities_mm | C13: 0 | E13: =IF(D13="",C13,D13) | F13: $mm | G13: folded_into_net_debt
A14: Company | B14: options_value_mm | C14: 999.6 | E14: =IF(D14="",C14,D14) | F14: $mm | G14: sbc_proxy
A15: Company | B15: convertibles_value_mm | C15: 0 | E15: =IF(D15="",C15,D15) | F15: $mm | G15: default
A16: Operating | B16: revenue_mm | C16: 6656.4 | E16: =IF(D16="",C16,D16) | F16: $mm | G16: yfinance
A17: Operating | B17: cogs_pct_of_revenue | C17: 0.4883 | E17: =IF(D17="",C17,D17) | F17: % rev
A18: Operating | B18: growth_terminal_pct | C18: 0.03 | E18: =IF(D18="",C18,D18) | F18: %
A19: WACC | B19: wacc | C19: 0.09419 | E19: =IF(D19="",C19,D19) | F19: %
A20: WACC | B20: cost_of_equity | C20: 0.09549 | E20: =IF(D20="",C20,D20) | F20: % | G20: yfinance_capm|story_sector
A21: WACC | B21: cost_of_debt | E21: =IF(D21="",C21,D21) | F21: %
A22: WACC | B22: risk_free_rate | E22: =IF(D22="",C22,D22) | F22: %
A23: WACC | B23: equity_risk_premium | E23: =IF(D23="",C23,D23) | F23: %
A24: WACC | B24: beta_relevered | C24: 0.98 | E24: =IF(D24="",C24,D24) | F24: x
A25: WACC | B25: size_premium | C25: 0.005 | E25: =IF(D25="",C25,D25) | F25: %
A26: WACC | B26: equity_weight | C26: 0.9764 | E26: =IF(D26="",C26,D26) | F26: % cap
A27: WACC | B27: debt_weight | C27: 0.0236 | E27: =IF(D27="",C27,D27) | F27: % cap | G27: yfinance_capm
A28: Terminal | B28: exit_multiple | C28: 14.7 | E28: =IF(D28="",C28,D28) | F28: x | G28: default|story_sector
A29: Terminal | B29: exit_metric | C29: ev_ebitda | E29: =IF(D29="",C29,D29) | F29: text
A30: Terminal | B30: ronic_terminal | C30: 0.14 | E30: =IF(D30="",C30,D30) | F30: % | G30: default
A31: Terminal | B31: terminal_blend_gordon_weight | C31: 0.64 | E31: =IF(D31="",C31,D31) | F31: %
A32: Terminal | B32: terminal_blend_exit_weight | C32: 0.36 | E32: =IF(D32="",C32,D32) | F32: %
A33: Scenario | B33: scenario_prob_bear | C33: 0.2 | E33: =IF(D33="",C33,D33) | F33: %
A34: Scenario | B34: scenario_prob_base | C34: 0.6 | E34: =IF(D34="",C34,D34) | F34: %
A35: Scenario | B35: scenario_prob_bull | C35: 0.2 | E35: =IF(D35="",C35,D35) | F35: %
A36: Backend | B36: backend_iv_base | C36: 179.38 | E36: =IF(D36="",C36,D36) | F36: $/sh
A37: Backend | B37: backend_iv_gordon | C37: 128.68 | E37: =IF(D37="",C37,D37) | F37: $/sh
A38: Backend | B38: backend_iv_exit | C38: 269.53 | E38: =IF(D38="",C38,D38) | F38: $/sh
A39: Backend | B39: backend_tv_pct_ev | C39: 0.532 | E39: =IF(D39="",C39,D39) | F39: %

Sheet Historical_Financials
A1: Historical Financials
A2: Annual CIQ actuals captured in valuation JSON
A3: No historical actuals available for this ticker (no CIQ Standard workbook / SEC history in the valuation JSON). The DCF and reconciliation are unaffected — they run off the forecast — but trend review needs a CIQ/SEC history source.
A4: Fiscal Year | B4: Period | C4: Revenue | D4: Rev Growth | E4: EBIT | F4: EBIT Margin | G4: EBITDA | H4: EBITDA Margin | I4: D&A | J4: D&A % | K4: Capex | L4: Capex % | M4: CFO | N4: Pretax | O4: Tax | P4: Tax Rate | Q4: Cash | R4: Debt | S4: Net Debt | T4: Tot Assets | U4: Tot Equity | V4: Source

Sheet Input_Forecast
A1: Base Forecast (deterministic backend)
A2: Per-year Base-case drivers and outputs. The DCF_Base tab recomputes the bridge from these.
A4: Year | B4: Revenue | C4: Growth | D4: EBIT Margin | E4: Tax Rate | F4: Capex % | G4: D&A % | H4: DSO | I4: DIO | J4: DPO | K4: EBIT | L4: NOPAT | M4: D&A | N4: Capex | O4: AR | P4: Inventory | Q4: AP | R4: NWC | S4: Delta NWC | T4: FCFF | U4: Disc Factor | V4: PV FCFF | W4: ROIC | X4: Econ Profit
A5: 1 | B5: 7519.569 | C5: 0.129675 | D5: 0.02 | E5: 0.21 | F5: 0.027 | G5: 0.2 | H5: 45.6 | I5: 5 | J5: 25.9 | K5: 150.391 | L5: 118.809 | M5: 1503.914 | N5: 203.028 | O5: 939.431 | P5: 50.299 | Q5: 260.547 | R5: 729.182 | S5: 83.703 | T5: 1335.992 | U5: 1.09419 | V5: 1220.987 | W5: 0.022635063 | X5: -375.585
A6: 2 | B6: 8494.669 | C6: 0.129675 | D6: 0.030222222 | E6: 0.21 | F6: 0.02685 | G6: 0.19888889 | H6: 45.942222 | I6: 6.9444444 | J6: 27.152222 | K6: 256.728 | L6: 202.815 | M6: 1689.495 | N6: 228.082 | O6: 1069.216 | P6: 78.918 | Q6: 308.564 | R6: 839.57 | S6: 110.388 | T6: 1553.84 | U6: 1.1972518 | V6: 1297.839 | W6: 0.05030485 | X6: -176.933
A7: 3 | B7: 9596.215 | C7: 0.129675 | D7: 0.040444444 | E7: 0.21 | F7: 0.0267 | G7: 0.19777778 | H7: 46.284444 | I7: 8.8888889 | J7: 28.404444 | K7: 388.114 | L7: 306.61 | M7: 1897.918 | N7: 256.219 | O7: 1216.864 | P7: 114.115 | Q7: 364.653 | R7: 966.326 | S7: 126.755 | T7: 1821.553 | U7: 1.3100209 | V7: 1390.477 | W7: 0.11437709 | X7: 54.115
A8: 4 | B8: 10778.96 | C8: 0.12325125 | D8: 0.050666667 | E8: 0.21 | F8: 0.02655 | G8: 0.19666667 | H8: 46.626667 | I8: 10.833333 | J8: 29.656667 | K8: 546.134 | L8: 431.446 | M8: 2119.862 | N8: 286.181 | O8: 1376.951 | P8: 156.219 | Q8: 427.655 | R8: 1105.515 | S8: 139.189 | T8: 2125.938 | U8: 1.4334118 | V8: 1483.131 | W8: 0.37010215 | X8: 321.644
A9: 5 | B9: 12038.239 | C9: 0.1168275 | D9: 0.060888889 | E9: 0.21 | F9: 0.0264 | G9: 0.19555556 | H9: 46.968889 | I9: 12.777778 | J9: 30.908889 | K9: 732.995 | L9: 579.066 | M9: 2354.145 | N9: 317.81 | O9: 1549.103 | P9: 205.784 | Q9: 497.783 | R9: 1257.104 | S9: 151.59 | T9: 2463.811 | U9: 1.5684248 | V9: 1570.883 | W9: 5.7906605e+08 | X9: 579.066
A10: 6 | B10: 13367.306 | C10: 0.11040375 | D10: 0.071111111 | E10: 0.21 | F10: 0.02625 | G10: 0.19444444 | H10: 47.311111 | I10: 14.722222 | J10: 32.161111 | K10: 950.564 | L10: 750.946 | M10: 2599.198 | N10: 350.892 | O10: 1732.663 | P10: 263.276 | Q10: 575.134 | R10: 1420.806 | S10: 163.701 | T10: 2835.551 | U10: 1.7161548 | V10: 1652.27 | W10: 7.5094554e+08 | X10: 750.946
A11: 7 | B11: 14757.238 | C11: 0.10398 | D11: 0.081333333 | E11: 0.21 | F11: 0.0261 | G11: 0.19333333 | H11: 47.653333 | I11: 16.666667 | J11: 33.413333 | K11: 1200.255 | L11: 948.202 | M11: 2853.066 | N11: 385.164 | O11: 1926.662 | P11: 329.039 | Q11: 659.658 | R11: 1596.043 | S11: 175.238 | T11: 3240.866 | U11: 1.8777994 | V11: 1725.885 | W11: 9.4820176e+08 | X11: 948.202
A12: 8 | B12: 16196.899 | C12: 0.09755625 | D12: 0.091555556 | E12: 0.21 | F12: 0.02595 | G12: 0.19222222 | H12: 47.995556 | I12: 18.611111 | J12: 34.665556 | K12: 1482.916 | L12: 1171.504 | M12: 3113.404 | N12: 420.31 | O12: 2129.806 | P12: 403.272 | Q12: 751.145 | R12: 1781.933 | S12: 185.889 | T12: 3678.709 | U12: 2.0546693 | V12: 1790.414 | W12: 1.1715037e+09 | X12: 1171.504
A13: 9 | B13: 17672.963 | C13: 0.0911325 | D13: 0.10177778 | E13: 0.21 | F13: 0.0258 | G13: 0.19111111 | H13: 48.337778 | I13: 20.555556 | J13: 35.917778 | K13: 1798.715 | L13: 1420.985 | M13: 3377.5 | N13: 455.962 | O13: 2340.471 | P13: 485.996 | Q13: 849.205 | R13: 1977.261 | S13: 195.328 | T13: 4147.194 | U13: 2.2481986 | V13: 1844.674 | W13: 1.4209848e+09 | X13: 1420.985
A14: 10 | B14: 19170.018 | C14: 0.08470875 | D14: 0.112 | E14: 0.21 | F14: 0.02565 | G14: 0.19 | H14: 48.68 | I14: 22.5 | J14: 37.17 | K14: 2147.042 | L14: 1696.163 | M14: 3642.303 | N14: 491.711 | O14: 2556.703 | P14: 577.031 | Q14: 953.255 | R14: 2180.479 | S14: 203.218 | T14: 4643.538 | U14: 2.4599564 | V14: 1887.65 | W14: 1.6961632e+09 | X14: 1696.163

Sheet WACC
A1: WACC
A2: Cost of capital build. Edit components via Assumptions overrides.
A4: Line | B4: Value | C4: Notes
A5: Backend WACC (used in DCF) | B5: ='Assumptions'!$E$19 | C5: Default discount rate from backend
A6: Cost of equity | B6: ='Assumptions'!$E$20 | C6: CAPM cost of equity
A7: Risk-free rate | B7: ='Assumptions'!$E$22 | C7: Blank if unavailable
A8: Equity risk premium | B8: ='Assumptions'!$E$23 | C8: Blank if unavailable
A9: Relevered beta | B9: ='Assumptions'!$E$24 | C9: Peer/structure beta
A10: Size premium | B10: ='Assumptions'!$E$25 | C10: Duff & Phelps
A11: Cost of debt | B11: ='Assumptions'!$E$21 | C11: Blank if unavailable
A12: Equity weight | B12: ='Assumptions'!$E$26 | C12: Market-value weight
A13: Debt weight | B13: ='Assumptions'!$E$27 | C13: Market-value weight
A14: Rebuilt cost of equity (check) | B14: =IF(OR(ISBLANK('Assumptions'!$E$22),ISBLANK('Assumptions'!$E$23)),'Assumptions'!$E$20,'Assumptions'!$E$22+'Assumptions'!$E$24*'Assumptions'!$E$23+'Assumptions'!$E$25) | C14: CAPM rebuild; falls back to backend Ke

Sheet DCF_Base
A1: Base Case DCF (transparent rebuild)
A2: Recomputes the bridge from backend per-year drivers; reconciles to backend Base IV.
A4: Operating model
C5: Y1 | D5: Y2 | E5: Y3 | F5: Y4 | G5: Y5 | H5: Y6 | I5: Y7 | J5: Y8 | K5: Y9 | L5: Y10
A6: Revenue | C6: ='Input_Forecast'!$B$5 | D6: ='Input_Forecast'!$B$6 | E6: ='Input_Forecast'!$B$7 | F6: ='Input_Forecast'!$B$8 | G6: ='Input_Forecast'!$B$9 | H6: ='Input_Forecast'!$B$10 | I6: ='Input_Forecast'!$B$11 | J6: ='Input_Forecast'!$B$12 | K6: ='Input_Forecast'!$B$13 | L6: ='Input_Forecast'!$B$14
A7: Revenue growth | C7: ='Input_Forecast'!$C$5 | D7: ='Input_Forecast'!$C$6 | E7: ='Input_Forecast'!$C$7 | F7: ='Input_Forecast'!$C$8 | G7: ='Input_Forecast'!$C$9 | H7: ='Input_Forecast'!$C$10 | I7: ='Input_Forecast'!$C$11 | J7: ='Input_Forecast'!$C$12 | K7: ='Input_Forecast'!$C$13 | L7: ='Input_Forecast'!$C$14
A8: EBIT margin | C8: ='Input_Forecast'!$D$5 | D8: ='Input_Forecast'!$D$6 | E8: ='Input_Forecast'!$D$7 | F8: ='Input_Forecast'!$D$8 | G8: ='Input_Forecast'!$D$9 | H8: ='Input_Forecast'!$D$10 | I8: ='Input_Forecast'!$D$11 | J8: ='Input_Forecast'!$D$12 | K8: ='Input_Forecast'!$D$13 | L8: ='Input_Forecast'!$D$14
A9: EBIT | C9: =C6*C8 | D9: =D6*D8 | E9: =E6*E8 | F9: =F6*F8 | G9: =G6*G8 | H9: =H6*H8 | I9: =I6*I8 | J9: =J6*J8 | ... L9: =L6*L8
A10: Tax rate | C10: ='Input_Forecast'!$E$5 | D10: ='Input_Forecast'!$E$6 | E10: ='Input_Forecast'!$E$7 | F10: ='Input_Forecast'!$E$8 | G10: ='Input_Forecast'!$E$9 | H10: ='Input_Forecast'!$E$10 | I10: ='Input_Forecast'!$E$11 | J10: ='Input_Forecast'!$E$12 | K10: ='Input_Forecast'!$E$13 | L10: ='Input_Forecast'!$E$14
A11: NOPAT | C11: =C9*(1-C10) | D11: =D9*(1-D10) | E11: =E9*(1-E10) | F11: =F9*(1-F10) | G11: =G9*(1-G10) | H11: =H9*(1-H10) | I11: =I9*(1-I10) | J11: =J9*(1-J10) | ... L11: =L9*(1-L10)
A12: D&A | C12: ='Input_Forecast'!$M$5 | D12: ='Input_Forecast'!$M$6 | E12: ='Input_Forecast'!$M$7 | F12: ='Input_Forecast'!$M$8 | G12: ='Input_Forecast'!$M$9 | H12: ='Input_Forecast'!$M$10 | I12: ='Input_Forecast'!$M$11 | J12: ='Input_Forecast'!$M$12 | K12: ='Input_Forecast'!$M$13 | L12: ='Input_Forecast'!$M$14
A13: Capex | C13: ='Input_Forecast'!$N$5 | D13: ='Input_Forecast'!$N$6 | E13: ='Input_Forecast'!$N$7 | F13: ='Input_Forecast'!$N$8 | G13: ='Input_Forecast'!$N$9 | H13: ='Input_Forecast'!$N$10 | I13: ='Input_Forecast'!$N$11 | J13: ='Input_Forecast'!$N$12 | K13: ='Input_Forecast'!$N$13 | L13: ='Input_Forecast'!$N$14
A14: Net working capital | C14: ='Input_Forecast'!$R$5 | D14: ='Input_Forecast'!$R$6 | E14: ='Input_Forecast'!$R$7 | F14: ='Input_Forecast'!$R$8 | G14: ='Input_Forecast'!$R$9 | H14: ='Input_Forecast'!$R$10 | I14: ='Input_Forecast'!$R$11 | J14: ='Input_Forecast'!$R$12 | K14: ='Input_Forecast'!$R$13 | L14: ='Input_Forecast'!$R$14
A15: Delta NWC | C15: ='Input_Forecast'!$S$5 | D15: =D14-C14 | E15: =E14-D14 | F15: =F14-E14 | G15: =G14-F14 | H15: =H14-G14 | I15: =I14-H14 | J15: =J14-I14 | K15: =K14-J14 | L15: =L14-K14
A16: FCFF (NOPAT+D&A-Capex-dNWC) | C16: =C11+C12-C13-C15 | D16: =D11+D12-D13-D15 | E16: =E11+E12-E13-E15 | F16: =F11+F12-F13-F15 | G16: =G11+G12-G13-G15 | H16: =H11+H12-H13-H15 | I16: =I11+I12-I13-I15 | J16: =J11+J12-J13-J15 | ... L16: =L11+L12-L13-L15
A17: FCFF — backend (foot check) | C17: ='Input_Forecast'!$T$5 | D17: ='Input_Forecast'!$T$6 | E17: ='Input_Forecast'!$T$7 | F17: ='Input_Forecast'!$T$8 | G17: ='Input_Forecast'!$T$9 | H17: ='Input_Forecast'!$T$10 | I17: ='Input_Forecast'!$T$11 | J17: ='Input_Forecast'!$T$12 | K17: ='Input_Forecast'!$T$13 | L17: ='Input_Forecast'!$T$14
A18: Discount factor | C18: =POWER(1+'Assumptions'!$E$19,1) | D18: =POWER(1+'Assumptions'!$E$19,2) | E18: =POWER(1+'Assumptions'!$E$19,3) | F18: =POWER(1+'Assumptions'!$E$19,4) | G18: =POWER(1+'Assumptions'!$E$19,5) | H18: =POWER(1+'Assumptions'!$E$19,6) | I18: =POWER(1+'Assumptions'!$E$19,7) | J18: =POWER(1+'Assumptions'!$E$19,8) | K18: =POWER(1+'Assumptions'!$E$19,9) | L18: =POWER(1+'Assumptions'!$E$19,10)
A19: PV of FCFF | C19: =C16/C18 | D19: =D16/D18 | E19: =E16/E18 | F19: =F16/F18 | G19: =G16/G18 | H19: =H16/H18 | I19: =I16/I18 | J19: =J16/J18 | ... L19: =L16/L18
A20: EBITDA | C20: =C9+C12 | D20: =D9+D12 | E20: =E9+E12 | F20: =F9+F12 | G20: =G9+G12 | H20: =H9+H12 | I20: =I9+I12 | J20: =J9+J12 | ... L20: =L9+L12
A22: Terminal value & equity bridge
A23: Terminal revenue (Y+1) | B23: =L6*(1+'Assumptions'!$E$18)
A24: Terminal EBIT | B24: =B23*L8
A25: Terminal NOPAT | B25: =B24*(1-L10)
A26: Terminal reinvestment rate (g/RONIC) | B26: ='Assumptions'!$E$18/'Assumptions'!$E$30
A27: Terminal FCFF (value-driver) | B27: =B25*(1-B26)
A28: Gordon terminal value | B28: =IF('Assumptions'!$E$19<='Assumptions'!$E$18,NA(),B27/('Assumptions'!$E$19-'Assumptions'!$E$18))
A29: Exit terminal value | B29: =IF('Assumptions'!$E$29="ev_ebit",L9,L20)*'Assumptions'!$E$28
A30: PV of Gordon TV | B30: =B28/POWER(1+'Assumptions'!$E$19,10)
A31: PV of exit TV | B31: =B29/POWER(1+'Assumptions'!$E$19,10)
A32: PV of blended TV | B32: ='Assumptions'!$E$31*B30+'Assumptions'!$E$32*B31
A33: PV of explicit FCFF | B33: =SUM(C19:L19)
A34: Enterprise value — operations | B34: =B33+B32
A35: Terminal value % of EV | B35: =B32/B34
A36: Non-operating assets | B36: ='Assumptions'!$E$9
A37: Non-equity claims | B37: ='Assumptions'!$E$8+'Assumptions'!$E$10+'Assumptions'!$E$11+'Assumptions'!$E$12+'Assumptions'!$E$13+'Assumptions'!$E$14+'Assumptions'!$E$15
A38: Equity value | B38: =B34+B36-B37
A39: Diluted terminal shares | B39: ='Assumptions'!$E$6*POWER(1+'Assumptions'!$E$7,10)
A40: Intrinsic value / share | B40: =B38/B39
A41: IV / share — Gordon only | B41: =(B33+B30+B36-B37)/B39
A42: IV / share — exit only | B42: =(B33+B31+B36-B37)/B39
...

Sheet Scenarios
A1: Scenarios
A2: Backend deterministic scenario outputs. Official is canonical; context-advisory shown alongside.
A4: Official scenarios (canonical)
A5: Scenario | B5: Prob | C5: Growth mult | D5: Margin shift | E5: WACC shift | F5: Exit mult | G5: Backend IV | H5: Upside | I5: Prob-weighted IV
A6: bear | B6: 0.2 | C6: 0.8 | D6: -0.02 | E6: 0.01 | F6: 0.9 | G6: 120.55 | H6: -0.442
A7: base | B7: 0.6 | C7: 1 | D7: 0 | E7: 0 | F7: 1 | G7: 179.38 | H7: -0.17
A8: bull | B8: 0.2 | C8: 1.2 | D8: 0.02 | E8: -0.01 | F8: 1.1 | G8: 272.01 | H8: 0.258
A9: Expected (prob-weighted) | G9: 186.14 | H9: -0.139
A11: Context-advisory scenarios (cyclicality-aware, not canonical)
A12: Scenario | B12: Prob | C12: Growth mult | D12: Margin shift | E12: WACC shift | F12: Exit mult
A13: bear | B13: 0.1 | C13: 0.92 | D13: -0.0161 | E13: 0.0085 | F13: 0.915
A14: base | B14: 0.55 | C14: 1 | D14: 0 | E14: 0 | F14: 1
A15: bull | B15: 0.35 | C15: 1.26 | D15: 0.0179 | E15: -0.0085 | F15: 1.175
A16: Context expected IV | B16: 212.99
A18: Policy: context_advisory_v1 | official: fixed_default

Sheet Valuation_Bridge
A1: Valuation Bridge
A2: Where each method lands — the spread is the discussion.
A4: Method | B4: Low | C4: Mid | D4: High | E4: Note
A5: DCF — scenario range (backend) | B5: 120.55 | C5: 179.38 | D5: 272.01 | E5: Bear / Base / Bull
A6: DCF — terminal method (this wb) | B6: ='DCF_Base'!$B$42 | C6: ='DCF_Base'!$B$40 | D6: ='DCF_Base'!$B$41 | E6: Exit / Blended / Gordon (rebuilt)
A7: Economic profit (EP) IV | C7: 100.04 | E7: Invested capital + PV economic profit
A8: FCFE IV | C8: 133.63 | E8: Direct-to-equity cross-check
A9: Comps | E9: EV/EBITDA / blended / P/E
A10: Market / street | B10: 216.23 | C10: 279.10516 | E10: Current price / analyst target
A12: Implied growth priced in | B12: 0.159
A13: DCF vs EP gap | B13: -0.4306

Sheet Sensitivity
A1: Sensitivity
A2: Live tables off the rebuilt Base mechanics; change Assumptions to refresh.
A4: IV/share: WACC (cols) vs terminal growth (rows) — Gordon path
A5: g \ WACC | B5: ='Assumptions'!$E$19+-0.01 | C5: ='Assumptions'!$E$19+-0.005 | D5: ='Assumptions'!$E$19+0.0 | E5: ='Assumptions'!$E$19+0.005 | F5: ='Assumptions'!$E$19+0.01
A6: ='Assumptions'!$E$18+-0.01 | B6: =IF(B5<=A6,NA(),(('DCF_Base'!C16/POWER(1+B5,1)+'DCF_Base'!D16/POWER(1+B5,2)+'DCF_Base'!E16/POWER(1+B5,3)+'DCF_Base'!F16/POWER(1+B5,4)+'DCF_Base'!G16/POWER(1+B5,5)+'DCF_Base'!H16/POWER(1+B5,6)+'DCF_Base'!I16/POWER(1+B5,7)+'DCF_Base'!J16/POWER(1+B5,8)+'DCF_Base'!K16/POWER(1+B5,9)+'DCF_Base'!L16/POWER(1+B5,10))+(('DCF_Base'!L11*(1+A6))*(1-A6/'Assumptions'!$E$30)/(B5-A6))/POWER(1+B5,10)+'Assumptions'!$E$9-('Assumptions'!$E$8+'Assumptions'!$E$10+'Assumptions'!$E$11+'Assumptions'!$E$12+'Assumptions'!$E$13+'Assumptions'!$E$14+'Assumptions'!$E$15))/('Assumptions'!$E$6*POWER(1+'Assumptions'!$E$7,10))) | C6: =IF(C5<=A6,NA(),(('DCF_Base'!C16/POWER(1+C5,1)+'DCF_Base'!D16/POWER(1+C5,2)+'DCF_Base'!E16/POWER(1+C5,3)+'DCF_Base'!F16/POWER(1+C5,4)+'DCF_Base'!G16/POWER(1+C5,5)+'DCF_Base'!H16/POWER(1+C5,6)+'DCF_Base'!I16/POWER(1+C5,7)+'DCF_Base'!J16/POWER(1+C5,8)+'DCF_Base'!K16/POWER(1+C5,9)+'DCF_Base'!L16/POWER(1+C5,10))+(('DCF_Base'!L11*(1+A6))*(1-A6/'Assumptions'!$E$30)/(C5-A6))/POWER(1+C5,10)+'Assumptions'!$E$9-('Assumptions'!$E$8+'Assumptions'!$E$10+'Assumptions'!$E$11+'Assumptions'!$E$12+'Assumptions'!$E$13+'Assumptions'!$E$14+'Assumptions'!$E$15))/('Assumptions'!$E$6*POWER(1+'Assumptions'!$E$7,10))) | D6: =IF(D5<=A6,NA(),(('DCF_Base'!C16/POWER(1+D5,1)+'DCF_Base'!D16/POWER(1+D5,2)+'DCF_Base'!E16/POWER(1+D5,3)+'DCF_Base'!F16/POWER(1+D5,4)+'DCF_Base'!G16/POWER(1+D5,5)+'DCF_Base'!H16/POWER(1+D5,6)+'DCF_Base'!I16/POWER(1+D5,7)+'DCF_Base'!J16/POWER(1+D5,8)+'DCF_Base'!K16/POWER(1+D5,9)+'DCF_Base'!L16/POWER(1+D5,10))+(('DCF_Base'!L11*(1+A6))*(1-A6/'Assumptions'!$E$30)/(D5-A6))/POWER(1+D5,10)+'Assumptions'!$E$9-('Assumptions'!$E$8+'Assumptions'!$E$10+'Assumptions'!$E$11+'Assumptions'!$E$12+'Assumptions'!$E$13+'Assumptions'!$E$14+'Assumptions'!$E$15))/('Assumptions'!$E$6*POWER(1+'Assumptions'!$E$7,10))) | E6: =IF(E5<=A6,NA(),(('DCF_Base'!C16/POWER(1+E5,1)+'DCF_Base'!D16/POWER(1+E5,2)+'DCF_Base'!E16/POWER(1+E5,3)+'DCF_Base'!F16/POWER(1+E5,4)+'DCF_Base'!G16/POWER(1+E5,5)+'DCF_Base'!H16/POWER(1+E5,6)+'DCF_Base'!I16/POWER(1+E5,7)+'DCF_Base'!J16/POWER(1+E5,8)+'DCF_Base'!K16/POWER(1+E5,9)+'DCF_Base'!L16/POWER(1+E5,10))+(('DCF_Base'!L11*(1+A6))*(1-A6/'Assumptions'!$E$30)/(E5-A6))/POWER(1+E5,10)+'Assumptions'!$E$9-('Assumptions'!$E$8+'Assumptions'!$E$10+'Assumptions'!$E$11+'Assumptions'!$E$12+'Assumptions'!$E$13+'Assumptions'!$E$14+'Assumptions'!$E$15))/('Assumptions'!$E$6*POWER(1+'Assumptions'!$E$7,10))) | F6: =IF(F5<=A6,NA(),(('DCF_Base'!C16/POWER(1+F5,1)+'DCF_Base'!D16/POWER(1+F5,2)+'DCF_Base'!E16/POWER(1+F5,3)+'DCF_Base'!F16/POWER(1+F5,4)+'DCF_Base'!G16/POWER(1+F5,5)+'DCF_Base'!H16/POWER(1+F5,6)+'DCF_Base'!I16/POWER(1+F5,7)+'DCF_Base'!J16/POWER(1+F5,8)+'DCF_Base'!K16/POWER(1+F5,9)+'DCF_Base'!L16/POWER(1+F5,10))+(('DCF_Base'!L11*(1+A6))*(1-A6/'Assumptions'!$E$30)/(F5-A6))/POWER(1+F5,10)+'Assumptions'!$E$9-('Assumptions'!$E$8+'Assumptions'!$E$10+'Assumptions'!$E$11+'Assumptions'!$E$12+'Assumptions'!$E$13+'Assumptions'!$E$14+'Assumptions'!$E$15))/('Assumptions'!$E$6*POWER(1+'Assumptions'!$E$7,10)))
A7: ='Assumptions'!$E$18+-0.005 | B7: =IF(B5<=A7,NA(),(('DCF_Base'!C16/POWER(1+B5,1)+'DCF_Base'!D16/POWER(1+B5,2)+'DCF_Base'!E16/POWER(1+B5,3)+'DCF_Base'!F16/POWER(1+B5,4)+'DCF_Base'!G16/POWER(1+B5,5)+'DCF_Base'!H16/POWER(1+B5,6)+'DCF_Base'!I16/POWER(1+B5,7)+'DCF_Base'!J16/POWER(1+B5,8)+'DCF_Base'!K16/POWER(1+B5,9)+'DCF_Base'!L16/POWER(1+B5,10))+(('DCF_Base'!L11*(1+A7))*(1-A7/'Assumptions'!$E$30)/(B5-A7))/POWER(1+B5,10)+'Assumptions'!$E$9-('Assumptions'!$E$8+'Assumptions'!$E$10+'Assumptions'!$E$11+'Assumptions'!$E$12+'Assumptions'!$E$13+'Assumptions'!$E$14+'Assumptions'!$E$15))/('Assumptions'!$E$6*POWER(1+'Assumptions'!$E$7,10))) | C7: =IF(C5<=A7,NA(),(('DCF_Base'!C16/POWER(1+C5,1)+'DCF_Base'!D16/POWER(1+C5,2)+'DCF_Base'!E16/POWER(1+C5,3)+'DCF_Base'!F16/POWER(1+C5,4)+'DCF_Base'!G16/POWER(1+C5,5)+'DCF_Base'!H16/POWER(1+C5,6)+'DCF_Base'!I16/POWER(1+C5,7)+'DCF_Base'!J16/POWER(1+C5,8)+'DCF_Base'!K16/POWER(1+C5,9)+'DCF_Base'!L16/POWER(1+C5,10))+(('DCF_Base'!L11*(1+A7))*(1-A7/'Assumptions'!$E$30)/(C5-A7))/POWER(1+C5,10)+'Assumptions'!$E$9-('Assumptions'!$E$8+'Assumptions'!$E$10+'Assumptions'!$E$11+'Assumptions'!$E$12+'Assumptions'!$E$13+'Assumptions'!$E$14+'Assumptions'!$E$15))/('Assumptions'!$E$6*POWER(1+'Assumptions'!$E$7,10))) | D7: =IF(D5<=A7,NA(),(('DCF_Base'!C16/POWER(1+D5,1)+'DCF_Base'!D16/POWER(1+D5,2)+'DCF_Base'!E16/POWER(1+D5,3)+'DCF_Base'!F16/POWER(1+D5,4)+'DCF_Base'!G16/POWER(1+D5,5)+'DCF_Base'!H16/POWER(1+D5,6)+'DCF_Base'!I16/POWER(1+D5,7)+'DCF_Base'!J16/POWER(1+D5,8)+'DCF_Base'!K16/POWER(1+D5,9)+'DCF_Base'!L16/POWER(1+D5,10))+(('DCF_Base'!L11*(1+A7))*(1-A7/'Assumptions'!$E$30)/(D5-A7))/POWER(1+D5,10)+'Assumptions'!$E$9-('Assumptions'!$E$8+'Assumptions'!$E$10+'Assumptions'!$E$11+'Assumptions'!$E$12+'Assumptions'!$E$13+'Assumptions'!$E$14+'Assumptions'!$E$15))/('Assumptions'!$E$6*POWER(1+'Assumptions'!$E$7,10))) | E7: =IF(E5<=A7,NA(),(('DCF_Base'!C16/POWER(1+E5,1)+'DCF_Base'!D16/POWER(1+E5,2)+'DCF_Base'!E16/POWER(1+E5,3)+'DCF_Base'!F16/POWER(1+E5,4)+'DCF_Base'!G16/POWER(1+E5,5)+'DCF_Base'!H16/POWER(1+E5,6)+'DCF_Base'!I16/POWER(1+E5,7)+'DCF_Base'!J16/POWER(1+E5,8)+'DCF_Base'!K16/POWER(1+E5,9)+'DCF_Base'!L16/POWER(1+E5,10))+(('DCF_Base'!L11*(1+A7))*(1-A7/'Assumptions'!$E$30)/(E5-A7))/POWER(1+E5,10)+'Assumptions'!$E$9-('Assumptions'!$E$8+'Assumptions'!$E$10+'Assumptions'!$E$11+'Assumptions'!$E$12+'Assumptions'!$E$13+'Assumptions'!$E$14+'Assumptions'!$E$15))/('Assumptions'!$E$6*POWER(1+'Assumptions'!$E$7,10))) | F7: =IF(F5<=A7,NA(),(('DCF_Base'!C16/POWER(1+F5,1)+'DCF_Base'!D16/POWER(1+F5,2)+'DCF_Base'!E16/POWER(1+F5,3)+'DCF_Base'!F16/POWER(1+F5,4)+'DCF_Base'!G16/POWER(1+F5,5)+'DCF_Base'!H16/POWER(1+F5,6)+'DCF_Base'!I16/POWER(1+F5,7)+'DCF_Base'!J16/POWER(1+F5,8)+'DCF_Base'!K16/POWER(1+F5,9)+'DCF_Base'!L16/POWER(1+F5,10))+(('DCF_Base'!L11*(1+A7))*(1-A7/'Assumptions'!$E$30)/(F5-A7))/POWER(1+F5,10)+'Assumptions'!$E$9-('Assumptions'!$E$8+'Assumptions'!$E$10+'Assumptions'!$E$11+'Assumptions'!$E$12+'Assumptions'!$E$13+'Assumptions'!$E$14+'Assumptions'!$E$15))/('Assumptions'!$E$6*POWER(1+'Assumptions'!$E$7,10)))
A8: ='Assumptions'!$E$18+0.0 | B8: =IF(B5<=A8,NA(),(('DCF_Base'!C16/POWER(1+B5,1)+'DCF_Base'!D16/POWER(1+B5,2)+'DCF_Base'!E16/POWER(1+B5,3)+'DCF_Base'!F16/POWER(1+B5,4)+'DCF_Base'!G16/POWER(1+B5,5)+'DCF_Base'!H16/POWER(1+B5,6)+'DCF_Base'!I16/POWER(1+B5,7)+'DCF_Base'!J16/POWER(1+B5,8)+'DCF_Base'!K16/POWER(1+B5,9)+'DCF_Base'!L16/POWER(1+B5,10))+(('DCF_Base'!L11*(1+A8))*(1-A8/'Assumptions'!$E$30)/(B5-A8))/POWER(1+B5,10)+'Assumptions'!$E$9-('Assumptions'!$E$8+'Assumptions'!$E$10+'Assumptions'!$E$11+'Assumptions'!$E$12+'Assumptions'!$E$13+'Assumptions'!$E$14+'Assumptions'!$E$15))/('Assumptions'!$E$6*POWER(1+'Assumptions'!$E$7,10))) | C8: =IF(C5<=A8,NA(),(('DCF_Base'!C16/POWER(1+C5,1)+'DCF_Base'!D16/POWER(1+C5,2)+'DCF_Base'!E16/POWER(1+C5,3)+'DCF_Base'!F16/POWER(1+C5,4)+'DCF_Base'!G16/POWER(1+C5,5)+'DCF_Base'!H16/POWER(1+C5,6)+'DCF_Base'!I16/POWER(1+C5,7)+'DCF_Base'!J16/POWER(1+C5,8)+'DCF_Base'!K16/POWER(1+C5,9)+'DCF_Base'!L16/POWER(1+C5,10))+(('DCF_Base'!L11*(1+A8))*(1-A8/'Assumptions'!$E$30)/(C5-A8))/POWER(1+C5,10)+'Assumptions'!$E$9-('Assumptions'!$E$8+'Assumptions'!$E$10+'Assumptions'!$E$11+'Assumptions'!$E$12+'Assumptions'!$E$13+'Assumptions'!$E$14+'Assumptions'!$E$15))/('Assumptions'!$E$6*POWER(1+'Assumptions'!$E$7,10))) | D8: =IF(D5<=A8,NA(),(('DCF_Base'!C16/POWER(1+D5,1)+'DCF_Base'!D16/POWER(1+D5,2)+'DCF_Base'!E16/POWER(1+D5,3)+'DCF_Base'!F16/POWER(1+D5,4)+'DCF_Base'!G16/POWER(1+D5,5)+'DCF_Base'!H16/POWER(1+D5,6)+'DCF_Base'!I16/POWER(1+D5,7)+'DCF_Base'!J16/POWER(1+D5,8)+'DCF_Base'!K16/POWER(1+D5,9)+'DCF_Base'!L16/POWER(1+D5,10))+(('DCF_Base'!L11*(1+A8))*(1-A8/'Assumptions'!$E$30)/(D5-A8))/POWER(1+D5,10)+'Assumptions'!$E$9-('Assumptions'!$E$8+'Assumptions'!$E$10+'Assumptions'!$E$11+'Assumptions'!$E$12+'Assumptions'!$E$13+'Assumptions'!$E$14+'Assumptions'!$E$15))/('Assumptions'!$E$6*POWER(1+'Assumptions'!$E$7,10))) | E8: =IF(E5<=A8,NA(),(('DCF_Base'!C16/POWER(1+E5,1)+'DCF_Base'!D16/POWER(1+E5,2)+'DCF_Base'!E16/POWER(1+E5,3)+'DCF_Base'!F16/POWER(1+E5,4)+'DCF_Base'!G16/POWER(1+E5,5)+'DCF_Base'!H16/POWER(1+E5,6)+'DCF_Base'!I16/POWER(1+E5,7)+'DCF_Base'!J16/POWER(1+E5,8)+'DCF_Base'!K16/POWER(1+E5,9)+'DCF_Base'!L16/POWER(1+E5,10))+(('DCF_Base'!L11*(1+A8))*(1-A8/'Assumptions'!$E$30)/(E5-A8))/POWER(1+E5,10)+'Assumptions'!$E$9-('Assumptions'!$E$8+'Assumptions'!$E$10+'Assumptions'!$E$11+'Assumptions'!$E$12+'Assumptions'!$E$13+'Assumptions'!$E$14+'Assumptions'!$E$15))/('Assumptions'!$E$6*POWER(1+'Assumptions'!$E$7,10))) | F8: =IF(F5<=A8,NA(),(('DCF_Base'!C16/POWER(1+F5,1)+'DCF_Base'!D16/POWER(1+F5,2)+'DCF_Base'!E16/POWER(1+F5,3)+'DCF_Base'!F16/POWER(1+F5,4)+'DCF_Base'!G16/POWER(1+F5,5)+'DCF_Base'!H16/POWER(1+F5,6)+'DCF_Base'!I16/POWER(1+F5,7)+'DCF_Base'!J16/POWER(1+F5,8)+'DCF_Base'!K16/POWER(1+F5,9)+'DCF_Base'!L16/POWER(1+F5,10))+(('DCF_Base'!L11*(1+A8))*(1-A8/'Assumptions'!$E$30)/(F5-A8))/POWER(1+F5,10)+'Assumptions'!$E$9-('Assumptions'!$E$8+'Assumptions'!$E$10+'Assumptions'!$E$11+'Assumptions'!$E$12+'Assumptions'!$E$13+'Assumptions'!$E$14+'Assumptions'!$E$15))/('Assumptions'!$E$6*POWER(1+'Assumptions'!$E$7,10)))
A9: ='Assumptions'!$E$18+0.005 | B9: =IF(B5<=A9,NA(),(('DCF_Base'!C16/POWER(1+B5,1)+'DCF_Base'!D16/POWER(1+B5,2)+'DCF_Base'!E16/POWER(1+B5,3)+'DCF_Base'!F16/POWER(1+B5,4)+'DCF_Base'!G16/POWER(1+B5,5)+'DCF_Base'!H16/POWER(1+B5,6)+'DCF_Base'!I16/POWER(1+B5,7)+'DCF_Base'!J16/POWER(1+B5,8)+'DCF_Base'!K16/POWER(1+B5,9)+'DCF_Base'!L16/POWER(1+B5,10))+(('DCF_Base'!L11*(1+A9))*(1-A9/'Assumptions'!$E$30)/(B5-A9))/POWER(1+B5,10)+'Assumptions'!$E$9-('Assumptions'!$E$8+'Assumptions'!$E$10+'Assumptions'!$E$11+'Assumptions'!$E$12+'Assumptions'!$E$13+'Assumptions'!$E$14+'Assumptions'!$E$15))/('Assumptions'!$E$6*POWER(1+'Assumptions'!$E$7,10))) | C9: =IF(C5<=A9,NA(),(('DCF_Base'!C16/POWER(1+C5,1)+'DCF_Base'!D16/POWER(1+C5,2)+'DCF_Base'!E16/POWER(1+C5,3)+'DCF_Base'!F16/POWER(1+C5,4)+'DCF_Base'!G16/POWER(1+C5,5)+'DCF_Base'!H16/POWER(1+C5,6)+'DCF_Base'!I16/POWER(1+C5,7)+'DCF_Base'!J16/POWER(1+C5,8)+'DCF_Base'!K16/POWER(1+C5,9)+'DCF_Base'!L16/POWER(1+C5,10))+(('DCF_Base'!L11*(1+A9))*(1-A9/'Assumptions'!$E$30)/(C5-A9))/POWER(1+C5,10)+'Assumptions'!$E$9-('Assumptions'!$E$8+'Assumptions'!$E$10+'Assumptions'!$E$11+'Assumptions'!$E$12+'Assumptions'!$E$13+'Assumptions'!$E$14+'Assumptions'!$E$15))/('Assumptions'!$E$6*POWER(1+'Assumptions'!$E$7,10))) | D9: =IF(D5<=A9,NA(),(('DCF_Base'!C16/POWER(1+D5,1)+'DCF_Base'!D16/POWER(1+D5,2)+'DCF_Base'!E16/POWER(1+D5,3)+'DCF_Base'!F16/POWER(1+D5,4)+'DCF_Base'!G16/POWER(1+D5,5)+'DCF_Base'!H16/POWER(1+D5,6)+'DCF_Base'!I16/POWER(1+D5,7)+'DCF_Base'!J16/POWER(1+D5,8)+'DCF_Base'!K16/POWER(1+D5,9)+'DCF_Base'!L16/POWER(1+D5,10))+(('DCF_Base'!L11*(1+A9))*(1-A9/'Assumptions'!$E$30)/(D5-A9))/POWER(1+D5,10)+'Assumptions'!$E$9-('Assumptions'!$E$8+'Assumptions'!$E$10+'Assumptions'!$E$11+'Assumptions'!$E$12+'Assumptions'!$E$13+'Assumptions'!$E$14+'Assumptions'!$E$15))/('Assumptions'!$E$6*POWER(1+'Assumptions'!$E$7,10))) | E9: =IF(E5<=A9,NA(),(('DCF_Base'!C16/POWER(1+E5,1)+'DCF_Base'!D16/POWER(1+E5,2)+'DCF_Base'!E16/POWER(1+E5,3)+'DCF_Base'!F16/POWER(1+E5,4)+'DCF_Base'!G16/POWER(1+E5,5)+'DCF_Base'!H16/POWER(1+E5,6)+'DCF_Base'!I16/POWER(1+E5,7)+'DCF_Base'!J16/POWER(1+E5,8)+'DCF_Base'!K16/POWER(1+E5,9)+'DCF_Base'!L16/POWER(1+E5,10))+(('DCF_Base'!L11*(1+A9))*(1-A9/'Assumptions'!$E$30)/(E5-A9))/POWER(1+E5,10)+'Assumptions'!$E$9-('Assumptions'!$E$8+'Assumptions'!$E$10+'Assumptions'!$E$11+'Assumptions'!$E$12+'Assumptions'!$E$13+'Assumptions'!$E$14+'Assumptions'!$E$15))/('Assumptions'!$E$6*POWER(1+'Assumptions'!$E$7,10))) | F9: =IF(F5<=A9,NA(),(('DCF_Base'!C16/POWER(1+F5,1)+'DCF_Base'!D16/POWER(1+F5,2)+'DCF_Base'!E16/POWER(1+F5,3)+'DCF_Base'!F16/POWER(1+F5,4)+'DCF_Base'!G16/POWER(1+F5,5)+'DCF_Base'!H16/POWER(1+F5,6)+'DCF_Base'!I16/POWER(1+F5,7)+'DCF_Base'!J16/POWER(1+F5,8)+'DCF_Base'!K16/POWER(1+F5,9)+'DCF_Base'!L16/POWER(1+F5,10))+(('DCF_Base'!L11*(1+A9))*(1-A9/'Assumptions'!$E$30)/(F5-A9))/POWER(1+F5,10)+'Assumptions'!$E$9-('Assumptions'!$E$8+'Assumptions'!$E$10+'Assumptions'!$E$11+'Assumptions'!$E$12+'Assumptions'!$E$13+'Assumptions'!$E$14+'Assumptions'!$E$15))/('Assumptions'!$E$6*POWER(1+'Assumptions'!$E$7,10)))
A10: ='Assumptions'!$E$18+0.01 | B10: =IF(B5<=A10,NA(),(('DCF_Base'!C16/POWER(1+B5,1)+'DCF_Base'!D16/POWER(1+B5,2)+'DCF_Base'!E16/POWER(1+B5,3)+'DCF_Base'!F16/POWER(1+B5,4)+'DCF_Base'!G16/POWER(1+B5,5)+'DCF_Base'!H16/POWER(1+B5,6)+'DCF_Base'!I16/POWER(1+B5,7)+'DCF_Base'!J16/POWER(1+B5,8)+'DCF_Base'!K16/POWER(1+B5,9)+'DCF_Base'!L16/POWER(1+B5,10))+(('DCF_Base'!L11*(1+A10))*(1-A10/'Assumptions'!$E$30)/(B5-A10))/POWER(1+B5,10)+'Assumptions'!$E$9-('Assumptions'!$E$8+'Assumptions'!$E$10+'Assumptions'!$E$11+'Assumptions'!$E$12+'Assumptions'!$E$13+'Assumptions'!$E$14+'Assumptions'!$E$15))/('Assumptions'!$E$6*POWER(1+'Assumptions'!$E$7,10))) | C10: =IF(C5<=A10,NA(),(('DCF_Base'!C16/POWER(1+C5,1)+'DCF_Base'!D16/POWER(1+C5,2)+'DCF_Base'!E16/POWER(1+C5,3)+'DCF_Base'!F16/POWER(1+C5,4)+'DCF_Base'!G16/POWER(1+C5,5)+'DCF_Base'!H16/POWER(1+C5,6)+'DCF_Base'!I16/POWER(1+C5,7)+'DCF_Base'!J16/POWER(1+C5,8)+'DCF_Base'!K16/POWER(1+C5,9)+'DCF_Base'!L16/POWER(1+C5,10))+(('DCF_Base'!L11*(1+A10))*(1-A10/'Assumptions'!$E$30)/(C5-A10))/POWER(1+C5,10)+'Assumptions'!$E$9-('Assumptions'!$E$8+'Assumptions'!$E$10+'Assumptions'!$E$11+'Assumptions'!$E$12+'Assumptions'!$E$13+'Assumptions'!$E$14+'Assumptions'!$E$15))/('Assumptions'!$E$6*POWER(1+'Assumptions'!$E$7,10))) | D10: =IF(D5<=A10,NA(),(('DCF_Base'!C16/POWER(1+D5,1)+'DCF_Base'!D16/POWER(1+D5,2)+'DCF_Base'!E16/POWER(1+D5,3)+'DCF_Base'!F16/POWER(1+D5,4)+'DCF_Base'!G16/POWER(1+D5,5)+'DCF_Base'!H16/POWER(1+D5,6)+'DCF_Base'!I16/POWER(1+D5,7)+'DCF_Base'!J16/POWER(1+D5,8)+'DCF_Base'!K16/POWER(1+D5,9)+'DCF_Base'!L16/POWER(1+D5,10))+(('DCF_Base'!L11*(1+A10))*(1-A10/'Assumptions'!$E$30)/(D5-A10))/POWER(1+D5,10)+'Assumptions'!$E$9-('Assumptions'!$E$8+'Assumptions'!$E$10+'Assumptions'!$E$11+'Assumptions'!$E$12+'Assumptions'!$E$13+'Assumptions'!$E$14+'Assumptions'!$E$15))/('Assumptions'!$E$6*POWER(1+'Assumptions'!$E$7,10))) | E10: =IF(E5<=A10,NA(),(('DCF_Base'!C16/POWER(1+E5,1)+'DCF_Base'!D16/POWER(1+E5,2)+'DCF_Base'!E16/POWER(1+E5,3)+'DCF_Base'!F16/POWER(1+E5,4)+'DCF_Base'!G16/POWER(1+E5,5)+'DCF_Base'!H16/POWER(1+E5,6)+'DCF_Base'!I16/POWER(1+E5,7)+'DCF_Base'!J16/POWER(1+E5,8)+'DCF_Base'!K16/POWER(1+E5,9)+'DCF_Base'!L16/POWER(1+E5,10))+(('DCF_Base'!L11*(1+A10))*(1-A10/'Assumptions'!$E$30)/(E5-A10))/POWER(1+E5,10)+'Assumptions'!$E$9-('Assumptions'!$E$8+'Assumptions'!$E$10+'Assumptions'!$E$11+'Assumptions'!$E$12+'Assumptions'!$E$13+'Assumptions'!$E$14+'Assumptions'!$E$15))/('Assumptions'!$E$6*POWER(1+'Assumptions'!$E$7,10))) | F10: =IF(F5<=A10,NA(),(('DCF_Base'!C16/POWER(1+F5,1)+'DCF_Base'!D16/POWER(1+F5,2)+'DCF_Base'!E16/POWER(1+F5,3)+'DCF_Base'!F16/POWER(1+F5,4)+'DCF_Base'!G16/POWER(1+F5,5)+'DCF_Base'!H16/POWER(1+F5,6)+'DCF_Base'!I16/POWER(1+F5,7)+'DCF_Base'!J16/POWER(1+F5,8)+'DCF_Base'!K16/POWER(1+F5,9)+'DCF_Base'!L16/POWER(1+F5,10))+(('DCF_Base'!L11*(1+A10))*(1-A10/'Assumptions'!$E$30)/(F5-A10))/POWER(1+F5,10)+'Assumptions'!$E$9-('Assumptions'!$E$8+'Assumptions'!$E$10+'Assumptions'!$E$11+'Assumptions'!$E$12+'Assumptions'!$E$13+'Assumptions'!$E$14+'Assumptions'!$E$15))/('Assumptions'!$E$6*POWER(1+'Assumptions'!$E$7,10)))
A13: IV/share: WACC (cols) vs exit multiple (rows) — exit path
A14: Exit \ WACC | B14: ='Assumptions'!$E$19+-0.01 | C14: ='Assumptions'!$E$19+-0.005 | D14: ='Assumptions'!$E$19+0.0 | E14: ='Assumptions'!$E$19+0.005 | F14: ='Assumptions'!$E$19+0.01
A15: ='Assumptions'!$E$28+-2 | B15: =(('DCF_Base'!C16/POWER(1+B14,1)+'DCF_Base'!D16/POWER(1+B14,2)+'DCF_Base'!E16/POWER(1+B14,3)+'DCF_Base'!F16/POWER(1+B14,4)+'DCF_Base'!G16/POWER(1+B14,5)+'DCF_Base'!H16/POWER(1+B14,6)+'DCF_Base'!I16/POWER(1+B14,7)+'DCF_Base'!J16/POWER(1+B14,8)+'DCF_Base'!K16/POWER(1+B14,9)+'DCF_Base'!L16/POWER(1+B14,10))+(IF('Assumptions'!$E$29="ev_ebit",'DCF_Base'!L9,'DCF_Base'!L20)*A15)/POWER(1+B14,10)+'Assumptions'!$E$9-('Assumptions'!$E$8+'Assumptions'!$E$10+'Assumptions'!$E$11+'Assumptions'!$E$12+'Assumptions'!$E$13+'Assumptions'!$E$14+'Assumptions'!$E$15))/('Assumptions'!$E$6*POWER(1+'Assumptions'!$E$7,10)) | C15: =(('DCF_Base'!C16/POWER(1+C14,1)+'DCF_Base'!D16/POWER(1+C14,2)+'DCF_Base'!E16/POWER(1+C14,3)+'DCF_Base'!F16/POWER(1+C14,4)+'DCF_Base'!G16/POWER(1+C14,5)+'DCF_Base'!H16/POWER(1+C14,6)+'DCF_Base'!I16/POWER(1+C14,7)+'DCF_Base'!J16/POWER(1+C14,8)+'DCF_Base'!K16/POWER(1+C14,9)+'DCF_Base'!L16/POWER(1+C14,10))+(IF('Assumptions'!$E$29="ev_ebit",'DCF_Base'!L9,'DCF_Base'!L20)*A15)/POWER(1+C14,10)+'Assumptions'!$E$9-('Assumptions'!$E$8+'Assumptions'!$E$10+'Assumptions'!$E$11+'Assumptions'!$E$12+'Assumptions'!$E$13+'Assumptions'!$E$14+'Assumptions'!$E$15))/('Assumptions'!$E$6*POWER(1+'Assumptions'!$E$7,10)) | D15: =(('DCF_Base'!C16/POWER(1+D14,1)+'DCF_Base'!D16/POWER(1+D14,2)+'DCF_Base'!E16/POWER(1+D14,3)+'DCF_Base'!F16/POWER(1+D14,4)+'DCF_Base'!G16/POWER(1+D14,5)+'DCF_Base'!H16/POWER(1+D14,6)+'DCF_Base'!I16/POWER(1+D14,7)+'DCF_Base'!J16/POWER(1+D14,8)+'DCF_Base'!K16/POWER(1+D14,9)+'DCF_Base'!L16/POWER(1+D14,10))+(IF('Assumptions'!$E$29="ev_ebit",'DCF_Base'!L9,'DCF_Base'!L20)*A15)/POWER(1+D14,10)+'Assumptions'!$E$9-('Assumptions'!$E$8+'Assumptions'!$E$10+'Assumptions'!$E$11+'Assumptions'!$E$12+'Assumptions'!$E$13+'Assumptions'!$E$14+'Assumptions'!$E$15))/('Assumptions'!$E$6*POWER(1+'Assumptions'!$E$7,10)) | E15: =(('DCF_Base'!C16/POWER(1+E14,1)+'DCF_Base'!D16/POWER(1+E14,2)+'DCF_Base'!E16/POWER(1+E14,3)+'DCF_Base'!F16/POWER(1+E14,4)+'DCF_Base'!G16/POWER(1+E14,5)+'DCF_Base'!H16/POWER(1+E14,6)+'DCF_Base'!I16/POWER(1+E14,7)+'DCF_Base'!J16/POWER(1+E14,8)+'DCF_Base'!K16/POWER(1+E14,9)+'DCF_Base'!L16/POWER(1+E14,10))+(IF('Assumptions'!$E$29="ev_ebit",'DCF_Base'!L9,'DCF_Base'!L20)*A15)/POWER(1+E14,10)+'Assumptions'!$E$9-('Assumptions'!$E$8+'Assumptions'!$E$10+'Assumptions'!$E$11+'Assumptions'!$E$12+'Assumptions'!$E$13+'Assumptions'!$E$14+'Assumptions'!$E$15))/('Assumptions'!$E$6*POWER(1+'Assumptions'!$E$7,10)) | F15: =(('DCF_Base'!C16/POWER(1+F14,1)+'DCF_Base'!D16/POWER(1+F14,2)+'DCF_Base'!E16/POWER(1+F14,3)+'DCF_Base'!F16/POWER(1+F14,4)+'DCF_Base'!G16/POWER(1+F14,5)+'DCF_Base'!H16/POWER(1+F14,6)+'DCF_Base'!I16/POWER(1+F14,7)+'DCF_Base'!J16/POWER(1+F14,8)+'DCF_Base'!K16/POWER(1+F14,9)+'DCF_Base'!L16/POWER(1+F14,10))+(IF('Assumptions'!$E$29="ev_ebit",'DCF_Base'!L9,'DCF_Base'!L20)*A15)/POWER(1+F14,10)+'Assumptions'!$E$9-('Assumptions'!$E$8+'Assumptions'!$E$10+'Assumptions'!$E$11+'Assumptions'!$E$12+'Assumptions'!$E$13+'Assumptions'!$E$14+'Assumptions'!$E$15))/('Assumptions'!$E$6*POWER(1+'Assumptions'!$E$7,10))
A16: ='Assumptions'!$E$28+-1 | B16: =(('DCF_Base'!C16/POWER(1+B14,1)+'DCF_Base'!D16/POWER(1+B14,2)+'DCF_Base'!E16/POWER(1+B14,3)+'DCF_Base'!F16/POWER(1+B14,4)+'DCF_Base'!G16/POWER(1+B14,5)+'DCF_Base'!H16/POWER(1+B14,6)+'DCF_Base'!I16/POWER(1+B14,7)+'DCF_Base'!J16/POWER(1+B14,8)+'DCF_Base'!K16/POWER(1+B14,9)+'DCF_Base'!L16/POWER(1+B14,10))+(IF('Assumptions'!$E$29="ev_ebit",'DCF_Base'!L9,'DCF_Base'!L20)*A16)/POWER(1+B14,10)+'Assumptions'!$E$9-('Assumptions'!$E$8+'Assumptions'!$E$10+'Assumptions'!$E$11+'Assumptions'!$E$12+'Assumptions'!$E$13+'Assumptions'!$E$14+'Assumptions'!$E$15))/('Assumptions'!$E$6*POWER(1+'Assumptions'!$E$7,10)) | C16: =(('DCF_Base'!C16/POWER(1+C14,1)+'DCF_Base'!D16/POWER(1+C14,2)+'DCF_Base'!E16/POWER(1+C14,3)+'DCF_Base'!F16/POWER(1+C14,4)+'DCF_Base'!G16/POWER(1+C14,5)+'DCF_Base'!H16/POWER(1+C14,6)+'DCF_Base'!I16/POWER(1+C14,7)+'DCF_Base'!J16/POWER(1+C14,8)+'DCF_Base'!K16/POWER(1+C14,9)+'DCF_Base'!L16/POWER(1+C14,10))+(IF('Assumptions'!$E$29="ev_ebit",'DCF_Base'!L9,'DCF_Base'!L20)*A16)/POWER(1+C14,10)+'Assumptions'!$E$9-('Assumptions'!$E$8+'Assumptions'!$E$10+'Assumptions'!$E$11+'Assumptions'!$E$12+'Assumptions'!$E$13+'Assumptions'!$E$14+'Assumptions'!$E$15))/('Assumptions'!$E$6*POWER(1+'Assumptions'!$E$7,10)) | D16: =(('DCF_Base'!C16/POWER(1+D14,1)+'DCF_Base'!D16/POWER(1+D14,2)+'DCF_Base'!E16/POWER(1+D14,3)+'DCF_Base'!F16/POWER(1+D14,4)+'DCF_Base'!G16/POWER(1+D14,5)+'DCF_Base'!H16/POWER(1+D14,6)+'DCF_Base'!I16/POWER(1+D14,7)+'DCF_Base'!J16/POWER(1+D14,8)+'DCF_Base'!K16/POWER(1+D14,9)+'DCF_Base'!L16/POWER(1+D14,10))+(IF('Assumptions'!$E$29="ev_ebit",'DCF_Base'!L9,'DCF_Base'!L20)*A16)/POWER(1+D14,10)+'Assumptions'!$E$9-('Assumptions'!$E$8+'Assumptions'!$E$10+'Assumptions'!$E$11+'Assumptions'!$E$12+'Assumptions'!$E$13+'Assumptions'!$E$14+'Assumptions'!$E$15))/('Assumptions'!$E$6*POWER(1+'Assumptions'!$E$7,10)) | E16: =(('DCF_Base'!C16/POWER(1+E14,1)+'DCF_Base'!D16/POWER(1+E14,2)+'DCF_Base'!E16/POWER(1+E14,3)+'DCF_Base'!F16/POWER(1+E14,4)+'DCF_Base'!G16/POWER(1+E14,5)+'DCF_Base'!H16/POWER(1+E14,6)+'DCF_Base'!I16/POWER(1+E14,7)+'DCF_Base'!J16/POWER(1+E14,8)+'DCF_Base'!K16/POWER(1+E14,9)+'DCF_Base'!L16/POWER(1+E14,10))+(IF('Assumptions'!$E$29="ev_ebit",'DCF_Base'!L9,'DCF_Base'!L20)*A16)/POWER(1+E14,10)+'Assumptions'!$E$9-('Assumptions'!$E$8+'Assumptions'!$E$10+'Assumptions'!$E$11+'Assumptions'!$E$12+'Assumptions'!$E$13+'Assumptions'!$E$14+'Assumptions'!$E$15))/('Assumptions'!$E$6*POWER(1+'Assumptions'!$E$7,10)) | F16: =(('DCF_Base'!C16/POWER(1+F14,1)+'DCF_Base'!D16/POWER(1+F14,2)+'DCF_Base'!E16/POWER(1+F14,3)+'DCF_Base'!F16/POWER(1+F14,4)+'DCF_Base'!G16/POWER(1+F14,5)+'DCF_Base'!H16/POWER(1+F14,6)+'DCF_Base'!I16/POWER(1+F14,7)+'DCF_Base'!J16/POWER(1+F14,8)+'DCF_Base'!K16/POWER(1+F14,9)+'DCF_Base'!L16/POWER(1+F14,10))+(IF('Assumptions'!$E$29="ev_ebit",'DCF_Base'!L9,'DCF_Base'!L20)*A16)/POWER(1+F14,10)+'Assumptions'!$E$9-('Assumptions'!$E$8+'Assumptions'!$E$10+'Assumptions'!$E$11+'Assumptions'!$E$12+'Assumptions'!$E$13+'Assumptions'!$E$14+'Assumptions'!$E$15))/('Assumptions'!$E$6*POWER(1+'Assumptions'!$E$7,10))
A17: ='Assumptions'!$E$28+0 | B17: =(('DCF_Base'!C16/POWER(1+B14,1)+'DCF_Base'!D16/POWER(1+B14,2)+'DCF_Base'!E16/POWER(1+B14,3)+'DCF_Base'!F16/POWER(1+B14,4)+'DCF_Base'!G16/POWER(1+B14,5)+'DCF_Base'!H16/POWER(1+B14,6)+'DCF_Base'!I16/POWER(1+B14,7)+'DCF_Base'!J16/POWER(1+B14,8)+'DCF_Base'!K16/POWER(1+B14,9)+'DCF_Base'!L16/POWER(1+B14,10))+(IF('Assumptions'!$E$29="ev_ebit",'DCF_Base'!L9,'DCF_Base'!L20)*A17)/POWER(1+B14,10)+'Assumptions'!$E$9-('Assumptions'!$E$8+'Assumptions'!$E$10+'Assumptions'!$E$11+'Assumptions'!$E$12+'Assumptions'!$E$13+'Assumptions'!$E$14+'Assumptions'!$E$15))/('Assumptions'!$E$6*POWER(1+'Assumptions'!$E$7,10)) | C17: =(('DCF_Base'!C16/POWER(1+C14,1)+'DCF_Base'!D16/POWER(1+C14,2)+'DCF_Base'!E16/POWER(1+C14,3)+'DCF_Base'!F16/POWER(1+C14,4)+'DCF_Base'!G16/POWER(1+C14,5)+'DCF_Base'!H16/POWER(1+C14,6)+'DCF_Base'!I16/POWER(1+C14,7)+'DCF_Base'!J16/POWER(1+C14,8)+'DCF_Base'!K16/POWER(1+C14,9)+'DCF_Base'!L16/POWER(1+C14,10))+(IF('Assumptions'!$E$29="ev_ebit",'DCF_Base'!L9,'DCF_Base'!L20)*A17)/POWER(1+C14,10)+'Assumptions'!$E$9-('Assumptions'!$E$8+'Assumptions'!$E$10+'Assumptions'!$E$11+'Assumptions'!$E$12+'Assumptions'!$E$13+'Assumptions'!$E$14+'Assumptions'!$E$15))/('Assumptions'!$E$6*POWER(1+'Assumptions'!$E$7,10)) | D17: =(('DCF_Base'!C16/POWER(1+D14,1)+'DCF_Base'!D16/POWER(1+D14,2)+'DCF_Base'!E16/POWER(1+D14,3)+'DCF_Base'!F16/POWER(1+D14,4)+'DCF_Base'!G16/POWER(1+D14,5)+'DCF_Base'!H16/POWER(1+D14,6)+'DCF_Base'!I16/POWER(1+D14,7)+'DCF_Base'!J16/POWER(1+D14,8)+'DCF_Base'!K16/POWER(1+D14,9)+'DCF_Base'!L16/POWER(1+D14,10))+(IF('Assumptions'!$E$29="ev_ebit",'DCF_Base'!L9,'DCF_Base'!L20)*A17)/POWER(1+D14,10)+'Assumptions'!$E$9-('Assumptions'!$E$8+'Assumptions'!$E$10+'Assumptions'!$E$11+'Assumptions'!$E$12+'Assumptions'!$E$13+'Assumptions'!$E$14+'Assumptions'!$E$15))/('Assumptions'!$E$6*POWER(1+'Assumptions'!$E$7,10)) | E17: =(('DCF_Base'!C16/POWER(1+E14,1)+'DCF_Base'!D16/POWER(1+E14,2)+'DCF_Base'!E16/POWER(1+E14,3)+'DCF_Base'!F16/POWER(1+E14,4)+'DCF_Base'!G16/POWER(1+E14,5)+'DCF_Base'!H16/POWER(1+E14,6)+'DCF_Base'!I16/POWER(1+E14,7)+'DCF_Base'!J16/POWER(1+E14,8)+'DCF_Base'!K16/POWER(1+E14,9)+'DCF_Base'!L16/POWER(1+E14,10))+(IF('Assumptions'!$E$29="ev_ebit",'DCF_Base'!L9,'DCF_Base'!L20)*A17)/POWER(1+E14,10)+'Assumptions'!$E$9-('Assumptions'!$E$8+'Assumptions'!$E$10+'Assumptions'!$E$11+'Assumptions'!$E$12+'Assumptions'!$E$13+'Assumptions'!$E$14+'Assumptions'!$E$15))/('Assumptions'!$E$6*POWER(1+'Assumptions'!$E$7,10)) | F17: =(('DCF_Base'!C16/POWER(1+F14,1)+'DCF_Base'!D16/POWER(1+F14,2)+'DCF_Base'!E16/POWER(1+F14,3)+'DCF_Base'!F16/POWER(1+F14,4)+'DCF_Base'!G16/POWER(1+F14,5)+'DCF_Base'!H16/POWER(1+F14,6)+'DCF_Base'!I16/POWER(1+F14,7)+'DCF_Base'!J16/POWER(1+F14,8)+'DCF_Base'!K16/POWER(1+F14,9)+'DCF_Base'!L16/POWER(1+F14,10))+(IF('Assumptions'!$E$29="ev_ebit",'DCF_Base'!L9,'DCF_Base'!L20)*A17)/POWER(1+F14,10)+'Assumptions'!$E$9-('Assumptions'!$E$8+'Assumptions'!$E$10+'Assumptions'!$E$11+'Assumptions'!$E$12+'Assumptions'!$E$13+'Assumptions'!$E$14+'Assumptions'!$E$15))/('Assumptions'!$E$6*POWER(1+'Assumptions'!$E$7,10))
A18: ='Assumptions'!$E$28+1 | B18: =(('DCF_Base'!C16/POWER(1+B14,1)+'DCF_Base'!D16/POWER(1+B14,2)+'DCF_Base'!E16/POWER(1+B14,3)+'DCF_Base'!F16/POWER(1+B14,4)+'DCF_Base'!G16/POWER(1+B14,5)+'DCF_Base'!H16/POWER(1+B14,6)+'DCF_Base'!I16/POWER(1+B14,7)+'DCF_Base'!J16/POWER(1+B14,8)+'DCF_Base'!K16/POWER(1+B14,9)+'DCF_Base'!L16/POWER(1+B14,10))+(IF('Assumptions'!$E$29="ev_ebit",'DCF_Base'!L9,'DCF_Base'!L20)*A18)/POWER(1+B14,10)+'Assumptions'!$E$9-('Assumptions'!$E$8+'Assumptions'!$E$10+'Assumptions'!$E$11+'Assumptions'!$E$12+'Assumptions'!$E$13+'Assumptions'!$E$14+'Assumptions'!$E$15))/('Assumptions'!$E$6*POWER(1+'Assumptions'!$E$7,10)) | C18: =(('DCF_Base'!C16/POWER(1+C14,1)+'DCF_Base'!D16/POWER(1+C14,2)+'DCF_Base'!E16/POWER(1+C14,3)+'DCF_Base'!F16/POWER(1+C14,4)+'DCF_Base'!G16/POWER(1+C14,5)+'DCF_Base'!H16/POWER(1+C14,6)+'DCF_Base'!I16/POWER(1+C14,7)+'DCF_Base'!J16/POWER(1+C14,8)+'DCF_Base'!K16/POWER(1+C14,9)+'DCF_Base'!L16/POWER(1+C14,10))+(IF('Assumptions'!$E$29="ev_ebit",'DCF_Base'!L9,'DCF_Base'!L20)*A18)/POWER(1+C14,10)+'Assumptions'!$E$9-('Assumptions'!$E$8+'Assumptions'!$E$10+'Assumptions'!$E$11+'Assumptions'!$E$12+'Assumptions'!$E$13+'Assumptions'!$E$14+'Assumptions'!$E$15))/('Assumptions'!$E$6*POWER(1+'Assumptions'!$E$7,10)) | D18: =(('DCF_Base'!C16/POWER(1+D14,1)+'DCF_Base'!D16/POWER(1+D14,2)+'DCF_Base'!E16/POWER(1+D14,3)+'DCF_Base'!F16/POWER(1+D14,4)+'DCF_Base'!G16/POWER(1+D14,5)+'DCF_Base'!H16/POWER(1+D14,6)+'DCF_Base'!I16/POWER(1+D14,7)+'DCF_Base'!J16/POWER(1+D14,8)+'DCF_Base'!K16/POWER(1+D14,9)+'DCF_Base'!L16/POWER(1+D14,10))+(IF('Assumptions'!$E$29="ev_ebit",'DCF_Base'!L9,'DCF_Base'!L20)*A18)/POWER(1+D14,10)+'Assumptions'!$E$9-('Assumptions'!$E$8+'Assumptions'!$E$10+'Assumptions'!$E$11+'Assumptions'!$E$12+'Assumptions'!$E$13+'Assumptions'!$E$14+'Assumptions'!$E$15))/('Assumptions'!$E$6*POWER(1+'Assumptions'!$E$7,10)) | E18: =(('DCF_Base'!C16/POWER(1+E14,1)+'DCF_Base'!D16/POWER(1+E14,2)+'DCF_Base'!E16/POWER(1+E14,3)+'DCF_Base'!F16/POWER(1+E14,4)+'DCF_Base'!G16/POWER(1+E14,5)+'DCF_Base'!H16/POWER(1+E14,6)+'DCF_Base'!I16/POWER(1+E14,7)+'DCF_Base'!J16/POWER(1+E14,8)+'DCF_Base'!K16/POWER(1+E14,9)+'DCF_Base'!L16/POWER(1+E14,10))+(IF('Assumptions'!$E$29="ev_ebit",'DCF_Base'!L9,'DCF_Base'!L20)*A18)/POWER(1+E14,10)+'Assumptions'!$E$9-('Assumptions'!$E$8+'Assumptions'!$E$10+'Assumptions'!$E$11+'Assumptions'!$E$12+'Assumptions'!$E$13+'Assumptions'!$E$14+'Assumptions'!$E$15))/('Assumptions'!$E$6*POWER(1+'Assumptions'!$E$7,10)) | F18: =(('DCF_Base'!C16/POWER(1+F14,1)+'DCF_Base'!D16/POWER(1+F14,2)+'DCF_Base'!E16/POWER(1+F14,3)+'DCF_Base'!F16/POWER(1+F14,4)+'DCF_Base'!G16/POWER(1+F14,5)+'DCF_Base'!H16/POWER(1+F14,6)+'DCF_Base'!I16/POWER(1+F14,7)+'DCF_Base'!J16/POWER(1+F14,8)+'DCF_Base'!K16/POWER(1+F14,9)+'DCF_Base'!L16/POWER(1+F14,10))+(IF('Assumptions'!$E$29="ev_ebit",'DCF_Base'!L9,'DCF_Base'!L20)*A18)/POWER(1+F14,10)+'Assumptions'!$E$9-('Assumptions'!$E$8+'Assumptions'!$E$10+'Assumptions'!$E$11+'Assumptions'!$E$12+'Assumptions'!$E$13+'Assumptions'!$E$14+'Assumptions'!$E$15))/('Assumptions'!$E$6*POWER(1+'Assumptions'!$E$7,10))
A19: ='Assumptions'!$E$28+2 | B19: =(('DCF_Base'!C16/POWER(1+B14,1)+'DCF_Base'!D16/POWER(1+B14,2)+'DCF_Base'!E16/POWER(1+B14,3)+'DCF_Base'!F16/POWER(1+B14,4)+'DCF_Base'!G16/POWER(1+B14,5)+'DCF_Base'!H16/POWER(1+B14,6)+'DCF_Base'!I16/POWER(1+B14,7)+'DCF_Base'!J16/POWER(1+B14,8)+'DCF_Base'!K16/POWER(1+B14,9)+'DCF_Base'!L16/POWER(1+B14,10))+(IF('Assumptions'!$E$29="ev_ebit",'DCF_Base'!L9,'DCF_Base'!L20)*A19)/POWER(1+B14,10)+'Assumptions'!$E$9-('Assumptions'!$E$8+'Assumptions'!$E$10+'Assumptions'!$E$11+'Assumptions'!$E$12+'Assumptions'!$E$13+'Assumptions'!$E$14+'Assumptions'!$E$15))/('Assumptions'!$E$6*POWER(1+'Assumptions'!$E$7,10)) | C19: =(('DCF_Base'!C16/POWER(1+C14,1)+'DCF_Base'!D16/POWER(1+C14,2)+'DCF_Base'!E16/POWER(1+C14,3)+'DCF_Base'!F16/POWER(1+C14,4)+'DCF_Base'!G16/POWER(1+C14,5)+'DCF_Base'!H16/POWER(1+C14,6)+'DCF_Base'!I16/POWER(1+C14,7)+'DCF_Base'!J16/POWER(1+C14,8)+'DCF_Base'!K16/POWER(1+C14,9)+'DCF_Base'!L16/POWER(1+C14,10))+(IF('Assumptions'!$E$29="ev_ebit",'DCF_Base'!L9,'DCF_Base'!L20)*A19)/POWER(1+C14,10)+'Assumptions'!$E$9-('Assumptions'!$E$8+'Assumptions'!$E$10+'Assumptions'!$E$11+'Assumptions'!$E$12+'Assumptions'!$E$13+'Assumptions'!$E$14+'Assumptions'!$E$15))/('Assumptions'!$E$6*POWER(1+'Assumptions'!$E$7,10)) | D19: =(('DCF_Base'!C16/POWER(1+D14,1)+'DCF_Base'!D16/POWER(1+D14,2)+'DCF_Base'!E16/POWER(1+D14,3)+'DCF_Base'!F16/POWER(1+D14,4)+'DCF_Base'!G16/POWER(1+D14,5)+'DCF_Base'!H16/POWER(1+D14,6)+'DCF_Base'!I16/POWER(1+D14,7)+'DCF_Base'!J16/POWER(1+D14,8)+'DCF_Base'!K16/POWER(1+D14,9)+'DCF_Base'!L16/POWER(1+D14,10))+(IF('Assumptions'!$E$29="ev_ebit",'DCF_Base'!L9,'DCF_Base'!L20)*A19)/POWER(1+D14,10)+'Assumptions'!$E$9-('Assumptions'!$E$8+'Assumptions'!$E$10+'Assumptions'!$E$11+'Assumptions'!$E$12+'Assumptions'!$E$13+'Assumptions'!$E$14+'Assumptions'!$E$15))/('Assumptions'!$E$6*POWER(1+'Assumptions'!$E$7,10)) | E19: =(('DCF_Base'!C16/POWER(1+E14,1)+'DCF_Base'!D16/POWER(1+E14,2)+'DCF_Base'!E16/POWER(1+E14,3)+'DCF_Base'!F16/POWER(1+E14,4)+'DCF_Base'!G16/POWER(1+E14,5)+'DCF_Base'!H16/POWER(1+E14,6)+'DCF_Base'!I16/POWER(1+E14,7)+'DCF_Base'!J16/POWER(1+E14,8)+'DCF_Base'!K16/POWER(1+E14,9)+'DCF_Base'!L16/POWER(1+E14,10))+(IF('Assumptions'!$E$29="ev_ebit",'DCF_Base'!L9,'DCF_Base'!L20)*A19)/POWER(1+E14,10)+'Assumptions'!$E$9-('Assumptions'!$E$8+'Assumptions'!$E$10+'Assumptions'!$E$11+'Assumptions'!$E$12+'Assumptions'!$E$13+'Assumptions'!$E$14+'Assumptions'!$E$15))/('Assumptions'!$E$6*POWER(1+'Assumptions'!$E$7,10)) | F19: =(('DCF_Base'!C16/POWER(1+F14,1)+'DCF_Base'!D16/POWER(1+F14,2)+'DCF_Base'!E16/POWER(1+F14,3)+'DCF_Base'!F16/POWER(1+F14,4)+'DCF_Base'!G16/POWER(1+F14,5)+'DCF_Base'!H16/POWER(1+F14,6)+'DCF_Base'!I16/POWER(1+F14,7)+'DCF_Base'!J16/POWER(1+F14,8)+'DCF_Base'!K16/POWER(1+F14,9)+'DCF_Base'!L16/POWER(1+F14,10))+(IF('Assumptions'!$E$29="ev_ebit",'DCF_Base'!L9,'DCF_Base'!L20)*A19)/POWER(1+F14,10)+'Assumptions'!$E$9-('Assumptions'!$E$8+'Assumptions'!$E$10+'Assumptions'!$E$11+'Assumptions'!$E$12+'Assumptions'!$E$13+'Assumptions'!$E$14+'Assumptions'!$E$15))/('Assumptions'!$E$6*POWER(1+'Assumptions'!$E$7,10))
A21: Backend Base IV | B21: ='Assumptions'!$E$36

Sheet Checks
A1: Checks
A2: Clear every Fail/Review before using this for an investment discussion.
A4: Check | B4: Value | C4: Status | D4: Notes
A5: Reconciles to backend Base IV | B5: ='DCF_Base'!$B$40-'Assumptions'!$E$36 | C5: =IF(ABS(B5)<=0.1,"OK","FAIL") | D5: Rebuilt Base IV must equal backend iv_base
A6: WACC greater than terminal growth | B6: ='Assumptions'!$E$19-'Assumptions'!$E$18 | C6: =IF(B6>0,"OK","FAIL") | D6: Gordon invalid if WACC <= g
A7: RONIC greater than terminal growth | B7: ='Assumptions'!$E$30-'Assumptions'!$E$18 | C7: =IF(B7>0,"OK","FAIL") | D7: Value-driver TV requires RONIC > g
A8: Terminal value share of EV | B8: ='DCF_Base'!$B$35 | C8: =IF(AND(B8>=0.4,B8<=0.85),"OK","REVIEW") | D8: Outside 40-85% deserves a look
A9: Scenario probabilities sum to 100% | B9: ='Assumptions'!$E$33+'Assumptions'!$E$34+'Assumptions'!$E$35 | C9: =IF(ABS(B9-1)<0.001,"OK","FAIL") | D9: Edit probabilities in Assumptions
A10: Exit metric present | B10: ='Assumptions'!$E$29 | C10: =IF(B10<>"","OK","FAIL") | D10: Needed for exit terminal value
A11: Model applicability | B11: dcf_applicable | C11: =IF(B11="dcf_applicable","OK","REVIEW") | D11: Backend DCF applicability gate
A12: Model trust state | B12: watch | C12: =IF(B12="ok","OK","REVIEW") | D12: Register flags: {'none': 26, 'watch': 7, 'review_required': 0, 'critical': 0}
A13: PM review items outstanding | B13: 2 | C13: =IF(B13=0,"OK","REVIEW") | D13: See PM_Review_Queue tab
A14: No hidden writeback | B14: Review artifact only | C14: ="OK" | D14: Workbook never mutates the database or approved assumptions
