Workbook
Name as_of_date: Cover!$C$8
Name IQ_CH: 110000
Name IQ_CQ: 5000
Name IQ_CY: 10000
Name IQ_DAILY: 500000
Name IQ_FH: 100000
Name IQ_FQ: 500
Name IQ_FY: 1000
Name IQ_LTM: 2000
Name IQ_MONTH: 15000
Name IQ_NTM: 6000
Name IQ_WEEK: 50000
Name IQ_YTD: 3000
Name json_path: Config!$B$2
Name Price: _Data!$B$47
Name Ticker: Cover!$B$2

Sheet Cover
B2: =_Data!E4 -> BAH
B4: EQUITY VALUATION MODEL
B5: =_Data!E4 & " - " & _Data!E5 -> BAH - Booz Allen Hamilton Holding Corporation
B7: Sector | C7: =_Data!E6 -> Industrials
B8: As of | C8: =DATEVALUE(_xlfn.TEXTBEFORE(_Data!E3, "T")) -> 46187
B9: Price | C9: =Price -> 77.41
B10: EV ($mm) | C10: =_Data!B49 -> 12664
B11: Shares | C11: =_Data!B21 -> 122.375
B12: Model | C12: DCF Bear / Base / Bull + Comps + EP cross-check
B14: Sheet Guide
B15: Assumptions — All inputs with JSON baseline + PM override column (yellow)
B16: DCF_Base — 10-year FCFF projection, live formulas, Base scenario
B17: DCF_Bear — Bear scenario (growth ×0.6, margin ×0.75, WACC +200bp)
B18: DCF_Bull — Bull scenario (growth ×1.4, margin ×1.15, WACC -100bp)
B19: Equity_Bridge— Enterprise → Equity value, IV per share, expected IV
B20: Comps — Peer multiples table, live medians, exclude toggle
B21: Sensitivity — IV grid: WACC × terminal growth (±200bp each)
B22: QoE — Quality of Earnings signals (Sloan, cash conv, NWC drift)
B23: Output — Summary dashboard with colour-coded upside flags
B25: Override pattern: Col B = JSON baseline (blue) | Col C = PM override (yellow, type here) | Col D = Active (formula: =IF(C="",B,C))
B26: Press F9 to recalculate all formulas after editing.

Sheet Assumptions
A1: Driver | B1: JSON Baseline | C1: PM Override | D1: Active | E1: Source
A2: MARKET DATA | C2: ← Type override here (yellow cells)
A3: DCF GROWTH DRIVERS | B3: =_Data!B2 -> 11217 | D3: =IF(C3="",B3,C3) -> 11217 | E3: CIQ
A4: Revenue Growth — Near (Y1–Y5) | B4: =_Data!B3 -> 0.0024725167 | D4: =IF(C4="",B4,C4) -> 0.0024725167 | E4: CIQ consensus
A5: Revenue Growth — Mid (Y6–Y10) | B5: =_Data!B4 -> 0.0013598842 | D5: =IF(C5="",B5,C5) -> 0.0013598842 | E5: CIQ consensus blend
A6: Terminal Revenue Growth | B6: =_Data!B5 -> 0.025 | D6: =IF(C6="",B6,C6) -> 0.025 | E6: GDP anchor
A7: MARGIN DRIVERS
A8: EBIT Margin — Start | B8: =_Data!B6 -> 0.098363684 | D8: =IF(C8="",B8,C8) -> 0.098363684 | E8: CIQ LTM
A9: EBIT Margin — Target (Y10) | B9: =_Data!B7 -> 0.11418184 | D9: =IF(C9="",B9,C9) -> 0.11418184 | E9: Sector median
A10: D&A / CAPEX
A11: D&A % Revenue | B11: =_Data!B9 -> 0.014562066 | D11: =IF(C11="",B11,C11) -> 0.014562066 | E11: CIQ LTM
A12: Capex % Revenue | B12: =_Data!B8 -> 0.01 | D12: =IF(C12="",B12,C12) -> 0.01 | E12: CIQ LTM
A13: TAX
A14: Effective Tax Rate — Start | B14: =_Data!B10 -> 0.20564844 | D14: =IF(C14="",B14,C14) -> 0.20564844 | E14: CIQ LTM
A15: Effective Tax Rate — Target | B15: =_Data!B11 -> 0.20564844 | D15: =IF(C15="",B15,C15) -> 0.20564844 | E15: Company guidance
A16: WORKING CAPITAL DRIVERS
A17: DSO Start (days) | B17: =_Data!B12 -> 67.1 | D17: =IF(C17="",B17,C17) -> 67.1 | E17: CIQ LTM
A18: DSO Target (days) | B18: =_Data!B13 -> 58.63 | D18: =IF(C18="",B18,C18) -> 58.63 | E18: Sector median
A19: DIO Start (days) | B19: =_Data!B14 -> 5 | D19: =IF(C19="",B19,C19) -> 5 | E19: CIQ LTM
A20: DIO Target (days) | B20: =_Data!B15 -> 43.5 | D20: =IF(C20="",B20,C20) -> 43.5 | E20: Sector median
A21: DPO Start (days) | B21: =_Data!B16 -> 19.3 | D21: =IF(C21="",B21,C21) -> 19.3 | E21: CIQ LTM
A22: DPO Target (days) | B22: =_Data!B17 -> 40.79 | D22: =IF(C22="",B22,C22) -> 40.79 | E22: Sector median
A23: TERMINAL VALUE
A24: Exit Multiple (EV/EBITDA) | B24: =_Data!B18 -> 8.51724 | D24: =IF(C24="",B24,C24) -> 8.51724 | E24: Forward comps
A25: RONIC Terminal | B25: =_Data!B19 -> 0.11 | D25: =IF(C25="",B25,C25) -> 0.11 | E25: ROIC estimate
A26: WACC BUILD-UP
A27: Risk-Free Rate | B27: 0.045 | D27: =IF(C27="",B27,C27) -> 0.045 | E27: 10Y UST
A28: Equity Risk Premium | B28: 0.05 | D28: =IF(C28="",B28,C28) -> 0.05 | E28: Damodaran
A29: Beta (re-levered) | B29: =_Data!B35 -> 0.27 | D29: =IF(C29="",B29,C29) -> 0.27 | E29: Hamada / peers
A30: Size Premium | B30: =_Data!B36 -> 0.6 | D30: =IF(C30="",B30,C30) -> 0.6 | E30: Duff & Phelps
A31: Cost of Equity (Ke) | B31: =WACC[[#This Row],[Value]] -> 0.07463 | D31: =IF(C31="",D27+D29*D28+D30,C31) -> 0.6585 | E31: CAPM: Rf + β×ERP + size premium
A32: Cost of Debt (pre-tax) | B32: 0.027804687 | D32: =IF(C32="",B32,C32) -> 0.027804687 | E32: Interest expense / total debt (CIQ)
A33: Tax Rate (for Kd) | D33: =D14 -> 0.20564844 | E33: =Assumptions D14 -> #NAME?
A34: Cost of Debt after-tax (Kd) | B34: 0.023705963 | D34: =IF(C34="",D32*(1-D33),C34) -> 0.022086696 | E34: Kd × (1 - tax)
A35: Equity Weight | B35: =_Data!B37 -> 0.7323 | D35: =IF(C35="",B35,C35) -> 0.7323 | E35: Market cap / TEV
A36: Debt Weight | B36: =_Data!B38 -> 0.2677 | D36: =IF(C36="",B36,C36) -> 0.2677 | E36: Net debt / TEV
A37: WACC | B37: 0.07043 | D37: =IF(C37="",B37,C37) -> 0.07043 | E37: JSON baseline (batch_runner) — override C37 to adjust
A38: EQUITY BRIDGE ITEMS ($mm)
A39: Net Debt ($mm) | B39: =_Data!B20 -> 3394 | D39: =IF(C39="",B39,C39) -> 3394 | E39: CIQ balance sheet
A40: Shares Outstanding (mm) | B40: =_Data!B21 -> 122.375 | D40: =IF(C40="",B40,C40) -> 122.375 | E40: CIQ
...

Sheet DCF_Base
A1: =Ticker&" — BASE SCENARIO | "&Ticker&" Valuation" -> BAH — BASE SCENARIO | BAH Valuation
A2: 10-YEAR FCFF PROJECTION ($mm) | B2: LTM | C2: Y1 | D2: Y2 | E2: Y3 | F2: Y4 | G2: Y5 | H2: Y6 | I2: Y7 | J2: Y8 | K2: Y9 | L2: Y10 | M2: Terminal
A3: ── REVENUE ─────────────────────────────────
A4: Revenue ($mm) | B4: =Assumptions!$D$3 -> 11217 | C4: =B4*(1+Assumptions!$D$4) -> 11244.734 | D4: =C4*(1+Assumptions!$D$4) -> 11272.537 | E4: =D4*(1+Assumptions!$D$4) -> 11300.409 | F4: =E4*(1+Assumptions!$D$4) -> 11328.349 | G4: =F4*(1+Assumptions!$D$4) -> 11356.359 | H4: =G4*(1+Assumptions!$D$5) -> 11371.802 | I4: =H4*(1+Assumptions!$D$5) -> 11387.266 | J4: =I4*(1+Assumptions!$D$5) -> 11402.752 | K4: =J4*(1+Assumptions!$D$5) -> 11418.258 | L4: =K4*(1+Assumptions!$D$5) -> 11433.785 | M4: =L4*(1+Assumptions!$D$6) -> 11719.63
A5: Revenue Growth % | C5: =C4/B4-1 -> 0.0024725167 | D5: =D4/C4-1 -> 0.0024725167 | E5: =E4/D4-1 -> 0.0024725167 | F5: =F4/E4-1 -> 0.0024725167 | G5: =G4/F4-1 -> 0.0024725167 | H5: =H4/G4-1 -> 0.0013598842 | I5: =I4/H4-1 -> 0.0013598842 | J5: =J4/I4-1 -> 0.0013598842 | ... M5: =M4/L4-1 -> 0.025
A6: ── PROFITABILITY ────────────────────────────
A7: EBIT Margin % | C7: =Assumptions!$D$8+(Assumptions!$D$9-Assumptions!$D$8)*(COLUMN()-2)/10 -> 0.0999455 | D7: =Assumptions!$D$8+(Assumptions!$D$9-Assumptions!$D$8)*(COLUMN()-2)/10 -> 0.10152732 | E7: =Assumptions!$D$8+(Assumptions!$D$9-Assumptions!$D$8)*(COLUMN()-2)/10 -> 0.10310913 | F7: =Assumptions!$D$8+(Assumptions!$D$9-Assumptions!$D$8)*(COLUMN()-2)/10 -> 0.10469095 | G7: =Assumptions!$D$8+(Assumptions!$D$9-Assumptions!$D$8)*(COLUMN()-2)/10 -> 0.10627276 | H7: =Assumptions!$D$8+(Assumptions!$D$9-Assumptions!$D$8)*(COLUMN()-2)/10 -> 0.10785458 | I7: =Assumptions!$D$8+(Assumptions!$D$9-Assumptions!$D$8)*(COLUMN()-2)/10 -> 0.10943639 | J7: =Assumptions!$D$8+(Assumptions!$D$9-Assumptions!$D$8)*(COLUMN()-2)/10 -> 0.11101821 | ... L7: =Assumptions!$D$8+(Assumptions!$D$9-Assumptions!$D$8)*(COLUMN()-2)/10 -> 0.11418184 | M7: =Assumptions!$D$9 -> 0.11418184
A8: EBIT ($mm) | C8: =C4*C7 -> 1123.8606 | D8: =D4*D7 -> 1144.4704 | E8: =E4*E7 -> 1165.1753 | F8: =F4*F7 -> 1185.9756 | G8: =G4*G7 -> 1206.8716 | H8: =H4*H7 -> 1226.5009 | I8: =I4*I7 -> 1246.1814 | J8: =J4*J7 -> 1265.9131 | ... M8: =M4*M7 -> 1338.169
A9: EBITDA ($mm) | C9: =C8+C14 -> 1287.6072 | D9: =D8+D14 -> 1308.6219 | E9: =E8+E14 -> 1329.7326 | F9: =F8+F14 -> 1350.9398 | G9: =G8+G14 -> 1372.2436 | H9: =H8+H14 -> 1392.0978 | I9: =I8+I14 -> 1412.0035 | J9: =J8+J14 -> 1431.9607 | ... M9: =M8+M14 -> 1508.831
A10: Tax Rate % | C10: =Assumptions!$D$14+(Assumptions!$D$15-Assumptions!$D$14)*(COLUMN()-2)/10 -> 0.20564844 | D10: =Assumptions!$D$14+(Assumptions!$D$15-Assumptions!$D$14)*(COLUMN()-2)/10 -> 0.20564844 | E10: =Assumptions!$D$14+(Assumptions!$D$15-Assumptions!$D$14)*(COLUMN()-2)/10 -> 0.20564844 | F10: =Assumptions!$D$14+(Assumptions!$D$15-Assumptions!$D$14)*(COLUMN()-2)/10 -> 0.20564844 | G10: =Assumptions!$D$14+(Assumptions!$D$15-Assumptions!$D$14)*(COLUMN()-2)/10 -> 0.20564844 | H10: =Assumptions!$D$14+(Assumptions!$D$15-Assumptions!$D$14)*(COLUMN()-2)/10 -> 0.20564844 | I10: =Assumptions!$D$14+(Assumptions!$D$15-Assumptions!$D$14)*(COLUMN()-2)/10 -> 0.20564844 | J10: =Assumptions!$D$14+(Assumptions!$D$15-Assumptions!$D$14)*(COLUMN()-2)/10 -> 0.20564844 | ... L10: =Assumptions!$D$14+(Assumptions!$D$15-Assumptions!$D$14)*(COLUMN()-2)/10 -> 0.20564844 | M10: =Assumptions!$D$15 -> 0.20564844
A11: NOPAT ($mm) | C11: =C8*(1-C10) -> 892.74041 | D11: =D8*(1-D10) -> 909.11187 | E11: =E8*(1-E10) -> 925.55883 | F11: =F8*(1-F10) -> 942.08156 | G11: =G8*(1-G10) -> 958.68034 | H11: =H8*(1-H10) -> 974.27291 | I11: =I8*(1-I10) -> 989.90611 | J11: =J8*(1-J10) -> 1005.58 | ... M11: =M8*(1-M10) -> 1062.9766
A12: ── D&A / CAPEX ──────────────────────────────
A13: D&A % Revenue | B13: =Assumptions!$D$11 -> 0.014562066 | C13: =Assumptions!$D$11 -> 0.014562066 | D13: =Assumptions!$D$11 -> 0.014562066 | E13: =Assumptions!$D$11 -> 0.014562066 | F13: =Assumptions!$D$11 -> 0.014562066 | G13: =Assumptions!$D$11 -> 0.014562066 | H13: =Assumptions!$D$11 -> 0.014562066 | I13: =Assumptions!$D$11 -> 0.014562066 | ... M13: =Assumptions!$D$11 -> 0.014562066
A14: D&A ($mm) | C14: =C4*C13 -> 163.74657 | D14: =D4*D13 -> 164.15143 | E14: =E4*E13 -> 164.5573 | F14: =F4*F13 -> 164.96417 | G14: =G4*G13 -> 165.37205 | H14: =H4*H13 -> 165.59693 | I14: =I4*I13 -> 165.82213 | J14: =J4*J13 -> 166.04762 | ... M14: =M4*M13 -> 170.66203
A15: Capex % Revenue | B15: =Assumptions!$D$12 -> 0.01 | C15: =Assumptions!$D$12 -> 0.01 | D15: =Assumptions!$D$12 -> 0.01 | E15: =Assumptions!$D$12 -> 0.01 | F15: =Assumptions!$D$12 -> 0.01 | G15: =Assumptions!$D$12 -> 0.01 | H15: =Assumptions!$D$12 -> 0.01 | I15: =Assumptions!$D$12 -> 0.01 | ... L15: =Assumptions!$D$12 -> 0.01
A16: Capex ($mm) | C16: =C4*C15 -> 112.44734 | D16: =D4*D15 -> 112.72537 | E16: =E4*E15 -> 113.00409 | F16: =F4*F15 -> 113.28349 | G16: =G4*G15 -> 113.56359 | H16: =H4*H15 -> 113.71802 | I16: =I4*I15 -> 113.87266 | J16: =J4*J15 -> 114.02752 | ... L16: =L4*L15 -> 114.33785
A17: ── NWC DRIVERS ──────────────────────────────
A18: DSO (days) | B18: =Assumptions!$D$17 -> 67.1 | C18: =Assumptions!$D$17+(Assumptions!$D$18-Assumptions!$D$17)*(COLUMN()-2)/10 -> 66.253 | D18: =Assumptions!$D$17+(Assumptions!$D$18-Assumptions!$D$17)*(COLUMN()-2)/10 -> 65.406 | E18: =Assumptions!$D$17+(Assumptions!$D$18-Assumptions!$D$17)*(COLUMN()-2)/10 -> 64.559 | F18: =Assumptions!$D$17+(Assumptions!$D$18-Assumptions!$D$17)*(COLUMN()-2)/10 -> 63.712 | G18: =Assumptions!$D$17+(Assumptions!$D$18-Assumptions!$D$17)*(COLUMN()-2)/10 -> 62.865 | H18: =Assumptions!$D$17+(Assumptions!$D$18-Assumptions!$D$17)*(COLUMN()-2)/10 -> 62.018 | I18: =Assumptions!$D$17+(Assumptions!$D$18-Assumptions!$D$17)*(COLUMN()-2)/10 -> 61.171 | J18: =Assumptions!$D$17+(Assumptions!$D$18-Assumptions!$D$17)*(COLUMN()-2)/10 -> 60.324 | ... L18: =Assumptions!$D$17+(Assumptions!$D$18-Assumptions!$D$17)*(COLUMN()-2)/10 -> 58.63
A19: DIO (days) | B19: =Assumptions!$D$19 -> 5 | C19: =Assumptions!$D$19+(Assumptions!$D$20-Assumptions!$D$19)*(COLUMN()-2)/10 -> 8.85 | D19: =Assumptions!$D$19+(Assumptions!$D$20-Assumptions!$D$19)*(COLUMN()-2)/10 -> 12.7 | E19: =Assumptions!$D$19+(Assumptions!$D$20-Assumptions!$D$19)*(COLUMN()-2)/10 -> 16.55 | F19: =Assumptions!$D$19+(Assumptions!$D$20-Assumptions!$D$19)*(COLUMN()-2)/10 -> 20.4 | G19: =Assumptions!$D$19+(Assumptions!$D$20-Assumptions!$D$19)*(COLUMN()-2)/10 -> 24.25 | H19: =Assumptions!$D$19+(Assumptions!$D$20-Assumptions!$D$19)*(COLUMN()-2)/10 -> 28.1 | I19: =Assumptions!$D$19+(Assumptions!$D$20-Assumptions!$D$19)*(COLUMN()-2)/10 -> 31.95 | J19: =Assumptions!$D$19+(Assumptions!$D$20-Assumptions!$D$19)*(COLUMN()-2)/10 -> 35.8 | ... L19: =Assumptions!$D$19+(Assumptions!$D$20-Assumptions!$D$19)*(COLUMN()-2)/10 -> 43.5
A20: DPO (days) | B20: =Assumptions!$D$21 -> 19.3 | C20: =Assumptions!$D$21+(Assumptions!$D$22-Assumptions!$D$21)*(COLUMN()-2)/10 -> 21.449 | D20: =Assumptions!$D$21+(Assumptions!$D$22-Assumptions!$D$21)*(COLUMN()-2)/10 -> 23.598 | E20: =Assumptions!$D$21+(Assumptions!$D$22-Assumptions!$D$21)*(COLUMN()-2)/10 -> 25.747 | F20: =Assumptions!$D$21+(Assumptions!$D$22-Assumptions!$D$21)*(COLUMN()-2)/10 -> 27.896 | G20: =Assumptions!$D$21+(Assumptions!$D$22-Assumptions!$D$21)*(COLUMN()-2)/10 -> 30.045 | H20: =Assumptions!$D$21+(Assumptions!$D$22-Assumptions!$D$21)*(COLUMN()-2)/10 -> 32.194 | I20: =Assumptions!$D$21+(Assumptions!$D$22-Assumptions!$D$21)*(COLUMN()-2)/10 -> 34.343 | J20: =Assumptions!$D$21+(Assumptions!$D$22-Assumptions!$D$21)*(COLUMN()-2)/10 -> 36.492 | ... L20: =Assumptions!$D$21+(Assumptions!$D$22-Assumptions!$D$21)*(COLUMN()-2)/10 -> 40.79
A21: AR ($mm) | B21: =B4/365*B18 -> 2062.0841 | C21: =C4/365*C18 -> 2041.0887 | D21: =D4/365*D18 -> 2019.9769 | E21: =E4/365*E18 -> 1998.7482 | F21: =F4/365*F18 -> 1977.4021 | G21: =G4/365*G18 -> 1955.9383 | H21: =H4/365*H18 -> 1932.2093 | I21: =I4/365*I18 -> 1908.4122 | ... L21: =L4/365*L18 -> 1836.6105
A22: Inventory ($mm) | B22: =B4/365*B19 -> 153.65753 | C22: =C4/365*C19 -> 272.6463 | D22: =D4/365*D19 -> 392.22252 | E22: =E4/365*E19 -> 512.38839 | F22: =F4/365*F19 -> 633.14608 | G22: =G4/365*G19 -> 754.49779 | H22: =H4/365*H19 -> 875.47297 | I22: =I4/365*I19 -> 996.77577 | ... L22: =L4/365*L19 -> 1362.6566
A23: AP ($mm) | B23: =B4/365*B20 -> 593.11808 | C23: =C4/365*C20 -> 660.78987 | D23: =D4/365*D20 -> 728.79268 | E23: =E4/365*E20 -> 797.12772 | F23: =F4/365*F20 -> 865.79623 | G23: =G4/365*G20 -> 934.79943 | H23: =H4/365*H20 -> 1003.0241 | I23: =I4/365*I20 -> 1071.4326 | ... L23: =L4/365*L20 -> 1277.7647
A24: NWC ($mm) | B24: =B21+B22-B23 -> 1622.6236 | C24: =C21+C22-C23 -> 1652.9451 | D24: =D21+D22-D23 -> 1683.4067 | E24: =E21+E22-E23 -> 1714.0088 | F24: =F21+F22-F23 -> 1744.752 | G24: =G21+G22-G23 -> 1775.6367 | H24: =H21+H22-H23 -> 1804.6582 | I24: =I21+I22-I23 -> 1833.7554 | ... L24: =L21+L22-L23 -> 1921.5025
A25: ΔNWC ($mm) | C25: =C24-B24 -> 30.321561 | D25: =D24-C24 -> 30.461583 | E25: =E24-D24 -> 30.602111 | F25: =F24-E24 -> 30.743148 | G25: =G24-F24 -> 30.884696 | H25: =H24-G24 -> 29.021561 | I25: =I24-H24 -> 29.097209 | J25: =J24-I24 -> 29.17301 | ... L25: =L24-K24 -> 29.325068
A26: ── FREE CASH FLOW ───────────────────────────
A27: FCFF ($mm) | C27: =C11+C14-C16-C25 -> 913.71808 | D27: =D11+D14-D16-D25 -> 930.07635 | E27: =E11+E14-E16-E25 -> 946.50994 | F27: =F11+F14-F16-F25 -> 963.0191 | G27: =G11+G14-G16-G25 -> 979.60411 | H27: =H11+H14-H16-H25 -> 997.13026 | I27: =I11+I14-I16-I25 -> 1012.7584 | J27: =J11+J14-J16-J25 -> 1028.4271 | ... L27: =L11+L14-L16-L25 -> 1059.887
A28: Discount Factor | C28: =1/(1+Assumptions!$D$37)^1 -> 0.93420401 | D28: =1/(1+Assumptions!$D$37)^2 -> 0.87273714 | E28: =1/(1+Assumptions!$D$37)^3 -> 0.81531453 | F28: =1/(1+Assumptions!$D$37)^4 -> 0.76167011 | G28: =1/(1+Assumptions!$D$37)^5 -> 0.71155527 | H28: =1/(1+Assumptions!$D$37)^6 -> 0.66473779 | I28: =1/(1+Assumptions!$D$37)^7 -> 0.62100071 | J28: =1/(1+Assumptions!$D$37)^8 -> 0.58014135 | K28: =1/(1+Assumptions!$D$37)^9 -> 0.54197038 | L28: =1/(1+Assumptions!$D$37)^10 -> 0.5063109 | M28: =1/(1+Assumptions!$D$37)^10 -> 0.5063109
A29: PV FCFF ($mm) | C29: =C27*C28 -> 853.59909 | D29: =D27*D28 -> 811.71217 | E29: =E27*E28 -> 771.70331 | F29: =F27*F28 -> 733.50286 | G29: =G27*G28 -> 697.04247 | H29: =H27*H28 -> 662.83017 | I29: =I27*I28 -> 628.92366 | J29: =J27*J28 -> 596.63311 | ... L29: =L27*L28 -> 536.63233
A30: Cumulative PV FCFF ($mm) | C30: =C29 -> 853.59909 | D30: =C30+D29 -> 1665.3113 | E30: =D30+E29 -> 2437.0146 | F30: =E30+F29 -> 3170.5174 | G30: =F30+G29 -> 3867.5599 | H30: =G30+H29 -> 4530.3901 | I30: =H30+I29 -> 5159.3137 | J30: =I30+J29 -> 5755.9468 | K30: =J30+K29 -> 6321.838 | L30: =K30+L29 -> 6858.4703
A31: ── RETURNS ──────────────────────────────────
A32: Invested Capital ($mm) | B32: =Assumptions!$D$41 -> 41749.375 | C32: =B32+C16+C25-C14 -> 41728.397 | D32: =C32+D16+D25-D14 -> 41707.433 | E32: =D32+E16+E25-E14 -> 41686.482 | F32: =E32+F16+F25-F14 -> 41665.544 | G32: =F32+G16+G25-G14 -> 41644.62 | H32: =G32+H16+H25-H14 -> 41621.763 | I32: =H32+I16+I25-I14 -> 41598.911 | J32: =I32+J16+J25-J14 -> 41576.064 | ... L32: =K32+L16+L25-L14 -> 41530.385
A33: ROIC % | C33: =C11/B32 -> 0.021383324 | D33: =D11/C32 -> 0.021786408 | E33: =E11/D32 -> 0.0221917 | F33: =F11/E32 -> 0.02259921 | G33: =G11/F32 -> 0.023008948 | H33: =H11/G32 -> 0.023394928 | I33: =I11/H32 -> 0.023783378 | J33: =J11/I32 -> 0.02417323 | ... L33: =L11/K32 -> 0.024957159
A34: Economic Profit ($mm) | C34: =C11-B32*Assumptions!$D$37 -> -2047.6681 | D34: =D11-C32*Assumptions!$D$37 -> -2029.8192 | E34: =E11-D32*Assumptions!$D$37 -> -2011.8957 | F34: =F11-E32*Assumptions!$D$37 -> -1993.8973 | G34: =G11-F32*Assumptions!$D$37 -> -1975.8239 | H34: =H11-G32*Assumptions!$D$37 -> -1958.7577 | I34: =I11-H32*Assumptions!$D$37 -> -1941.5147 | J34: =J11-I32*Assumptions!$D$37 -> -1924.2313 | ... L34: =L11-K32*Assumptions!$D$37 -> -1889.5431
A35: TERMINAL VALUE & EV SUMMARY
A36: Gordon Growth TV ($mm) | M36: =IF(Assumptions!$D$37>Assumptions!$D$6,M11*(1-Assumptions!$D$6/Assumptions!$D$25)/(Assumptions!$D$37-Assumptions!$D$6),0) -> 18080.366
A37: Exit Multiple TV ($mm) | M37: =L9*Assumptions!$D$24 -> 12537.635
A38: Blended TV ($mm) | M38: =(M36+M37)/2 -> 15309
A39: PV of Blended TV ($mm) | M39: =M38*L28 -> 7751.1137
A41: Sum PV FCFF ($mm) | M41: =L30 -> 6858.4703
...

Sheet DCF_Bear
A1: =Ticker&" — BEAR SCENARIO | "&Ticker&" Valuation" -> BAH — BEAR SCENARIO | BAH Valuation
A2: SCENARIO PARAMETERS
A3: Growth Multiplier | B3: 0.6
A4: EBIT Margin Multiplier | B4: 0.75
A5: Capex Multiplier | B5: 1.2
A6: WACC Adjustment (add) | B6: 0.02
A7: Exit Multiple Multiplier | B7: 0.7
A9: 10-YEAR FCFF PROJECTION ($mm) | B9: LTM | C9: Y1 | D9: Y2 | E9: Y3 | F9: Y4 | G9: Y5 | H9: Y6 | I9: Y7 | J9: Y8 | K9: Y9 | L9: Y10 | M9: Terminal
A10: ── REVENUE ─────────────────────────────────
A11: Revenue ($mm) | B11: =Assumptions!$D$3 -> 11217 | C11: =B11*(1+Assumptions!$D$4*$B$3) -> 11233.641 | D11: =C11*(1+Assumptions!$D$4*$B$3) -> 11250.306 | E11: =D11*(1+Assumptions!$D$4*$B$3) -> 11266.996 | F11: =E11*(1+Assumptions!$D$4*$B$3) -> 11283.71 | G11: =F11*(1+Assumptions!$D$4*$B$3) -> 11300.45 | H11: =G11*(1+Assumptions!$D$5*$B$3) -> 11309.67 | I11: =H11*(1+Assumptions!$D$5*$B$3) -> 11318.898 | J11: =I11*(1+Assumptions!$D$5*$B$3) -> 11328.134 | K11: =J11*(1+Assumptions!$D$5*$B$3) -> 11337.377 | L11: =K11*(1+Assumptions!$D$5*$B$3) -> 11346.627 | M11: =L11*(1+Assumptions!$D$6) -> 11630.293
A12: Revenue Growth % | C12: =C11/B11-1 -> 0.00148351 | D12: =D11/C11-1 -> 0.00148351 | E12: =E11/D11-1 -> 0.00148351 | F12: =F11/E11-1 -> 0.00148351 | G12: =G11/F11-1 -> 0.00148351 | H12: =H11/G11-1 -> 0.00081593052 | I12: =I11/H11-1 -> 0.00081593052 | J12: =J11/I11-1 -> 0.00081593052 | ... M12: =M11/L11-1 -> 0.025
A13: ── PROFITABILITY ────────────────────────────
A14: EBIT Margin % | C14: =Assumptions!$D$8+(Assumptions!$D$9*$B$4-Assumptions!$D$8)*(COLUMN()-2)/10 -> 0.097090954 | D14: =Assumptions!$D$8+(Assumptions!$D$9*$B$4-Assumptions!$D$8)*(COLUMN()-2)/10 -> 0.095818224 | E14: =Assumptions!$D$8+(Assumptions!$D$9*$B$4-Assumptions!$D$8)*(COLUMN()-2)/10 -> 0.094545494 | F14: =Assumptions!$D$8+(Assumptions!$D$9*$B$4-Assumptions!$D$8)*(COLUMN()-2)/10 -> 0.093272763 | G14: =Assumptions!$D$8+(Assumptions!$D$9*$B$4-Assumptions!$D$8)*(COLUMN()-2)/10 -> 0.092000033 | H14: =Assumptions!$D$8+(Assumptions!$D$9*$B$4-Assumptions!$D$8)*(COLUMN()-2)/10 -> 0.090727303 | I14: =Assumptions!$D$8+(Assumptions!$D$9*$B$4-Assumptions!$D$8)*(COLUMN()-2)/10 -> 0.089454572 | J14: =Assumptions!$D$8+(Assumptions!$D$9*$B$4-Assumptions!$D$8)*(COLUMN()-2)/10 -> 0.088181842 | ... L14: =Assumptions!$D$8+(Assumptions!$D$9*$B$4-Assumptions!$D$8)*(COLUMN()-2)/10 -> 0.085636382 | M14: =Assumptions!$D$9 -> 0.11418184
A15: EBIT ($mm) | C15: =C11*C14 -> 1090.6849 | D15: =D11*D14 -> 1077.9843 | E15: =E11*E14 -> 1065.2437 | F15: =F11*F14 -> 1052.4628 | G15: =G11*G14 -> 1039.6418 | H15: =H11*H14 -> 1026.0959 | I15: =I11*I14 -> 1012.5272 | J15: =J11*J14 -> 998.93569 | ... M15: =M11*M14 -> 1327.9683
A16: EBITDA ($mm) | C16: =C15+C21 -> 1254.2699 | D16: =D15+D21 -> 1241.812 | E16: =E15+E21 -> 1229.3144 | F16: =F15+F21 -> 1216.777 | G16: =G15+G21 -> 1204.1997 | H16: =H15+H21 -> 1190.788 | I16: =I15+I21 -> 1177.3537 | J16: =J15+J21 -> 1163.8967 | ... M16: =M15+M21 -> 1497.3293
A17: Tax Rate % | C17: =Assumptions!$D$14+(Assumptions!$D$15-Assumptions!$D$14)*(COLUMN()-2)/10 -> 0.20564844 | D17: =Assumptions!$D$14+(Assumptions!$D$15-Assumptions!$D$14)*(COLUMN()-2)/10 -> 0.20564844 | E17: =Assumptions!$D$14+(Assumptions!$D$15-Assumptions!$D$14)*(COLUMN()-2)/10 -> 0.20564844 | F17: =Assumptions!$D$14+(Assumptions!$D$15-Assumptions!$D$14)*(COLUMN()-2)/10 -> 0.20564844 | G17: =Assumptions!$D$14+(Assumptions!$D$15-Assumptions!$D$14)*(COLUMN()-2)/10 -> 0.20564844 | H17: =Assumptions!$D$14+(Assumptions!$D$15-Assumptions!$D$14)*(COLUMN()-2)/10 -> 0.20564844 | I17: =Assumptions!$D$14+(Assumptions!$D$15-Assumptions!$D$14)*(COLUMN()-2)/10 -> 0.20564844 | J17: =Assumptions!$D$14+(Assumptions!$D$15-Assumptions!$D$14)*(COLUMN()-2)/10 -> 0.20564844 | ... L17: =Assumptions!$D$14+(Assumptions!$D$15-Assumptions!$D$14)*(COLUMN()-2)/10 -> 0.20564844 | M17: =Assumptions!$D$15 -> 0.20564844
A18: NOPAT ($mm) | C18: =C15*(1-C17) -> 866.38724 | D18: =D15*(1-D17) -> 856.29853 | E18: =E15*(1-E17) -> 846.17797 | F18: =F15*(1-F17) -> 836.02551 | G18: =G15*(1-G17) -> 825.84106 | H18: =H15*(1-H17) -> 815.08087 | I18: =I15*(1-I17) -> 804.30256 | J18: =J15*(1-J17) -> 793.50613 | ... M18: =M15*(1-M17) -> 1054.8737
A19: ── D&A / CAPEX ──────────────────────────────
A20: D&A % Revenue | B20: =Assumptions!$D$11 -> 0.014562066 | C20: =Assumptions!$D$11 -> 0.014562066 | D20: =Assumptions!$D$11 -> 0.014562066 | E20: =Assumptions!$D$11 -> 0.014562066 | F20: =Assumptions!$D$11 -> 0.014562066 | G20: =Assumptions!$D$11 -> 0.014562066 | H20: =Assumptions!$D$11 -> 0.014562066 | I20: =Assumptions!$D$11 -> 0.014562066 | ... M20: =Assumptions!$D$11 -> 0.014562066
A21: D&A ($mm) | C21: =C11*C20 -> 163.58502 | D21: =D11*D20 -> 163.8277 | E21: =E11*E20 -> 164.07074 | F21: =F11*F20 -> 164.31414 | G21: =G11*G20 -> 164.5579 | H21: =H11*H20 -> 164.69217 | I21: =I11*I20 -> 164.82655 | J21: =J11*J20 -> 164.96103 | ... M21: =M11*M20 -> 169.3611
A22: Capex % Revenue | B22: =Assumptions!$D$12 -> 0.01 | C22: =Assumptions!$D$12*$B$5 -> 0.012 | D22: =Assumptions!$D$12*$B$5 -> 0.012 | E22: =Assumptions!$D$12*$B$5 -> 0.012 | F22: =Assumptions!$D$12*$B$5 -> 0.012 | G22: =Assumptions!$D$12*$B$5 -> 0.012 | H22: =Assumptions!$D$12*$B$5 -> 0.012 | I22: =Assumptions!$D$12*$B$5 -> 0.012 | J22: =Assumptions!$D$12*$B$5 -> 0.012 | ... L22: =Assumptions!$D$12*$B$5 -> 0.012
A23: Capex ($mm) | C23: =C11*C22 -> 134.80369 | D23: =D11*D22 -> 135.00367 | E23: =E11*E22 -> 135.20395 | F23: =F11*F22 -> 135.40452 | G23: =G11*G22 -> 135.6054 | H23: =H11*H22 -> 135.71604 | I23: =I11*I22 -> 135.82678 | J23: =J11*J22 -> 135.9376 | ... L23: =L11*L22 -> 136.15953
A24: ── NWC DRIVERS ──────────────────────────────
A25: DSO (days) | B25: =Assumptions!$D$17 -> 67.1 | C25: =Assumptions!$D$17+(Assumptions!$D$18-Assumptions!$D$17)*(COLUMN()-2)/10 -> 66.253 | D25: =Assumptions!$D$17+(Assumptions!$D$18-Assumptions!$D$17)*(COLUMN()-2)/10 -> 65.406 | E25: =Assumptions!$D$17+(Assumptions!$D$18-Assumptions!$D$17)*(COLUMN()-2)/10 -> 64.559 | F25: =Assumptions!$D$17+(Assumptions!$D$18-Assumptions!$D$17)*(COLUMN()-2)/10 -> 63.712 | G25: =Assumptions!$D$17+(Assumptions!$D$18-Assumptions!$D$17)*(COLUMN()-2)/10 -> 62.865 | H25: =Assumptions!$D$17+(Assumptions!$D$18-Assumptions!$D$17)*(COLUMN()-2)/10 -> 62.018 | I25: =Assumptions!$D$17+(Assumptions!$D$18-Assumptions!$D$17)*(COLUMN()-2)/10 -> 61.171 | J25: =Assumptions!$D$17+(Assumptions!$D$18-Assumptions!$D$17)*(COLUMN()-2)/10 -> 60.324 | ... L25: =Assumptions!$D$17+(Assumptions!$D$18-Assumptions!$D$17)*(COLUMN()-2)/10 -> 58.63
A26: DIO (days) | B26: =Assumptions!$D$19 -> 5 | C26: =Assumptions!$D$19+(Assumptions!$D$20-Assumptions!$D$19)*(COLUMN()-2)/10 -> 8.85 | D26: =Assumptions!$D$19+(Assumptions!$D$20-Assumptions!$D$19)*(COLUMN()-2)/10 -> 12.7 | E26: =Assumptions!$D$19+(Assumptions!$D$20-Assumptions!$D$19)*(COLUMN()-2)/10 -> 16.55 | F26: =Assumptions!$D$19+(Assumptions!$D$20-Assumptions!$D$19)*(COLUMN()-2)/10 -> 20.4 | G26: =Assumptions!$D$19+(Assumptions!$D$20-Assumptions!$D$19)*(COLUMN()-2)/10 -> 24.25 | H26: =Assumptions!$D$19+(Assumptions!$D$20-Assumptions!$D$19)*(COLUMN()-2)/10 -> 28.1 | I26: =Assumptions!$D$19+(Assumptions!$D$20-Assumptions!$D$19)*(COLUMN()-2)/10 -> 31.95 | J26: =Assumptions!$D$19+(Assumptions!$D$20-Assumptions!$D$19)*(COLUMN()-2)/10 -> 35.8 | ... L26: =Assumptions!$D$19+(Assumptions!$D$20-Assumptions!$D$19)*(COLUMN()-2)/10 -> 43.5
A27: DPO (days) | B27: =Assumptions!$D$21 -> 19.3 | C27: =Assumptions!$D$21+(Assumptions!$D$22-Assumptions!$D$21)*(COLUMN()-2)/10 -> 21.449 | D27: =Assumptions!$D$21+(Assumptions!$D$22-Assumptions!$D$21)*(COLUMN()-2)/10 -> 23.598 | E27: =Assumptions!$D$21+(Assumptions!$D$22-Assumptions!$D$21)*(COLUMN()-2)/10 -> 25.747 | F27: =Assumptions!$D$21+(Assumptions!$D$22-Assumptions!$D$21)*(COLUMN()-2)/10 -> 27.896 | G27: =Assumptions!$D$21+(Assumptions!$D$22-Assumptions!$D$21)*(COLUMN()-2)/10 -> 30.045 | H27: =Assumptions!$D$21+(Assumptions!$D$22-Assumptions!$D$21)*(COLUMN()-2)/10 -> 32.194 | I27: =Assumptions!$D$21+(Assumptions!$D$22-Assumptions!$D$21)*(COLUMN()-2)/10 -> 34.343 | J27: =Assumptions!$D$21+(Assumptions!$D$22-Assumptions!$D$21)*(COLUMN()-2)/10 -> 36.492 | ... L27: =Assumptions!$D$21+(Assumptions!$D$22-Assumptions!$D$21)*(COLUMN()-2)/10 -> 40.79
A28: AR ($mm) | B28: =B11/365*B25 -> 2062.0841 | C28: =C11/365*C25 -> 2039.075 | D28: =D11/365*D25 -> 2015.9931 | E28: =E11/365*E25 -> 1992.8383 | F28: =F11/365*F25 -> 1969.6103 | G28: =G11/365*G25 -> 1946.309 | H28: =H11/365*H25 -> 1921.6524 | I28: =I11/365*I25 -> 1896.9543 | ... L28: =L11/365*L25 -> 1822.6103
A29: Inventory ($mm) | B29: =B11/365*B26 -> 153.65753 | C29: =C11/365*C26 -> 272.37731 | D29: =D11/365*D26 -> 391.44899 | E29: =E11/365*E26 -> 510.87337 | F29: =F11/365*F26 -> 630.65121 | G29: =G11/365*G26 -> 750.78331 | H29: =H11/365*H26 -> 870.68968 | I29: =I11/365*I26 -> 990.79122 | ... L29: =L11/365*L26 -> 1352.2693
A30: AP ($mm) | B30: =B11/365*B27 -> 593.11808 | C30: =C11/365*C27 -> 660.13796 | D30: =D11/365*D27 -> 727.35538 | E30: =E11/365*E27 -> 794.77079 | F30: =F11/365*F27 -> 862.38462 | G30: =G11/365*G27 -> 930.19731 | H30: =H11/365*H27 -> 997.5439 | I30: =I11/365*I27 -> 1064.9998 | ... L30: =L11/365*L27 -> 1268.0244
A31: NWC ($mm) | B31: =B28+B29-B30 -> 1622.6236 | C31: =C28+C29-C30 -> 1651.3144 | D31: =D28+D29-D30 -> 1680.0868 | E31: =E28+E29-E30 -> 1708.9409 | F31: =F28+F29-F30 -> 1737.8769 | G31: =G28+G29-G30 -> 1766.895 | H31: =H28+H29-H30 -> 1794.7982 | I31: =I28+I29-I30 -> 1822.7457 | ... L31: =L28+L29-L30 -> 1906.8551
A32: ΔNWC ($mm) | C32: =C31-B31 -> 28.690819 | D32: =D31-C31 -> 28.772375 | E32: =E31-D31 -> 28.854109 | F32: =F31-E31 -> 28.936022 | G32: =G31-F31 -> 29.018115 | H32: =H31-G31 -> 27.903193 | I32: =I31-H31 -> 27.947551 | J32: =J31-I31 -> 27.991963 | ... L32: =L31-K31 -> 28.080948
A33: ── FREE CASH FLOW ───────────────────────────
A34: FCFF ($mm) | C34: =C18+C21-C23-C32 -> 866.47775 | D34: =D18+D21-D23-D32 -> 856.35018 | E34: =E18+E21-E23-E32 -> 846.19066 | F34: =F18+F21-F23-F32 -> 835.9991 | G34: =G18+G21-G23-G32 -> 825.77545 | H34: =H18+H21-H23-H32 -> 816.1538 | I34: =I18+I21-I23-I32 -> 805.35478 | J34: =J18+J21-J23-J32 -> 794.5376 | ... L34: =L18+L21-L23-L32 -> 772.84864
A35: Discount Factor | C35: =1/(1+(Assumptions!$D$37+$B$6))^1 -> 0.91706941 | D35: =1/(1+(Assumptions!$D$37+$B$6))^2 -> 0.84101631 | E35: =1/(1+(Assumptions!$D$37+$B$6))^3 -> 0.77127033 | F35: =1/(1+(Assumptions!$D$37+$B$6))^4 -> 0.70730843 | G35: =1/(1+(Assumptions!$D$37+$B$6))^5 -> 0.64865093 | H35: =1/(1+(Assumptions!$D$37+$B$6))^6 -> 0.59485793 | I35: =1/(1+(Assumptions!$D$37+$B$6))^7 -> 0.54552601 | J35: =1/(1+(Assumptions!$D$37+$B$6))^8 -> 0.50028522 | K35: =1/(1+(Assumptions!$D$37+$B$6))^9 -> 0.45879627 | L35: =1/(1+(Assumptions!$D$37+$B$6))^10 -> 0.42074803 | M35: =1/(1+(Assumptions!$D$37+$B$6))^10 -> 0.42074803
A36: PV FCFF ($mm) | C36: =C34*C35 -> 794.62024 | D36: =D34*D35 -> 720.20447 | E36: =E34*E35 -> 652.64175 | F36: =F34*F35 -> 591.30921 | G36: =G34*G35 -> 535.64001 | H36: =H34*H35 -> 485.49556 | I36: =I34*I35 -> 439.34198 | J36: =J34*J35 -> 397.49541 | ... L36: =L34*L35 -> 325.17454
A37: Cumulative PV FCFF ($mm) | C37: =C36 -> 794.62024 | D37: =C37+D36 -> 1514.8247 | E37: =D37+E36 -> 2167.4665 | F37: =E37+F36 -> 2758.7757 | G37: =F37+G36 -> 3294.4157 | H37: =G37+H36 -> 3779.9112 | I37: =H37+I36 -> 4219.2532 | J37: =I37+J36 -> 4616.7486 | K37: =J37+K36 -> 4976.3083 | L37: =K37+L36 -> 5301.4828
A38: ── RETURNS ──────────────────────────────────
A39: Invested Capital ($mm) | B39: =Assumptions!$D$41 -> 41749.375 | C39: =B39+C23+C32-C21 -> 41749.284 | D39: =C39+D23+D32-D21 -> 41749.233 | E39: =D39+E23+E32-E21 -> 41749.22 | F39: =E39+F23+F32-F21 -> 41749.247 | G39: =F39+G23+G32-G21 -> 41749.312 | H39: =G39+H23+H32-H21 -> 41748.239 | I39: =H39+I23+I32-I21 -> 41747.187 | J39: =I39+J23+J32-J21 -> 41746.156 | ... L39: =K39+L23+L32-L21 -> 41744.155
A40: ROIC % | C40: =C18/B39 -> 0.020752101 | D40: =D18/C39 -> 0.020510496 | E40: =E18/D39 -> 0.020268108 | F40: =F18/E39 -> 0.020024937 | G40: =G18/F39 -> 0.019780981 | H40: =H18/G39 -> 0.019523217 | I40: =I18/H39 -> 0.019265545 | J40: =J18/I39 -> 0.019007415 | ... L40: =L18/K39 -> 0.018489786
A41: Economic Profit ($mm) | C41: =C18-B39*(Assumptions!$D$37+$B$6) -> -2909.0087 | D41: =D18-C39*(Assumptions!$D$37+$B$6) -> -2919.0893 | E41: =E18-D39*(Assumptions!$D$37+$B$6) -> -2929.2052 | F41: =F18-E39*(Assumptions!$D$37+$B$6) -> -2939.3565 | G41: =G18-F39*(Assumptions!$D$37+$B$6) -> -2949.5433 | H41: =H18-G39*(Assumptions!$D$37+$B$6) -> -2960.3094 | I41: =I18-H39*(Assumptions!$D$37+$B$6) -> -2970.9907 | J41: =J18-I39*(Assumptions!$D$37+$B$6) -> -2981.692 | ... L41: =L18-K39*(Assumptions!$D$37+$B$6) -> -3003.1547
...

Sheet DCF_Bull
A1: =Ticker&" — BULL SCENARIO | "&Ticker&" Valuation" -> BAH — BULL SCENARIO | BAH Valuation
A2: SCENARIO PARAMETERS
A3: Growth Multiplier | B3: 1.4
A4: EBIT Margin Multiplier | B4: 1.15
A5: Capex Multiplier | B5: 0.9
A6: WACC Adjustment (add) | B6: -0.01
A7: Exit Multiple Multiplier | B7: 1.3
A9: 10-YEAR FCFF PROJECTION ($mm) | B9: LTM | C9: Y1 | D9: Y2 | E9: Y3 | F9: Y4 | G9: Y5 | H9: Y6 | I9: Y7 | J9: Y8 | K9: Y9 | L9: Y10 | M9: Terminal
A10: ── REVENUE ─────────────────────────────────
A11: Revenue ($mm) | B11: =Assumptions!$D$3 -> 11217 | C11: =B11*(1+Assumptions!$D$4*$B$3) -> 11255.828 | D11: =C11*(1+Assumptions!$D$4*$B$3) -> 11294.79 | E11: =D11*(1+Assumptions!$D$4*$B$3) -> 11333.887 | F11: =E11*(1+Assumptions!$D$4*$B$3) -> 11373.12 | G11: =F11*(1+Assumptions!$D$4*$B$3) -> 11412.488 | H11: =G11*(1+Assumptions!$D$5*$B$3) -> 11434.216 | I11: =H11*(1+Assumptions!$D$5*$B$3) -> 11455.985 | J11: =I11*(1+Assumptions!$D$5*$B$3) -> 11477.795 | K11: =J11*(1+Assumptions!$D$5*$B$3) -> 11499.647 | L11: =K11*(1+Assumptions!$D$5*$B$3) -> 11521.54 | M11: =L11*(1+Assumptions!$D$6) -> 11809.579
A12: Revenue Growth % | C12: =C11/B11-1 -> 0.0034615234 | D12: =D11/C11-1 -> 0.0034615234 | E12: =E11/D11-1 -> 0.0034615234 | F12: =F11/E11-1 -> 0.0034615234 | G12: =G11/F11-1 -> 0.0034615234 | H12: =H11/G11-1 -> 0.0019038379 | I12: =I11/H11-1 -> 0.0019038379 | J12: =J11/I11-1 -> 0.0019038379 | ... M12: =M11/L11-1 -> 0.025
A13: ── PROFITABILITY ────────────────────────────
A14: EBIT Margin % | C14: =Assumptions!$D$8+(Assumptions!$D$9*$B$4-Assumptions!$D$8)*(COLUMN()-2)/10 -> 0.10165823 | D14: =Assumptions!$D$8+(Assumptions!$D$9*$B$4-Assumptions!$D$8)*(COLUMN()-2)/10 -> 0.10495277 | E14: =Assumptions!$D$8+(Assumptions!$D$9*$B$4-Assumptions!$D$8)*(COLUMN()-2)/10 -> 0.10824731 | F14: =Assumptions!$D$8+(Assumptions!$D$9*$B$4-Assumptions!$D$8)*(COLUMN()-2)/10 -> 0.11154186 | G14: =Assumptions!$D$8+(Assumptions!$D$9*$B$4-Assumptions!$D$8)*(COLUMN()-2)/10 -> 0.1148364 | H14: =Assumptions!$D$8+(Assumptions!$D$9*$B$4-Assumptions!$D$8)*(COLUMN()-2)/10 -> 0.11813094 | I14: =Assumptions!$D$8+(Assumptions!$D$9*$B$4-Assumptions!$D$8)*(COLUMN()-2)/10 -> 0.12142549 | J14: =Assumptions!$D$8+(Assumptions!$D$9*$B$4-Assumptions!$D$8)*(COLUMN()-2)/10 -> 0.12472003 | ... L14: =Assumptions!$D$8+(Assumptions!$D$9*$B$4-Assumptions!$D$8)*(COLUMN()-2)/10 -> 0.13130912 | M14: =Assumptions!$D$9 -> 0.11418184
A15: EBIT ($mm) | C15: =C11*C14 -> 1144.2475 | D15: =D11*D14 -> 1185.4195 | E15: =E11*E14 -> 1226.8629 | F15: =F11*F14 -> 1268.5789 | G15: =G11*G14 -> 1310.5691 | H15: =H11*H14 -> 1350.7347 | I15: =I11*I14 -> 1391.0485 | J15: =J11*J14 -> 1431.511 | ... M15: =M11*M14 -> 1348.4395
A16: EBITDA ($mm) | C16: =C15+C21 -> 1308.1556 | D16: =D15+D21 -> 1349.895 | E16: =E15+E21 -> 1391.9077 | F16: =F15+F21 -> 1434.1951 | G16: =G15+G21 -> 1476.7585 | H16: =H15+H21 -> 1517.2405 | I16: =I15+I21 -> 1557.8713 | J16: =J15+J21 -> 1598.6514 | ... M16: =M15+M21 -> 1520.4113
A17: Tax Rate % | C17: =Assumptions!$D$14+(Assumptions!$D$15-Assumptions!$D$14)*(COLUMN()-2)/10 -> 0.20564844 | D17: =Assumptions!$D$14+(Assumptions!$D$15-Assumptions!$D$14)*(COLUMN()-2)/10 -> 0.20564844 | E17: =Assumptions!$D$14+(Assumptions!$D$15-Assumptions!$D$14)*(COLUMN()-2)/10 -> 0.20564844 | F17: =Assumptions!$D$14+(Assumptions!$D$15-Assumptions!$D$14)*(COLUMN()-2)/10 -> 0.20564844 | G17: =Assumptions!$D$14+(Assumptions!$D$15-Assumptions!$D$14)*(COLUMN()-2)/10 -> 0.20564844 | H17: =Assumptions!$D$14+(Assumptions!$D$15-Assumptions!$D$14)*(COLUMN()-2)/10 -> 0.20564844 | I17: =Assumptions!$D$14+(Assumptions!$D$15-Assumptions!$D$14)*(COLUMN()-2)/10 -> 0.20564844 | J17: =Assumptions!$D$14+(Assumptions!$D$15-Assumptions!$D$14)*(COLUMN()-2)/10 -> 0.20564844 | ... L17: =Assumptions!$D$14+(Assumptions!$D$15-Assumptions!$D$14)*(COLUMN()-2)/10 -> 0.20564844 | M17: =Assumptions!$D$15 -> 0.20564844
A18: NOPAT ($mm) | C18: =C15*(1-C17) -> 908.9348 | D18: =D15*(1-D17) -> 941.63986 | E18: =E15*(1-E17) -> 974.56044 | F18: =F15*(1-F17) -> 1007.6977 | G18: =G15*(1-G17) -> 1041.0526 | H18: =H15*(1-H17) -> 1072.9582 | I18: =I15*(1-I17) -> 1104.9816 | J18: =J15*(1-J17) -> 1137.123 | ... M18: =M15*(1-M17) -> 1071.135
A19: ── D&A / CAPEX ──────────────────────────────
A20: D&A % Revenue | B20: =Assumptions!$D$11 -> 0.014562066 | C20: =Assumptions!$D$11 -> 0.014562066 | D20: =Assumptions!$D$11 -> 0.014562066 | E20: =Assumptions!$D$11 -> 0.014562066 | F20: =Assumptions!$D$11 -> 0.014562066 | G20: =Assumptions!$D$11 -> 0.014562066 | H20: =Assumptions!$D$11 -> 0.014562066 | I20: =Assumptions!$D$11 -> 0.014562066 | ... M20: =Assumptions!$D$11 -> 0.014562066
A21: D&A ($mm) | C21: =C11*C20 -> 163.90811 | D21: =D11*D20 -> 164.47548 | E21: =E11*E20 -> 165.04482 | F21: =F11*F20 -> 165.61613 | G21: =G11*G20 -> 166.18941 | H21: =H11*H20 -> 166.50581 | I21: =I11*I20 -> 166.82281 | J21: =J11*J20 -> 167.14041 | ... M21: =M11*M20 -> 171.97187
A22: Capex % Revenue | B22: =Assumptions!$D$12 -> 0.01 | C22: =Assumptions!$D$12*$B$5 -> 0.009 | D22: =Assumptions!$D$12*$B$5 -> 0.009 | E22: =Assumptions!$D$12*$B$5 -> 0.009 | F22: =Assumptions!$D$12*$B$5 -> 0.009 | G22: =Assumptions!$D$12*$B$5 -> 0.009 | H22: =Assumptions!$D$12*$B$5 -> 0.009 | I22: =Assumptions!$D$12*$B$5 -> 0.009 | J22: =Assumptions!$D$12*$B$5 -> 0.009 | ... L22: =Assumptions!$D$12*$B$5 -> 0.009
A23: Capex ($mm) | C23: =C11*C22 -> 101.30245 | D23: =D11*D22 -> 101.65311 | E23: =E11*E22 -> 102.00499 | F23: =F11*F22 -> 102.35808 | G23: =G11*G22 -> 102.71239 | H23: =H11*H22 -> 102.90794 | I23: =I11*I22 -> 103.10386 | J23: =J11*J22 -> 103.30015 | ... L23: =L11*L22 -> 103.69386
A24: ── NWC DRIVERS ──────────────────────────────
A25: DSO (days) | B25: =Assumptions!$D$17 -> 67.1 | C25: =Assumptions!$D$17+(Assumptions!$D$18-Assumptions!$D$17)*(COLUMN()-2)/10 -> 66.253 | D25: =Assumptions!$D$17+(Assumptions!$D$18-Assumptions!$D$17)*(COLUMN()-2)/10 -> 65.406 | E25: =Assumptions!$D$17+(Assumptions!$D$18-Assumptions!$D$17)*(COLUMN()-2)/10 -> 64.559 | F25: =Assumptions!$D$17+(Assumptions!$D$18-Assumptions!$D$17)*(COLUMN()-2)/10 -> 63.712 | G25: =Assumptions!$D$17+(Assumptions!$D$18-Assumptions!$D$17)*(COLUMN()-2)/10 -> 62.865 | H25: =Assumptions!$D$17+(Assumptions!$D$18-Assumptions!$D$17)*(COLUMN()-2)/10 -> 62.018 | I25: =Assumptions!$D$17+(Assumptions!$D$18-Assumptions!$D$17)*(COLUMN()-2)/10 -> 61.171 | J25: =Assumptions!$D$17+(Assumptions!$D$18-Assumptions!$D$17)*(COLUMN()-2)/10 -> 60.324 | ... L25: =Assumptions!$D$17+(Assumptions!$D$18-Assumptions!$D$17)*(COLUMN()-2)/10 -> 58.63
A26: DIO (days) | B26: =Assumptions!$D$19 -> 5 | C26: =Assumptions!$D$19+(Assumptions!$D$20-Assumptions!$D$19)*(COLUMN()-2)/10 -> 8.85 | D26: =Assumptions!$D$19+(Assumptions!$D$20-Assumptions!$D$19)*(COLUMN()-2)/10 -> 12.7 | E26: =Assumptions!$D$19+(Assumptions!$D$20-Assumptions!$D$19)*(COLUMN()-2)/10 -> 16.55 | F26: =Assumptions!$D$19+(Assumptions!$D$20-Assumptions!$D$19)*(COLUMN()-2)/10 -> 20.4 | G26: =Assumptions!$D$19+(Assumptions!$D$20-Assumptions!$D$19)*(COLUMN()-2)/10 -> 24.25 | H26: =Assumptions!$D$19+(Assumptions!$D$20-Assumptions!$D$19)*(COLUMN()-2)/10 -> 28.1 | I26: =Assumptions!$D$19+(Assumptions!$D$20-Assumptions!$D$19)*(COLUMN()-2)/10 -> 31.95 | J26: =Assumptions!$D$19+(Assumptions!$D$20-Assumptions!$D$19)*(COLUMN()-2)/10 -> 35.8 | ... L26: =Assumptions!$D$19+(Assumptions!$D$20-Assumptions!$D$19)*(COLUMN()-2)/10 -> 43.5
A27: DPO (days) | B27: =Assumptions!$D$21 -> 19.3 | C27: =Assumptions!$D$21+(Assumptions!$D$22-Assumptions!$D$21)*(COLUMN()-2)/10 -> 21.449 | D27: =Assumptions!$D$21+(Assumptions!$D$22-Assumptions!$D$21)*(COLUMN()-2)/10 -> 23.598 | E27: =Assumptions!$D$21+(Assumptions!$D$22-Assumptions!$D$21)*(COLUMN()-2)/10 -> 25.747 | F27: =Assumptions!$D$21+(Assumptions!$D$22-Assumptions!$D$21)*(COLUMN()-2)/10 -> 27.896 | G27: =Assumptions!$D$21+(Assumptions!$D$22-Assumptions!$D$21)*(COLUMN()-2)/10 -> 30.045 | H27: =Assumptions!$D$21+(Assumptions!$D$22-Assumptions!$D$21)*(COLUMN()-2)/10 -> 32.194 | I27: =Assumptions!$D$21+(Assumptions!$D$22-Assumptions!$D$21)*(COLUMN()-2)/10 -> 34.343 | J27: =Assumptions!$D$21+(Assumptions!$D$22-Assumptions!$D$21)*(COLUMN()-2)/10 -> 36.492 | ... L27: =Assumptions!$D$21+(Assumptions!$D$22-Assumptions!$D$21)*(COLUMN()-2)/10 -> 40.79
A28: AR ($mm) | B28: =B11/365*B25 -> 2062.0841 | C28: =C11/365*C25 -> 2043.1024 | D28: =D11/365*D25 -> 2023.9645 | E28: =E11/365*E25 -> 2004.6697 | F28: =F11/365*F25 -> 1985.217 | G28: =G11/365*G25 -> 1965.6057 | H28: =H11/365*H25 -> 1942.8142 | I28: =I11/365*I25 -> 1919.9289 | ... L28: =L11/365*L25 -> 1850.7066
A29: Inventory ($mm) | B29: =B11/365*B26 -> 153.65753 | C29: =C11/365*C26 -> 272.91528 | D29: =D11/365*D26 -> 392.99681 | E29: =E11/365*E26 -> 513.9064 | F29: =F11/365*F26 -> 635.64835 | G29: =G11/365*G26 -> 758.22696 | H29: =H11/365*H26 -> 880.27798 | I29: =I11/365*I26 -> 1002.791 | ... L29: =L11/365*L26 -> 1373.1151
A30: AP ($mm) | B30: =B11/365*B27 -> 593.11808 | C30: =C11/365*C27 -> 661.44179 | D30: =D11/365*D27 -> 730.2314 | E30: =E11/365*E27 -> 799.48931 | F30: =F11/365*F27 -> 869.21795 | G30: =G11/365*G27 -> 939.41975 | H30: =H11/365*H27 -> 1008.5292 | I30: =I11/365*I27 -> 1077.8983 | ... L30: =L11/365*L27 -> 1287.5716
A31: NWC ($mm) | B31: =B28+B29-B30 -> 1622.6236 | C31: =C28+C29-C30 -> 1654.5759 | D31: =D28+D29-D30 -> 1686.7299 | E31: =E28+E29-E30 -> 1719.0868 | F31: =F28+F29-F30 -> 1751.6474 | G31: =G28+G29-G30 -> 1784.4129 | H31: =H28+H29-H30 -> 1814.5631 | I31: =I28+I29-I30 -> 1844.8216 | ... L31: =L28+L29-L30 -> 1936.2501
A32: ΔNWC ($mm) | C32: =C31-B31 -> 31.952303 | D32: =D31-C31 -> 32.154068 | E32: =E31-D31 -> 32.356846 | F32: =F31-E31 -> 32.560644 | G32: =G31-F31 -> 32.765464 | H32: =H31-G31 -> 30.150165 | I32: =I31-H31 -> 30.258499 | J32: =J31-I31 -> 30.367137 | ... L32: =L31-K31 -> 30.585325
A33: ── FREE CASH FLOW ───────────────────────────
A34: FCFF ($mm) | C34: =C18+C21-C23-C32 -> 939.58816 | D34: =D18+D21-D23-D32 -> 972.30817 | E34: =E18+E21-E23-E32 -> 1005.2434 | F34: =F18+F21-F23-F32 -> 1038.3951 | G34: =G18+G21-G23-G32 -> 1071.7642 | H34: =H18+H21-H23-H32 -> 1106.4059 | I34: =I18+I21-I23-I32 -> 1138.442 | J34: =J18+J21-J23-J32 -> 1170.5961 | ... L34: =L18+L21-L23-L32 -> 1235.2595
A35: Discount Factor | C35: =1/(1+(Assumptions!$D$37+$B$6))^1 -> 0.94301368 | D35: =1/(1+(Assumptions!$D$37+$B$6))^2 -> 0.88927481 | E35: =1/(1+(Assumptions!$D$37+$B$6))^3 -> 0.83859831 | F35: =1/(1+(Assumptions!$D$37+$B$6))^4 -> 0.79080968 | G35: =1/(1+(Assumptions!$D$37+$B$6))^5 -> 0.74574435 | H35: =1/(1+(Assumptions!$D$37+$B$6))^6 -> 0.70324713 | I35: =1/(1+(Assumptions!$D$37+$B$6))^7 -> 0.66317166 | J35: =1/(1+(Assumptions!$D$37+$B$6))^8 -> 0.62537995 | K35: =1/(1+(Assumptions!$D$37+$B$6))^9 -> 0.58974185 | L35: =1/(1+(Assumptions!$D$37+$B$6))^10 -> 0.55613464 | M35: =1/(1+(Assumptions!$D$37+$B$6))^10 -> 0.55613464
A36: PV FCFF ($mm) | C36: =C34*C35 -> 886.04449 | D36: =D34*D35 -> 864.64916 | E36: =E34*E35 -> 842.99544 | F36: =F34*F35 -> 821.17287 | G36: =G34*G35 -> 799.26206 | H36: =H34*H35 -> 778.07679 | I36: =I34*I35 -> 754.98249 | J36: =J34*J35 -> 732.06733 | ... L36: =L34*L35 -> 686.97057
A37: Cumulative PV FCFF ($mm) | C37: =C36 -> 886.04449 | D37: =C37+D36 -> 1750.6937 | E37: =D37+E36 -> 2593.6891 | F37: =E37+F36 -> 3414.862 | G37: =F37+G36 -> 4214.124 | H37: =G37+H36 -> 4992.2008 | I37: =H37+I36 -> 5747.1833 | J37: =I37+J36 -> 6479.2506 | K37: =J37+K36 -> 7188.6325 | L37: =K37+L36 -> 7875.6031
A38: ── RETURNS ──────────────────────────────────
A39: Invested Capital ($mm) | B39: =Assumptions!$D$41 -> 41749.375 | C39: =B39+C23+C32-C21 -> 41718.722 | D39: =C39+D23+D32-D21 -> 41688.053 | E39: =D39+E23+E32-E21 -> 41657.37 | F39: =E39+F23+F32-F21 -> 41626.673 | G39: =F39+G23+G32-G21 -> 41595.961 | H39: =G39+H23+H32-H21 -> 41562.514 | I39: =H39+I23+I32-I21 -> 41529.053 | J39: =I39+J23+J32-J21 -> 41495.58 | ... L39: =K39+L23+L32-L21 -> 41428.596
A40: ROIC % | C40: =C18/B39 -> 0.021771219 | D40: =D18/C39 -> 0.022571158 | E40: =E18/D39 -> 0.023377451 | F40: =F18/E39 -> 0.024190141 | G40: =G18/F39 -> 0.025009268 | H40: =H18/G39 -> 0.025794769 | I40: =I18/H39 -> 0.026586014 | J40: =J18/I39 -> 0.027381384 | ... L40: =L18/K39 -> 0.028984576
A41: Economic Profit ($mm) | C41: =C18-B39*(Assumptions!$D$37+$B$6) -> -1613.9799 | D41: =D18-C39*(Assumptions!$D$37+$B$6) -> -1579.4225 | E41: =E18-D39*(Assumptions!$D$37+$B$6) -> -1544.6486 | F41: =F18-E39*(Assumptions!$D$37+$B$6) -> -1509.6572 | G41: =G18-F39*(Assumptions!$D$37+$B$6) -> -1474.4472 | H41: =H18-G39*(Assumptions!$D$37+$B$6) -> -1440.6857 | I41: =I18-H39*(Assumptions!$D$37+$B$6) -> -1406.6411 | J41: =J18-I39*(Assumptions!$D$37+$B$6) -> -1372.4777 | ... L41: =L18-K39*(Assumptions!$D$37+$B$6) -> -1303.7931
...

Sheet Equity_Bridge
A1: =Ticker&" — Equity Bridge" -> BAH — Equity Bridge
A2: Item | B2: Bear | C2: Base | D2: Bull | E2: Notes
A3: Sum PV FCFF (Y1-Y10) $mm | B3: =DCF_Bear!M48 -> 5301.4828 | C3: =DCF_Base!M41 -> 6858.4703 | D3: =DCF_Bull!M48 -> 7875.6031
A4: PV Terminal Value $mm | B4: =DCF_Bear!M46 -> 4046.8392 | C4: =DCF_Base!M39 -> 7751.1137 | D4: =DCF_Bull!M46 -> 11670.594 | E4: Blended (Gordon+Exit)/2
A5: EV — Operations $mm | B5: =DCF_Bear!M49 -> 9348.322 | C5: =DCF_Base!M42 -> 14609.584 | D5: =DCF_Bull!M49 -> 19546.197
A6: TV % of EV | B6: =DCF_Bear!M50 -> 0.43289471 | C6: =DCF_Base!M43 -> 0.53054993 | D6: =DCF_Bull!M50 -> 0.59707748 | E6: Flag if >75%
A7: (+) Non-Operating Assets $mm | B7: =Assumptions!$D$42 -> 503.66 | C7: =Assumptions!$D$42 -> 503.66 | D7: =Assumptions!$D$42 -> 503.66
A8: EV — Total $mm | B8: =B5+B7 -> 9851.982 | C8: =C5+C7 -> 15113.244 | D8: =D5+D7 -> 20049.857 | E8: EV_ops + Non-op assets
A9: (-) Net Debt $mm | B9: =Assumptions!$D$39 -> 3394 | C9: =Assumptions!$D$39 -> 3394 | D9: =Assumptions!$D$39 -> 3394
A10: (-) Minority Interest $mm | B10: =Assumptions!$D$43 -> 0 | C10: =Assumptions!$D$43 -> 0 | D10: =Assumptions!$D$43 -> 0
A11: (-) Preferred Equity $mm | B11: =Assumptions!$D$44 -> 0 | C11: =Assumptions!$D$44 -> 0 | D11: =Assumptions!$D$44 -> 0
A12: (-) Pension Deficit $mm | B12: =Assumptions!$D$45 -> 0 | C12: =Assumptions!$D$45 -> 0 | D12: =Assumptions!$D$45 -> 0
A13: (-) Lease Liabilities $mm | B13: =Assumptions!$D$46 -> 0 | C13: =Assumptions!$D$46 -> 0 | D13: =Assumptions!$D$46 -> 0
A14: (-) Options Value $mm | B14: =Assumptions!$D$47 -> 0 | C14: =Assumptions!$D$47 -> 0 | D14: =Assumptions!$D$47 -> 0
A15: (-) Convertibles $mm | B15: =Assumptions!$D$48 -> 0 | C15: =Assumptions!$D$48 -> 0 | D15: =Assumptions!$D$48 -> 0
A16: Equity Value $mm | B16: =B8-B9-B10-B11-B12-B13-B14-B15 -> 6457.982 | C16: =C8-C9-C10-C11-C12-C13-C14-C15 -> 11719.244 | D16: =D8-D9-D10-D11-D12-D13-D14-D15 -> 16655.857 | E16: EV_Total − all claims
A17: Shares Outstanding (mm) | B17: =Assumptions!$D$40 -> 122.375 | C17: =Assumptions!$D$40 -> 122.375 | D17: =Assumptions!$D$40 -> 122.375
A18: Intrinsic Value / Share | B18: =B16/B17 -> 52.772069 | C18: =C16/C17 -> 95.765017 | D18: =D16/D17 -> 136.10506 | E18: Equity / Shares
A19: Market Price | B19: =Price -> 77.41 | C19: =Price -> 77.41 | D19: =Price -> 77.41 | E19: As of 2026-03-09
A20: Upside / (Downside) % | B20: =B18/B19-1 -> -0.31827839 | C20: =C18/C19-1 -> 0.23711429 | D20: =D18/D19-1 -> 0.7582362
A21: EXPECTED INTRINSIC VALUE
A22: Expected IV / Share (probability-weighted) | C22: =B18*Assumptions!$D$50+C18*Assumptions!$D$51+D18*Assumptions!$D$52 -> 95.234437
A23: Expected Upside % | C23: =C22/B19-1 -> 0.23026014

Sheet Comps
A1: =Ticker&" — Comparable Companies Analysis" -> BAH — Comparable Companies Analysis
A2: Excl. | B2: Ticker | C2: Company | D2: MCap $mm | E2: TEV $mm | F2: Revenue $mm | G2: EBITDA $mm | H2: EBIT $mm | I2: EPS | J2: EV/EBITDA LTM | K2: EV/EBITDA Fwd | L2: EV/EBIT | M2: P/E
B3: IBM | C3: International Business Machines Corporation | D3: 237632 | E3: 293093 | F3: 66799 | J3: 18.184 | M3: 22.761005
B4: ORCL | D4: 439620.96 | E4: 552090.96 | F4: 61016 | G4: 26266 | H4: 0 | I4: 5.32668 | J4: 19.42683 | K4: 13.8225 | L4: 0 | M4: 28.71585
B5: ACN | D5: 132290.95 | E5: 131892.42 | F5: 70725.557 | G5: 12458.011 | H5: 0 | I5: 12.08706 | J5: 9.82953 | K5: 7.7932 | L5: 0 | M5: 17.78762
B6: HPE | D6: 28077.722 | E6: 47174.722 | F6: 34296 | G6: 4491 | H6: 0 | I6: -0.04456 | J6: 9.66695 | K6: 7.99156 | L6: 0 | M6: 0
B7: CTSH | D7: 31688.641 | E7: 30948.641 | F7: 21108 | G7: 3834 | H7: 0 | I7: 4.56 | J7: 7.63034 | K7: 7.42554 | L7: 0 | M7: 14.5307
B8: SNX | D8: 12607.549 | E8: 15254.142 | F8: 62508.086 | G8: 1836.742 | H8: 0 | I8: 9.95013 | J8: 7.72294 | K8: 7.64777 | L8: 0 | M8: 15.71538
B9: MSFT | D9: 3036785.3 | E9: 3070601.3 | F9: 305453 | G9: 175259 | H9: 0 | I9: 15.98055 | J9: 16.31624 | K9: 14.35137 | L9: 0 | M9: 25.59112
B10: DXC | D10: 2198.3915 | E10: 5058.3915 | F10: 12683 | G10: 1914 | H10: 0 | I10: 2.3206 | J10: 2.21084 | K10: 2.84159 | L10: 0 | M10: 5.58045
B11: HON | D11: 149568.14 | E11: 173327.14 | F11: 37442 | G11: 8468 | H11: 0 | I11: 6.88707 | J11: 19.78846 | K11: 17.30579 | L11: 0 | M11: 34.16403
A12: MEDIAN (excluding "x" peers) | J12: =IFERROR(MEDIAN(IF(A4:A11<>"x",J4:J11)),MEDIAN(J4:J11)) -> 9.74824 | K12: =IFERROR(MEDIAN(IF(A4:A11<>"x",K4:K11)),MEDIAN(K4:K11)) -> 7.89238 | L12: =IFERROR(MEDIAN(IF(A4:A11<>"x",L4:L11)),MEDIAN(L4:L11)) -> 0 | M12: =IFERROR(MEDIAN(IF(A4:A11<>"x",M4:M11)),MEDIAN(M4:M11)) -> 16.7515
A14: IMPLIED INTRINSIC VALUE (Comps) | B14: TEV ($mm) | C14: Equity ($mm) | D14: IV/Share | E14: Upside %
A15: EV/EBITDA LTM approach | C15: =B15+Assumptions!$D$42-(Assumptions!$D$39+Assumptions!$D$43+Assumptions!$D$44+Assumptions!$D$45+Assumptions!$D$46+Assumptions!$D$47+Assumptions!$D$48) -> -2890.34 | D15: =C15/Assumptions!$D$40 -> -23.618713 | E15: =D15/253.33-1 -> -1.093233
A16: EV/EBIT LTM approach | B16: =L12*Assumptions!$D$3*Assumptions!$D$8 -> 0 | C16: =B16+Assumptions!$D$42-(Assumptions!$D$39+Assumptions!$D$43+Assumptions!$D$44+Assumptions!$D$45+Assumptions!$D$46+Assumptions!$D$47+Assumptions!$D$48) -> -2890.34 | D16: =C16/Assumptions!$D$40 -> -23.618713 | E16: =D16/253.33-1 -> -1.093233
A17: P/E approach | B17: =(M12*Assumptions!$D$3*Assumptions!$D$8*(1-Assumptions!$D$14)+Assumptions!$D$42-(Assumptions!$D$39+Assumptions!$D$43+Assumptions!$D$44+Assumptions!$D$45+Assumptions!$D$46+Assumptions!$D$47+Assumptions!$D$48)) -> 11791.415 | C17: =B17+Assumptions!$D$42-(Assumptions!$D$39+Assumptions!$D$43+Assumptions!$D$44+Assumptions!$D$45+Assumptions!$D$46+Assumptions!$D$47+Assumptions!$D$48) -> 8901.0747 | D17: =C17/Assumptions!$D$40 -> 72.736055 | E17: =D17/253.33-1 -> -0.71288022

Sheet Sensitivity
A1: =Ticker&" — Sensitivity Analysis" -> BAH — Sensitivity Analysis
A2: IV/Share ($) — WACC (rows) × Terminal Growth (cols)
A3: WACC \ Term. g | B3: 0.015 | C3: 0.02 | D3: 0.025 | E3: 0.03 | F3: 0.035 | G3: 0.04 | H3: 0.045 | I3: 0.05 | J3: 0.055
A4: 0.05043 | B4: 380.03 | C4: 421.19 | D4: 478.37 | E4: 563.34 | F4: 703.1 | G4: 976.46 | H4: 1752.47 | I4: 20565.41 | J4: 55.18
A5: 0.05543 | B5: 323.99 | C5: 352.3 | D5: 389.78 | E5: 441.83 | F5: 519.18 | G5: 646.38 | H5: 895.17 | I5: 1601.39 | J5: 18722.08
A6: 0.06043 | B6: 280.4 | C6: 300.54 | D6: 326.25 | E6: 360.29 | F6: 407.56 | G6: 477.78 | H6: 593.26 | I6: 819.1 | J6: 1460.15
A7: 0.06543 | B7: 245.55 | C7: 260.25 | D7: 278.5 | E7: 301.78 | F7: 332.61 | G7: 375.41 | H7: 438.98 | I7: 543.52 | J7: 747.93
A8: 0.07043 | B8: 217.08 | C8: 228.02 | D8: 241.3 | E8: 257.78 | F8: 278.8 | G8: 306.63 | H8: 345.25 | I8: 402.62 | J8: 496.93
A9: 0.07543 | B9: 193.39 | C9: 201.67 | D9: 211.52 | E9: 223.48 | F9: 238.3 | G9: 257.22 | H9: 282.24 | I9: 316.97 | J9: 368.54
A10: 0.08043 | B10: 173.39 | C10: 179.73 | D10: 187.16 | E10: 196 | F10: 206.71 | G10: 220 | H10: 236.94 | I10: 259.35 | J10: 290.45
A11: 0.08543 | B11: 156.29 | C11: 161.19 | D11: 166.86 | E11: 173.49 | F11: 181.38 | G11: 190.94 | H11: 202.79 | I11: 217.9 | J11: 237.88
A12: 0.09043 | B12: 141.51 | C12: 145.33 | D12: 149.69 | E12: 154.73 | F12: 160.63 | G12: 167.63 | H12: 176.11 | I12: 186.62 | J12: 200.02
A14: Price = $253.33 | Green = IV > Price+20% | Yellow = within 5% | Red = IV < Price-5%

Sheet QoE
A1: =Ticker&" — Quality of Earnings Signals" -> BAH — Quality of Earnings Signals
A2: QoE Composite Score: 3/5 | Flag: AMBER | As of 2026-03-09
A3: Signal | B3: Value | C3: Score | D3: Threshold | E3: Interpretation
A4: Sloan Accruals Ratio | B4: 0.045 | C4: AMBER | D4: <5% green / >10% red | E4: Earnings quality (lower = better)
A5: Cash Conversion (CFO/NOPAT) | B5: 0.82 | C5: AMBER | D5: >90% green / <70% red | E5: Cash backing for earnings
A6: DSO Drift (vs 3Y baseline) | B6: 0 | C6: GREEN | D6: <3d green / >7d red | E6: AR quality; negative = improving
A7: Capex/D&A Ratio | B7: 0 | C7: GREEN | D7: <1.5x green / >2.5x red | E7: Maintenance vs growth capex
A8: DIO Drift | B8: 0 | C8: GREEN | D8: <5d green / >10d red | E8: Inventory build-up check
A9: Revenue recognition flag | B9: N/A | C9: GREEN | D9: N/A | E9: No restatements flagged
A10: Auditor flag | B10: None | C10: GREEN | D10: N/A | E10: Clean Big-4 opinion
A13: NWC BASELINE DETAIL
A14: DSO — Current | B14: 47
A15: DSO — 3Y Baseline | B15: 0
A16: DSO — Drift | B16: 0

Sheet Output
A1: =Ticker&" — Valuation Summary | As of "& TEXT(as_of_date, "dd mmm yyyy") -> BAH — Valuation Summary | As of 14 Jun 2026
A2: MARKET DATA
A3: Price | B3: =Price -> 77.41
A4: Market Cap ($mm) | B4: =_Data!B48 -> 9284
A5: Enterprise Value ($mm) | B5: =_Data!B49 -> 12664
A6: P/E (Trailing) | B6: =_Data!B50 -> 11.218841
A7: P/E (Forward) | B7: =_Data!B51 -> 11.284323
A8: EV/EBITDA | B8: =_Data!B52 -> 10.066
A9: Analyst Target | B9: =_Data!B53 -> 93.76923
A10: Analyst Rec. | B10: =_Data!B54 -> hold
A11: # Analysts | B11: 19
A13: INTRINSIC VALUE SUMMARY
B14: Bear | C14: Base | D14: Bull
A15: Intrinsic Value / Share | B15: =Equity_Bridge!B18 -> 52.772069 | C15: =Equity_Bridge!C18 -> 95.765017 | D15: =Equity_Bridge!D18 -> 136.10506
A16: Upside / (Downside) | B16: =Equity_Bridge!B20 -> -0.31827839 | C16: =Equity_Bridge!C20 -> 0.23711429 | D16: =Equity_Bridge!D20 -> 0.7582362
A17: Scenario Probability | B17: =Assumptions!$D$50 -> 0.2 | C17: =Assumptions!$D$51 -> 0.6 | D17: =Assumptions!$D$52 -> 0.2
A18: Expected IV / Share | B18: =Equity_Bridge!C22 -> 95.234437
A19: Expected Upside | B19: =Equity_Bridge!C23 -> 0.23026014
A21: WACC SUMMARY
A22: WACC | B22: =Assumptions!$D$37 -> 0.07043
A23: Cost of Equity | B23: =Assumptions!$D$31 -> 0.6585
A24: Cost of Debt (at) | B24: =Assumptions!$D$34 -> 0.022086696
A25: Beta (Re-levered) | B25: =Assumptions!$D$29 -> 0.27
A26: Equity Weight | B26: =Assumptions!$D$35 -> 0.7323
A28: QoE FLAGS
A29: QoE Score | B29: 3
A30: QoE Flag | B30: AMBER
A31: Sloan Accruals Ratio | B31: 0.045
A32: Cash Conversion | B32: 0.82
A33: DSO Drift (days) | B33: 0

Sheet Config
A1: Setting | B1: Value
A2: json_path | B2: C:\Projects\03-Finance\ai-fund\data\valuations\json\BAH_latest.json
A4: Instructions:
A5: 1. Change B2 to point at a different ticker (e.g. ORCL_latest.json)
A6: 2. Data → Refresh All (Ctrl+Alt+F5)
A7: 3. All Assumptions Col B values update from the new JSON.
A8: 4. The path must match what batch_runner --json last wrote.

Sheet _Data
A1: Key | B1: Value | D1: Name | E1: Value
A2: revenue_mm | B2: 11217 | D2: $schema_version | E2: 1.0
A3: growth_near | B3: 0.0024725167 | D3: generated_at | E3: 2026-06-14T19:49:23
A4: growth_mid | B4: 0.0013598842 | D4: ticker | E4: BAH
A5: growth_terminal | B5: 0.025 | D5: company_name | E5: Booz Allen Hamilton Holding Corporation
A6: ebit_margin_start | B6: 0.098363684 | D6: sector | E6: Industrials
A7: ebit_margin_target | B7: 0.11418184 | D7: industry | E7: Consulting Services
A8: capex_pct | B8: 0.01 | D8: market | E8: [Record]
A9: da_pct | B9: 0.014562066 | D9: assumptions | E9: [Record]
A10: tax_rate_start | B10: 0.20564844 | D10: wacc | E10: [Record]
A11: tax_rate_target | B11: 0.20564844 | D11: valuation | E11: [Record]
A12: dso_start | B12: 67.1 | D12: scenarios | E12: [Record]
A13: dso_target | B13: 58.63 | D13: terminal | E13: [Record]
... A27: prob_bull | B27: 0.2 | D27: comps_detail | E27: [Record]
D28: comps_analysis | E28: [Record]
A29: Key | B29: Value
A30: wacc | B30: 0.06801
A31: ke | B31: 0.07463
A32: kd
A33: rf
A34: erp
A35: beta_rel | B35: 0.27
A36: size_prem | B36: 0.6
A37: eq_wt | B37: 0.7323
A38: debt_wt | B38: 0.2677
A40: Scenario | B40: IV | C40: Upside_pct
A41: Bear | B41: 59.2 | C41: -23.5
A42: Base | B42: 97.75 | C42: 26.3
A43: Bull | B43: 161.42 | C43: 108.5
A44: Expected | B44: 102.78 | C44: 32.8
A46: Key | B46: Value
A47: price | B47: 77.41
A48: market_cap_mm | B48: 9284
A49: ev_mm | B49: 12664
A50: pe_trailing | B50: 11.218841
A51: pe_forward | B51: 11.284323
A52: ev_ebitda | B52: 10.066
A53: analyst_target | B53: 93.76923
A54: analyst_rec | B54: hold
A56: ticker | B56: name | C56: market_cap_mm | D56: tev_mm | E56: revenue_ltm_mm | F56: ebitda_ltm_mm | G56: eps_ltm | H56: tev_ebitda_ltm | I56: tev_ebitda_fwd | J56: pe_ltm
...
