Workbook
Name Ccy: Input!$B$7
Name Conv: Input!$B$8
Name Date: Input!$B$6
Name InputTicker: Input!$B$2
Name IQ_CH: 110000
Name IQ_CQ: 5000
Name IQ_CY: 10000
Name IQ_DAILY: 500000
Name IQ_FH: 100000
Name IQ_FQ: 500
Name IQ_FY: 1000
Name IQ_LTM: 2000
Name IQ_MONTH: 15000
Name IQ_NTM: 6000
Name IQ_WEEK: 50000
Name IQ_YTD: 3000
Name Languages: OFFSET(#REF!,,,#REF!)
Name SPWS_WBID: "0D145571-4AA7-4C6E-B8EB-4DF0FED2B8BC"

Sheet Input_Raw
A1: Name | B1: Value
A2: ticker | B2: NASDAQ:CALM
A3: date_year | B3: 2026
A4: date_month | B4: 7
A5: date_day | B5: 31
A6: currency | B6: USD

Sheet Input
A1: =Input_Raw!A1 -> Name | B1: =Input_Raw!B1 -> Value
A2: =Input_Raw!A2 -> ticker | B2: =Input_Raw!B2 -> NASDAQ:CALM | D2: 990 | E2: =D2+1 -> 991 | F2: =E2+1 -> 992 | G2: =F2+1 -> 993 | H2: =G2+1 -> 994 | I2: =H2+1 -> 995 | J2: =I2+1 -> 996 | K2: =J2+1 -> 997 | L2: =K2+1 -> 998 | ... N2: =M2+1 -> 1000 | O2: 2000
A3: =Input_Raw!A3 -> date_year | B3: =Input_Raw!B3 -> 2026
A4: =Input_Raw!A4 -> date_month | B4: =Input_Raw!B4 -> 7
A5: =Input_Raw!A5 -> date_day | B5: =Input_Raw!B5 -> 31
A6: date | B6: =DATE(B3,B4,B5) -> 46234
A7: =Input_Raw!A6 -> currency | B7: =Input_Raw!B6 -> USD
A8: conversion | B8: H

Sheet Financial Statements
A1: Period | B1: ="FY"&RIGHT(YEAR(B2),2) -> FY16 | C1: ="FY"&RIGHT(YEAR(C2),2) -> FY17 | D1: ="FY"&RIGHT(YEAR(D2),2) -> FY18 | E1: ="FY"&RIGHT(YEAR(E2),2) -> FY19 | F1: ="FY"&RIGHT(YEAR(F2),2) -> FY20 | G1: ="FY"&RIGHT(YEAR(G2),2) -> FY21 | H1: ="FY"&RIGHT(YEAR(H2),2) -> FY22 | I1: ="FY"&RIGHT(YEAR(I2),2) -> FY23 | ... L1: ="FY"&RIGHT(YEAR(L2),2) -> FY26 | M1: LTM
A2: Period Date | B2: =_xll.ciqfunctions.udf.CIQ(InputTicker, "IQ_PERIODDATE",Input!D$2,Date) -> 42518 | C2: =_xll.ciqfunctions.udf.CIQ(InputTicker, "IQ_PERIODDATE",Input!E$2,Date) -> 42889 | D2: =_xll.ciqfunctions.udf.CIQ(InputTicker, "IQ_PERIODDATE",Input!F$2,Date) -> 43253 | E2: =_xll.ciqfunctions.udf.CIQ(InputTicker, "IQ_PERIODDATE",Input!G$2,Date) -> 43617 | F2: =_xll.ciqfunctions.udf.CIQ(InputTicker, "IQ_PERIODDATE",Input!H$2,Date) -> 43981 | G2: =_xll.ciqfunctions.udf.CIQ(InputTicker, "IQ_PERIODDATE",Input!I$2,Date) -> 44345 | H2: =_xll.ciqfunctions.udf.CIQ(InputTicker, "IQ_PERIODDATE",Input!J$2,Date) -> 44709 | I2: =_xll.ciqfunctions.udf.CIQ(InputTicker, "IQ_PERIODDATE",Input!K$2,Date) -> 45080 | ... M2: =_xll.ciqfunctions.udf.CIQ(InputTicker, "IQ_PERIODDATE",Input!O$2,Date) -> 46172
A3: Revenues | B3: =_xll.ciqfunctions.udf.CIQ(InputTicker, "IQ_REV",Input!D$2,Date,,,Ccy,Conv) -> 1908.65 | C3: =_xll.ciqfunctions.udf.CIQ(InputTicker, "IQ_REV",Input!E$2,Date,,,Ccy,Conv) -> 1074.513 | D3: =_xll.ciqfunctions.udf.CIQ(InputTicker, "IQ_REV",Input!F$2,Date,,,Ccy,Conv) -> 1502.932 | E3: =_xll.ciqfunctions.udf.CIQ(InputTicker, "IQ_REV",Input!G$2,Date,,,Ccy,Conv) -> 1361.188 | F3: =_xll.ciqfunctions.udf.CIQ(InputTicker, "IQ_REV",Input!H$2,Date,,,Ccy,Conv) -> 1351.609 | G3: =_xll.ciqfunctions.udf.CIQ(InputTicker, "IQ_REV",Input!I$2,Date,,,Ccy,Conv) -> 1348.987 | H3: =_xll.ciqfunctions.udf.CIQ(InputTicker, "IQ_REV",Input!J$2,Date,,,Ccy,Conv) -> 1777.159 | I3: =_xll.ciqfunctions.udf.CIQ(InputTicker, "IQ_REV",Input!K$2,Date,,,Ccy,Conv) -> 3146.217 | ... M3: =_xll.ciqfunctions.udf.CIQ(InputTicker, "IQ_REV",Input!O$2,Date,,,Ccy,Conv) -> 2911.632
A4: Finance Div. Revenues | B4: =_xll.ciqfunctions.udf.CIQ(InputTicker,"IQ_FIN_DIV_REV",Input!D$2,Date,,,Ccy,Conv) -> 0 | C4: =_xll.ciqfunctions.udf.CIQ(InputTicker,"IQ_FIN_DIV_REV",Input!E$2,Date,,,Ccy,Conv) -> 0 | D4: =_xll.ciqfunctions.udf.CIQ(InputTicker,"IQ_FIN_DIV_REV",Input!F$2,Date,,,Ccy,Conv) -> 0 | E4: =_xll.ciqfunctions.udf.CIQ(InputTicker,"IQ_FIN_DIV_REV",Input!G$2,Date,,,Ccy,Conv) -> 0 | F4: =_xll.ciqfunctions.udf.CIQ(InputTicker,"IQ_FIN_DIV_REV",Input!H$2,Date,,,Ccy,Conv) -> 0 | G4: =_xll.ciqfunctions.udf.CIQ(InputTicker,"IQ_FIN_DIV_REV",Input!I$2,Date,,,Ccy,Conv) -> 0 | H4: =_xll.ciqfunctions.udf.CIQ(InputTicker,"IQ_FIN_DIV_REV",Input!J$2,Date,,,Ccy,Conv) -> 0 | I4: =_xll.ciqfunctions.udf.CIQ(InputTicker,"IQ_FIN_DIV_REV",Input!K$2,Date,,,Ccy,Conv) -> 0 | ... M4: =_xll.ciqfunctions.udf.CIQ(InputTicker,"IQ_FIN_DIV_REV",Input!O$2,Date,,,Ccy,Conv) -> 0
A5: Insurance Div. Revenues | B5: =_xll.ciqfunctions.udf.CIQ(InputTicker, "IQ_INS_DIV_REV",Input!D$2,Date,,,Ccy,Conv) -> 0 | C5: =_xll.ciqfunctions.udf.CIQ(InputTicker, "IQ_INS_DIV_REV",Input!E$2,Date,,,Ccy,Conv) -> 0 | D5: =_xll.ciqfunctions.udf.CIQ(InputTicker, "IQ_INS_DIV_REV",Input!F$2,Date,,,Ccy,Conv) -> 0 | E5: =_xll.ciqfunctions.udf.CIQ(InputTicker, "IQ_INS_DIV_REV",Input!G$2,Date,,,Ccy,Conv) -> 0 | F5: =_xll.ciqfunctions.udf.CIQ(InputTicker, "IQ_INS_DIV_REV",Input!H$2,Date,,,Ccy,Conv) -> 0 | G5: =_xll.ciqfunctions.udf.CIQ(InputTicker, "IQ_INS_DIV_REV",Input!I$2,Date,,,Ccy,Conv) -> 0 | H5: =_xll.ciqfunctions.udf.CIQ(InputTicker, "IQ_INS_DIV_REV",Input!J$2,Date,,,Ccy,Conv) -> 0 | I5: =_xll.ciqfunctions.udf.CIQ(InputTicker, "IQ_INS_DIV_REV",Input!K$2,Date,,,Ccy,Conv) -> 0 | ... M5: =_xll.ciqfunctions.udf.CIQ(InputTicker, "IQ_INS_DIV_REV",Input!O$2,Date,,,Ccy,Conv) -> 0
A6: Gain/(Loss) on Sale Of Assets (Rev) | B6: =_xll.ciqfunctions.udf.CIQ(InputTicker, "IQ_GAIN_ASSETS_REV",Input!D$2,Date,,,Ccy,Conv) -> 0 | C6: =_xll.ciqfunctions.udf.CIQ(InputTicker, "IQ_GAIN_ASSETS_REV",Input!E$2,Date,,,Ccy,Conv) -> 0 | D6: =_xll.ciqfunctions.udf.CIQ(InputTicker, "IQ_GAIN_ASSETS_REV",Input!F$2,Date,,,Ccy,Conv) -> 0 | E6: =_xll.ciqfunctions.udf.CIQ(InputTicker, "IQ_GAIN_ASSETS_REV",Input!G$2,Date,,,Ccy,Conv) -> 0 | F6: =_xll.ciqfunctions.udf.CIQ(InputTicker, "IQ_GAIN_ASSETS_REV",Input!H$2,Date,,,Ccy,Conv) -> 0 | G6: =_xll.ciqfunctions.udf.CIQ(InputTicker, "IQ_GAIN_ASSETS_REV",Input!I$2,Date,,,Ccy,Conv) -> 0 | H6: =_xll.ciqfunctions.udf.CIQ(InputTicker, "IQ_GAIN_ASSETS_REV",Input!J$2,Date,,,Ccy,Conv) -> 0 | I6: =_xll.ciqfunctions.udf.CIQ(InputTicker, "IQ_GAIN_ASSETS_REV",Input!K$2,Date,,,Ccy,Conv) -> 0 | ... M6: =_xll.ciqfunctions.udf.CIQ(InputTicker, "IQ_GAIN_ASSETS_REV",Input!O$2,Date,,,Ccy,Conv) -> 0
A7: Gain/(Loss) on Sale Of Invest.(Rev) | B7: =_xll.ciqfunctions.udf.CIQ(InputTicker, "IQ_GAIN_INVEST_REV",Input!D$2,Date,,,Ccy,Conv) -> 0 | C7: =_xll.ciqfunctions.udf.CIQ(InputTicker, "IQ_GAIN_INVEST_REV",Input!E$2,Date,,,Ccy,Conv) -> 0 | D7: =_xll.ciqfunctions.udf.CIQ(InputTicker, "IQ_GAIN_INVEST_REV",Input!F$2,Date,,,Ccy,Conv) -> 0 | E7: =_xll.ciqfunctions.udf.CIQ(InputTicker, "IQ_GAIN_INVEST_REV",Input!G$2,Date,,,Ccy,Conv) -> 0 | F7: =_xll.ciqfunctions.udf.CIQ(InputTicker, "IQ_GAIN_INVEST_REV",Input!H$2,Date,,,Ccy,Conv) -> 0 | G7: =_xll.ciqfunctions.udf.CIQ(InputTicker, "IQ_GAIN_INVEST_REV",Input!I$2,Date,,,Ccy,Conv) -> 0 | H7: =_xll.ciqfunctions.udf.CIQ(InputTicker, "IQ_GAIN_INVEST_REV",Input!J$2,Date,,,Ccy,Conv) -> 0 | I7: =_xll.ciqfunctions.udf.CIQ(InputTicker, "IQ_GAIN_INVEST_REV",Input!K$2,Date,,,Ccy,Conv) -> 0 | ... M7: =_xll.ciqfunctions.udf.CIQ(InputTicker, "IQ_GAIN_INVEST_REV",Input!O$2,Date,,,Ccy,Conv) -> 0 | AG7: (User access restricted) | AH7: (User access restricted) | AJ7: (User access restricted) | AK7: (User access restricted) | AM7: (User access restricted) | AN7: (User access restricted) | AP7: (User access restricted) | AQ7: (User access restricted) | AS7: (User access restricted) | AT7: (User access restricted) | AV7: (User access restricted) | AW7: (User access restricted) | AY7: (User access restricted) | AZ7: (User access restricted) | BB7: (User access restricted) | BC7: (User access restricted) | BE7: (User access restricted) | BF7: (User access restricted) | BH7: (User access restricted) | BI7: (User access restricted) | BK7: (User access restricted) | BL7: (User access restricted)
A8: Interest And Invest. Income (Rev) | B8: =_xll.ciqfunctions.udf.CIQ(InputTicker, "IQ_INT_INV_INC",Input!D$2,Date,,,Ccy,Conv) -> 0 | C8: =_xll.ciqfunctions.udf.CIQ(InputTicker, "IQ_INT_INV_INC",Input!E$2,Date,,,Ccy,Conv) -> 0 | D8: =_xll.ciqfunctions.udf.CIQ(InputTicker, "IQ_INT_INV_INC",Input!F$2,Date,,,Ccy,Conv) -> 0 | E8: =_xll.ciqfunctions.udf.CIQ(InputTicker, "IQ_INT_INV_INC",Input!G$2,Date,,,Ccy,Conv) -> 0 | F8: =_xll.ciqfunctions.udf.CIQ(InputTicker, "IQ_INT_INV_INC",Input!H$2,Date,,,Ccy,Conv) -> 0 | G8: =_xll.ciqfunctions.udf.CIQ(InputTicker, "IQ_INT_INV_INC",Input!I$2,Date,,,Ccy,Conv) -> 0 | H8: =_xll.ciqfunctions.udf.CIQ(InputTicker, "IQ_INT_INV_INC",Input!J$2,Date,,,Ccy,Conv) -> 0 | I8: =_xll.ciqfunctions.udf.CIQ(InputTicker, "IQ_INT_INV_INC",Input!K$2,Date,,,Ccy,Conv) -> 0 | ... M8: =_xll.ciqfunctions.udf.CIQ(InputTicker, "IQ_INT_INV_INC",Input!O$2,Date,,,Ccy,Conv) -> 0
A9: Other Revenues | B9: =_xll.ciqfunctions.udf.CIQ(InputTicker, "IQ_OTHER_REV_SUPPL",Input!D$2,Date,,,Ccy,Conv) -> 0 | C9: =_xll.ciqfunctions.udf.CIQ(InputTicker, "IQ_OTHER_REV_SUPPL",Input!E$2,Date,,,Ccy,Conv) -> 0 | D9: =_xll.ciqfunctions.udf.CIQ(InputTicker, "IQ_OTHER_REV_SUPPL",Input!F$2,Date,,,Ccy,Conv) -> 0 | E9: =_xll.ciqfunctions.udf.CIQ(InputTicker, "IQ_OTHER_REV_SUPPL",Input!G$2,Date,,,Ccy,Conv) -> 0 | F9: =_xll.ciqfunctions.udf.CIQ(InputTicker, "IQ_OTHER_REV_SUPPL",Input!H$2,Date,,,Ccy,Conv) -> 0 | G9: =_xll.ciqfunctions.udf.CIQ(InputTicker, "IQ_OTHER_REV_SUPPL",Input!I$2,Date,,,Ccy,Conv) -> 0 | H9: =_xll.ciqfunctions.udf.CIQ(InputTicker, "IQ_OTHER_REV_SUPPL",Input!J$2,Date,,,Ccy,Conv) -> 0 | I9: =_xll.ciqfunctions.udf.CIQ(InputTicker, "IQ_OTHER_REV_SUPPL",Input!K$2,Date,,,Ccy,Conv) -> 0 | ... M9: =_xll.ciqfunctions.udf.CIQ(InputTicker, "IQ_OTHER_REV_SUPPL",Input!O$2,Date,,,Ccy,Conv) -> 0
A10: Total Revenues | B10: =_xll.ciqfunctions.udf.CIQ(InputTicker, "IQ_TOTAL_REV",Input!D$2,Date,,,Ccy,Conv) -> 1908.65 | C10: =_xll.ciqfunctions.udf.CIQ(InputTicker, "IQ_TOTAL_REV",Input!E$2,Date,,,Ccy,Conv) -> 1074.513 | D10: =_xll.ciqfunctions.udf.CIQ(InputTicker, "IQ_TOTAL_REV",Input!F$2,Date,,,Ccy,Conv) -> 1502.932 | E10: =_xll.ciqfunctions.udf.CIQ(InputTicker, "IQ_TOTAL_REV",Input!G$2,Date,,,Ccy,Conv) -> 1361.188 | F10: =_xll.ciqfunctions.udf.CIQ(InputTicker, "IQ_TOTAL_REV",Input!H$2,Date,,,Ccy,Conv) -> 1351.609 | G10: =_xll.ciqfunctions.udf.CIQ(InputTicker, "IQ_TOTAL_REV",Input!I$2,Date,,,Ccy,Conv) -> 1348.987 | H10: =_xll.ciqfunctions.udf.CIQ(InputTicker, "IQ_TOTAL_REV",Input!J$2,Date,,,Ccy,Conv) -> 1777.159 | I10: =_xll.ciqfunctions.udf.CIQ(InputTicker, "IQ_TOTAL_REV",Input!K$2,Date,,,Ccy,Conv) -> 3146.217 | ... M10: =_xll.ciqfunctions.udf.CIQ(InputTicker, "IQ_TOTAL_REV",Input!O$2,Date,,,Ccy,Conv) -> 2911.632
A11: Cost Of Goods Sold | B11: =_xll.ciqfunctions.udf.CIQ(InputTicker, "IQ_COGS",Input!D$2,Date,,,Ccy,Conv) -> 1260.576 | C11: =_xll.ciqfunctions.udf.CIQ(InputTicker, "IQ_COGS",Input!E$2,Date,,,Ccy,Conv) -> 1028.963 | D11: =_xll.ciqfunctions.udf.CIQ(InputTicker, "IQ_COGS",Input!F$2,Date,,,Ccy,Conv) -> 1141.886 | E11: =_xll.ciqfunctions.udf.CIQ(InputTicker, "IQ_COGS",Input!G$2,Date,,,Ccy,Conv) -> 1138.329 | F11: =_xll.ciqfunctions.udf.CIQ(InputTicker, "IQ_COGS",Input!H$2,Date,,,Ccy,Conv) -> 1172.021 | G11: =_xll.ciqfunctions.udf.CIQ(InputTicker, "IQ_COGS",Input!I$2,Date,,,Ccy,Conv) -> 1188.326 | H11: =_xll.ciqfunctions.udf.CIQ(InputTicker, "IQ_COGS",Input!J$2,Date,,,Ccy,Conv) -> 1440.1 | I11: =_xll.ciqfunctions.udf.CIQ(InputTicker, "IQ_COGS",Input!K$2,Date,,,Ccy,Conv) -> 1949.76 | ... M11: =_xll.ciqfunctions.udf.CIQ(InputTicker, "IQ_COGS",Input!O$2,Date,,,Ccy,Conv) -> 2239.583
A12: Finance Div. Operating Exp. | B12: =_xll.ciqfunctions.udf.CIQ(InputTicker, "IQ_FIN_DIV_EXP",Input!D$2,Date,,,Ccy,Conv) -> 0 | C12: =_xll.ciqfunctions.udf.CIQ(InputTicker, "IQ_FIN_DIV_EXP",Input!E$2,Date,,,Ccy,Conv) -> 0 | D12: =_xll.ciqfunctions.udf.CIQ(InputTicker, "IQ_FIN_DIV_EXP",Input!F$2,Date,,,Ccy,Conv) -> 0 | E12: =_xll.ciqfunctions.udf.CIQ(InputTicker, "IQ_FIN_DIV_EXP",Input!G$2,Date,,,Ccy,Conv) -> 0 | F12: =_xll.ciqfunctions.udf.CIQ(InputTicker, "IQ_FIN_DIV_EXP",Input!H$2,Date,,,Ccy,Conv) -> 0 | G12: =_xll.ciqfunctions.udf.CIQ(InputTicker, "IQ_FIN_DIV_EXP",Input!I$2,Date,,,Ccy,Conv) -> 0 | H12: =_xll.ciqfunctions.udf.CIQ(InputTicker, "IQ_FIN_DIV_EXP",Input!J$2,Date,,,Ccy,Conv) -> 0 | I12: =_xll.ciqfunctions.udf.CIQ(InputTicker, "IQ_FIN_DIV_EXP",Input!K$2,Date,,,Ccy,Conv) -> 0 | ... M12: =_xll.ciqfunctions.udf.CIQ(InputTicker, "IQ_FIN_DIV_EXP",Input!O$2,Date,,,Ccy,Conv) -> 0
A13: Insurance Div. Operating Exp. | B13: =_xll.ciqfunctions.udf.CIQ(InputTicker, "IQ_INS_DIV_EXP",Input!D$2,Date,,,Ccy,Conv) -> 0 | C13: =_xll.ciqfunctions.udf.CIQ(InputTicker, "IQ_INS_DIV_EXP",Input!E$2,Date,,,Ccy,Conv) -> 0 | D13: =_xll.ciqfunctions.udf.CIQ(InputTicker, "IQ_INS_DIV_EXP",Input!F$2,Date,,,Ccy,Conv) -> 0 | E13: =_xll.ciqfunctions.udf.CIQ(InputTicker, "IQ_INS_DIV_EXP",Input!G$2,Date,,,Ccy,Conv) -> 0 | F13: =_xll.ciqfunctions.udf.CIQ(InputTicker, "IQ_INS_DIV_EXP",Input!H$2,Date,,,Ccy,Conv) -> 0 | G13: =_xll.ciqfunctions.udf.CIQ(InputTicker, "IQ_INS_DIV_EXP",Input!I$2,Date,,,Ccy,Conv) -> 0 | H13: =_xll.ciqfunctions.udf.CIQ(InputTicker, "IQ_INS_DIV_EXP",Input!J$2,Date,,,Ccy,Conv) -> 0 | I13: =_xll.ciqfunctions.udf.CIQ(InputTicker, "IQ_INS_DIV_EXP",Input!K$2,Date,,,Ccy,Conv) -> 0 | ... M13: =_xll.ciqfunctions.udf.CIQ(InputTicker, "IQ_INS_DIV_EXP",Input!O$2,Date,,,Ccy,Conv) -> 0
A14: Interest Expense - Finance Division | B14: =_xll.ciqfunctions.udf.CIQ(InputTicker, "IQ_FIN_DIV_INT_EXP",Input!D$2,Date,,,Ccy,Conv) -> 0 | C14: =_xll.ciqfunctions.udf.CIQ(InputTicker, "IQ_FIN_DIV_INT_EXP",Input!E$2,Date,,,Ccy,Conv) -> 0 | D14: =_xll.ciqfunctions.udf.CIQ(InputTicker, "IQ_FIN_DIV_INT_EXP",Input!F$2,Date,,,Ccy,Conv) -> 0 | E14: =_xll.ciqfunctions.udf.CIQ(InputTicker, "IQ_FIN_DIV_INT_EXP",Input!G$2,Date,,,Ccy,Conv) -> 0 | F14: =_xll.ciqfunctions.udf.CIQ(InputTicker, "IQ_FIN_DIV_INT_EXP",Input!H$2,Date,,,Ccy,Conv) -> 0 | G14: =_xll.ciqfunctions.udf.CIQ(InputTicker, "IQ_FIN_DIV_INT_EXP",Input!I$2,Date,,,Ccy,Conv) -> 0 | H14: =_xll.ciqfunctions.udf.CIQ(InputTicker, "IQ_FIN_DIV_INT_EXP",Input!J$2,Date,,,Ccy,Conv) -> 0 | I14: =_xll.ciqfunctions.udf.CIQ(InputTicker, "IQ_FIN_DIV_INT_EXP",Input!K$2,Date,,,Ccy,Conv) -> 0 | ... M14: =_xll.ciqfunctions.udf.CIQ(InputTicker, "IQ_FIN_DIV_INT_EXP",Input!O$2,Date,,,Ccy,Conv) -> 0
A15: Gross Profit | B15: =_xll.ciqfunctions.udf.CIQ(InputTicker, "IQ_GP",Input!D$2,Date,,,Ccy,Conv) -> 648.074 | C15: =_xll.ciqfunctions.udf.CIQ(InputTicker, "IQ_GP",Input!E$2,Date,,,Ccy,Conv) -> 45.55 | D15: =_xll.ciqfunctions.udf.CIQ(InputTicker, "IQ_GP",Input!F$2,Date,,,Ccy,Conv) -> 361.046 | E15: =_xll.ciqfunctions.udf.CIQ(InputTicker, "IQ_GP",Input!G$2,Date,,,Ccy,Conv) -> 222.859 | F15: =_xll.ciqfunctions.udf.CIQ(InputTicker, "IQ_GP",Input!H$2,Date,,,Ccy,Conv) -> 179.588 | G15: =_xll.ciqfunctions.udf.CIQ(InputTicker, "IQ_GP",Input!I$2,Date,,,Ccy,Conv) -> 160.661 | H15: =_xll.ciqfunctions.udf.CIQ(InputTicker, "IQ_GP",Input!J$2,Date,,,Ccy,Conv) -> 337.059 | I15: =_xll.ciqfunctions.udf.CIQ(InputTicker, "IQ_GP",Input!K$2,Date,,,Ccy,Conv) -> 1196.457 | ... M15: =_xll.ciqfunctions.udf.CIQ(InputTicker, "IQ_GP",Input!O$2,Date,,,Ccy,Conv) -> 672.049
A16: Selling General & Admin Exp. | B16: =_xll.ciqfunctions.udf.CIQ(InputTicker, "IQ_SGA_SUPPL",Input!D$2,Date,,,Ccy,Conv) -> 177.76 | C16: =_xll.ciqfunctions.udf.CIQ(InputTicker, "IQ_SGA_SUPPL",Input!E$2,Date,,,Ccy,Conv) -> 176.032 | D16: =_xll.ciqfunctions.udf.CIQ(InputTicker, "IQ_SGA_SUPPL",Input!F$2,Date,,,Ccy,Conv) -> 179.316 | E16: =_xll.ciqfunctions.udf.CIQ(InputTicker, "IQ_SGA_SUPPL",Input!G$2,Date,,,Ccy,Conv) -> 177.045 | F16: =_xll.ciqfunctions.udf.CIQ(InputTicker, "IQ_SGA_SUPPL",Input!H$2,Date,,,Ccy,Conv) -> 178.237 | G16: =_xll.ciqfunctions.udf.CIQ(InputTicker, "IQ_SGA_SUPPL",Input!I$2,Date,,,Ccy,Conv) -> 183.943 | H16: =_xll.ciqfunctions.udf.CIQ(InputTicker, "IQ_SGA_SUPPL",Input!J$2,Date,,,Ccy,Conv) -> 198.631 | I16: =_xll.ciqfunctions.udf.CIQ(InputTicker, "IQ_SGA_SUPPL",Input!K$2,Date,,,Ccy,Conv) -> 232.207 | ... M16: =_xll.ciqfunctions.udf.CIQ(InputTicker, "IQ_SGA_SUPPL",Input!O$2,Date,,,Ccy,Conv) -> 328.697
A17: Exploration/Drilling Costs | B17: =_xll.ciqfunctions.udf.CIQ(InputTicker, "IQ_EXPLORE_DRILL",Input!D$2,Date,,,Ccy,Conv) -> 0 | C17: =_xll.ciqfunctions.udf.CIQ(InputTicker, "IQ_EXPLORE_DRILL",Input!E$2,Date,,,Ccy,Conv) -> 0 | D17: =_xll.ciqfunctions.udf.CIQ(InputTicker, "IQ_EXPLORE_DRILL",Input!F$2,Date,,,Ccy,Conv) -> 0 | E17: =_xll.ciqfunctions.udf.CIQ(InputTicker, "IQ_EXPLORE_DRILL",Input!G$2,Date,,,Ccy,Conv) -> 0 | F17: =_xll.ciqfunctions.udf.CIQ(InputTicker, "IQ_EXPLORE_DRILL",Input!H$2,Date,,,Ccy,Conv) -> 0 | G17: =_xll.ciqfunctions.udf.CIQ(InputTicker, "IQ_EXPLORE_DRILL",Input!I$2,Date,,,Ccy,Conv) -> 0 | H17: =_xll.ciqfunctions.udf.CIQ(InputTicker, "IQ_EXPLORE_DRILL",Input!J$2,Date,,,Ccy,Conv) -> 0 | I17: =_xll.ciqfunctions.udf.CIQ(InputTicker, "IQ_EXPLORE_DRILL",Input!K$2,Date,,,Ccy,Conv) -> 0 | ... M17: =_xll.ciqfunctions.udf.CIQ(InputTicker, "IQ_EXPLORE_DRILL",Input!O$2,Date,,,Ccy,Conv) -> 0
A18: Provision for Bad Debts | B18: =_xll.ciqfunctions.udf.CIQ(InputTicker, "IQ_PROV_BAD_DEBTS",Input!D$2,Date,,,Ccy,Conv) -> 0 | C18: =_xll.ciqfunctions.udf.CIQ(InputTicker, "IQ_PROV_BAD_DEBTS",Input!E$2,Date,,,Ccy,Conv) -> 0 | D18: =_xll.ciqfunctions.udf.CIQ(InputTicker, "IQ_PROV_BAD_DEBTS",Input!F$2,Date,,,Ccy,Conv) -> 0 | E18: =_xll.ciqfunctions.udf.CIQ(InputTicker, "IQ_PROV_BAD_DEBTS",Input!G$2,Date,,,Ccy,Conv) -> 0 | F18: =_xll.ciqfunctions.udf.CIQ(InputTicker, "IQ_PROV_BAD_DEBTS",Input!H$2,Date,,,Ccy,Conv) -> 0 | G18: =_xll.ciqfunctions.udf.CIQ(InputTicker, "IQ_PROV_BAD_DEBTS",Input!I$2,Date,,,Ccy,Conv) -> 0 | H18: =_xll.ciqfunctions.udf.CIQ(InputTicker, "IQ_PROV_BAD_DEBTS",Input!J$2,Date,,,Ccy,Conv) -> 0 | I18: =_xll.ciqfunctions.udf.CIQ(InputTicker, "IQ_PROV_BAD_DEBTS",Input!K$2,Date,,,Ccy,Conv) -> 0 | ... M18: =_xll.ciqfunctions.udf.CIQ(InputTicker, "IQ_PROV_BAD_DEBTS",Input!O$2,Date,,,Ccy,Conv) -> 0
A19: Stock-Based Compensation | B19: =_xll.ciqfunctions.udf.CIQ(InputTicker, "IQ_STOCK_BASED",Input!D$2,Date,,,Ccy,Conv) -> 0 | C19: =_xll.ciqfunctions.udf.CIQ(InputTicker, "IQ_STOCK_BASED",Input!E$2,Date,,,Ccy,Conv) -> 0 | D19: =_xll.ciqfunctions.udf.CIQ(InputTicker, "IQ_STOCK_BASED",Input!F$2,Date,,,Ccy,Conv) -> 0 | E19: =_xll.ciqfunctions.udf.CIQ(InputTicker, "IQ_STOCK_BASED",Input!G$2,Date,,,Ccy,Conv) -> 0 | F19: =_xll.ciqfunctions.udf.CIQ(InputTicker, "IQ_STOCK_BASED",Input!H$2,Date,,,Ccy,Conv) -> 0 | G19: =_xll.ciqfunctions.udf.CIQ(InputTicker, "IQ_STOCK_BASED",Input!I$2,Date,,,Ccy,Conv) -> 0 | H19: =_xll.ciqfunctions.udf.CIQ(InputTicker, "IQ_STOCK_BASED",Input!J$2,Date,,,Ccy,Conv) -> 0 | I19: =_xll.ciqfunctions.udf.CIQ(InputTicker, "IQ_STOCK_BASED",Input!K$2,Date,,,Ccy,Conv) -> 0 | ... M19: =_xll.ciqfunctions.udf.CIQ(InputTicker, "IQ_STOCK_BASED",Input!O$2,Date,,,Ccy,Conv) -> 0
A20: Pre-Opening Costs | B20: =_xll.ciqfunctions.udf.CIQ(InputTicker, "IQ_PRE_OPEN_COST",Input!D$2,Date,,,Ccy,Conv) -> 0 | C20: =_xll.ciqfunctions.udf.CIQ(InputTicker, "IQ_PRE_OPEN_COST",Input!E$2,Date,,,Ccy,Conv) -> 0 | D20: =_xll.ciqfunctions.udf.CIQ(InputTicker, "IQ_PRE_OPEN_COST",Input!F$2,Date,,,Ccy,Conv) -> 0 | E20: =_xll.ciqfunctions.udf.CIQ(InputTicker, "IQ_PRE_OPEN_COST",Input!G$2,Date,,,Ccy,Conv) -> 0 | F20: =_xll.ciqfunctions.udf.CIQ(InputTicker, "IQ_PRE_OPEN_COST",Input!H$2,Date,,,Ccy,Conv) -> 0 | G20: =_xll.ciqfunctions.udf.CIQ(InputTicker, "IQ_PRE_OPEN_COST",Input!I$2,Date,,,Ccy,Conv) -> 0 | H20: =_xll.ciqfunctions.udf.CIQ(InputTicker, "IQ_PRE_OPEN_COST",Input!J$2,Date,,,Ccy,Conv) -> 0 | I20: =_xll.ciqfunctions.udf.CIQ(InputTicker, "IQ_PRE_OPEN_COST",Input!K$2,Date,,,Ccy,Conv) -> 0 | ... M20: =_xll.ciqfunctions.udf.CIQ(InputTicker, "IQ_PRE_OPEN_COST",Input!O$2,Date,,,Ccy,Conv) -> 0
A21: R & D Exp. | B21: =_xll.ciqfunctions.udf.CIQ(InputTicker, "IQ_RD_EXP",Input!D$2,Date,,,Ccy,Conv) -> 0 | C21: =_xll.ciqfunctions.udf.CIQ(InputTicker, "IQ_RD_EXP",Input!E$2,Date,,,Ccy,Conv) -> 0 | D21: =_xll.ciqfunctions.udf.CIQ(InputTicker, "IQ_RD_EXP",Input!F$2,Date,,,Ccy,Conv) -> 0 | E21: =_xll.ciqfunctions.udf.CIQ(InputTicker, "IQ_RD_EXP",Input!G$2,Date,,,Ccy,Conv) -> 0 | F21: =_xll.ciqfunctions.udf.CIQ(InputTicker, "IQ_RD_EXP",Input!H$2,Date,,,Ccy,Conv) -> 0 | G21: =_xll.ciqfunctions.udf.CIQ(InputTicker, "IQ_RD_EXP",Input!I$2,Date,,,Ccy,Conv) -> 0 | H21: =_xll.ciqfunctions.udf.CIQ(InputTicker, "IQ_RD_EXP",Input!J$2,Date,,,Ccy,Conv) -> 0 | I21: =_xll.ciqfunctions.udf.CIQ(InputTicker, "IQ_RD_EXP",Input!K$2,Date,,,Ccy,Conv) -> 0 | ... M21: =_xll.ciqfunctions.udf.CIQ(InputTicker, "IQ_RD_EXP",Input!O$2,Date,,,Ccy,Conv) -> 0
A22: Depreciation & Amort. | B22: =_xll.ciqfunctions.udf.CIQ(InputTicker, "IQ_DA_SUPPL",Input!D$2,Date,,,Ccy,Conv) -> 0 | C22: =_xll.ciqfunctions.udf.CIQ(InputTicker, "IQ_DA_SUPPL",Input!E$2,Date,,,Ccy,Conv) -> 0 | D22: =_xll.ciqfunctions.udf.CIQ(InputTicker, "IQ_DA_SUPPL",Input!F$2,Date,,,Ccy,Conv) -> 0 | E22: =_xll.ciqfunctions.udf.CIQ(InputTicker, "IQ_DA_SUPPL",Input!G$2,Date,,,Ccy,Conv) -> 0 | F22: =_xll.ciqfunctions.udf.CIQ(InputTicker, "IQ_DA_SUPPL",Input!H$2,Date,,,Ccy,Conv) -> 0 | G22: =_xll.ciqfunctions.udf.CIQ(InputTicker, "IQ_DA_SUPPL",Input!I$2,Date,,,Ccy,Conv) -> 0 | H22: =_xll.ciqfunctions.udf.CIQ(InputTicker, "IQ_DA_SUPPL",Input!J$2,Date,,,Ccy,Conv) -> 0 | I22: =_xll.ciqfunctions.udf.CIQ(InputTicker, "IQ_DA_SUPPL",Input!K$2,Date,,,Ccy,Conv) -> 0 | ... M22: =_xll.ciqfunctions.udf.CIQ(InputTicker, "IQ_DA_SUPPL",Input!O$2,Date,,,Ccy,Conv) -> 0
A23: Amort. of Goodwill and Intangibles | B23: =_xll.ciqfunctions.udf.CIQ(InputTicker, "IQ_GW_INTAN_AMORT",Input!D$2,Date,,,Ccy,Conv) -> 0 | C23: =_xll.ciqfunctions.udf.CIQ(InputTicker, "IQ_GW_INTAN_AMORT",Input!E$2,Date,,,Ccy,Conv) -> 0 | D23: =_xll.ciqfunctions.udf.CIQ(InputTicker, "IQ_GW_INTAN_AMORT",Input!F$2,Date,,,Ccy,Conv) -> 0 | E23: =_xll.ciqfunctions.udf.CIQ(InputTicker, "IQ_GW_INTAN_AMORT",Input!G$2,Date,,,Ccy,Conv) -> 0 | F23: =_xll.ciqfunctions.udf.CIQ(InputTicker, "IQ_GW_INTAN_AMORT",Input!H$2,Date,,,Ccy,Conv) -> 0 | G23: =_xll.ciqfunctions.udf.CIQ(InputTicker, "IQ_GW_INTAN_AMORT",Input!I$2,Date,,,Ccy,Conv) -> 0 | H23: =_xll.ciqfunctions.udf.CIQ(InputTicker, "IQ_GW_INTAN_AMORT",Input!J$2,Date,,,Ccy,Conv) -> 0 | I23: =_xll.ciqfunctions.udf.CIQ(InputTicker, "IQ_GW_INTAN_AMORT",Input!K$2,Date,,,Ccy,Conv) -> 0 | ... M23: =_xll.ciqfunctions.udf.CIQ(InputTicker, "IQ_GW_INTAN_AMORT",Input!O$2,Date,,,Ccy,Conv) -> 0
A24: Impair. of Oil, Gas & Mineral Prop. | B24: =_xll.ciqfunctions.udf.CIQ(InputTicker, "IQ_IMPAIR_OIL",Input!D$2,Date,,,Ccy,Conv) -> 0 | C24: =_xll.ciqfunctions.udf.CIQ(InputTicker, "IQ_IMPAIR_OIL",Input!E$2,Date,,,Ccy,Conv) -> 0 | D24: =_xll.ciqfunctions.udf.CIQ(InputTicker, "IQ_IMPAIR_OIL",Input!F$2,Date,,,Ccy,Conv) -> 0 | E24: =_xll.ciqfunctions.udf.CIQ(InputTicker, "IQ_IMPAIR_OIL",Input!G$2,Date,,,Ccy,Conv) -> 0 | F24: =_xll.ciqfunctions.udf.CIQ(InputTicker, "IQ_IMPAIR_OIL",Input!H$2,Date,,,Ccy,Conv) -> 0 | G24: =_xll.ciqfunctions.udf.CIQ(InputTicker, "IQ_IMPAIR_OIL",Input!I$2,Date,,,Ccy,Conv) -> 0 | H24: =_xll.ciqfunctions.udf.CIQ(InputTicker, "IQ_IMPAIR_OIL",Input!J$2,Date,,,Ccy,Conv) -> 0 | I24: =_xll.ciqfunctions.udf.CIQ(InputTicker, "IQ_IMPAIR_OIL",Input!K$2,Date,,,Ccy,Conv) -> 0 | ... M24: =_xll.ciqfunctions.udf.CIQ(InputTicker, "IQ_IMPAIR_OIL",Input!O$2,Date,,,Ccy,Conv) -> 0
A25: Other Operating Expense/(Income) | B25: =_xll.ciqfunctions.udf.CIQ(InputTicker, "IQ_OTHER_OPER",Input!D$2,Date,,,Ccy,Conv) -> 0 | C25: =_xll.ciqfunctions.udf.CIQ(InputTicker, "IQ_OTHER_OPER",Input!E$2,Date,,,Ccy,Conv) -> 0 | D25: =_xll.ciqfunctions.udf.CIQ(InputTicker, "IQ_OTHER_OPER",Input!F$2,Date,,,Ccy,Conv) -> 0 | E25: =_xll.ciqfunctions.udf.CIQ(InputTicker, "IQ_OTHER_OPER",Input!G$2,Date,,,Ccy,Conv) -> 0 | F25: =_xll.ciqfunctions.udf.CIQ(InputTicker, "IQ_OTHER_OPER",Input!H$2,Date,,,Ccy,Conv) -> 0 | G25: =_xll.ciqfunctions.udf.CIQ(InputTicker, "IQ_OTHER_OPER",Input!I$2,Date,,,Ccy,Conv) -> 0 | H25: =_xll.ciqfunctions.udf.CIQ(InputTicker, "IQ_OTHER_OPER",Input!J$2,Date,,,Ccy,Conv) -> 0 | I25: =_xll.ciqfunctions.udf.CIQ(InputTicker, "IQ_OTHER_OPER",Input!K$2,Date,,,Ccy,Conv) -> 0 | ... M25: =_xll.ciqfunctions.udf.CIQ(InputTicker, "IQ_OTHER_OPER",Input!O$2,Date,,,Ccy,Conv) -> 0
A26: Other Operating Exp., Total | B26: =_xll.ciqfunctions.udf.CIQ(InputTicker, "IQ_TOTAL_OTHER_OPER",Input!D$2,Date,,,Ccy,Conv) -> 177.76 | C26: =_xll.ciqfunctions.udf.CIQ(InputTicker, "IQ_TOTAL_OTHER_OPER",Input!E$2,Date,,,Ccy,Conv) -> 176.032 | D26: =_xll.ciqfunctions.udf.CIQ(InputTicker, "IQ_TOTAL_OTHER_OPER",Input!F$2,Date,,,Ccy,Conv) -> 179.316 | E26: =_xll.ciqfunctions.udf.CIQ(InputTicker, "IQ_TOTAL_OTHER_OPER",Input!G$2,Date,,,Ccy,Conv) -> 177.045 | F26: =_xll.ciqfunctions.udf.CIQ(InputTicker, "IQ_TOTAL_OTHER_OPER",Input!H$2,Date,,,Ccy,Conv) -> 178.237 | G26: =_xll.ciqfunctions.udf.CIQ(InputTicker, "IQ_TOTAL_OTHER_OPER",Input!I$2,Date,,,Ccy,Conv) -> 183.943 | H26: =_xll.ciqfunctions.udf.CIQ(InputTicker, "IQ_TOTAL_OTHER_OPER",Input!J$2,Date,,,Ccy,Conv) -> 198.631 | I26: =_xll.ciqfunctions.udf.CIQ(InputTicker, "IQ_TOTAL_OTHER_OPER",Input!K$2,Date,,,Ccy,Conv) -> 232.207 | ... M26: =_xll.ciqfunctions.udf.CIQ(InputTicker, "IQ_TOTAL_OTHER_OPER",Input!O$2,Date,,,Ccy,Conv) -> 328.697
A27: Operating Income | B27: =_xll.ciqfunctions.udf.CIQ(InputTicker, "IQ_OPER_INC",Input!D$2,Date,,,Ccy,Conv) -> 470.314 | C27: =_xll.ciqfunctions.udf.CIQ(InputTicker, "IQ_OPER_INC",Input!E$2,Date,,,Ccy,Conv) -> -130.482 | D27: =_xll.ciqfunctions.udf.CIQ(InputTicker, "IQ_OPER_INC",Input!F$2,Date,,,Ccy,Conv) -> 181.73 | E27: =_xll.ciqfunctions.udf.CIQ(InputTicker, "IQ_OPER_INC",Input!G$2,Date,,,Ccy,Conv) -> 45.814 | F27: =_xll.ciqfunctions.udf.CIQ(InputTicker, "IQ_OPER_INC",Input!H$2,Date,,,Ccy,Conv) -> 1.351 | G27: =_xll.ciqfunctions.udf.CIQ(InputTicker, "IQ_OPER_INC",Input!I$2,Date,,,Ccy,Conv) -> -23.282 | H27: =_xll.ciqfunctions.udf.CIQ(InputTicker, "IQ_OPER_INC",Input!J$2,Date,,,Ccy,Conv) -> 138.428 | I27: =_xll.ciqfunctions.udf.CIQ(InputTicker, "IQ_OPER_INC",Input!K$2,Date,,,Ccy,Conv) -> 964.25 | ... M27: =_xll.ciqfunctions.udf.CIQ(InputTicker, "IQ_OPER_INC",Input!O$2,Date,,,Ccy,Conv) -> 343.352
A28: Interest Expense | B28: =_xll.ciqfunctions.udf.CIQ(InputTicker, "IQ_INTEREST_EXP",Input!D$2,Date,,,Ccy,Conv) -> -1.156 | C28: =_xll.ciqfunctions.udf.CIQ(InputTicker, "IQ_INTEREST_EXP",Input!E$2,Date,,,Ccy,Conv) -> -0.318 | D28: =_xll.ciqfunctions.udf.CIQ(InputTicker, "IQ_INTEREST_EXP",Input!F$2,Date,,,Ccy,Conv) -> -0.265 | E28: =_xll.ciqfunctions.udf.CIQ(InputTicker, "IQ_INTEREST_EXP",Input!G$2,Date,,,Ccy,Conv) -> -0.644 | F28: =_xll.ciqfunctions.udf.CIQ(InputTicker, "IQ_INTEREST_EXP",Input!H$2,Date,,,Ccy,Conv) -> -0.498 | G28: =_xll.ciqfunctions.udf.CIQ(InputTicker, "IQ_INTEREST_EXP",Input!I$2,Date,,,Ccy,Conv) -> -0.213 | H28: =_xll.ciqfunctions.udf.CIQ(InputTicker, "IQ_INTEREST_EXP",Input!J$2,Date,,,Ccy,Conv) -> -0.403 | I28: =_xll.ciqfunctions.udf.CIQ(InputTicker, "IQ_INTEREST_EXP",Input!K$2,Date,,,Ccy,Conv) -> -0.583 | ... M28: =_xll.ciqfunctions.udf.CIQ(InputTicker, "IQ_INTEREST_EXP",Input!O$2,Date,,,Ccy,Conv) -> -0.556
A29: Interest and Invest. Income | B29: =_xll.ciqfunctions.udf.CIQ(InputTicker, "IQ_INTEREST_INVEST_INC",Input!D$2,Date,,,Ccy,Conv) -> 11.244 | C29: =_xll.ciqfunctions.udf.CIQ(InputTicker, "IQ_INTEREST_INVEST_INC",Input!E$2,Date,,,Ccy,Conv) -> 10.768 | D29: =_xll.ciqfunctions.udf.CIQ(InputTicker, "IQ_INTEREST_INVEST_INC",Input!F$2,Date,,,Ccy,Conv) -> 11.983 | E29: =_xll.ciqfunctions.udf.CIQ(InputTicker, "IQ_INTEREST_INVEST_INC",Input!G$2,Date,,,Ccy,Conv) -> 18.46 | F29: =_xll.ciqfunctions.udf.CIQ(InputTicker, "IQ_INTEREST_INVEST_INC",Input!H$2,Date,,,Ccy,Conv) -> 15.058 | G29: =_xll.ciqfunctions.udf.CIQ(InputTicker, "IQ_INTEREST_INVEST_INC",Input!I$2,Date,,,Ccy,Conv) -> 11.832 | H29: =_xll.ciqfunctions.udf.CIQ(InputTicker, "IQ_INTEREST_INVEST_INC",Input!J$2,Date,,,Ccy,Conv) -> 11.118 | I29: =_xll.ciqfunctions.udf.CIQ(InputTicker, "IQ_INTEREST_INVEST_INC",Input!K$2,Date,,,Ccy,Conv) -> 28.792 | ... M29: =_xll.ciqfunctions.udf.CIQ(InputTicker, "IQ_INTEREST_INVEST_INC",Input!O$2,Date,,,Ccy,Conv) -> 58.401
A30: Net Interest Exp. | B30: =_xll.ciqfunctions.udf.CIQ(InputTicker, "IQ_NET_INTEREST_EXP",Input!D$2,Date,,,Ccy,Conv) -> 10.088 | C30: =_xll.ciqfunctions.udf.CIQ(InputTicker, "IQ_NET_INTEREST_EXP",Input!E$2,Date,,,Ccy,Conv) -> 10.45 | D30: =_xll.ciqfunctions.udf.CIQ(InputTicker, "IQ_NET_INTEREST_EXP",Input!F$2,Date,,,Ccy,Conv) -> 11.718 | E30: =_xll.ciqfunctions.udf.CIQ(InputTicker, "IQ_NET_INTEREST_EXP",Input!G$2,Date,,,Ccy,Conv) -> 17.816 | F30: =_xll.ciqfunctions.udf.CIQ(InputTicker, "IQ_NET_INTEREST_EXP",Input!H$2,Date,,,Ccy,Conv) -> 14.56 | G30: =_xll.ciqfunctions.udf.CIQ(InputTicker, "IQ_NET_INTEREST_EXP",Input!I$2,Date,,,Ccy,Conv) -> 11.619 | H30: =_xll.ciqfunctions.udf.CIQ(InputTicker, "IQ_NET_INTEREST_EXP",Input!J$2,Date,,,Ccy,Conv) -> 10.715 | I30: =_xll.ciqfunctions.udf.CIQ(InputTicker, "IQ_NET_INTEREST_EXP",Input!K$2,Date,,,Ccy,Conv) -> 28.209 | ... M30: =_xll.ciqfunctions.udf.CIQ(InputTicker, "IQ_NET_INTEREST_EXP",Input!O$2,Date,,,Ccy,Conv) -> 57.845
A31: Income / (Loss) from Affiliates | B31: =_xll.ciqfunctions.udf.CIQ(InputTicker, "IQ_INC_EQUITY",Input!D$2,Date,,,Ccy,Conv) -> 5.016 | C31: =_xll.ciqfunctions.udf.CIQ(InputTicker, "IQ_INC_EQUITY",Input!E$2,Date,,,Ccy,Conv) -> 1.39 | D31: =_xll.ciqfunctions.udf.CIQ(InputTicker, "IQ_INC_EQUITY",Input!F$2,Date,,,Ccy,Conv) -> 3.517 | E31: =_xll.ciqfunctions.udf.CIQ(InputTicker, "IQ_INC_EQUITY",Input!G$2,Date,,,Ccy,Conv) -> 4.776 | F31: =_xll.ciqfunctions.udf.CIQ(InputTicker, "IQ_INC_EQUITY",Input!H$2,Date,,,Ccy,Conv) -> 0.534 | G31: =_xll.ciqfunctions.udf.CIQ(InputTicker, "IQ_INC_EQUITY",Input!I$2,Date,,,Ccy,Conv) -> 0.622 | H31: =_xll.ciqfunctions.udf.CIQ(InputTicker, "IQ_INC_EQUITY",Input!J$2,Date,,,Ccy,Conv) -> 1.943 | I31: =_xll.ciqfunctions.udf.CIQ(InputTicker, "IQ_INC_EQUITY",Input!K$2,Date,,,Ccy,Conv) -> 0.746 | ... M31: =_xll.ciqfunctions.udf.CIQ(InputTicker, "IQ_INC_EQUITY",Input!O$2,Date,,,Ccy,Conv) -> -1.3
A32: Currency Exchange Gains (Loss) | B32: =_xll.ciqfunctions.udf.CIQ(InputTicker, "IQ_CURRENCY_GAIN",Input!D$2,Date,,,Ccy,Conv) -> 0 | C32: =_xll.ciqfunctions.udf.CIQ(InputTicker, "IQ_CURRENCY_GAIN",Input!E$2,Date,,,Ccy,Conv) -> 0 | D32: =_xll.ciqfunctions.udf.CIQ(InputTicker, "IQ_CURRENCY_GAIN",Input!F$2,Date,,,Ccy,Conv) -> 0 | E32: =_xll.ciqfunctions.udf.CIQ(InputTicker, "IQ_CURRENCY_GAIN",Input!G$2,Date,,,Ccy,Conv) -> 0 | F32: =_xll.ciqfunctions.udf.CIQ(InputTicker, "IQ_CURRENCY_GAIN",Input!H$2,Date,,,Ccy,Conv) -> 0 | G32: =_xll.ciqfunctions.udf.CIQ(InputTicker, "IQ_CURRENCY_GAIN",Input!I$2,Date,,,Ccy,Conv) -> 0 | H32: =_xll.ciqfunctions.udf.CIQ(InputTicker, "IQ_CURRENCY_GAIN",Input!J$2,Date,,,Ccy,Conv) -> 0 | I32: =_xll.ciqfunctions.udf.CIQ(InputTicker, "IQ_CURRENCY_GAIN",Input!K$2,Date,,,Ccy,Conv) -> 0 | ... M32: =_xll.ciqfunctions.udf.CIQ(InputTicker, "IQ_CURRENCY_GAIN",Input!O$2,Date,,,Ccy,Conv) -> 0
A33: Other Non-Operating Inc. (Exp.) | B33: =_xll.ciqfunctions.udf.CIQ(InputTicker, "IQ_OTHER_NON_OPER_EXP_SUPPL",Input!D$2,Date,,,Ccy,Conv) -> 0.247 | C33: =_xll.ciqfunctions.udf.CIQ(InputTicker, "IQ_OTHER_NON_OPER_EXP_SUPPL",Input!E$2,Date,,,Ccy,Conv) -> 7.788 | D33: =_xll.ciqfunctions.udf.CIQ(InputTicker, "IQ_OTHER_NON_OPER_EXP_SUPPL",Input!F$2,Date,,,Ccy,Conv) -> 1.63 | E33: =_xll.ciqfunctions.udf.CIQ(InputTicker, "IQ_OTHER_NON_OPER_EXP_SUPPL",Input!G$2,Date,,,Ccy,Conv) -> 2.408 | F33: =_xll.ciqfunctions.udf.CIQ(InputTicker, "IQ_OTHER_NON_OPER_EXP_SUPPL",Input!H$2,Date,,,Ccy,Conv) -> 3.557 | G33: =_xll.ciqfunctions.udf.CIQ(InputTicker, "IQ_OTHER_NON_OPER_EXP_SUPPL",Input!I$2,Date,,,Ccy,Conv) -> 5.425 | H33: =_xll.ciqfunctions.udf.CIQ(InputTicker, "IQ_OTHER_NON_OPER_EXP_SUPPL",Input!J$2,Date,,,Ccy,Conv) -> 9.715 | I33: =_xll.ciqfunctions.udf.CIQ(InputTicker, "IQ_OTHER_NON_OPER_EXP_SUPPL",Input!K$2,Date,,,Ccy,Conv) -> 5.25 | ... M33: =_xll.ciqfunctions.udf.CIQ(InputTicker, "IQ_OTHER_NON_OPER_EXP_SUPPL",Input!O$2,Date,,,Ccy,Conv) -> 13.092
A34: EBT Excl Unusual Items | B34: =_xll.ciqfunctions.udf.CIQ(InputTicker, "IQ_EBT_EXCL",Input!D$2,Date,,,Ccy,Conv) -> 485.665 | C34: =_xll.ciqfunctions.udf.CIQ(InputTicker, "IQ_EBT_EXCL",Input!E$2,Date,,,Ccy,Conv) -> -110.854 | D34: =_xll.ciqfunctions.udf.CIQ(InputTicker, "IQ_EBT_EXCL",Input!F$2,Date,,,Ccy,Conv) -> 198.595 | E34: =_xll.ciqfunctions.udf.CIQ(InputTicker, "IQ_EBT_EXCL",Input!G$2,Date,,,Ccy,Conv) -> 70.814 | F34: =_xll.ciqfunctions.udf.CIQ(InputTicker, "IQ_EBT_EXCL",Input!H$2,Date,,,Ccy,Conv) -> 20.002 | G34: =_xll.ciqfunctions.udf.CIQ(InputTicker, "IQ_EBT_EXCL",Input!I$2,Date,,,Ccy,Conv) -> -5.616 | H34: =_xll.ciqfunctions.udf.CIQ(InputTicker, "IQ_EBT_EXCL",Input!J$2,Date,,,Ccy,Conv) -> 160.801 | I34: =_xll.ciqfunctions.udf.CIQ(InputTicker, "IQ_EBT_EXCL",Input!K$2,Date,,,Ccy,Conv) -> 998.455 | ... M34: =_xll.ciqfunctions.udf.CIQ(InputTicker, "IQ_EBT_EXCL",Input!O$2,Date,,,Ccy,Conv) -> 412.989
A35: Restructuring Charges | B35: =_xll.ciqfunctions.udf.CIQ(InputTicker, "IQ_RESTRUCTURE",Input!D$2,Date,,,Ccy,Conv) -> 0 | C35: =_xll.ciqfunctions.udf.CIQ(InputTicker, "IQ_RESTRUCTURE",Input!E$2,Date,,,Ccy,Conv) -> 0 | D35: =_xll.ciqfunctions.udf.CIQ(InputTicker, "IQ_RESTRUCTURE",Input!F$2,Date,,,Ccy,Conv) -> 0 | E35: =_xll.ciqfunctions.udf.CIQ(InputTicker, "IQ_RESTRUCTURE",Input!G$2,Date,,,Ccy,Conv) -> 0 | F35: =_xll.ciqfunctions.udf.CIQ(InputTicker, "IQ_RESTRUCTURE",Input!H$2,Date,,,Ccy,Conv) -> 0 | G35: =_xll.ciqfunctions.udf.CIQ(InputTicker, "IQ_RESTRUCTURE",Input!I$2,Date,,,Ccy,Conv) -> 0 | H35: =_xll.ciqfunctions.udf.CIQ(InputTicker, "IQ_RESTRUCTURE",Input!J$2,Date,,,Ccy,Conv) -> 0 | I35: =_xll.ciqfunctions.udf.CIQ(InputTicker, "IQ_RESTRUCTURE",Input!K$2,Date,,,Ccy,Conv) -> 0 | ... M35: =_xll.ciqfunctions.udf.CIQ(InputTicker, "IQ_RESTRUCTURE",Input!O$2,Date,,,Ccy,Conv) -> 0
A36: Merger & Related Restruct. Charges | B36: =_xll.ciqfunctions.udf.CIQ(InputTicker, "IQ_MERGER",Input!D$2,Date,,,Ccy,Conv) -> 0 | C36: =_xll.ciqfunctions.udf.CIQ(InputTicker, "IQ_MERGER",Input!E$2,Date,,,Ccy,Conv) -> 0 | D36: =_xll.ciqfunctions.udf.CIQ(InputTicker, "IQ_MERGER",Input!F$2,Date,,,Ccy,Conv) -> 0 | E36: =_xll.ciqfunctions.udf.CIQ(InputTicker, "IQ_MERGER",Input!G$2,Date,,,Ccy,Conv) -> 0 | F36: =_xll.ciqfunctions.udf.CIQ(InputTicker, "IQ_MERGER",Input!H$2,Date,,,Ccy,Conv) -> 0 | G36: =_xll.ciqfunctions.udf.CIQ(InputTicker, "IQ_MERGER",Input!I$2,Date,,,Ccy,Conv) -> 0 | H36: =_xll.ciqfunctions.udf.CIQ(InputTicker, "IQ_MERGER",Input!J$2,Date,,,Ccy,Conv) -> 0 | I36: =_xll.ciqfunctions.udf.CIQ(InputTicker, "IQ_MERGER",Input!K$2,Date,,,Ccy,Conv) -> 0 | ... M36: =_xll.ciqfunctions.udf.CIQ(InputTicker, "IQ_MERGER",Input!O$2,Date,,,Ccy,Conv) -> -0.594
A37: Impairment of Goodwill | B37: =_xll.ciqfunctions.udf.CIQ(InputTicker, "IQ_IMPAIRMENT_GW",Input!D$2,Date,,,Ccy,Conv) -> 0 | C37: =_xll.ciqfunctions.udf.CIQ(InputTicker, "IQ_IMPAIRMENT_GW",Input!E$2,Date,,,Ccy,Conv) -> 0 | D37: =_xll.ciqfunctions.udf.CIQ(InputTicker, "IQ_IMPAIRMENT_GW",Input!F$2,Date,,,Ccy,Conv) -> 0 | E37: =_xll.ciqfunctions.udf.CIQ(InputTicker, "IQ_IMPAIRMENT_GW",Input!G$2,Date,,,Ccy,Conv) -> 0 | F37: =_xll.ciqfunctions.udf.CIQ(InputTicker, "IQ_IMPAIRMENT_GW",Input!H$2,Date,,,Ccy,Conv) -> 0 | G37: =_xll.ciqfunctions.udf.CIQ(InputTicker, "IQ_IMPAIRMENT_GW",Input!I$2,Date,,,Ccy,Conv) -> 0 | H37: =_xll.ciqfunctions.udf.CIQ(InputTicker, "IQ_IMPAIRMENT_GW",Input!J$2,Date,,,Ccy,Conv) -> 0 | I37: =_xll.ciqfunctions.udf.CIQ(InputTicker, "IQ_IMPAIRMENT_GW",Input!K$2,Date,,,Ccy,Conv) -> 0 | ... M37: =_xll.ciqfunctions.udf.CIQ(InputTicker, "IQ_IMPAIRMENT_GW",Input!O$2,Date,,,Ccy,Conv) -> 0
A38: Gain (Loss) On Sale Of Invest. | B38: =_xll.ciqfunctions.udf.CIQ(InputTicker, "IQ_GAIN_INVEST",Input!D$2,Date,,,Ccy,Conv) -> 0.021 | C38: =_xll.ciqfunctions.udf.CIQ(InputTicker, "IQ_GAIN_INVEST",Input!E$2,Date,,,Ccy,Conv) -> 0.224 | D38: =_xll.ciqfunctions.udf.CIQ(InputTicker, "IQ_GAIN_INVEST",Input!F$2,Date,,,Ccy,Conv) -> -0.035 | E38: =_xll.ciqfunctions.udf.CIQ(InputTicker, "IQ_GAIN_INVEST",Input!G$2,Date,,,Ccy,Conv) -> 0.024 | F38: =_xll.ciqfunctions.udf.CIQ(InputTicker, "IQ_GAIN_INVEST",Input!H$2,Date,,,Ccy,Conv) -> 0.139 | G38: =_xll.ciqfunctions.udf.CIQ(InputTicker, "IQ_GAIN_INVEST",Input!I$2,Date,,,Ccy,Conv) -> -1.351 | H38: =_xll.ciqfunctions.udf.CIQ(InputTicker, "IQ_GAIN_INVEST",Input!J$2,Date,,,Ccy,Conv) -> 0.105 | I38: =_xll.ciqfunctions.udf.CIQ(InputTicker, "IQ_GAIN_INVEST",Input!K$2,Date,,,Ccy,Conv) -> -0.036 | ... M38: =_xll.ciqfunctions.udf.CIQ(InputTicker, "IQ_GAIN_INVEST",Input!O$2,Date,,,Ccy,Conv) -> 0
A39: Gain (Loss) On Sale Of Assets | B39: =_xll.ciqfunctions.udf.CIQ(InputTicker, "IQ_GAIN_ASSETS",Input!D$2,Date,,,Ccy,Conv) -> 1.563 | C39: =_xll.ciqfunctions.udf.CIQ(InputTicker, "IQ_GAIN_ASSETS",Input!E$2,Date,,,Ccy,Conv) -> -3.664 | D39: =_xll.ciqfunctions.udf.CIQ(InputTicker, "IQ_GAIN_ASSETS",Input!F$2,Date,,,Ccy,Conv) -> -0.473 | E39: =_xll.ciqfunctions.udf.CIQ(InputTicker, "IQ_GAIN_ASSETS",Input!G$2,Date,,,Ccy,Conv) -> -0.033 | F39: =_xll.ciqfunctions.udf.CIQ(InputTicker, "IQ_GAIN_ASSETS",Input!H$2,Date,,,Ccy,Conv) -> -0.082 | G39: =_xll.ciqfunctions.udf.CIQ(InputTicker, "IQ_GAIN_ASSETS",Input!I$2,Date,,,Ccy,Conv) -> -2.982 | H39: =_xll.ciqfunctions.udf.CIQ(InputTicker, "IQ_GAIN_ASSETS",Input!J$2,Date,,,Ccy,Conv) -> -0.383 | I39: =_xll.ciqfunctions.udf.CIQ(InputTicker, "IQ_GAIN_ASSETS",Input!K$2,Date,,,Ccy,Conv) -> 0.131 | ... M39: =_xll.ciqfunctions.udf.CIQ(InputTicker, "IQ_GAIN_ASSETS",Input!O$2,Date,,,Ccy,Conv) -> -1.391
A40: Asset Writedown | B40: =_xll.ciqfunctions.udf.CIQ(InputTicker, "IQ_ASSET_WRITEDOWN",Input!D$2,Date,,,Ccy,Conv) -> 0 | C40: =_xll.ciqfunctions.udf.CIQ(InputTicker, "IQ_ASSET_WRITEDOWN",Input!E$2,Date,,,Ccy,Conv) -> 0 | D40: =_xll.ciqfunctions.udf.CIQ(InputTicker, "IQ_ASSET_WRITEDOWN",Input!F$2,Date,,,Ccy,Conv) -> 0 | E40: =_xll.ciqfunctions.udf.CIQ(InputTicker, "IQ_ASSET_WRITEDOWN",Input!G$2,Date,,,Ccy,Conv) -> 0 | F40: =_xll.ciqfunctions.udf.CIQ(InputTicker, "IQ_ASSET_WRITEDOWN",Input!H$2,Date,,,Ccy,Conv) -> 0 | G40: =_xll.ciqfunctions.udf.CIQ(InputTicker, "IQ_ASSET_WRITEDOWN",Input!I$2,Date,,,Ccy,Conv) -> 0 | H40: =_xll.ciqfunctions.udf.CIQ(InputTicker, "IQ_ASSET_WRITEDOWN",Input!J$2,Date,,,Ccy,Conv) -> 0 | I40: =_xll.ciqfunctions.udf.CIQ(InputTicker, "IQ_ASSET_WRITEDOWN",Input!K$2,Date,,,Ccy,Conv) -> 0 | ... M40: =_xll.ciqfunctions.udf.CIQ(InputTicker, "IQ_ASSET_WRITEDOWN",Input!O$2,Date,,,Ccy,Conv) -> 0
...

Sheet Common Size
A1: Period | B1: ="FY"&RIGHT(YEAR(B2),2) -> FY16 | C1: ="FY"&RIGHT(YEAR(C2),2) -> FY17 | D1: ="FY"&RIGHT(YEAR(D2),2) -> FY18 | E1: ="FY"&RIGHT(YEAR(E2),2) -> FY19 | F1: ="FY"&RIGHT(YEAR(F2),2) -> FY20 | G1: ="FY"&RIGHT(YEAR(G2),2) -> FY21 | H1: ="FY"&RIGHT(YEAR(H2),2) -> FY22 | I1: ="FY"&RIGHT(YEAR(I2),2) -> FY23 | ... L1: ="FY"&RIGHT(YEAR(L2),2) -> FY26 | M1: LTM
A2: Period Date | B2: ='Financial Statements'!B$2 -> 42518 | C2: ='Financial Statements'!C$2 -> 42889 | D2: ='Financial Statements'!D$2 -> 43253 | E2: ='Financial Statements'!E$2 -> 43617 | F2: ='Financial Statements'!F$2 -> 43981 | G2: ='Financial Statements'!G$2 -> 44345 | H2: ='Financial Statements'!H$2 -> 44709 | I2: ='Financial Statements'!I$2 -> 45080 | ... M2: ='Financial Statements'!M$2 -> 46172
A3: Revenues | B3: ='Financial Statements'!B3/'Financial Statements'!B$10 -> 1 | C3: ='Financial Statements'!C3/'Financial Statements'!C$10 -> 1 | D3: ='Financial Statements'!D3/'Financial Statements'!D$10 -> 1 | E3: ='Financial Statements'!E3/'Financial Statements'!E$10 -> 1 | F3: ='Financial Statements'!F3/'Financial Statements'!F$10 -> 1 | G3: ='Financial Statements'!G3/'Financial Statements'!G$10 -> 1 | H3: ='Financial Statements'!H3/'Financial Statements'!H$10 -> 1 | I3: ='Financial Statements'!I3/'Financial Statements'!I$10 -> 1 | ... M3: ='Financial Statements'!M3/'Financial Statements'!M$10 -> 1
A4: Finance Div. Revenues | B4: ='Financial Statements'!B4/'Financial Statements'!B$10 -> 0 | C4: ='Financial Statements'!C4/'Financial Statements'!C$10 -> 0 | D4: ='Financial Statements'!D4/'Financial Statements'!D$10 -> 0 | E4: ='Financial Statements'!E4/'Financial Statements'!E$10 -> 0 | F4: ='Financial Statements'!F4/'Financial Statements'!F$10 -> 0 | G4: ='Financial Statements'!G4/'Financial Statements'!G$10 -> 0 | H4: ='Financial Statements'!H4/'Financial Statements'!H$10 -> 0 | I4: ='Financial Statements'!I4/'Financial Statements'!I$10 -> 0 | ... M4: ='Financial Statements'!M4/'Financial Statements'!M$10 -> 0
A5: Insurance Div. Revenues | B5: ='Financial Statements'!B5/'Financial Statements'!B$10 -> 0 | C5: ='Financial Statements'!C5/'Financial Statements'!C$10 -> 0 | D5: ='Financial Statements'!D5/'Financial Statements'!D$10 -> 0 | E5: ='Financial Statements'!E5/'Financial Statements'!E$10 -> 0 | F5: ='Financial Statements'!F5/'Financial Statements'!F$10 -> 0 | G5: ='Financial Statements'!G5/'Financial Statements'!G$10 -> 0 | H5: ='Financial Statements'!H5/'Financial Statements'!H$10 -> 0 | I5: ='Financial Statements'!I5/'Financial Statements'!I$10 -> 0 | ... M5: ='Financial Statements'!M5/'Financial Statements'!M$10 -> 0
A6: Gain/(Loss) on Sale Of Assets (Rev) | B6: ='Financial Statements'!B6/'Financial Statements'!B$10 -> 0 | C6: ='Financial Statements'!C6/'Financial Statements'!C$10 -> 0 | D6: ='Financial Statements'!D6/'Financial Statements'!D$10 -> 0 | E6: ='Financial Statements'!E6/'Financial Statements'!E$10 -> 0 | F6: ='Financial Statements'!F6/'Financial Statements'!F$10 -> 0 | G6: ='Financial Statements'!G6/'Financial Statements'!G$10 -> 0 | H6: ='Financial Statements'!H6/'Financial Statements'!H$10 -> 0 | I6: ='Financial Statements'!I6/'Financial Statements'!I$10 -> 0 | ... M6: ='Financial Statements'!M6/'Financial Statements'!M$10 -> 0
A7: Gain/(Loss) on Sale Of Invest.(Rev) | B7: ='Financial Statements'!B7/'Financial Statements'!B$10 -> 0 | C7: ='Financial Statements'!C7/'Financial Statements'!C$10 -> 0 | D7: ='Financial Statements'!D7/'Financial Statements'!D$10 -> 0 | E7: ='Financial Statements'!E7/'Financial Statements'!E$10 -> 0 | F7: ='Financial Statements'!F7/'Financial Statements'!F$10 -> 0 | G7: ='Financial Statements'!G7/'Financial Statements'!G$10 -> 0 | H7: ='Financial Statements'!H7/'Financial Statements'!H$10 -> 0 | I7: ='Financial Statements'!I7/'Financial Statements'!I$10 -> 0 | ... M7: ='Financial Statements'!M7/'Financial Statements'!M$10 -> 0
A8: Interest And Invest. Income (Rev) | B8: ='Financial Statements'!B8/'Financial Statements'!B$10 -> 0 | C8: ='Financial Statements'!C8/'Financial Statements'!C$10 -> 0 | D8: ='Financial Statements'!D8/'Financial Statements'!D$10 -> 0 | E8: ='Financial Statements'!E8/'Financial Statements'!E$10 -> 0 | F8: ='Financial Statements'!F8/'Financial Statements'!F$10 -> 0 | G8: ='Financial Statements'!G8/'Financial Statements'!G$10 -> 0 | H8: ='Financial Statements'!H8/'Financial Statements'!H$10 -> 0 | I8: ='Financial Statements'!I8/'Financial Statements'!I$10 -> 0 | ... M8: ='Financial Statements'!M8/'Financial Statements'!M$10 -> 0
A9: Other Revenues | B9: ='Financial Statements'!B9/'Financial Statements'!B$10 -> 0 | C9: ='Financial Statements'!C9/'Financial Statements'!C$10 -> 0 | D9: ='Financial Statements'!D9/'Financial Statements'!D$10 -> 0 | E9: ='Financial Statements'!E9/'Financial Statements'!E$10 -> 0 | F9: ='Financial Statements'!F9/'Financial Statements'!F$10 -> 0 | G9: ='Financial Statements'!G9/'Financial Statements'!G$10 -> 0 | H9: ='Financial Statements'!H9/'Financial Statements'!H$10 -> 0 | I9: ='Financial Statements'!I9/'Financial Statements'!I$10 -> 0 | ... M9: ='Financial Statements'!M9/'Financial Statements'!M$10 -> 0
A10: Total Revenues | B10: ='Financial Statements'!B10/'Financial Statements'!B$10 -> 1 | C10: ='Financial Statements'!C10/'Financial Statements'!C$10 -> 1 | D10: ='Financial Statements'!D10/'Financial Statements'!D$10 -> 1 | E10: ='Financial Statements'!E10/'Financial Statements'!E$10 -> 1 | F10: ='Financial Statements'!F10/'Financial Statements'!F$10 -> 1 | G10: ='Financial Statements'!G10/'Financial Statements'!G$10 -> 1 | H10: ='Financial Statements'!H10/'Financial Statements'!H$10 -> 1 | I10: ='Financial Statements'!I10/'Financial Statements'!I$10 -> 1 | ... M10: ='Financial Statements'!M10/'Financial Statements'!M$10 -> 1
A11: Cost Of Goods Sold | B11: ='Financial Statements'!B11/'Financial Statements'!B$10 -> 0.66045425 | C11: ='Financial Statements'!C11/'Financial Statements'!C$10 -> 0.9576087 | D11: ='Financial Statements'!D11/'Financial Statements'!D$10 -> 0.75977223 | E11: ='Financial Statements'!E11/'Financial Statements'!E$10 -> 0.83627611 | F11: ='Financial Statements'!F11/'Financial Statements'!F$10 -> 0.86713021 | G11: ='Financial Statements'!G11/'Financial Statements'!G$10 -> 0.88090248 | H11: ='Financial Statements'!H11/'Financial Statements'!H$10 -> 0.8103383 | I11: ='Financial Statements'!I11/'Financial Statements'!I$10 -> 0.61971568 | ... M11: ='Financial Statements'!M11/'Financial Statements'!M$10 -> 0.76918477
A12: Finance Div. Operating Exp. | B12: ='Financial Statements'!B12/'Financial Statements'!B$10 -> 0 | C12: ='Financial Statements'!C12/'Financial Statements'!C$10 -> 0 | D12: ='Financial Statements'!D12/'Financial Statements'!D$10 -> 0 | E12: ='Financial Statements'!E12/'Financial Statements'!E$10 -> 0 | F12: ='Financial Statements'!F12/'Financial Statements'!F$10 -> 0 | G12: ='Financial Statements'!G12/'Financial Statements'!G$10 -> 0 | H12: ='Financial Statements'!H12/'Financial Statements'!H$10 -> 0 | I12: ='Financial Statements'!I12/'Financial Statements'!I$10 -> 0 | ... M12: ='Financial Statements'!M12/'Financial Statements'!M$10 -> 0
A13: Insurance Div. Operating Exp. | B13: ='Financial Statements'!B13/'Financial Statements'!B$10 -> 0 | C13: ='Financial Statements'!C13/'Financial Statements'!C$10 -> 0 | D13: ='Financial Statements'!D13/'Financial Statements'!D$10 -> 0 | E13: ='Financial Statements'!E13/'Financial Statements'!E$10 -> 0 | F13: ='Financial Statements'!F13/'Financial Statements'!F$10 -> 0 | G13: ='Financial Statements'!G13/'Financial Statements'!G$10 -> 0 | H13: ='Financial Statements'!H13/'Financial Statements'!H$10 -> 0 | I13: ='Financial Statements'!I13/'Financial Statements'!I$10 -> 0 | ... M13: ='Financial Statements'!M13/'Financial Statements'!M$10 -> 0
A14: Interest Expense - Finance Division | B14: ='Financial Statements'!B14/'Financial Statements'!B$10 -> 0 | C14: ='Financial Statements'!C14/'Financial Statements'!C$10 -> 0 | D14: ='Financial Statements'!D14/'Financial Statements'!D$10 -> 0 | E14: ='Financial Statements'!E14/'Financial Statements'!E$10 -> 0 | F14: ='Financial Statements'!F14/'Financial Statements'!F$10 -> 0 | G14: ='Financial Statements'!G14/'Financial Statements'!G$10 -> 0 | H14: ='Financial Statements'!H14/'Financial Statements'!H$10 -> 0 | I14: ='Financial Statements'!I14/'Financial Statements'!I$10 -> 0 | ... M14: ='Financial Statements'!M14/'Financial Statements'!M$10 -> 0
... A55: NI to Common Excl Extra Items | B55: ='Financial Statements'!B55/'Financial Statements'!B$10 -> 0.16558353 | C55: ='Financial Statements'!C55/'Financial Statements'!C$10 -> -0.06912713 | D55: ='Financial Statements'!D55/'Financial Statements'!D$10 -> 0.083790883 | E55: ='Financial Statements'!E55/'Financial Statements'!E$10 -> 0.039839464 | F55: ='Financial Statements'!F55/'Financial Statements'!F$10 -> 0.013606746 | G55: ='Financial Statements'!G55/'Financial Statements'!G$10 -> 0.0015270718 | H55: ='Financial Statements'!H55/'Financial Statements'!H$10 -> 0.074641605 | I55: ='Financial Statements'!I55/'Financial Statements'!I$10 -> 0.24093189 | ... M55: ='Financial Statements'!M55/'Financial Statements'!M$10 -> 0.10876443
A56: Cash And Equivalents | B56: ='Financial Statements'!B281/'Financial Statements'!B$311 -> 0.026126025 | C56: ='Financial Statements'!C281/'Financial Statements'!C$311 -> 0.017001357 | D56: ='Financial Statements'!D281/'Financial Statements'!D$311 -> 0.04209755 | E56: ='Financial Statements'!E281/'Financial Statements'!E$311 -> 0.059887847 | F56: ='Financial Statements'!F281/'Financial Statements'!F$311 -> 0.064747152 | G56: ='Financial Statements'!G281/'Financial Statements'!G$311 -> 0.046658976 | H56: ='Financial Statements'!H281/'Financial Statements'!H$311 -> 0.041390161 | I56: ='Financial Statements'!I281/'Financial Statements'!I$311 -> 0.1498185 | ... M56: ='Financial Statements'!M281/'Financial Statements'!M$311 -> 0.034501878
A57: Short Term Investments | B57: ='Financial Statements'!B282/'Financial Statements'!B$311 -> 0.32425827 | C57: ='Financial Statements'!C282/'Financial Statements'!C$311 -> 0.13402653 | D57: ='Financial Statements'!D282/'Financial Statements'!D$311 -> 0.24563148 | E57: ='Financial Statements'!E282/'Financial Statements'!E$311 -> 0.21636752 | F57: ='Financial Statements'!F282/'Financial Statements'!F$311 -> 0.1277565 | G57: ='Financial Statements'!G282/'Financial Statements'!G$311 -> 0.091246642 | H57: ='Financial Statements'!H282/'Financial Statements'!H$311 -> 0.080861569 | I57: ='Financial Statements'!I282/'Financial Statements'!I$311 -> 0.18167585 | ... M57: ='Financial Statements'!M282/'Financial Statements'!M$311 -> 0.2628549
A58: Trading Asset Securities | B58: ='Financial Statements'!B283/'Financial Statements'!B$311 -> 0 | C58: ='Financial Statements'!C283/'Financial Statements'!C$311 -> 0 | D58: ='Financial Statements'!D283/'Financial Statements'!D$311 -> 0 | E58: ='Financial Statements'!E283/'Financial Statements'!E$311 -> 0 | F58: ='Financial Statements'!F283/'Financial Statements'!F$311 -> 0 | G58: ='Financial Statements'!G283/'Financial Statements'!G$311 -> 0 | H58: ='Financial Statements'!H283/'Financial Statements'!H$311 -> 0 | I58: ='Financial Statements'!I283/'Financial Statements'!I$311 -> 0 | ... M58: ='Financial Statements'!M283/'Financial Statements'!M$311 -> 0
A59: Total Cash & ST Investments | B59: ='Financial Statements'!B284/'Financial Statements'!B$311 -> 0.3503843 | C59: ='Financial Statements'!C284/'Financial Statements'!C$311 -> 0.15102788 | D59: ='Financial Statements'!D284/'Financial Statements'!D$311 -> 0.28772903 | E59: ='Financial Statements'!E284/'Financial Statements'!E$311 -> 0.27625536 | F59: ='Financial Statements'!F284/'Financial Statements'!F$311 -> 0.19250365 | G59: ='Financial Statements'!G284/'Financial Statements'!G$311 -> 0.13790562 | H59: ='Financial Statements'!H284/'Financial Statements'!H$311 -> 0.12225173 | I59: ='Financial Statements'!I284/'Financial Statements'!I$311 -> 0.33149435 | ... M59: ='Financial Statements'!M284/'Financial Statements'!M$311 -> 0.29735678
A60: Accounts Receivable | B60: ='Financial Statements'!B285/'Financial Statements'!B$311 -> 0.055777975 | C60: ='Financial Statements'!C285/'Financial Statements'!C$311 -> 0.059298573 | D60: ='Financial Statements'!D285/'Financial Statements'!D$311 -> 0.070173593 | E60: ='Financial Statements'!E285/'Financial Statements'!E$311 -> 0.049347129 | F60: ='Financial Statements'!F285/'Financial Statements'!F$311 -> 0.070420504 | G60: ='Financial Statements'!G285/'Financial Statements'!G$311 -> 0.064324498 | H60: ='Financial Statements'!H285/'Financial Statements'!H$311 -> 0.11846606 | I60: ='Financial Statements'!I285/'Financial Statements'!I$311 -> 0.056781059 | ... M60: ='Financial Statements'!M285/'Financial Statements'!M$311 -> 0.043844226
A61: Other Receivables | B61: ='Financial Statements'!B286/'Financial Statements'!B$311 -> 0.01553026 | C61: ='Financial Statements'!C286/'Financial Statements'!C$311 -> 0.054147057 | D61: ='Financial Statements'!D286/'Financial Statements'!D$311 -> 0.0044400133 | E61: ='Financial Statements'!E286/'Financial Statements'!E$311 -> 0.01271407 | F61: ='Financial Statements'!F286/'Financial Statements'!F$311 -> 0.011103892 | G61: ='Financial Statements'!G286/'Financial Statements'!G$311 -> 0.038703227 | H61: ='Financial Statements'!H286/'Financial Statements'!H$311 -> 0.035233196 | I61: ='Financial Statements'!I286/'Financial Statements'!I$311 -> 0.039003338 | ... M61: ='Financial Statements'!M286/'Financial Statements'!M$311 -> 0.041248307
A62: Notes Receivable | B62: ='Financial Statements'!B287/'Financial Statements'!B$311 -> 0 | C62: ='Financial Statements'!C287/'Financial Statements'!C$311 -> 0 | D62: ='Financial Statements'!D287/'Financial Statements'!D$311 -> 0 | E62: ='Financial Statements'!E287/'Financial Statements'!E$311 -> 0 | F62: ='Financial Statements'!F287/'Financial Statements'!F$311 -> 0 | G62: ='Financial Statements'!G287/'Financial Statements'!G$311 -> 0 | H62: ='Financial Statements'!H287/'Financial Statements'!H$311 -> 0 | I62: ='Financial Statements'!I287/'Financial Statements'!I$311 -> 0 | ... M62: ='Financial Statements'!M287/'Financial Statements'!M$311 -> 0
A63: Total Receivables | B63: ='Financial Statements'!B288/'Financial Statements'!B$311 -> 0.071308235 | C63: ='Financial Statements'!C288/'Financial Statements'!C$311 -> 0.11344563 | D63: ='Financial Statements'!D288/'Financial Statements'!D$311 -> 0.074613607 | E63: ='Financial Statements'!E288/'Financial Statements'!E$311 -> 0.0620612 | F63: ='Financial Statements'!F288/'Financial Statements'!F$311 -> 0.081524396 | G63: ='Financial Statements'!G288/'Financial Statements'!G$311 -> 0.10302772 | H63: ='Financial Statements'!H288/'Financial Statements'!H$311 -> 0.15369926 | I63: ='Financial Statements'!I288/'Financial Statements'!I$311 -> 0.095784398 | ... M63: ='Financial Statements'!M288/'Financial Statements'!M$311 -> 0.085092532
A64: Inventory | B64: ='Financial Statements'!B289/'Financial Statements'!B$311 -> 0.13923716 | C64: ='Financial Statements'!C289/'Financial Statements'!C$311 -> 0.15554441 | D64: ='Financial Statements'!D289/'Financial Statements'!D$311 -> 0.14658998 | E64: ='Financial Statements'!E289/'Financial Statements'!E$311 -> 0.14895812 | F64: ='Financial Statements'!F289/'Financial Statements'!F$311 -> 0.15514787 | G64: ='Financial Statements'!G289/'Financial Statements'!G$311 -> 0.17765996 | H64: ='Financial Statements'!H289/'Financial Statements'!H$311 -> 0.18446097 | I64: ='Financial Statements'!I289/'Financial Statements'!I$311 -> 0.14551771 | ... M64: ='Financial Statements'!M289/'Financial Statements'!M$311 -> 0.12075834
A65: Prepaid Exp. | B65: ='Financial Statements'!B290/'Financial Statements'!B$311 -> 0.0023934914 | C65: ='Financial Statements'!C290/'Financial Statements'!C$311 -> 0.0022147065 | D65: ='Financial Statements'!D290/'Financial Statements'!D$311 -> 0.0017558393 | E65: ='Financial Statements'!E290/'Financial Statements'!E$311 -> 0.0037430445 | F65: ='Financial Statements'!F290/'Financial Statements'!F$311 -> 0.0036189788 | G65: ='Financial Statements'!G290/'Financial Statements'!G$311 -> 0.004398889 | H65: ='Financial Statements'!H290/'Financial Statements'!H$311 -> 0.003002475 | I65: ='Financial Statements'!I290/'Financial Statements'!I$311 -> 0.0027525869 | ... M65: ='Financial Statements'!M290/'Financial Statements'!M$311 -> 0.003697101
A66: Finance Div. Loans and Leases, ST | B66: ='Financial Statements'!B291/'Financial Statements'!B$311 -> 0 | C66: ='Financial Statements'!C291/'Financial Statements'!C$311 -> 0 | D66: ='Financial Statements'!D291/'Financial Statements'!D$311 -> 0 | E66: ='Financial Statements'!E291/'Financial Statements'!E$311 -> 0 | F66: ='Financial Statements'!F291/'Financial Statements'!F$311 -> 0 | G66: ='Financial Statements'!G291/'Financial Statements'!G$311 -> 0 | H66: ='Financial Statements'!H291/'Financial Statements'!H$311 -> 0 | I66: ='Financial Statements'!I291/'Financial Statements'!I$311 -> 0 | ... M66: ='Financial Statements'!M291/'Financial Statements'!M$311 -> 0
A67: Finance Div. Other Curr. Assets | B67: ='Financial Statements'!B292/'Financial Statements'!B$311 -> 0 | C67: ='Financial Statements'!C292/'Financial Statements'!C$311 -> 0 | D67: ='Financial Statements'!D292/'Financial Statements'!D$311 -> 0 | E67: ='Financial Statements'!E292/'Financial Statements'!E$311 -> 0 | F67: ='Financial Statements'!F292/'Financial Statements'!F$311 -> 0 | G67: ='Financial Statements'!G292/'Financial Statements'!G$311 -> 0 | H67: ='Financial Statements'!H292/'Financial Statements'!H$311 -> 0 | I67: ='Financial Statements'!I292/'Financial Statements'!I$311 -> 0 | ... M67: ='Financial Statements'!M292/'Financial Statements'!M$311 -> 0
... A86: Total Assets | B86: ='Financial Statements'!B311/'Financial Statements'!B$311 -> 1 | C86: ='Financial Statements'!C311/'Financial Statements'!C$311 -> 1 | D86: ='Financial Statements'!D311/'Financial Statements'!D$311 -> 1 | E86: ='Financial Statements'!E311/'Financial Statements'!E$311 -> 1 | F86: ='Financial Statements'!F311/'Financial Statements'!F$311 -> 1 | G86: ='Financial Statements'!G311/'Financial Statements'!G$311 -> 1 | H86: ='Financial Statements'!H311/'Financial Statements'!H$311 -> 1 | I86: ='Financial Statements'!I311/'Financial Statements'!I$311 -> 1 | ... M86: ='Financial Statements'!M311/'Financial Statements'!M$311 -> 1
A87: Accounts Payable | B87: ='Financial Statements'!B312/'Financial Statements'!B$346 -> 0.032616605 | C87: ='Financial Statements'!C312/'Financial Statements'!C$346 -> 0.029647835 | D87: ='Financial Statements'!D312/'Financial Statements'!D$346 -> 0.032891563 | E87: ='Financial Statements'!E312/'Financial Statements'!E$346 -> 0.03391053 | F87: ='Financial Statements'!F312/'Financial Statements'!F$346 -> 0.046328232 | G87: ='Financial Statements'!G312/'Financial Statements'!G$346 -> 0.042942659 | H87: ='Financial Statements'!H312/'Financial Statements'!H$346 -> 0.057477851 | I87: ='Financial Statements'!I312/'Financial Statements'!I$346 -> 0.042255791 | ... M87: ='Financial Statements'!M312/'Financial Statements'!M$346 -> 0.030926415
A88: Accrued Exp. | B88: ='Financial Statements'!B313/'Financial Statements'!B$346 -> 0.02776576 | C88: ='Financial Statements'!C313/'Financial Statements'!C$346 -> 0.028287842 | D88: ='Financial Statements'!D313/'Financial Statements'!D$346 -> 0.027748345 | E88: ='Financial Statements'!E313/'Financial Statements'!E$346 -> 0.029405558 | F88: ='Financial Statements'!F313/'Financial Statements'!F$346 -> 0.03006396 | G88: ='Financial Statements'!G313/'Financial Statements'!G$346 -> 0.029619078 | H88: ='Financial Statements'!H313/'Financial Statements'!H$346 -> 0.028218781 | I88: ='Financial Statements'!I313/'Financial Statements'!I$346 -> 0.027998107 | ... M88: ='Financial Statements'!M313/'Financial Statements'!M$346 -> 0.035207574
A89: Short-term Borrowings | B89: ='Financial Statements'!B314/'Financial Statements'!B$346 -> 0 | C89: ='Financial Statements'!C314/'Financial Statements'!C$346 -> 0 | D89: ='Financial Statements'!D314/'Financial Statements'!D$346 -> 0 | E89: ='Financial Statements'!E314/'Financial Statements'!E$346 -> 0 | F89: ='Financial Statements'!F314/'Financial Statements'!F$346 -> 0 | G89: ='Financial Statements'!G314/'Financial Statements'!G$346 -> 0 | H89: ='Financial Statements'!H314/'Financial Statements'!H$346 -> 0 | I89: ='Financial Statements'!I314/'Financial Statements'!I$346 -> 0 | ... M89: ='Financial Statements'!M314/'Financial Statements'!M$346 -> 0
A90: Current Portion of Long Term Debt | B90: ='Financial Statements'!B315/'Financial Statements'!B$346 -> 0.014679361 | C90: ='Financial Statements'!C315/'Financial Statements'!C$346 -> 0.0046714045 | D90: ='Financial Statements'!D315/'Financial Statements'!D$346 -> 0.0030735879 | E90: ='Financial Statements'!E315/'Financial Statements'!E$346 -> 0.0012972659 | F90: ='Financial Statements'!F315/'Financial Statements'!F$346 -> 0 | G90: ='Financial Statements'!G315/'Financial Statements'!G$346 -> 0 | H90: ='Financial Statements'!H315/'Financial Statements'!H$346 -> 0 | I90: ='Financial Statements'!I315/'Financial Statements'!I$346 -> 0 | ... M90: ='Financial Statements'!M315/'Financial Statements'!M$346 -> 0
