Workbook

Sheet Cover
A1: BAH Advanced DCF Model
A2: Formula-driven Excel review artifact sourced from valuation JSON
A4: Company | B4: Booz Allen Hamilton Holding Corporation
A5: Ticker | B5: BAH
A6: Sector | B6: Industrials
A7: Industry | B7: Consulting Services
A8: Generated | B8: 2026-06-14T23:27:56
A9: Source JSON | B9: C:\Projects\03-Finance\ai-fund\data\valuations\json\BAH_latest.json
A10: Purpose | B10: PM review workbook: assumptions, operating forecast, scenario DCF, sensitivities, checks
A11: Important | B11: This workbook is a review artifact and does not write back into the deterministic pipeline.
A14: Workbook Flow
A15: Input_JSON | B15: Flattened source values from backend JSON
A16: Historical_Financials | B16: CIQ annual actuals used for trend review
A17: Assumptions | B17: PM-editable override layer; formulas use Effective Value
A18: DCF_Base/Bear/Bull | B18: Operating model and valuation by scenario
A19: Sensitivity | B19: WACC/growth and WACC/exit-multiple explicit tables
A20: Checks | B20: Completeness, plausibility, and model hygiene flags

Sheet Model_Map
A1: Model Map
A4: Sheet | B4: Role | C4: User Action
A5: Cover | B5: Workbook orientation | C5: Read only
A6: Input_JSON | B6: Raw flat source values imported from backend JSON | C6: Read only
A7: Historical_Financials | B7: Historical annual actuals and margin checks | C7: Read only
A8: Assumptions | B8: Source values, PM overrides, and effective assumptions | C8: Edit PM Override only
A9: WACC | B9: Cost of capital build and scenario WACC bridge | C9: Review; edit overrides in Assumptions
A10: DCF_Base | B10: Base case operating forecast and DCF | C10: Review formulas and outputs
A11: DCF_Bear | B11: Downside scenario using visible multipliers | C11: Review formulas and outputs
A12: DCF_Bull | B12: Upside scenario using visible multipliers | C12: Review formulas and outputs
A13: Equity_Bridge | B13: EV to equity value reconciliation | C13: Review
A14: Sensitivity | B14: Explicit sensitivity tables | C14: Review
A15: Comps | B15: Peer and comps valuation source data | C15: Review
... A17: Checks | B17: Model sanity checks | C17: Resolve Fail/Review flags

Sheet Input_JSON
A1: Input JSON
A2: Flattened source tables from the valuation JSON
A4: metadata
A5: key | B5: value
A6: schema_version | B6: 1.0
A7: generated_at | B7: 2026-06-14T20:34:19
A8: ticker | B8: BAH
A9: company_name | B9: Booz Allen Hamilton Holding Corporation
A10: sector | B10: Industrials
A11: industry | B11: Consulting Services
A14: assumptions
A15: key | B15: value
A16: revenue_mm | B16: 11217
A17: growth_near_pct | B17: 0.0024725167
A18: growth_mid_pct | B18: 0.0013598842
A19: growth_terminal_pct | B19: 0.025
A20: ebit_margin_start_pct | B20: 0.098363684
A21: ebit_margin_target_pct | B21: 0.11418184
A22: capex_pct | B22: 0.01
A23: da_pct | B23: 0.014562066
A24: tax_rate_start_pct | B24: 0.20564844
A25: tax_rate_target_pct | B25: 0.20564844
A26: dso_start | B26: 67.1
A27: dso_target | B27: 58.63
... A32: exit_multiple | B32: 8.51724
A33: exit_metric | B33: ev_ebit
A34: net_debt_mm | B34: 3394
A35: shares_outstanding_mm | B35: 122.375
A36: ronic_terminal_pct | B36: 0.11
A37: invested_capital_mm | B37: 4727
A38: non_operating_assets_mm | B38: 503.66
A39: minority_interest_mm | B39: 0
A40: preferred_equity_mm | B40: 0
A41: pension_deficit_mm | B41: 0
A42: lease_liabilities_mm | B42: 0
A43: options_value_mm | B43: 207
A44: convertibles_value_mm | B44: 0
A45: scenario_prob_bear | B45: 0.2
... A47: scenario_prob_bull | B47: 0.2
A50: wacc
...

Sheet Assumptions
A1: Assumptions
A2: Only edit the PM Override column; scenario semantics remain visible inputs.
A4: Category | B4: Key | C4: Source Value | D4: PM Override | E4: Effective Value | F4: Unit | G4: Source / Meaning
A5: Company | B5: current_price | C5: 77.41 | E5: =IF(ISBLANK(D5),C5,D5) | F5: $ / share | G5: Market price from valuation JSON
A6: Company | B6: shares_outstanding_mm | C6: 122.375 | E6: =IF(ISBLANK(D6),C6,D6) | F6: mm shares | G6: Diluted share count
A7: Company | B7: net_debt_mm | C7: 3394 | E7: =IF(ISBLANK(D7),C7,D7) | F7: $mm | G7: Debt less cash / equivalents
A8: Company | B8: non_operating_assets_mm | C8: 503.66 | E8: =IF(ISBLANK(D8),C8,D8) | F8: $mm | G8: Assets added after enterprise value
A9: Company | B9: minority_interest_mm | C9: 0 | E9: =IF(ISBLANK(D9),C9,D9) | F9: $mm | G9: Non-equity claim
A10: Company | B10: preferred_equity_mm | C10: 0 | E10: =IF(ISBLANK(D10),C10,D10) | F10: $mm | G10: Non-equity claim
A11: Company | B11: pension_deficit_mm | C11: 0 | E11: =IF(ISBLANK(D11),C11,D11) | F11: $mm | G11: Non-equity claim
A12: Company | B12: lease_liabilities_mm | C12: 0 | E12: =IF(ISBLANK(D12),C12,D12) | F12: $mm | G12: Non-equity claim
A13: Company | B13: options_value_mm | C13: 207 | E13: =IF(ISBLANK(D13),C13,D13) | F13: $mm | G13: Non-equity claim
A14: Company | B14: convertibles_value_mm | C14: 0 | E14: =IF(ISBLANK(D14),C14,D14) | F14: $mm | G14: Non-equity claim
A15: Operating | B15: revenue_mm | C15: 11217 | E15: =IF(ISBLANK(D15),C15,D15) | F15: $mm | G15: Starting revenue
A16: Operating | B16: growth_near_pct | C16: 0.0024725167 | E16: =IF(ISBLANK(D16),C16,D16) | F16: % | G16: Near-term revenue growth
... A32: WACC | B32: cost_of_equity | C32: 0.07463 | E32: =IF(ISBLANK(D32),C32,D32) | F32: % | G32: Cost of equity
A33: WACC | B33: cost_of_debt | E33: =IF(ISBLANK(D33),C33,D33) | F33: % | G33: Cost of debt; blank if unavailable
A34: WACC | B34: risk_free_rate | E34: =IF(ISBLANK(D34),C34,D34) | F34: % | G34: Risk-free rate; blank if unavailable
A35: WACC | B35: equity_risk_premium | E35: =IF(ISBLANK(D35),C35,D35) | F35: % | G35: ERP; blank if unavailable
A36: WACC | B36: beta_relevered | C36: 0.27 | E36: =IF(ISBLANK(D36),C36,D36) | F36: x | G36: Relevered beta
A37: WACC | B37: size_premium | C37: 0.6 | E37: =IF(ISBLANK(D37),C37,D37) | F37: % | G37: Size premium
A38: WACC | B38: equity_weight | C38: 0.7323 | E38: =IF(ISBLANK(D38),C38,D38) | F38: % capital | G38: Market value capital weight
A39: WACC | B39: debt_weight | C39: 0.2677 | E39: =IF(ISBLANK(D39),C39,D39) | F39: % capital | G39: Market value capital weight
A40: Terminal | B40: exit_multiple | C40: 8.51724 | E40: =IF(ISBLANK(D40),C40,D40) | F40: x | G40: Exit multiple
A41: Terminal | B41: exit_metric | C41: ev_ebit | E41: =IF(ISBLANK(D41),C41,D41) | F41: text | G41: Exit metric, usually ev_ebit or ev_ebitda
A42: Terminal | B42: terminal_blend_gordon_weight | C42: 0.5 | E42: =IF(ISBLANK(D42),C42,D42) | F42: % | G42: Weight on Gordon TV; remaining weight goes to exit TV
A43: Scenario | B43: bear_growth_multiplier | C43: 0.7 | E43: =IF(ISBLANK(D43),C43,D43) | F43: x | G43: PM-owned bear growth multiplier
A44: Scenario | B44: bear_margin_multiplier | C44: 0.85 | E44: =IF(ISBLANK(D44),C44,D44) | F44: x | G44: PM-owned bear margin multiplier
A45: Scenario | B45: bear_capex_multiplier | C45: 1.15 | E45: =IF(ISBLANK(D45),C45,D45) | F45: x | G45: PM-owned bear capex intensity multiplier
A46: Scenario | B46: bear_wacc_spread | C46: 0.015 | E46: =IF(ISBLANK(D46),C46,D46) | F46: % | G46: Bear spread added to base WACC
A47: Scenario | B47: bear_exit_multiple_multiplier | C47: 0.8 | E47: =IF(ISBLANK(D47),C47,D47) | F47: x | G47: PM-owned bear exit multiple multiplier
A48: Scenario | B48: bull_growth_multiplier | C48: 1.3 | E48: =IF(ISBLANK(D48),C48,D48) | F48: x | G48: PM-owned bull growth multiplier
A49: Scenario | B49: bull_margin_multiplier | C49: 1.1 | E49: =IF(ISBLANK(D49),C49,D49) | F49: x | G49: PM-owned bull margin multiplier
A50: Scenario | B50: bull_capex_multiplier | C50: 0.9 | E50: =IF(ISBLANK(D50),C50,D50) | F50: x | G50: PM-owned bull capex intensity multiplier
A51: Scenario | B51: bull_wacc_spread | C51: -0.01 | E51: =IF(ISBLANK(D51),C51,D51) | F51: % | G51: Bull spread added to base WACC
A52: Scenario | B52: bull_exit_multiple_multiplier | C52: 1.2 | E52: =IF(ISBLANK(D52),C52,D52) | F52: x | G52: PM-owned bull exit multiple multiplier
A53: Scenario | B53: scenario_prob_bear | C53: 0.2 | E53: =IF(ISBLANK(D53),C53,D53) | F53: % | G53: Bear case probability
... A55: Scenario | B55: scenario_prob_bull | C55: 0.2 | E55: =IF(ISBLANK(D55),C55,D55) | F55: % | G55: Bull case probability
A56: Model | B56: mid_year_convention | C56: TRUE | E56: =IF(ISBLANK(D56),C56,D56) | F56: TRUE/FALSE | G56: Use mid-year discounting when TRUE
A57: Backend Outputs | B57: backend_iv_base | C57: 97.75 | E57: =IF(ISBLANK(D57),C57,D57) | F57: $ / share | G57: Backend deterministic base IV for comparison
...

Sheet Historical_Financials
A1: Historical Financials
A2: Annual actuals from the CIQ Standard workbook captured in valuation JSON
A4: Fiscal Year | B4: Period | C4: Revenue | D4: Revenue Growth | E4: EBIT | F4: EBIT Margin | G4: EBITDA | H4: EBITDA Margin | I4: D&A | J4: D&A % Revenue | K4: Capex | L4: Capex % Revenue | M4: CFO | N4: Pretax Income | O4: Tax Expense | P4: Tax Rate | Q4: Cash | R4: Debt | S4: Net Debt | T4: Total Assets | U4: Total Equity | V4: Source
A5: FY17 | B5: 2017-03-31 | C5: 5809.491 | D5: 0.074689709 | E5: 501.98 | F5: 0.086406881 | G5: 561.524 | H5: 0.096656316 | I5: 41.644 | J5: 0.00716827 | K5: 53.919 | L5: 0.0092811918 | M5: 382.277 | N5: 429.457 | O5: 164.832 | P5: 0.38381491 | Q5: 217.417 | R5: 1743.324 | S5: 1525.907 | T5: 3373.105 | U5: 573.591 | V5: BAH_Standard.xlsx
A6: FY18 | B6: 2018-03-31 | C6: 6167.6 | D6: 0.061642061 | E6: 512.444 | F6: 0.083086452 | G6: 577.2 | H6: 0.093585836 | I6: 44.056 | J6: 0.0071431351 | K6: 78.437 | L6: 0.012717589 | M6: 369.143 | N6: 430.036 | O6: 128.344 | P6: 0.29844943 | Q6: 286.958 | R6: 1898.579 | S6: 1611.621 | T6: 3606.619 | U6: 562.491 | V6: BAH_Standard.xlsx
A7: FY19 | B7: 2019-03-31 | C7: 6704.037 | D7: 0.08697662 | E7: 595.156 | F7: 0.088775763 | G7: 663.731 | H7: 0.099004674 | I7: 47.675 | J7: 0.0071113868 | K7: 94.681 | L7: 0.014122983 | M7: 499.61 | N7: 515.403 | O7: 96.874 | P7: 0.18795777 | Q7: 283.99 | R7: 1845.037 | S7: 1561.047 | T7: 3831.841 | U7: 675.366 | V7: BAH_Standard.xlsx
A8: FY20 | B8: 2020-03-31 | C8: 7463.841 | D8: 0.11333529 | E8: 664.343 | F8: 0.089008193 | G8: 745.424 | H8: 0.099871366 | I8: 58.781 | J8: 0.0078754357 | K8: 128.079 | L8: 0.017159931 | M8: 551.428 | N8: 580.885 | O8: 96.831 | P8: 0.16669565 | Q8: 741.901 | R8: 2561.781 | S8: 1819.88 | T8: 4793.966 | U8: 856.356 | V8: BAH_Standard.xlsx
A9: FY21 | B9: 2021-03-31 | C9: 7858.938 | D9: 0.052934809 | E9: 750.134 | F9: 0.095449792 | G9: 834.449 | H9: 0.10617834 | I9: 65.015 | J9: 0.0082727463 | K9: 87.21 | L9: 0.011096919 | M9: 718.684 | N9: 662.439 | O9: 53.481 | P9: 0.080733471 | Q9: 990.955 | R9: 2712.858 | S9: 1721.903 | T9: 5499.601 | U9: 1071.176 | V9: BAH_Standard.xlsx
A10: FY22 | B10: 2022-03-31 | C10: 8363.7 | D10: 0.064227762 | E10: 681.118 | F10: 0.081437402 | G10: 826.865 | H10: 0.098863541 | I10: 69.547 | J10: 0.0083153389 | K10: 79.964 | L10: 0.0095608403 | M10: 736.526 | N10: 604.043 | O10: 137.466 | P10: 0.22757651 | Q10: 695.91 | R10: 3103.839 | S10: 2407.929 | T10: 6025.575 | U10: 1046.721 | V10: BAH_Standard.xlsx
A11: FY23 | B11: 2023-03-31 | C11: 9259 | D11: 0.10704592 | E11: 811 | F11: 0.087590453 | G11: 976 | H11: 0.10541095 | I11: 71 | J11: 0.0076682147 | K11: 76 | L11: 0.0082082298 | M11: 603 | N11: 687 | O11: 97 | P11: 0.1411936 | Q11: 404.862 | R11: 3062.896 | S11: 2658.034 | T11: 6550.652 | U11: 992.002 | V11: BAH_Standard.xlsx
A12: FY24 | B12: 2024-03-31 | C12: 10662 | D12: 0.15152824 | E12: 1025 | F12: 0.096135809 | G12: 1189 | H12: 0.11151754 | I12: 71 | J12: 0.0066591634 | K12: 67 | L12: 0.0062839992 | M12: 259 | N12: 881 | O12: 248 | P12: 0.2814983 | Q12: 554 | R12: 3637 | S12: 3083 | T12: 6564 | U12: 1047 | V12: BAH_Standard.xlsx
A13: FY25 | B13: 2025-03-31 | C13: 11980 | D13: 0.12361658 | E13: 1214 | F13: 0.10133556 | G13: 1379 | H13: 0.11510851 | I13: 70 | J13: 0.0058430718 | K13: 98 | L13: 0.0081803005 | M13: 1009 | N13: 1104 | O13: 284 | P13: 0.25724638 | Q13: 885 | R13: 4219 | S13: 3334 | T13: 7312 | U13: 1003 | V13: BAH_Standard.xlsx
A14: FY26 | B14: 2026-03-31 | C14: 11217 | D14: -0.063689482 | E14: 1095 | F14: 0.097619684 | G14: 1258 | H14: 0.1121512 | I14: 68 | J14: 0.006062227 | K14: 90 | L14: 0.0080235357 | M14: 1041 | N14: 917 | O14: 11 | P14: 0.011995638 | Q14: 728 | R14: 4122 | S14: 3394 | T14: 7118 | U14: 1105 | V14: BAH_Standard.xlsx

Sheet Input_Forecast
A1: Input Forecast
A2: Flattened backend forecast values used as the Base case source
A4: Year | B4: Revenue | C4: Growth | D4: EBIT Margin | E4: Tax Rate | F4: Capex % Revenue | G4: D&A % Revenue | H4: DSO | I4: DIO | J4: DPO | K4: EBIT | L4: NOPAT | M4: D&A | N4: Capex | O4: AR | P4: Inventory | Q4: AP | R4: NWC | S4: Delta NWC | T4: FCFF | U4: Discount Factor | V4: PV FCFF | W4: ROIC | X4: Economic Profit
A5: 1 | B5: 11244.734 | C5: 0.0024725167 | D5: 0.098363684 | E5: 0.20564844 | F5: 0.01 | G5: 0.014562066 | H5: 67.1 | I5: 5 | J5: 19.3 | K5: 1106.073 | L5: 878.611 | M5: 163.747 | N5: 112.447 | O5: 2067.183 | P5: 71.212 | Q5: 274.876 | R5: 1863.518 | S5: 4.596 | T5: 925.314 | U5: 1.06801 | V5: 866.391 | W5: 0.18587079 | X5: 557.128
A6: 2 | B6: 11272.537 | C6: 0.0024725167 | D6: 0.10012126 | E6: 0.20564844 | F6: 0.011055556 | G6: 0.015036722 | H6: 66.158889 | I6: 9.2777778 | J6: 21.687778 | K6: 1128.621 | L6: 896.522 | M6: 169.502 | N6: 124.624 | O6: 2043.229 | P6: 132.464 | Q6: 309.648 | R6: 1866.045 | S6: 2.527 | T6: 938.872 | U6: 1.1406454 | V6: 823.106 | W6: 0.19155227 | X6: 578.215
A7: 3 | B7: 11300.409 | C7: 0.0024725167 | D7: 0.10187883 | E7: 0.20564844 | F7: 0.012111111 | G7: 0.015511377 | H7: 65.217778 | I7: 13.555556 | J7: 24.075556 | K7: 1151.272 | L7: 914.515 | M7: 175.285 | N7: 136.861 | O7: 2019.144 | P7: 194.018 | Q7: 344.589 | R7: 1868.573 | S7: 2.528 | T7: 950.411 | U7: 1.2182207 | V7: 780.163 | W7: 0.19718103 | X7: 599.088
A8: 4 | B8: 11326.553 | C8: 0.0023135692 | D8: 0.1036364 | E8: 0.20564844 | F8: 0.013166667 | G8: 0.015986032 | H8: 64.276667 | I8: 17.833333 | J8: 26.463333 | K8: 1173.843 | L8: 932.444 | M8: 181.067 | N8: 149.133 | O8: 1994.611 | P8: 255.836 | Q8: 379.641 | R8: 1870.806 | S8: 2.233 | T8: 962.145 | U8: 1.3010718 | V8: 739.502 | W8: 0.20261496 | X8: 619.459
A9: 5 | B9: 11350.957 | C9: 0.0021546217 | D9: 0.10539398 | E9: 0.20564844 | F9: 0.014222222 | G9: 0.016460687 | H9: 63.335556 | I9: 22.111111 | J9: 28.851111 | K9: 1196.323 | L9: 950.301 | M9: 186.845 | N9: 161.436 | O9: 1969.642 | P9: 317.888 | Q9: 414.788 | R9: 1872.742 | S9: 1.936 | T9: 973.773 | U9: 1.3895577 | V9: 700.779 | W9: 0.20783642 | X9: 639.335
A10: 6 | B10: 11373.61 | C10: 0.0019956742 | D10: 0.10715155 | E10: 0.20564844 | F10: 0.015277778 | G10: 0.016935342 | H10: 62.394444 | I10: 26.388889 | J10: 31.238889 | K10: 1218.7 | L10: 968.076 | M10: 192.616 | N10: 173.763 | O10: 1944.247 | P10: 380.146 | Q10: 450.013 | R10: 1874.38 | S10: 1.638 | T10: 985.29 | U10: 1.4840616 | V10: 663.915 | W10: 0.21281656 | X10: 658.707
A11: 7 | B11: 11394.5 | C11: 0.0018367267 | D11: 0.10890912 | E11: 0.20564844 | F11: 0.016333333 | G11: 0.017409997 | H11: 61.453333 | I11: 30.666667 | J11: 33.626667 | K11: 1240.965 | L11: 985.763 | M11: 198.378 | N11: 186.11 | O11: 1918.438 | P11: 442.581 | Q11: 485.3 | R11: 1875.72 | S11: 1.34 | T11: 996.691 | U11: 1.5849926 | V11: 628.83 | W11: 0.21752781 | X11: 677.564
A12: 8 | B12: 11413.618 | C12: 0.0016777792 | D12: 0.1106667 | E12: 0.20564844 | F12: 0.017388889 | G12: 0.017884653 | H12: 60.512222 | I12: 34.944444 | J12: 36.014444 | K12: 1263.107 | L12: 1003.351 | M12: 204.129 | N12: 198.47 | O12: 1892.228 | P12: 505.164 | Q12: 520.632 | R12: 1876.76 | S12: 1.041 | T12: 1007.969 | U12: 1.6927879 | V12: 595.449 | W12: 0.22194435 | X12: 695.896
A13: 9 | B13: 11430.953 | C13: 0.0015188317 | D13: 0.11242427 | E13: 0.20564844 | F13: 0.018444444 | G13: 0.018359308 | H13: 59.571111 | I13: 39.222222 | J13: 38.402222 | K13: 1285.117 | L13: 1020.834 | M13: 209.864 | N13: 210.838 | O13: 1865.629 | P13: 567.866 | Q13: 555.994 | R13: 1877.501 | S13: 740795.34 | T13: 1019.12 | U13: 1.8079144 | V13: 563.699 | W13: 0.22604255 | X13: 713.693
A14: 10 | B14: 11446.498 | C14: 0.0013598842 | D14: 0.11418184 | E14: 0.20564844 | F14: 0.0195 | G14: 0.018833963 | H14: 58.63 | I14: 43.5 | J14: 40.79 | K14: 1306.982 | L14: 1038.203 | M14: 215.583 | N14: 223.207 | O14: 1838.653 | P14: 630.657 | Q14: 591.367 | R14: 1877.942 | S14: 440627.44 | T14: 1030.139 | U14: 1.9308707 | V14: 533.51 | W14: 0.22980134 | X14: 730.946

Sheet WACC
A1: WACC Build
A2: Scenario discount rates use the effective WACC plus visible scenario spreads.
A4: Line | B4: Formula / Source | C4: Value | D4: Notes
A5: Backend WACC | B5: 'Assumptions'!$E$31 | C5: ='Assumptions'!$E$31 | D5: Default discount rate from backend
A6: Cost of Equity | B6: 'Assumptions'!$E$32 | C6: ='Assumptions'!$E$32 | D6: Source value when risk-free / ERP are unavailable
A7: Risk-free Rate | B7: 'Assumptions'!$E$34 | C7: ='Assumptions'!$E$34 | D7: Blank if not supplied
A8: Equity Risk Premium | B8: 'Assumptions'!$E$35 | C8: ='Assumptions'!$E$35 | D8: Blank if not supplied
A9: Relevered Beta | B9: 'Assumptions'!$E$36 | C9: ='Assumptions'!$E$36 | D9: Peer / capital-structure beta
A10: Size Premium | B10: 'Assumptions'!$E$37 | C10: ='Assumptions'!$E$37 | D10: Source value
A11: Equity Weight | B11: 'Assumptions'!$E$38 | C11: ='Assumptions'!$E$38 | D11: Market value capital weight
A12: Debt Weight | B12: 'Assumptions'!$E$39 | C12: ='Assumptions'!$E$39 | D12: Market value capital weight
A13: Cost of Debt | B13: 'Assumptions'!$E$33 | C13: ='Assumptions'!$E$33 | D13: Blank if not supplied
A14: Rebuilt Cost of Equity | B14: =IF(OR(ISBLANK('Assumptions'!$E$34),ISBLANK('Assumptions'!$E$35)),'Assumptions'!$E$32,'Assumptions'!$E$34+'Assumptions'!$E$36*'Assumptions'!$E$35+'Assumptions'!$E$37) | C14: =IF(OR(ISBLANK('Assumptions'!$E$34),ISBLANK('Assumptions'!$E$35)),'Assumptions'!$E$32,'Assumptions'!$E$34+'Assumptions'!$E$36*'Assumptions'!$E$35+'Assumptions'!$E$37) | D14: Falls back to backend cost of equity
A15: Base Case WACC | B15: 'Assumptions'!$E$31 | C15: ='Assumptions'!$E$31 | D15: Used in DCF_Base
A16: Bear Case WACC | B16: ='Assumptions'!$E$31+'Assumptions'!$E$46 | C16: ='Assumptions'!$E$31+'Assumptions'!$E$46 | D16: Used in DCF_Bear
A17: Bull Case WACC | B17: ='Assumptions'!$E$31+'Assumptions'!$E$51 | C17: ='Assumptions'!$E$31+'Assumptions'!$E$51 | D17: Used in DCF_Bull

Sheet DCF_Base
A1: Base Case DCF
A2: Operating forecast, FCFF bridge, terminal value, and equity value per share
A4: Scenario Controls
A5: WACC | B5: ='Assumptions'!$E$31
A6: Terminal Growth | B6: ='Assumptions'!$E$18
A7: Exit Multiple | B7: ='Assumptions'!$E$40
A8: Terminal Gordon Weight | B8: ='Assumptions'!$E$42
A9: Current Price | B9: ='Assumptions'!$E$5
A12: Forecast
C13: Y1E | D13: Y2E | E13: Y3E | F13: Y4E | G13: Y5E | H13: Y6E | I13: Y7E | J13: Y8E | K13: Y9E | L13: Y10E
A14: Revenue | B14: $mm | C14: ='Input_Forecast'!$B$5 | D14: ='Input_Forecast'!$B$6 | E14: ='Input_Forecast'!$B$7 | F14: ='Input_Forecast'!$B$8 | G14: ='Input_Forecast'!$B$9 | H14: ='Input_Forecast'!$B$10 | I14: ='Input_Forecast'!$B$11 | J14: ='Input_Forecast'!$B$12 | K14: ='Input_Forecast'!$B$13 | L14: ='Input_Forecast'!$B$14
A15: Revenue Growth | B15: % | C15: ='Input_Forecast'!$C$5 | D15: ='Input_Forecast'!$C$6 | E15: ='Input_Forecast'!$C$7 | F15: ='Input_Forecast'!$C$8 | G15: ='Input_Forecast'!$C$9 | H15: ='Input_Forecast'!$C$10 | I15: ='Input_Forecast'!$C$11 | J15: ='Input_Forecast'!$C$12 | K15: ='Input_Forecast'!$C$13 | L15: ='Input_Forecast'!$C$14
A16: EBIT Margin | B16: % | C16: ='Input_Forecast'!$D$5 | D16: ='Input_Forecast'!$D$6 | E16: ='Input_Forecast'!$D$7 | F16: ='Input_Forecast'!$D$8 | G16: ='Input_Forecast'!$D$9 | H16: ='Input_Forecast'!$D$10 | I16: ='Input_Forecast'!$D$11 | J16: ='Input_Forecast'!$D$12 | K16: ='Input_Forecast'!$D$13 | L16: ='Input_Forecast'!$D$14
A17: EBIT | B17: $mm | C17: =C14*C16 | D17: =D14*D16 | E17: =E14*E16 | F17: =F14*F16 | G17: =G14*G16 | H17: =H14*H16 | I17: =I14*I16 | J17: =J14*J16 | ... L17: =L14*L16
A18: Tax Rate | B18: % | C18: ='Input_Forecast'!$E$5 | D18: ='Input_Forecast'!$E$6 | E18: ='Input_Forecast'!$E$7 | F18: ='Input_Forecast'!$E$8 | G18: ='Input_Forecast'!$E$9 | H18: ='Input_Forecast'!$E$10 | I18: ='Input_Forecast'!$E$11 | J18: ='Input_Forecast'!$E$12 | K18: ='Input_Forecast'!$E$13 | L18: ='Input_Forecast'!$E$14
A19: NOPAT | B19: $mm | C19: =C17*(1-C18) | D19: =D17*(1-D18) | E19: =E17*(1-E18) | F19: =F17*(1-F18) | G19: =G17*(1-G18) | H19: =H17*(1-H18) | I19: =I17*(1-I18) | J19: =J17*(1-J18) | ... L19: =L17*(1-L18)
A20: D&A % Revenue | B20: % | C20: ='Input_Forecast'!$G$5 | D20: ='Input_Forecast'!$G$6 | E20: ='Input_Forecast'!$G$7 | F20: ='Input_Forecast'!$G$8 | G20: ='Input_Forecast'!$G$9 | H20: ='Input_Forecast'!$G$10 | I20: ='Input_Forecast'!$G$11 | J20: ='Input_Forecast'!$G$12 | K20: ='Input_Forecast'!$G$13 | L20: ='Input_Forecast'!$G$14
A21: D&A | B21: $mm | C21: =C14*C20 | D21: =D14*D20 | E21: =E14*E20 | F21: =F14*F20 | G21: =G14*G20 | H21: =H14*H20 | I21: =I14*I20 | J21: =J14*J20 | ... L21: =L14*L20
A22: Capex % Revenue | B22: % | C22: ='Input_Forecast'!$F$5 | D22: ='Input_Forecast'!$F$6 | E22: ='Input_Forecast'!$F$7 | F22: ='Input_Forecast'!$F$8 | G22: ='Input_Forecast'!$F$9 | H22: ='Input_Forecast'!$F$10 | I22: ='Input_Forecast'!$F$11 | J22: ='Input_Forecast'!$F$12 | K22: ='Input_Forecast'!$F$13 | L22: ='Input_Forecast'!$F$14
A23: Capex | B23: $mm | C23: =C14*C22 | D23: =D14*D22 | E23: =E14*E22 | F23: =F14*F22 | G23: =G14*G22 | H23: =H14*H22 | I23: =I14*I22 | J23: =J14*J22 | ... L23: =L14*L22
A24: DSO | B24: days | C24: ='Input_Forecast'!$H$5 | D24: ='Input_Forecast'!$H$6 | E24: ='Input_Forecast'!$H$7 | F24: ='Input_Forecast'!$H$8 | G24: ='Input_Forecast'!$H$9 | H24: ='Input_Forecast'!$H$10 | I24: ='Input_Forecast'!$H$11 | J24: ='Input_Forecast'!$H$12 | K24: ='Input_Forecast'!$H$13 | L24: ='Input_Forecast'!$H$14
A25: DIO | B25: days | C25: ='Input_Forecast'!$I$5 | D25: ='Input_Forecast'!$I$6 | E25: ='Input_Forecast'!$I$7 | F25: ='Input_Forecast'!$I$8 | G25: ='Input_Forecast'!$I$9 | H25: ='Input_Forecast'!$I$10 | I25: ='Input_Forecast'!$I$11 | J25: ='Input_Forecast'!$I$12 | K25: ='Input_Forecast'!$I$13 | L25: ='Input_Forecast'!$I$14
A26: DPO | B26: days | C26: ='Input_Forecast'!$J$5 | D26: ='Input_Forecast'!$J$6 | E26: ='Input_Forecast'!$J$7 | F26: ='Input_Forecast'!$J$8 | G26: ='Input_Forecast'!$J$9 | H26: ='Input_Forecast'!$J$10 | I26: ='Input_Forecast'!$J$11 | J26: ='Input_Forecast'!$J$12 | K26: ='Input_Forecast'!$J$13 | L26: ='Input_Forecast'!$J$14
A27: Accounts Receivable | B27: $mm | C27: =C14*C24/365 | D27: =D14*D24/365 | E27: =E14*E24/365 | F27: =F14*F24/365 | G27: =G14*G24/365 | H27: =H14*H24/365 | I27: =I14*I24/365 | J27: =J14*J24/365 | ... L27: =L14*L24/365
A28: Inventory | B28: $mm | C28: =C14*C25/365 | D28: =D14*D25/365 | E28: =E14*E25/365 | F28: =F14*F25/365 | G28: =G14*G25/365 | H28: =H14*H25/365 | I28: =I14*I25/365 | J28: =J14*J25/365 | ... L28: =L14*L25/365
A29: Accounts Payable | B29: $mm | C29: =C14*C26/365 | D29: =D14*D26/365 | E29: =E14*E26/365 | F29: =F14*F26/365 | G29: =G14*G26/365 | H29: =H14*H26/365 | I29: =I14*I26/365 | J29: =J14*J26/365 | ... L29: =L14*L26/365
A30: Net Working Capital | B30: $mm | C30: =C27+C28-C29 | D30: =D27+D28-D29 | E30: =E27+E28-E29 | F30: =F27+F28-F29 | G30: =G27+G28-G29 | H30: =H27+H28-H29 | I30: =I27+I28-I29 | J30: =J27+J28-J29 | ... L30: =L27+L28-L29
A31: Delta NWC | B31: $mm | C31: ='Input_Forecast'!$S$5 | D31: ='Input_Forecast'!$S$6 | E31: ='Input_Forecast'!$S$7 | F31: ='Input_Forecast'!$S$8 | G31: ='Input_Forecast'!$S$9 | H31: ='Input_Forecast'!$S$10 | I31: ='Input_Forecast'!$S$11 | J31: ='Input_Forecast'!$S$12 | K31: ='Input_Forecast'!$S$13 | L31: ='Input_Forecast'!$S$14
A32: Free Cash Flow to Firm | B32: $mm | C32: =C19+C21-C23-C31 | D32: =D19+D21-D23-D31 | E32: =E19+E21-E23-E31 | F32: =F19+F21-F23-F31 | G32: =G19+G21-G23-G31 | H32: =H19+H21-H23-H31 | I32: =I19+I21-I23-I31 | J32: =J19+J21-J23-J31 | ... L32: =L19+L21-L23-L31
A33: Discount Factor | B33: x | C33: =IF('Assumptions'!$E$56,POWER(1+$B$5,1-0.5),POWER(1+$B$5,1)) | D33: =IF('Assumptions'!$E$56,POWER(1+$B$5,2-0.5),POWER(1+$B$5,2)) | E33: =IF('Assumptions'!$E$56,POWER(1+$B$5,3-0.5),POWER(1+$B$5,3)) | F33: =IF('Assumptions'!$E$56,POWER(1+$B$5,4-0.5),POWER(1+$B$5,4)) | G33: =IF('Assumptions'!$E$56,POWER(1+$B$5,5-0.5),POWER(1+$B$5,5)) | H33: =IF('Assumptions'!$E$56,POWER(1+$B$5,6-0.5),POWER(1+$B$5,6)) | I33: =IF('Assumptions'!$E$56,POWER(1+$B$5,7-0.5),POWER(1+$B$5,7)) | J33: =IF('Assumptions'!$E$56,POWER(1+$B$5,8-0.5),POWER(1+$B$5,8)) | K33: =IF('Assumptions'!$E$56,POWER(1+$B$5,9-0.5),POWER(1+$B$5,9)) | L33: =IF('Assumptions'!$E$56,POWER(1+$B$5,10-0.5),POWER(1+$B$5,10))
A34: PV FCFF | B34: $mm | C34: =C32/C33 | D34: =D32/D33 | E34: =E32/E33 | F34: =F32/F33 | G34: =G32/G33 | H34: =H32/H33 | I34: =I32/I33 | J34: =J32/J33 | ... L34: =L32/L33
A35: EBITDA | B35: $mm | C35: =C17+C21 | D35: =D17+D21 | E35: =E17+E21 | F35: =F17+F21 | G35: =G17+G21 | H35: =H17+H21 | I35: =I17+I21 | J35: =J17+J21 | ... L35: =L17+L21
A38: Valuation
A39: Terminal FCFF | B39: =L32*(1+$B$6) | C39: $mm
A40: Gordon Terminal Value | B40: =IF($B$5<=$B$6,NA(),B39/($B$5-$B$6)) | C40: $mm
A41: Exit Terminal Value | B41: =IF('Assumptions'!$E$41="ev_ebit",L17,L35)*$B$7 | C41: $mm
A42: Blended Terminal Value | B42: =$B$8*B40+(1-$B$8)*B41 | C42: $mm
A43: PV Terminal Value | B43: =B42/POWER(1+$B$5,10) | C43: $mm
A44: PV Explicit FCFF | B44: =SUM(C34:L34) | C44: $mm
A45: Enterprise Value - Operations | B45: =B43+B44 | C45: $mm
...

Sheet DCF_Bear
A1: Bear Case DCF
A2: Operating forecast, FCFF bridge, terminal value, and equity value per share
A4: Scenario Controls
A5: WACC | B5: ='Assumptions'!$E$31+'Assumptions'!$E$46
A6: Terminal Growth | B6: ='Assumptions'!$E$18
A7: Exit Multiple | B7: ='Assumptions'!$E$40*'Assumptions'!$E$47
A8: Terminal Gordon Weight | B8: ='Assumptions'!$E$42
A9: Current Price | B9: ='Assumptions'!$E$5
A12: Forecast
C13: Y1E | D13: Y2E | E13: Y3E | F13: Y4E | G13: Y5E | H13: Y6E | I13: Y7E | J13: Y8E | K13: Y9E | L13: Y10E
A14: Revenue | B14: $mm | C14: ='Assumptions'!$E$15*(1+C15) | D14: =C14*(1+D15) | E14: =D14*(1+E15) | F14: =E14*(1+F15) | G14: =F14*(1+G15) | H14: =G14*(1+H15) | I14: =H14*(1+I15) | J14: =I14*(1+J15) | K14: =J14*(1+K15) | L14: =K14*(1+L15)
A15: Revenue Growth | B15: % | C15: ='Input_Forecast'!$C$5*'Assumptions'!$E$43 | D15: ='Input_Forecast'!$C$6*'Assumptions'!$E$43 | E15: ='Input_Forecast'!$C$7*'Assumptions'!$E$43 | F15: ='Input_Forecast'!$C$8*'Assumptions'!$E$43 | G15: ='Input_Forecast'!$C$9*'Assumptions'!$E$43 | H15: ='Input_Forecast'!$C$10*'Assumptions'!$E$43 | I15: ='Input_Forecast'!$C$11*'Assumptions'!$E$43 | J15: ='Input_Forecast'!$C$12*'Assumptions'!$E$43 | K15: ='Input_Forecast'!$C$13*'Assumptions'!$E$43 | L15: ='Input_Forecast'!$C$14*'Assumptions'!$E$43
A16: EBIT Margin | B16: % | C16: ='Input_Forecast'!$D$5*'Assumptions'!$E$44 | D16: ='Input_Forecast'!$D$6*'Assumptions'!$E$44 | E16: ='Input_Forecast'!$D$7*'Assumptions'!$E$44 | F16: ='Input_Forecast'!$D$8*'Assumptions'!$E$44 | G16: ='Input_Forecast'!$D$9*'Assumptions'!$E$44 | H16: ='Input_Forecast'!$D$10*'Assumptions'!$E$44 | I16: ='Input_Forecast'!$D$11*'Assumptions'!$E$44 | J16: ='Input_Forecast'!$D$12*'Assumptions'!$E$44 | K16: ='Input_Forecast'!$D$13*'Assumptions'!$E$44 | L16: ='Input_Forecast'!$D$14*'Assumptions'!$E$44
A17: EBIT | B17: $mm | C17: =C14*C16 | D17: =D14*D16 | E17: =E14*E16 | F17: =F14*F16 | G17: =G14*G16 | H17: =H14*H16 | I17: =I14*I16 | J17: =J14*J16 | ... L17: =L14*L16
A18: Tax Rate | B18: % | C18: ='Input_Forecast'!$E$5 | D18: ='Input_Forecast'!$E$6 | E18: ='Input_Forecast'!$E$7 | F18: ='Input_Forecast'!$E$8 | G18: ='Input_Forecast'!$E$9 | H18: ='Input_Forecast'!$E$10 | I18: ='Input_Forecast'!$E$11 | J18: ='Input_Forecast'!$E$12 | K18: ='Input_Forecast'!$E$13 | L18: ='Input_Forecast'!$E$14
A19: NOPAT | B19: $mm | C19: =C17*(1-C18) | D19: =D17*(1-D18) | E19: =E17*(1-E18) | F19: =F17*(1-F18) | G19: =G17*(1-G18) | H19: =H17*(1-H18) | I19: =I17*(1-I18) | J19: =J17*(1-J18) | ... L19: =L17*(1-L18)
A20: D&A % Revenue | B20: % | C20: ='Input_Forecast'!$G$5 | D20: ='Input_Forecast'!$G$6 | E20: ='Input_Forecast'!$G$7 | F20: ='Input_Forecast'!$G$8 | G20: ='Input_Forecast'!$G$9 | H20: ='Input_Forecast'!$G$10 | I20: ='Input_Forecast'!$G$11 | J20: ='Input_Forecast'!$G$12 | K20: ='Input_Forecast'!$G$13 | L20: ='Input_Forecast'!$G$14
A21: D&A | B21: $mm | C21: =C14*C20 | D21: =D14*D20 | E21: =E14*E20 | F21: =F14*F20 | G21: =G14*G20 | H21: =H14*H20 | I21: =I14*I20 | J21: =J14*J20 | ... L21: =L14*L20
A22: Capex % Revenue | B22: % | C22: ='Input_Forecast'!$F$5*'Assumptions'!$E$45 | D22: ='Input_Forecast'!$F$6*'Assumptions'!$E$45 | E22: ='Input_Forecast'!$F$7*'Assumptions'!$E$45 | F22: ='Input_Forecast'!$F$8*'Assumptions'!$E$45 | G22: ='Input_Forecast'!$F$9*'Assumptions'!$E$45 | H22: ='Input_Forecast'!$F$10*'Assumptions'!$E$45 | I22: ='Input_Forecast'!$F$11*'Assumptions'!$E$45 | J22: ='Input_Forecast'!$F$12*'Assumptions'!$E$45 | K22: ='Input_Forecast'!$F$13*'Assumptions'!$E$45 | L22: ='Input_Forecast'!$F$14*'Assumptions'!$E$45
A23: Capex | B23: $mm | C23: =C14*C22 | D23: =D14*D22 | E23: =E14*E22 | F23: =F14*F22 | G23: =G14*G22 | H23: =H14*H22 | I23: =I14*I22 | J23: =J14*J22 | ... L23: =L14*L22
A24: DSO | B24: days | C24: ='Input_Forecast'!$H$5 | D24: ='Input_Forecast'!$H$6 | E24: ='Input_Forecast'!$H$7 | F24: ='Input_Forecast'!$H$8 | G24: ='Input_Forecast'!$H$9 | H24: ='Input_Forecast'!$H$10 | I24: ='Input_Forecast'!$H$11 | J24: ='Input_Forecast'!$H$12 | K24: ='Input_Forecast'!$H$13 | L24: ='Input_Forecast'!$H$14
A25: DIO | B25: days | C25: ='Input_Forecast'!$I$5 | D25: ='Input_Forecast'!$I$6 | E25: ='Input_Forecast'!$I$7 | F25: ='Input_Forecast'!$I$8 | G25: ='Input_Forecast'!$I$9 | H25: ='Input_Forecast'!$I$10 | I25: ='Input_Forecast'!$I$11 | J25: ='Input_Forecast'!$I$12 | K25: ='Input_Forecast'!$I$13 | L25: ='Input_Forecast'!$I$14
A26: DPO | B26: days | C26: ='Input_Forecast'!$J$5 | D26: ='Input_Forecast'!$J$6 | E26: ='Input_Forecast'!$J$7 | F26: ='Input_Forecast'!$J$8 | G26: ='Input_Forecast'!$J$9 | H26: ='Input_Forecast'!$J$10 | I26: ='Input_Forecast'!$J$11 | J26: ='Input_Forecast'!$J$12 | K26: ='Input_Forecast'!$J$13 | L26: ='Input_Forecast'!$J$14
A27: Accounts Receivable | B27: $mm | C27: =C14*C24/365 | D27: =D14*D24/365 | E27: =E14*E24/365 | F27: =F14*F24/365 | G27: =G14*G24/365 | H27: =H14*H24/365 | I27: =I14*I24/365 | J27: =J14*J24/365 | ... L27: =L14*L24/365
A28: Inventory | B28: $mm | C28: =C14*C25/365 | D28: =D14*D25/365 | E28: =E14*E25/365 | F28: =F14*F25/365 | G28: =G14*G25/365 | H28: =H14*H25/365 | I28: =I14*I25/365 | J28: =J14*J25/365 | ... L28: =L14*L25/365
A29: Accounts Payable | B29: $mm | C29: =C14*C26/365 | D29: =D14*D26/365 | E29: =E14*E26/365 | F29: =F14*F26/365 | G29: =G14*G26/365 | H29: =H14*H26/365 | I29: =I14*I26/365 | J29: =J14*J26/365 | ... L29: =L14*L26/365
A30: Net Working Capital | B30: $mm | C30: =C27+C28-C29 | D30: =D27+D28-D29 | E30: =E27+E28-E29 | F30: =F27+F28-F29 | G30: =G27+G28-G29 | H30: =H27+H28-H29 | I30: =I27+I28-I29 | J30: =J27+J28-J29 | ... L30: =L27+L28-L29
A31: Delta NWC | B31: $mm | C31: =C30-('Assumptions'!$E$15*'Assumptions'!$E$25/365+'Assumptions'!$E$15*'Assumptions'!$E$27/365-'Assumptions'!$E$15*'Assumptions'!$E$29/365) | D31: =D30-C30 | E31: =E30-D30 | F31: =F30-E30 | G31: =G30-F30 | H31: =H30-G30 | I31: =I30-H30 | J31: =J30-I30 | K31: =K30-J30 | L31: =L30-K30
A32: Free Cash Flow to Firm | B32: $mm | C32: =C19+C21-C23-C31 | D32: =D19+D21-D23-D31 | E32: =E19+E21-E23-E31 | F32: =F19+F21-F23-F31 | G32: =G19+G21-G23-G31 | H32: =H19+H21-H23-H31 | I32: =I19+I21-I23-I31 | J32: =J19+J21-J23-J31 | ... L32: =L19+L21-L23-L31
A33: Discount Factor | B33: x | C33: =IF('Assumptions'!$E$56,POWER(1+$B$5,1-0.5),POWER(1+$B$5,1)) | D33: =IF('Assumptions'!$E$56,POWER(1+$B$5,2-0.5),POWER(1+$B$5,2)) | E33: =IF('Assumptions'!$E$56,POWER(1+$B$5,3-0.5),POWER(1+$B$5,3)) | F33: =IF('Assumptions'!$E$56,POWER(1+$B$5,4-0.5),POWER(1+$B$5,4)) | G33: =IF('Assumptions'!$E$56,POWER(1+$B$5,5-0.5),POWER(1+$B$5,5)) | H33: =IF('Assumptions'!$E$56,POWER(1+$B$5,6-0.5),POWER(1+$B$5,6)) | I33: =IF('Assumptions'!$E$56,POWER(1+$B$5,7-0.5),POWER(1+$B$5,7)) | J33: =IF('Assumptions'!$E$56,POWER(1+$B$5,8-0.5),POWER(1+$B$5,8)) | K33: =IF('Assumptions'!$E$56,POWER(1+$B$5,9-0.5),POWER(1+$B$5,9)) | L33: =IF('Assumptions'!$E$56,POWER(1+$B$5,10-0.5),POWER(1+$B$5,10))
A34: PV FCFF | B34: $mm | C34: =C32/C33 | D34: =D32/D33 | E34: =E32/E33 | F34: =F32/F33 | G34: =G32/G33 | H34: =H32/H33 | I34: =I32/I33 | J34: =J32/J33 | ... L34: =L32/L33
A35: EBITDA | B35: $mm | C35: =C17+C21 | D35: =D17+D21 | E35: =E17+E21 | F35: =F17+F21 | G35: =G17+G21 | H35: =H17+H21 | I35: =I17+I21 | J35: =J17+J21 | ... L35: =L17+L21
A38: Valuation
A39: Terminal FCFF | B39: =L32*(1+$B$6) | C39: $mm
A40: Gordon Terminal Value | B40: =IF($B$5<=$B$6,NA(),B39/($B$5-$B$6)) | C40: $mm
A41: Exit Terminal Value | B41: =IF('Assumptions'!$E$41="ev_ebit",L17,L35)*$B$7 | C41: $mm
A42: Blended Terminal Value | B42: =$B$8*B40+(1-$B$8)*B41 | C42: $mm
A43: PV Terminal Value | B43: =B42/POWER(1+$B$5,10) | C43: $mm
A44: PV Explicit FCFF | B44: =SUM(C34:L34) | C44: $mm
A45: Enterprise Value - Operations | B45: =B43+B44 | C45: $mm
...

Sheet DCF_Bull
A1: Bull Case DCF
A2: Operating forecast, FCFF bridge, terminal value, and equity value per share
A4: Scenario Controls
A5: WACC | B5: ='Assumptions'!$E$31+'Assumptions'!$E$51
A6: Terminal Growth | B6: ='Assumptions'!$E$18
A7: Exit Multiple | B7: ='Assumptions'!$E$40*'Assumptions'!$E$52
A8: Terminal Gordon Weight | B8: ='Assumptions'!$E$42
A9: Current Price | B9: ='Assumptions'!$E$5
A12: Forecast
C13: Y1E | D13: Y2E | E13: Y3E | F13: Y4E | G13: Y5E | H13: Y6E | I13: Y7E | J13: Y8E | K13: Y9E | L13: Y10E
A14: Revenue | B14: $mm | C14: ='Assumptions'!$E$15*(1+C15) | D14: =C14*(1+D15) | E14: =D14*(1+E15) | F14: =E14*(1+F15) | G14: =F14*(1+G15) | H14: =G14*(1+H15) | I14: =H14*(1+I15) | J14: =I14*(1+J15) | K14: =J14*(1+K15) | L14: =K14*(1+L15)
A15: Revenue Growth | B15: % | C15: ='Input_Forecast'!$C$5*'Assumptions'!$E$48 | D15: ='Input_Forecast'!$C$6*'Assumptions'!$E$48 | E15: ='Input_Forecast'!$C$7*'Assumptions'!$E$48 | F15: ='Input_Forecast'!$C$8*'Assumptions'!$E$48 | G15: ='Input_Forecast'!$C$9*'Assumptions'!$E$48 | H15: ='Input_Forecast'!$C$10*'Assumptions'!$E$48 | I15: ='Input_Forecast'!$C$11*'Assumptions'!$E$48 | J15: ='Input_Forecast'!$C$12*'Assumptions'!$E$48 | K15: ='Input_Forecast'!$C$13*'Assumptions'!$E$48 | L15: ='Input_Forecast'!$C$14*'Assumptions'!$E$48
A16: EBIT Margin | B16: % | C16: ='Input_Forecast'!$D$5*'Assumptions'!$E$49 | D16: ='Input_Forecast'!$D$6*'Assumptions'!$E$49 | E16: ='Input_Forecast'!$D$7*'Assumptions'!$E$49 | F16: ='Input_Forecast'!$D$8*'Assumptions'!$E$49 | G16: ='Input_Forecast'!$D$9*'Assumptions'!$E$49 | H16: ='Input_Forecast'!$D$10*'Assumptions'!$E$49 | I16: ='Input_Forecast'!$D$11*'Assumptions'!$E$49 | J16: ='Input_Forecast'!$D$12*'Assumptions'!$E$49 | K16: ='Input_Forecast'!$D$13*'Assumptions'!$E$49 | L16: ='Input_Forecast'!$D$14*'Assumptions'!$E$49
A17: EBIT | B17: $mm | C17: =C14*C16 | D17: =D14*D16 | E17: =E14*E16 | F17: =F14*F16 | G17: =G14*G16 | H17: =H14*H16 | I17: =I14*I16 | J17: =J14*J16 | ... L17: =L14*L16
A18: Tax Rate | B18: % | C18: ='Input_Forecast'!$E$5 | D18: ='Input_Forecast'!$E$6 | E18: ='Input_Forecast'!$E$7 | F18: ='Input_Forecast'!$E$8 | G18: ='Input_Forecast'!$E$9 | H18: ='Input_Forecast'!$E$10 | I18: ='Input_Forecast'!$E$11 | J18: ='Input_Forecast'!$E$12 | K18: ='Input_Forecast'!$E$13 | L18: ='Input_Forecast'!$E$14
A19: NOPAT | B19: $mm | C19: =C17*(1-C18) | D19: =D17*(1-D18) | E19: =E17*(1-E18) | F19: =F17*(1-F18) | G19: =G17*(1-G18) | H19: =H17*(1-H18) | I19: =I17*(1-I18) | J19: =J17*(1-J18) | ... L19: =L17*(1-L18)
A20: D&A % Revenue | B20: % | C20: ='Input_Forecast'!$G$5 | D20: ='Input_Forecast'!$G$6 | E20: ='Input_Forecast'!$G$7 | F20: ='Input_Forecast'!$G$8 | G20: ='Input_Forecast'!$G$9 | H20: ='Input_Forecast'!$G$10 | I20: ='Input_Forecast'!$G$11 | J20: ='Input_Forecast'!$G$12 | K20: ='Input_Forecast'!$G$13 | L20: ='Input_Forecast'!$G$14
A21: D&A | B21: $mm | C21: =C14*C20 | D21: =D14*D20 | E21: =E14*E20 | F21: =F14*F20 | G21: =G14*G20 | H21: =H14*H20 | I21: =I14*I20 | J21: =J14*J20 | ... L21: =L14*L20
A22: Capex % Revenue | B22: % | C22: ='Input_Forecast'!$F$5*'Assumptions'!$E$50 | D22: ='Input_Forecast'!$F$6*'Assumptions'!$E$50 | E22: ='Input_Forecast'!$F$7*'Assumptions'!$E$50 | F22: ='Input_Forecast'!$F$8*'Assumptions'!$E$50 | G22: ='Input_Forecast'!$F$9*'Assumptions'!$E$50 | H22: ='Input_Forecast'!$F$10*'Assumptions'!$E$50 | I22: ='Input_Forecast'!$F$11*'Assumptions'!$E$50 | J22: ='Input_Forecast'!$F$12*'Assumptions'!$E$50 | K22: ='Input_Forecast'!$F$13*'Assumptions'!$E$50 | L22: ='Input_Forecast'!$F$14*'Assumptions'!$E$50
A23: Capex | B23: $mm | C23: =C14*C22 | D23: =D14*D22 | E23: =E14*E22 | F23: =F14*F22 | G23: =G14*G22 | H23: =H14*H22 | I23: =I14*I22 | J23: =J14*J22 | ... L23: =L14*L22
A24: DSO | B24: days | C24: ='Input_Forecast'!$H$5 | D24: ='Input_Forecast'!$H$6 | E24: ='Input_Forecast'!$H$7 | F24: ='Input_Forecast'!$H$8 | G24: ='Input_Forecast'!$H$9 | H24: ='Input_Forecast'!$H$10 | I24: ='Input_Forecast'!$H$11 | J24: ='Input_Forecast'!$H$12 | K24: ='Input_Forecast'!$H$13 | L24: ='Input_Forecast'!$H$14
A25: DIO | B25: days | C25: ='Input_Forecast'!$I$5 | D25: ='Input_Forecast'!$I$6 | E25: ='Input_Forecast'!$I$7 | F25: ='Input_Forecast'!$I$8 | G25: ='Input_Forecast'!$I$9 | H25: ='Input_Forecast'!$I$10 | I25: ='Input_Forecast'!$I$11 | J25: ='Input_Forecast'!$I$12 | K25: ='Input_Forecast'!$I$13 | L25: ='Input_Forecast'!$I$14
A26: DPO | B26: days | C26: ='Input_Forecast'!$J$5 | D26: ='Input_Forecast'!$J$6 | E26: ='Input_Forecast'!$J$7 | F26: ='Input_Forecast'!$J$8 | G26: ='Input_Forecast'!$J$9 | H26: ='Input_Forecast'!$J$10 | I26: ='Input_Forecast'!$J$11 | J26: ='Input_Forecast'!$J$12 | K26: ='Input_Forecast'!$J$13 | L26: ='Input_Forecast'!$J$14
A27: Accounts Receivable | B27: $mm | C27: =C14*C24/365 | D27: =D14*D24/365 | E27: =E14*E24/365 | F27: =F14*F24/365 | G27: =G14*G24/365 | H27: =H14*H24/365 | I27: =I14*I24/365 | J27: =J14*J24/365 | ... L27: =L14*L24/365
A28: Inventory | B28: $mm | C28: =C14*C25/365 | D28: =D14*D25/365 | E28: =E14*E25/365 | F28: =F14*F25/365 | G28: =G14*G25/365 | H28: =H14*H25/365 | I28: =I14*I25/365 | J28: =J14*J25/365 | ... L28: =L14*L25/365
A29: Accounts Payable | B29: $mm | C29: =C14*C26/365 | D29: =D14*D26/365 | E29: =E14*E26/365 | F29: =F14*F26/365 | G29: =G14*G26/365 | H29: =H14*H26/365 | I29: =I14*I26/365 | J29: =J14*J26/365 | ... L29: =L14*L26/365
A30: Net Working Capital | B30: $mm | C30: =C27+C28-C29 | D30: =D27+D28-D29 | E30: =E27+E28-E29 | F30: =F27+F28-F29 | G30: =G27+G28-G29 | H30: =H27+H28-H29 | I30: =I27+I28-I29 | J30: =J27+J28-J29 | ... L30: =L27+L28-L29
A31: Delta NWC | B31: $mm | C31: =C30-('Assumptions'!$E$15*'Assumptions'!$E$25/365+'Assumptions'!$E$15*'Assumptions'!$E$27/365-'Assumptions'!$E$15*'Assumptions'!$E$29/365) | D31: =D30-C30 | E31: =E30-D30 | F31: =F30-E30 | G31: =G30-F30 | H31: =H30-G30 | I31: =I30-H30 | J31: =J30-I30 | K31: =K30-J30 | L31: =L30-K30
A32: Free Cash Flow to Firm | B32: $mm | C32: =C19+C21-C23-C31 | D32: =D19+D21-D23-D31 | E32: =E19+E21-E23-E31 | F32: =F19+F21-F23-F31 | G32: =G19+G21-G23-G31 | H32: =H19+H21-H23-H31 | I32: =I19+I21-I23-I31 | J32: =J19+J21-J23-J31 | ... L32: =L19+L21-L23-L31
A33: Discount Factor | B33: x | C33: =IF('Assumptions'!$E$56,POWER(1+$B$5,1-0.5),POWER(1+$B$5,1)) | D33: =IF('Assumptions'!$E$56,POWER(1+$B$5,2-0.5),POWER(1+$B$5,2)) | E33: =IF('Assumptions'!$E$56,POWER(1+$B$5,3-0.5),POWER(1+$B$5,3)) | F33: =IF('Assumptions'!$E$56,POWER(1+$B$5,4-0.5),POWER(1+$B$5,4)) | G33: =IF('Assumptions'!$E$56,POWER(1+$B$5,5-0.5),POWER(1+$B$5,5)) | H33: =IF('Assumptions'!$E$56,POWER(1+$B$5,6-0.5),POWER(1+$B$5,6)) | I33: =IF('Assumptions'!$E$56,POWER(1+$B$5,7-0.5),POWER(1+$B$5,7)) | J33: =IF('Assumptions'!$E$56,POWER(1+$B$5,8-0.5),POWER(1+$B$5,8)) | K33: =IF('Assumptions'!$E$56,POWER(1+$B$5,9-0.5),POWER(1+$B$5,9)) | L33: =IF('Assumptions'!$E$56,POWER(1+$B$5,10-0.5),POWER(1+$B$5,10))
A34: PV FCFF | B34: $mm | C34: =C32/C33 | D34: =D32/D33 | E34: =E32/E33 | F34: =F32/F33 | G34: =G32/G33 | H34: =H32/H33 | I34: =I32/I33 | J34: =J32/J33 | ... L34: =L32/L33
A35: EBITDA | B35: $mm | C35: =C17+C21 | D35: =D17+D21 | E35: =E17+E21 | F35: =F17+F21 | G35: =G17+G21 | H35: =H17+H21 | I35: =I17+I21 | J35: =J17+J21 | ... L35: =L17+L21
A38: Valuation
A39: Terminal FCFF | B39: =L32*(1+$B$6) | C39: $mm
A40: Gordon Terminal Value | B40: =IF($B$5<=$B$6,NA(),B39/($B$5-$B$6)) | C40: $mm
A41: Exit Terminal Value | B41: =IF('Assumptions'!$E$41="ev_ebit",L17,L35)*$B$7 | C41: $mm
A42: Blended Terminal Value | B42: =$B$8*B40+(1-$B$8)*B41 | C42: $mm
A43: PV Terminal Value | B43: =B42/POWER(1+$B$5,10) | C43: $mm
A44: PV Explicit FCFF | B44: =SUM(C34:L34) | C44: $mm
A45: Enterprise Value - Operations | B45: =B43+B44 | C45: $mm
...

Sheet Equity_Bridge
A1: Equity Bridge
A2: Enterprise value to equity value reconciliation by scenario
A4: Line | B4: Base | C4: Bear | D4: Bull | E4: Notes
A5: Enterprise Value - Operations | B5: ='DCF_Base'!$B$45 | C5: ='DCF_Bear'!$B$45 | D5: ='DCF_Bull'!$B$45 | E5: DCF scenario sheet
A6: Non-operating Assets | B6: ='DCF_Base'!$B$47 | C6: ='DCF_Bear'!$B$47 | D6: ='DCF_Bull'!$B$47 | E6: Added to EV
A7: Non-equity Claims | B7: ='DCF_Base'!$B$48 | C7: ='DCF_Bear'!$B$48 | D7: ='DCF_Bull'!$B$48 | E7: Net debt plus minority, preferred, pension, lease, options, convertibles
A8: Equity Value | B8: ='DCF_Base'!$B$49 | C8: ='DCF_Bear'!$B$49 | D8: ='DCF_Bull'!$B$49 | E8: EV + assets - claims
A9: Diluted Shares | B9: ='DCF_Base'!$B$50 | C9: ='DCF_Bear'!$B$50 | D9: ='DCF_Bull'!$B$50 | E9: Assumptions effective value
A10: Intrinsic Value / Share | B10: ='DCF_Base'!$B$51 | C10: ='DCF_Bear'!$B$51 | D10: ='DCF_Bull'!$B$51 | E10: Equity value / shares
A11: Upside / Downside | B11: ='DCF_Base'!$B$52 | C11: ='DCF_Bear'!$B$52 | D11: ='DCF_Bull'!$B$52 | E11: Relative to current price

Sheet Sensitivity
A1: Sensitivity Tables
A2: Explicit formula tables; change Assumptions to refresh the base mechanics.
A4: WACC vs Terminal Growth: Intrinsic Value / Share
A5: g / WACC | B5: ='Assumptions'!$E$31+-0.02 | C5: ='Assumptions'!$E$31+-0.01 | D5: ='Assumptions'!$E$31+0.0 | E5: ='Assumptions'!$E$31+0.01 | F5: ='Assumptions'!$E$31+0.02
A6: ='Assumptions'!$E$18+-0.01 | B6: =IF(B5<=A6,NA(),(('DCF_Base'!C32/POWER(1+B5,1-0.5)+'DCF_Base'!D32/POWER(1+B5,2-0.5)+'DCF_Base'!E32/POWER(1+B5,3-0.5)+'DCF_Base'!F32/POWER(1+B5,4-0.5)+'DCF_Base'!G32/POWER(1+B5,5-0.5)+'DCF_Base'!H32/POWER(1+B5,6-0.5)+'DCF_Base'!I32/POWER(1+B5,7-0.5)+'DCF_Base'!J32/POWER(1+B5,8-0.5)+'DCF_Base'!K32/POWER(1+B5,9-0.5)+'DCF_Base'!L32/POWER(1+B5,10-0.5))+(('DCF_Base'!L32*(1+A6))/(B5-A6))/POWER(1+B5,10)+'Assumptions'!$E$8-('Assumptions'!$E$7+'Assumptions'!$E$9+'Assumptions'!$E$10+'Assumptions'!$E$11+'Assumptions'!$E$12+'Assumptions'!$E$13+'Assumptions'!$E$14))/'Assumptions'!$E$6) | C6: =IF(C5<=A6,NA(),(('DCF_Base'!C32/POWER(1+C5,1-0.5)+'DCF_Base'!D32/POWER(1+C5,2-0.5)+'DCF_Base'!E32/POWER(1+C5,3-0.5)+'DCF_Base'!F32/POWER(1+C5,4-0.5)+'DCF_Base'!G32/POWER(1+C5,5-0.5)+'DCF_Base'!H32/POWER(1+C5,6-0.5)+'DCF_Base'!I32/POWER(1+C5,7-0.5)+'DCF_Base'!J32/POWER(1+C5,8-0.5)+'DCF_Base'!K32/POWER(1+C5,9-0.5)+'DCF_Base'!L32/POWER(1+C5,10-0.5))+(('DCF_Base'!L32*(1+A6))/(C5-A6))/POWER(1+C5,10)+'Assumptions'!$E$8-('Assumptions'!$E$7+'Assumptions'!$E$9+'Assumptions'!$E$10+'Assumptions'!$E$11+'Assumptions'!$E$12+'Assumptions'!$E$13+'Assumptions'!$E$14))/'Assumptions'!$E$6) | D6: =IF(D5<=A6,NA(),(('DCF_Base'!C32/POWER(1+D5,1-0.5)+'DCF_Base'!D32/POWER(1+D5,2-0.5)+'DCF_Base'!E32/POWER(1+D5,3-0.5)+'DCF_Base'!F32/POWER(1+D5,4-0.5)+'DCF_Base'!G32/POWER(1+D5,5-0.5)+'DCF_Base'!H32/POWER(1+D5,6-0.5)+'DCF_Base'!I32/POWER(1+D5,7-0.5)+'DCF_Base'!J32/POWER(1+D5,8-0.5)+'DCF_Base'!K32/POWER(1+D5,9-0.5)+'DCF_Base'!L32/POWER(1+D5,10-0.5))+(('DCF_Base'!L32*(1+A6))/(D5-A6))/POWER(1+D5,10)+'Assumptions'!$E$8-('Assumptions'!$E$7+'Assumptions'!$E$9+'Assumptions'!$E$10+'Assumptions'!$E$11+'Assumptions'!$E$12+'Assumptions'!$E$13+'Assumptions'!$E$14))/'Assumptions'!$E$6) | E6: =IF(E5<=A6,NA(),(('DCF_Base'!C32/POWER(1+E5,1-0.5)+'DCF_Base'!D32/POWER(1+E5,2-0.5)+'DCF_Base'!E32/POWER(1+E5,3-0.5)+'DCF_Base'!F32/POWER(1+E5,4-0.5)+'DCF_Base'!G32/POWER(1+E5,5-0.5)+'DCF_Base'!H32/POWER(1+E5,6-0.5)+'DCF_Base'!I32/POWER(1+E5,7-0.5)+'DCF_Base'!J32/POWER(1+E5,8-0.5)+'DCF_Base'!K32/POWER(1+E5,9-0.5)+'DCF_Base'!L32/POWER(1+E5,10-0.5))+(('DCF_Base'!L32*(1+A6))/(E5-A6))/POWER(1+E5,10)+'Assumptions'!$E$8-('Assumptions'!$E$7+'Assumptions'!$E$9+'Assumptions'!$E$10+'Assumptions'!$E$11+'Assumptions'!$E$12+'Assumptions'!$E$13+'Assumptions'!$E$14))/'Assumptions'!$E$6) | F6: =IF(F5<=A6,NA(),(('DCF_Base'!C32/POWER(1+F5,1-0.5)+'DCF_Base'!D32/POWER(1+F5,2-0.5)+'DCF_Base'!E32/POWER(1+F5,3-0.5)+'DCF_Base'!F32/POWER(1+F5,4-0.5)+'DCF_Base'!G32/POWER(1+F5,5-0.5)+'DCF_Base'!H32/POWER(1+F5,6-0.5)+'DCF_Base'!I32/POWER(1+F5,7-0.5)+'DCF_Base'!J32/POWER(1+F5,8-0.5)+'DCF_Base'!K32/POWER(1+F5,9-0.5)+'DCF_Base'!L32/POWER(1+F5,10-0.5))+(('DCF_Base'!L32*(1+A6))/(F5-A6))/POWER(1+F5,10)+'Assumptions'!$E$8-('Assumptions'!$E$7+'Assumptions'!$E$9+'Assumptions'!$E$10+'Assumptions'!$E$11+'Assumptions'!$E$12+'Assumptions'!$E$13+'Assumptions'!$E$14))/'Assumptions'!$E$6)
A7: ='Assumptions'!$E$18+-0.005 | B7: =IF(B5<=A7,NA(),(('DCF_Base'!C32/POWER(1+B5,1-0.5)+'DCF_Base'!D32/POWER(1+B5,2-0.5)+'DCF_Base'!E32/POWER(1+B5,3-0.5)+'DCF_Base'!F32/POWER(1+B5,4-0.5)+'DCF_Base'!G32/POWER(1+B5,5-0.5)+'DCF_Base'!H32/POWER(1+B5,6-0.5)+'DCF_Base'!I32/POWER(1+B5,7-0.5)+'DCF_Base'!J32/POWER(1+B5,8-0.5)+'DCF_Base'!K32/POWER(1+B5,9-0.5)+'DCF_Base'!L32/POWER(1+B5,10-0.5))+(('DCF_Base'!L32*(1+A7))/(B5-A7))/POWER(1+B5,10)+'Assumptions'!$E$8-('Assumptions'!$E$7+'Assumptions'!$E$9+'Assumptions'!$E$10+'Assumptions'!$E$11+'Assumptions'!$E$12+'Assumptions'!$E$13+'Assumptions'!$E$14))/'Assumptions'!$E$6) | C7: =IF(C5<=A7,NA(),(('DCF_Base'!C32/POWER(1+C5,1-0.5)+'DCF_Base'!D32/POWER(1+C5,2-0.5)+'DCF_Base'!E32/POWER(1+C5,3-0.5)+'DCF_Base'!F32/POWER(1+C5,4-0.5)+'DCF_Base'!G32/POWER(1+C5,5-0.5)+'DCF_Base'!H32/POWER(1+C5,6-0.5)+'DCF_Base'!I32/POWER(1+C5,7-0.5)+'DCF_Base'!J32/POWER(1+C5,8-0.5)+'DCF_Base'!K32/POWER(1+C5,9-0.5)+'DCF_Base'!L32/POWER(1+C5,10-0.5))+(('DCF_Base'!L32*(1+A7))/(C5-A7))/POWER(1+C5,10)+'Assumptions'!$E$8-('Assumptions'!$E$7+'Assumptions'!$E$9+'Assumptions'!$E$10+'Assumptions'!$E$11+'Assumptions'!$E$12+'Assumptions'!$E$13+'Assumptions'!$E$14))/'Assumptions'!$E$6) | D7: =IF(D5<=A7,NA(),(('DCF_Base'!C32/POWER(1+D5,1-0.5)+'DCF_Base'!D32/POWER(1+D5,2-0.5)+'DCF_Base'!E32/POWER(1+D5,3-0.5)+'DCF_Base'!F32/POWER(1+D5,4-0.5)+'DCF_Base'!G32/POWER(1+D5,5-0.5)+'DCF_Base'!H32/POWER(1+D5,6-0.5)+'DCF_Base'!I32/POWER(1+D5,7-0.5)+'DCF_Base'!J32/POWER(1+D5,8-0.5)+'DCF_Base'!K32/POWER(1+D5,9-0.5)+'DCF_Base'!L32/POWER(1+D5,10-0.5))+(('DCF_Base'!L32*(1+A7))/(D5-A7))/POWER(1+D5,10)+'Assumptions'!$E$8-('Assumptions'!$E$7+'Assumptions'!$E$9+'Assumptions'!$E$10+'Assumptions'!$E$11+'Assumptions'!$E$12+'Assumptions'!$E$13+'Assumptions'!$E$14))/'Assumptions'!$E$6) | E7: =IF(E5<=A7,NA(),(('DCF_Base'!C32/POWER(1+E5,1-0.5)+'DCF_Base'!D32/POWER(1+E5,2-0.5)+'DCF_Base'!E32/POWER(1+E5,3-0.5)+'DCF_Base'!F32/POWER(1+E5,4-0.5)+'DCF_Base'!G32/POWER(1+E5,5-0.5)+'DCF_Base'!H32/POWER(1+E5,6-0.5)+'DCF_Base'!I32/POWER(1+E5,7-0.5)+'DCF_Base'!J32/POWER(1+E5,8-0.5)+'DCF_Base'!K32/POWER(1+E5,9-0.5)+'DCF_Base'!L32/POWER(1+E5,10-0.5))+(('DCF_Base'!L32*(1+A7))/(E5-A7))/POWER(1+E5,10)+'Assumptions'!$E$8-('Assumptions'!$E$7+'Assumptions'!$E$9+'Assumptions'!$E$10+'Assumptions'!$E$11+'Assumptions'!$E$12+'Assumptions'!$E$13+'Assumptions'!$E$14))/'Assumptions'!$E$6) | F7: =IF(F5<=A7,NA(),(('DCF_Base'!C32/POWER(1+F5,1-0.5)+'DCF_Base'!D32/POWER(1+F5,2-0.5)+'DCF_Base'!E32/POWER(1+F5,3-0.5)+'DCF_Base'!F32/POWER(1+F5,4-0.5)+'DCF_Base'!G32/POWER(1+F5,5-0.5)+'DCF_Base'!H32/POWER(1+F5,6-0.5)+'DCF_Base'!I32/POWER(1+F5,7-0.5)+'DCF_Base'!J32/POWER(1+F5,8-0.5)+'DCF_Base'!K32/POWER(1+F5,9-0.5)+'DCF_Base'!L32/POWER(1+F5,10-0.5))+(('DCF_Base'!L32*(1+A7))/(F5-A7))/POWER(1+F5,10)+'Assumptions'!$E$8-('Assumptions'!$E$7+'Assumptions'!$E$9+'Assumptions'!$E$10+'Assumptions'!$E$11+'Assumptions'!$E$12+'Assumptions'!$E$13+'Assumptions'!$E$14))/'Assumptions'!$E$6)
A8: ='Assumptions'!$E$18+0.0 | B8: =IF(B5<=A8,NA(),(('DCF_Base'!C32/POWER(1+B5,1-0.5)+'DCF_Base'!D32/POWER(1+B5,2-0.5)+'DCF_Base'!E32/POWER(1+B5,3-0.5)+'DCF_Base'!F32/POWER(1+B5,4-0.5)+'DCF_Base'!G32/POWER(1+B5,5-0.5)+'DCF_Base'!H32/POWER(1+B5,6-0.5)+'DCF_Base'!I32/POWER(1+B5,7-0.5)+'DCF_Base'!J32/POWER(1+B5,8-0.5)+'DCF_Base'!K32/POWER(1+B5,9-0.5)+'DCF_Base'!L32/POWER(1+B5,10-0.5))+(('DCF_Base'!L32*(1+A8))/(B5-A8))/POWER(1+B5,10)+'Assumptions'!$E$8-('Assumptions'!$E$7+'Assumptions'!$E$9+'Assumptions'!$E$10+'Assumptions'!$E$11+'Assumptions'!$E$12+'Assumptions'!$E$13+'Assumptions'!$E$14))/'Assumptions'!$E$6) | C8: =IF(C5<=A8,NA(),(('DCF_Base'!C32/POWER(1+C5,1-0.5)+'DCF_Base'!D32/POWER(1+C5,2-0.5)+'DCF_Base'!E32/POWER(1+C5,3-0.5)+'DCF_Base'!F32/POWER(1+C5,4-0.5)+'DCF_Base'!G32/POWER(1+C5,5-0.5)+'DCF_Base'!H32/POWER(1+C5,6-0.5)+'DCF_Base'!I32/POWER(1+C5,7-0.5)+'DCF_Base'!J32/POWER(1+C5,8-0.5)+'DCF_Base'!K32/POWER(1+C5,9-0.5)+'DCF_Base'!L32/POWER(1+C5,10-0.5))+(('DCF_Base'!L32*(1+A8))/(C5-A8))/POWER(1+C5,10)+'Assumptions'!$E$8-('Assumptions'!$E$7+'Assumptions'!$E$9+'Assumptions'!$E$10+'Assumptions'!$E$11+'Assumptions'!$E$12+'Assumptions'!$E$13+'Assumptions'!$E$14))/'Assumptions'!$E$6) | D8: =IF(D5<=A8,NA(),(('DCF_Base'!C32/POWER(1+D5,1-0.5)+'DCF_Base'!D32/POWER(1+D5,2-0.5)+'DCF_Base'!E32/POWER(1+D5,3-0.5)+'DCF_Base'!F32/POWER(1+D5,4-0.5)+'DCF_Base'!G32/POWER(1+D5,5-0.5)+'DCF_Base'!H32/POWER(1+D5,6-0.5)+'DCF_Base'!I32/POWER(1+D5,7-0.5)+'DCF_Base'!J32/POWER(1+D5,8-0.5)+'DCF_Base'!K32/POWER(1+D5,9-0.5)+'DCF_Base'!L32/POWER(1+D5,10-0.5))+(('DCF_Base'!L32*(1+A8))/(D5-A8))/POWER(1+D5,10)+'Assumptions'!$E$8-('Assumptions'!$E$7+'Assumptions'!$E$9+'Assumptions'!$E$10+'Assumptions'!$E$11+'Assumptions'!$E$12+'Assumptions'!$E$13+'Assumptions'!$E$14))/'Assumptions'!$E$6) | E8: =IF(E5<=A8,NA(),(('DCF_Base'!C32/POWER(1+E5,1-0.5)+'DCF_Base'!D32/POWER(1+E5,2-0.5)+'DCF_Base'!E32/POWER(1+E5,3-0.5)+'DCF_Base'!F32/POWER(1+E5,4-0.5)+'DCF_Base'!G32/POWER(1+E5,5-0.5)+'DCF_Base'!H32/POWER(1+E5,6-0.5)+'DCF_Base'!I32/POWER(1+E5,7-0.5)+'DCF_Base'!J32/POWER(1+E5,8-0.5)+'DCF_Base'!K32/POWER(1+E5,9-0.5)+'DCF_Base'!L32/POWER(1+E5,10-0.5))+(('DCF_Base'!L32*(1+A8))/(E5-A8))/POWER(1+E5,10)+'Assumptions'!$E$8-('Assumptions'!$E$7+'Assumptions'!$E$9+'Assumptions'!$E$10+'Assumptions'!$E$11+'Assumptions'!$E$12+'Assumptions'!$E$13+'Assumptions'!$E$14))/'Assumptions'!$E$6) | F8: =IF(F5<=A8,NA(),(('DCF_Base'!C32/POWER(1+F5,1-0.5)+'DCF_Base'!D32/POWER(1+F5,2-0.5)+'DCF_Base'!E32/POWER(1+F5,3-0.5)+'DCF_Base'!F32/POWER(1+F5,4-0.5)+'DCF_Base'!G32/POWER(1+F5,5-0.5)+'DCF_Base'!H32/POWER(1+F5,6-0.5)+'DCF_Base'!I32/POWER(1+F5,7-0.5)+'DCF_Base'!J32/POWER(1+F5,8-0.5)+'DCF_Base'!K32/POWER(1+F5,9-0.5)+'DCF_Base'!L32/POWER(1+F5,10-0.5))+(('DCF_Base'!L32*(1+A8))/(F5-A8))/POWER(1+F5,10)+'Assumptions'!$E$8-('Assumptions'!$E$7+'Assumptions'!$E$9+'Assumptions'!$E$10+'Assumptions'!$E$11+'Assumptions'!$E$12+'Assumptions'!$E$13+'Assumptions'!$E$14))/'Assumptions'!$E$6)
A9: ='Assumptions'!$E$18+0.005 | B9: =IF(B5<=A9,NA(),(('DCF_Base'!C32/POWER(1+B5,1-0.5)+'DCF_Base'!D32/POWER(1+B5,2-0.5)+'DCF_Base'!E32/POWER(1+B5,3-0.5)+'DCF_Base'!F32/POWER(1+B5,4-0.5)+'DCF_Base'!G32/POWER(1+B5,5-0.5)+'DCF_Base'!H32/POWER(1+B5,6-0.5)+'DCF_Base'!I32/POWER(1+B5,7-0.5)+'DCF_Base'!J32/POWER(1+B5,8-0.5)+'DCF_Base'!K32/POWER(1+B5,9-0.5)+'DCF_Base'!L32/POWER(1+B5,10-0.5))+(('DCF_Base'!L32*(1+A9))/(B5-A9))/POWER(1+B5,10)+'Assumptions'!$E$8-('Assumptions'!$E$7+'Assumptions'!$E$9+'Assumptions'!$E$10+'Assumptions'!$E$11+'Assumptions'!$E$12+'Assumptions'!$E$13+'Assumptions'!$E$14))/'Assumptions'!$E$6) | C9: =IF(C5<=A9,NA(),(('DCF_Base'!C32/POWER(1+C5,1-0.5)+'DCF_Base'!D32/POWER(1+C5,2-0.5)+'DCF_Base'!E32/POWER(1+C5,3-0.5)+'DCF_Base'!F32/POWER(1+C5,4-0.5)+'DCF_Base'!G32/POWER(1+C5,5-0.5)+'DCF_Base'!H32/POWER(1+C5,6-0.5)+'DCF_Base'!I32/POWER(1+C5,7-0.5)+'DCF_Base'!J32/POWER(1+C5,8-0.5)+'DCF_Base'!K32/POWER(1+C5,9-0.5)+'DCF_Base'!L32/POWER(1+C5,10-0.5))+(('DCF_Base'!L32*(1+A9))/(C5-A9))/POWER(1+C5,10)+'Assumptions'!$E$8-('Assumptions'!$E$7+'Assumptions'!$E$9+'Assumptions'!$E$10+'Assumptions'!$E$11+'Assumptions'!$E$12+'Assumptions'!$E$13+'Assumptions'!$E$14))/'Assumptions'!$E$6) | D9: =IF(D5<=A9,NA(),(('DCF_Base'!C32/POWER(1+D5,1-0.5)+'DCF_Base'!D32/POWER(1+D5,2-0.5)+'DCF_Base'!E32/POWER(1+D5,3-0.5)+'DCF_Base'!F32/POWER(1+D5,4-0.5)+'DCF_Base'!G32/POWER(1+D5,5-0.5)+'DCF_Base'!H32/POWER(1+D5,6-0.5)+'DCF_Base'!I32/POWER(1+D5,7-0.5)+'DCF_Base'!J32/POWER(1+D5,8-0.5)+'DCF_Base'!K32/POWER(1+D5,9-0.5)+'DCF_Base'!L32/POWER(1+D5,10-0.5))+(('DCF_Base'!L32*(1+A9))/(D5-A9))/POWER(1+D5,10)+'Assumptions'!$E$8-('Assumptions'!$E$7+'Assumptions'!$E$9+'Assumptions'!$E$10+'Assumptions'!$E$11+'Assumptions'!$E$12+'Assumptions'!$E$13+'Assumptions'!$E$14))/'Assumptions'!$E$6) | E9: =IF(E5<=A9,NA(),(('DCF_Base'!C32/POWER(1+E5,1-0.5)+'DCF_Base'!D32/POWER(1+E5,2-0.5)+'DCF_Base'!E32/POWER(1+E5,3-0.5)+'DCF_Base'!F32/POWER(1+E5,4-0.5)+'DCF_Base'!G32/POWER(1+E5,5-0.5)+'DCF_Base'!H32/POWER(1+E5,6-0.5)+'DCF_Base'!I32/POWER(1+E5,7-0.5)+'DCF_Base'!J32/POWER(1+E5,8-0.5)+'DCF_Base'!K32/POWER(1+E5,9-0.5)+'DCF_Base'!L32/POWER(1+E5,10-0.5))+(('DCF_Base'!L32*(1+A9))/(E5-A9))/POWER(1+E5,10)+'Assumptions'!$E$8-('Assumptions'!$E$7+'Assumptions'!$E$9+'Assumptions'!$E$10+'Assumptions'!$E$11+'Assumptions'!$E$12+'Assumptions'!$E$13+'Assumptions'!$E$14))/'Assumptions'!$E$6) | F9: =IF(F5<=A9,NA(),(('DCF_Base'!C32/POWER(1+F5,1-0.5)+'DCF_Base'!D32/POWER(1+F5,2-0.5)+'DCF_Base'!E32/POWER(1+F5,3-0.5)+'DCF_Base'!F32/POWER(1+F5,4-0.5)+'DCF_Base'!G32/POWER(1+F5,5-0.5)+'DCF_Base'!H32/POWER(1+F5,6-0.5)+'DCF_Base'!I32/POWER(1+F5,7-0.5)+'DCF_Base'!J32/POWER(1+F5,8-0.5)+'DCF_Base'!K32/POWER(1+F5,9-0.5)+'DCF_Base'!L32/POWER(1+F5,10-0.5))+(('DCF_Base'!L32*(1+A9))/(F5-A9))/POWER(1+F5,10)+'Assumptions'!$E$8-('Assumptions'!$E$7+'Assumptions'!$E$9+'Assumptions'!$E$10+'Assumptions'!$E$11+'Assumptions'!$E$12+'Assumptions'!$E$13+'Assumptions'!$E$14))/'Assumptions'!$E$6)
A10: ='Assumptions'!$E$18+0.01 | B10: =IF(B5<=A10,NA(),(('DCF_Base'!C32/POWER(1+B5,1-0.5)+'DCF_Base'!D32/POWER(1+B5,2-0.5)+'DCF_Base'!E32/POWER(1+B5,3-0.5)+'DCF_Base'!F32/POWER(1+B5,4-0.5)+'DCF_Base'!G32/POWER(1+B5,5-0.5)+'DCF_Base'!H32/POWER(1+B5,6-0.5)+'DCF_Base'!I32/POWER(1+B5,7-0.5)+'DCF_Base'!J32/POWER(1+B5,8-0.5)+'DCF_Base'!K32/POWER(1+B5,9-0.5)+'DCF_Base'!L32/POWER(1+B5,10-0.5))+(('DCF_Base'!L32*(1+A10))/(B5-A10))/POWER(1+B5,10)+'Assumptions'!$E$8-('Assumptions'!$E$7+'Assumptions'!$E$9+'Assumptions'!$E$10+'Assumptions'!$E$11+'Assumptions'!$E$12+'Assumptions'!$E$13+'Assumptions'!$E$14))/'Assumptions'!$E$6) | C10: =IF(C5<=A10,NA(),(('DCF_Base'!C32/POWER(1+C5,1-0.5)+'DCF_Base'!D32/POWER(1+C5,2-0.5)+'DCF_Base'!E32/POWER(1+C5,3-0.5)+'DCF_Base'!F32/POWER(1+C5,4-0.5)+'DCF_Base'!G32/POWER(1+C5,5-0.5)+'DCF_Base'!H32/POWER(1+C5,6-0.5)+'DCF_Base'!I32/POWER(1+C5,7-0.5)+'DCF_Base'!J32/POWER(1+C5,8-0.5)+'DCF_Base'!K32/POWER(1+C5,9-0.5)+'DCF_Base'!L32/POWER(1+C5,10-0.5))+(('DCF_Base'!L32*(1+A10))/(C5-A10))/POWER(1+C5,10)+'Assumptions'!$E$8-('Assumptions'!$E$7+'Assumptions'!$E$9+'Assumptions'!$E$10+'Assumptions'!$E$11+'Assumptions'!$E$12+'Assumptions'!$E$13+'Assumptions'!$E$14))/'Assumptions'!$E$6) | D10: =IF(D5<=A10,NA(),(('DCF_Base'!C32/POWER(1+D5,1-0.5)+'DCF_Base'!D32/POWER(1+D5,2-0.5)+'DCF_Base'!E32/POWER(1+D5,3-0.5)+'DCF_Base'!F32/POWER(1+D5,4-0.5)+'DCF_Base'!G32/POWER(1+D5,5-0.5)+'DCF_Base'!H32/POWER(1+D5,6-0.5)+'DCF_Base'!I32/POWER(1+D5,7-0.5)+'DCF_Base'!J32/POWER(1+D5,8-0.5)+'DCF_Base'!K32/POWER(1+D5,9-0.5)+'DCF_Base'!L32/POWER(1+D5,10-0.5))+(('DCF_Base'!L32*(1+A10))/(D5-A10))/POWER(1+D5,10)+'Assumptions'!$E$8-('Assumptions'!$E$7+'Assumptions'!$E$9+'Assumptions'!$E$10+'Assumptions'!$E$11+'Assumptions'!$E$12+'Assumptions'!$E$13+'Assumptions'!$E$14))/'Assumptions'!$E$6) | E10: =IF(E5<=A10,NA(),(('DCF_Base'!C32/POWER(1+E5,1-0.5)+'DCF_Base'!D32/POWER(1+E5,2-0.5)+'DCF_Base'!E32/POWER(1+E5,3-0.5)+'DCF_Base'!F32/POWER(1+E5,4-0.5)+'DCF_Base'!G32/POWER(1+E5,5-0.5)+'DCF_Base'!H32/POWER(1+E5,6-0.5)+'DCF_Base'!I32/POWER(1+E5,7-0.5)+'DCF_Base'!J32/POWER(1+E5,8-0.5)+'DCF_Base'!K32/POWER(1+E5,9-0.5)+'DCF_Base'!L32/POWER(1+E5,10-0.5))+(('DCF_Base'!L32*(1+A10))/(E5-A10))/POWER(1+E5,10)+'Assumptions'!$E$8-('Assumptions'!$E$7+'Assumptions'!$E$9+'Assumptions'!$E$10+'Assumptions'!$E$11+'Assumptions'!$E$12+'Assumptions'!$E$13+'Assumptions'!$E$14))/'Assumptions'!$E$6) | F10: =IF(F5<=A10,NA(),(('DCF_Base'!C32/POWER(1+F5,1-0.5)+'DCF_Base'!D32/POWER(1+F5,2-0.5)+'DCF_Base'!E32/POWER(1+F5,3-0.5)+'DCF_Base'!F32/POWER(1+F5,4-0.5)+'DCF_Base'!G32/POWER(1+F5,5-0.5)+'DCF_Base'!H32/POWER(1+F5,6-0.5)+'DCF_Base'!I32/POWER(1+F5,7-0.5)+'DCF_Base'!J32/POWER(1+F5,8-0.5)+'DCF_Base'!K32/POWER(1+F5,9-0.5)+'DCF_Base'!L32/POWER(1+F5,10-0.5))+(('DCF_Base'!L32*(1+A10))/(F5-A10))/POWER(1+F5,10)+'Assumptions'!$E$8-('Assumptions'!$E$7+'Assumptions'!$E$9+'Assumptions'!$E$10+'Assumptions'!$E$11+'Assumptions'!$E$12+'Assumptions'!$E$13+'Assumptions'!$E$14))/'Assumptions'!$E$6)
A14: WACC vs Exit Multiple: Intrinsic Value / Share
A15: Exit / WACC | B15: ='Assumptions'!$E$31+-0.02 | C15: ='Assumptions'!$E$31+-0.01 | D15: ='Assumptions'!$E$31+0.0 | E15: ='Assumptions'!$E$31+0.01 | F15: ='Assumptions'!$E$31+0.02
